5:return {{["x"] = 1, ["param2"] = 16, ["y"] = 7, ["param1"] = 30, ["z"] = 3, ["name"] = "stones:s_222"}, {["x"] = 1, ["param2"] = 2, ["y"] = 7, ["param1"] = 46, ["z"] = 4, ["name"] = "stones:diagsteps_13"}, {["x"] = 1, ["param2"] = 18, ["y"] = 7, ["param1"] = 62, ["z"] = 5, ["name"] = "stones:s_52r"}, {["x"] = 1, ["param2"] = 16, ["y"] = 7, ["param1"] = 78, ["z"] = 6, ["name"] = "stones:s_52l"}, {["x"] = 1, ["param2"] = 1, ["y"] = 7, ["param1"] = 94, ["z"] = 7, ["name"] = "stones:panel"}, {["x"] = 1, ["param2"] = 18, ["y"] = 7, ["param1"] = 110, ["z"] = 8, ["name"] = "stones:s_52r"}, {["x"] = 1, ["param2"] = 16, ["y"] = 14, ["param1"] = 14, ["z"] = 7, ["name"] = "stones:s_52r"}, {["x"] = 1, ["param2"] = 20, ["y"] = 14, ["param1"] = 14, ["z"] = 8, ["name"] = "stones:c8r7"}, {["x"] = 1, ["param2"] = 5, ["y"] = 14, ["param1"] = 14, ["z"] = 9, ["name"] = "stones:s_52"}, {["x"] = 2, ["param2"] = 1, ["y"] = 7, ["param1"] = 30, ["z"] = 2, ["name"] = "stones:diagstep"}, {["x"] = 2, ["param2"] = 9, ["y"] = 7, ["param1"] = 46, ["z"] = 3, ["name"] = "stones:brushrock_527r"}, {["x"] = 2, ["y"] = 7, ["param1"] = 62, ["z"] = 4, ["name"] = "stones:brushrock_2"}, {["x"] = 2, ["param2"] = 18, ["y"] = 7, ["param1"] = 78, ["z"] = 5, ["name"] = "stones:brushrock_527r"}, {["x"] = 2, ["param2"] = 16, ["y"] = 7, ["param1"] = 94, ["z"] = 6, ["name"] = "stones:brushrock_527l"}, {["x"] = 2, ["param2"] = 3, ["y"] = 7, ["param1"] = 110, ["z"] = 7, ["name"] = "stones:brushrock_0"}, {["x"] = 2, ["param2"] = 18, ["y"] = 7, ["param1"] = 126, ["z"] = 8, ["name"] = "stones:brushrock_527r"}, {["x"] = 2, ["param2"] = 5, ["y"] = 7, ["param1"] = 142, ["z"] = 9, ["name"] = "stones:s_222"}, {["x"] = 2, ["param2"] = 23, ["y"] = 14, ["param1"] = 14, ["z"] = 6, ["name"] = "stones:c8ld"}, {["x"] = 2, ["param2"] = 23, ["y"] = 14, ["param1"] = 14, ["z"] = 7, ["name"] = "stones:diagsteps_52rh"}, {["x"] = 2, ["y"] = 14, ["param1"] = 14, ["z"] = 8, ["name"] = "stones:diagsteps_52z"}, {["x"] = 2, ["y"] = 14, ["param1"] = 30, ["z"] = 9, ["name"] = "stones:c8rf"}, {["x"] = 3, ["param2"] = 1, ["y"] = 7, ["param1"] = 46, ["z"] = 2, ["name"] = "stones:roch"}, {["x"] = 3, ["param2"] = 2, ["y"] = 7, ["param1"] = 62, ["z"] = 3, ["name"] = "stones:brushrock_0"}, {["x"] = 3, ["param2"] = 2, ["y"] = 7, ["param1"] = 78, ["z"] = 4, ["name"] = "stones:brushrock_0"}, {["x"] = 3, ["param2"] = 1, ["y"] = 7, ["param1"] = 94, ["z"] = 5, ["name"] = "stones:brush"}, {["x"] = 3, ["param2"] = 1, ["y"] = 7, ["param1"] = 110, ["z"] = 6, ["name"] = "stones:brushrock_8"}, {["x"] = 3, ["param2"] = 1, ["y"] = 7, ["param1"] = 126, ["z"] = 7, ["name"] = "stones:brushrock_0"}, {["x"] = 3, ["param2"] = 2, ["y"] = 7, ["param1"] = 142, ["z"] = 8, ["name"] = "stones:brushrock_8"}, {["x"] = 3, ["param2"] = 5, ["y"] = 7, ["param1"] = 158, ["z"] = 9, ["name"] = "stones:brushrock_527l"}, {["x"] = 3, ["param2"] = 2, ["y"] = 7, ["param1"] = 142, ["z"] = 10, ["name"] = "stones:diagstep"}, {["x"] = 3, ["param2"] = 19, ["y"] = 8, ["param1"] = 62, ["z"] = 4, ["name"] = "stones:s_52ul"}, {["x"] = 3, ["param2"] = 1, ["y"] = 8, ["param1"] = 109, ["z"] = 7, ["name"] = "stones:diaq"}, {["x"] = 3, ["param2"] = 19, ["y"] = 9, ["param1"] = 46, ["z"] = 4, ["name"] = "stones:s_52l"}, {["x"] = 3, ["param2"] = 1, ["y"] = 9, ["param1"] = 93, ["z"] = 7, ["name"] = "stones:diaq"}, {["x"] = 3, ["param2"] = 9, ["y"] = 10, ["param1"] = 77, ["z"] = 7, ["name"] = "stones:s_2"}, {["x"] = 3, ["param2"] = 22, ["y"] = 10, ["param1"] = 92, ["z"] = 8, ["name"] = "stones:s_52u"}, {["x"] = 3, ["param2"] = 20, ["y"] = 10, ["param1"] = 109, ["z"] = 9, ["name"] = "stones:roch"}, {["x"] = 3, ["param2"] = 23, ["y"] = 10, ["param1"] = 94, ["z"] = 10, ["name"] = "stones:diagstep"}, {["x"] = 3, ["param2"] = 1, ["y"] = 11, ["param1"] = 61, ["z"] = 7, ["name"] = "stones:diaq"}, {["x"] = 3, ["param2"] = 9, ["y"] = 11, ["param1"] = 93, ["z"] = 9, ["name"] = "stones:panel"}, {["x"] = 3, ["param2"] = 5, ["y"] = 11, ["param1"] = 78, ["z"] = 10, ["name"] = "stones:s_22"}, {["x"] = 3, ["param2"] = 1, ["y"] = 12, ["param1"] = 45, ["z"] = 7, ["name"] = "stones:diaq"}, {["x"] = 3, ["param2"] = 9, ["y"] = 12, ["param1"] = 77, ["z"] = 9, ["name"] = "stones:panel"}, {["x"] = 3, ["param2"] = 5, ["y"] = 12, ["param1"] = 62, ["z"] = 10, ["name"] = "stones:s_22"}, {["x"] = 3, ["param2"] = 1, ["y"] = 13, ["param1"] = 29, ["z"] = 7, ["name"] = "stones:diaq"}, {["x"] = 3, ["param2"] = 20, ["y"] = 13, ["param1"] = 45, ["z"] = 8, ["name"] = "stones:diagstep"}, {["x"] = 3, ["param2"] = 8, ["y"] = 13, ["param1"] = 61, ["z"] = 9, ["name"] = "stones:stair_2"}, {["x"] = 3, ["param2"] = 5, ["y"] = 13, ["param1"] = 46, ["z"] = 10, ["name"] = "stones:s_52"}, {["x"] = 3, ["param2"] = 11, ["y"] = 14, ["param1"] = 14, ["z"] = 6, ["name"] = "stones:s_52"}, {["x"] = 3, ["param2"] = 2, ["y"] = 14, ["param1"] = 14, ["z"] = 7, ["name"] = "stones:c8l1"}, {["x"] = 3, ["param2"] = 14, ["y"] = 14, ["param1"] = 30, ["z"] = 8, ["name"] = "stones:s_52ul"}, {["x"] = 3, ["y"] = 14, ["param1"] = 46, ["z"] = 9, ["name"] = "stones:c8re"}, {["x"] = 3, ["param2"] = 5, ["y"] = 14, ["param1"] = 30, ["z"] = 10, ["name"] = "stones:s_52"}, {["x"] = 4, ["param2"] = 11, ["y"] = 7, ["param1"] = 62, ["z"] = 2, ["name"] = "stones:s_52ul"}, {["x"] = 4, ["param2"] = 11, ["y"] = 7, ["param1"] = 78, ["z"] = 3, ["name"] = "stones:brushrock_527l"}, {["x"] = 4, ["param2"] = 1, ["y"] = 7, ["param1"] = 94, ["z"] = 4, ["name"] = "stones:brush"}, {["x"] = 4, ["param2"] = 1, ["y"] = 7, ["param1"] = 110, ["z"] = 5, ["name"] = "stones:brush"}, {["x"] = 4, ["param2"] = 2, ["y"] = 7, ["param1"] = 126, ["z"] = 6, ["name"] = "stones:brushrock_5"}, {["x"] = 4, ["y"] = 7, ["param1"] = 142, ["z"] = 7, ["name"] = "stones:rock"}, {["x"] = 4, ["param2"] = 2, ["y"] = 7, ["param1"] = 158, ["z"] = 8, ["name"] = "stones:brushrock_0"}, {["x"] = 4, ["param2"] = 2, ["y"] = 7, ["param1"] = 174, ["z"] = 9, ["name"] = "stones:brushrock_5"}, {["x"] = 4, ["y"] = 7, ["param1"] = 158, ["z"] = 10, ["name"] = "stones:rock"}, {["x"] = 4, ["param2"] = 11, ["y"] = 8, ["param1"] = 126, ["z"] = 7, ["name"] = "stones:s_52u"}, {["x"] = 4, ["param2"] = 3, ["y"] = 8, ["param1"] = 141, ["z"] = 10, ["name"] = "stones:s_21"}, {["x"] = 4, ["param2"] = 5, ["y"] = 8, ["param1"] = 126, ["z"] = 11, ["name"] = "stones:s_52"}, {["x"] = 4, ["param2"] = 18, ["y"] = 9, ["param1"] = 62, ["z"] = 4, ["name"] = "stones:arsh"}, {["x"] = 4, ["param2"] = 11, ["y"] = 9, ["param1"] = 110, ["z"] = 7, ["name"] = "stones:s_52u"}, {["x"] = 4, ["param2"] = 3, ["y"] = 9, ["param1"] = 125, ["z"] = 10, ["name"] = "stones:s_21"}, {["x"] = 4, ["param2"] = 5, ["y"] = 9, ["param1"] = 110, ["z"] = 11, ["name"] = "stones:s_52"}, {["x"] = 4, ["param2"] = 19, ["y"] = 10, ["param1"] = 46, ["z"] = 4, ["name"] = "stones:s_52ul"}, {["x"] = 4, ["param2"] = 11, ["y"] = 10, ["param1"] = 94, ["z"] = 7, ["name"] = "stones:s_52u"}, {["x"] = 4, ["param2"] = 22, ["y"] = 10, ["param1"] = 109, ["z"] = 8, ["name"] = "stones:vsect_2u"}, {["x"] = 4, ["param2"] = 20, ["y"] = 10, ["param1"] = 124, ["z"] = 9, ["name"] = "stones:roch"}, {["x"] = 4, ["param2"] = 20, ["y"] = 10, ["param1"] = 109, ["z"] = 10, ["name"] = "stones:s_21u"}, {["x"] = 4, ["param2"] = 5, ["y"] = 10, ["param1"] = 94, ["z"] = 11, ["name"] = "stones:s_52"}, {["x"] = 4, ["param2"] = 1, ["y"] = 11, ["param1"] = 30, ["z"] = 4, ["name"] = "stones:s_22r"}, {["x"] = 4, ["param2"] = 11, ["y"] = 11, ["param1"] = 78, ["z"] = 7, ["name"] = "stones:s_52u"}, {["x"] = 4, ["param2"] = 5, ["y"] = 11, ["param1"] = 94, ["z"] = 10, ["name"] = "stones:s_52u"}, {["x"] = 4, ["param2"] = 11, ["y"] = 12, ["param1"] = 62, ["z"] = 7, ["name"] = "stones:s_52u"}, {["x"] = 4, ["param2"] = 5, ["y"] = 12, ["param1"] = 78, ["z"] = 10, ["name"] = "stones:s_52u"}, {["x"] = 4, ["param2"] = 11, ["y"] = 13, ["param1"] = 46, ["z"] = 7, ["name"] = "stones:s_52u"}, {["x"] = 4, ["y"] = 13, ["param1"] = 62, ["z"] = 8, ["name"] = "stones:diagsteps_52z"}, {["x"] = 4, ["param2"] = 3, ["y"] = 13, ["param1"] = 78, ["z"] = 9, ["name"] = "stones:diagsteps_52lh"}, {["x"] = 4, ["param2"] = 3, ["y"] = 13, ["param1"] = 62, ["z"] = 10, ["name"] = "stones:c8rd"}, {["x"] = 4, ["param2"] = 2, ["y"] = 14, ["param1"] = 30, ["z"] = 7, ["name"] = "stones:c8l8"}, {["x"] = 4, ["param2"] = 3, ["y"] = 14, ["param1"] = 46, ["z"] = 10, ["name"] = "stones:dias52d"}, {["x"] = 5, ["param2"] = 11, ["y"] = 7, ["param1"] = 46, ["z"] = 2, ["name"] = "stones:s_52l"}, {["x"] = 5, ["y"] = 7, ["param1"] = 62, ["z"] = 3, ["name"] = "stones:diagsteps_52lh"}, {["x"] = 5, ["param2"] = 2, ["y"] = 7, ["param1"] = 78, ["z"] = 4, ["name"] = "stones:brushrock_1"}, {["x"] = 5, ["param2"] = 1, ["y"] = 7, ["param1"] = 94, ["z"] = 5, ["name"] = "stones:brush"}, {["x"] = 5, ["param2"] = 1, ["y"] = 7, ["param1"] = 110, ["z"] = 6, ["name"] = "stones:brush"}, {["x"] = 5, ["y"] = 7, ["param1"] = 126, ["z"] = 7, ["name"] = "stones:brushrock_2"}, {["x"] = 5, ["param2"] = 3, ["y"] = 7, ["param1"] = 142, ["z"] = 8, ["name"] = "stones:brushrock_8"}, {["x"] = 5, ["param2"] = 3, ["y"] = 7, ["param1"] = 158, ["z"] = 9, ["name"] = "stones:brushrock_5"}, {["x"] = 5, ["y"] = 7, ["param1"] = 142, ["z"] = 10, ["name"] = "stones:rock"}, {["x"] = 5, ["param2"] = 16, ["y"] = 8, ["param1"] = 142, ["z"] = 9, ["name"] = "stones:s_52l"}, {["x"] = 5, ["param2"] = 10, ["y"] = 8, ["param1"] = 125, ["z"] = 10, ["name"] = "stones:stair_5"}, {["x"] = 5, ["param2"] = 5, ["y"] = 8, ["param1"] = 109, ["z"] = 11, ["name"] = "stones:s_52u"}, {["x"] = 5, ["param2"] = 2, ["y"] = 9, ["param1"] = 46, ["z"] = 4, ["name"] = "stones:arcshol"}, {["x"] = 5, ["param2"] = 8, ["y"] = 9, ["param1"] = 109, ["z"] = 10, ["name"] = "stones:roch"}, {["x"] = 5, ["param2"] = 6, ["y"] = 9, ["param1"] = 93, ["z"] = 11, ["name"] = "stones:stair_5"}, {["x"] = 5, ["param2"] = 18, ["y"] = 9, ["param1"] = 78, ["z"] = 12, ["name"] = "stones:s_52l"}, {["x"] = 5, ["param2"] = 9, ["y"] = 9, ["param1"] = 110, ["z"] = 19, ["name"] = "stones:s_52"}, {["x"] = 5, ["param2"] = 3, ["y"] = 9, ["param1"] = 94, ["z"] = 20, ["name"] = "stones:brushrock_2"}, {["x"] = 5, ["param2"] = 1, ["y"] = 9, ["param1"] = 78, ["z"] = 21, ["name"] = "stones:brushrock_2"}, {["x"] = 5, ["param2"] = 5, ["y"] = 10, ["param1"] = 30, ["z"] = 4, ["name"] = "stones:s_52u"}, {["x"] = 5, ["y"] = 10, ["param1"] = 78, ["z"] = 7, ["name"] = "stones:arschol"}, {["x"] = 5, ["y"] = 10, ["param1"] = 94, ["z"] = 8, ["name"] = "stones:arschir"}, {["x"] = 5, ["param2"] = 12, ["y"] = 10, ["param1"] = 109, ["z"] = 9, ["name"] = "stones:s_52l"}, {["x"] = 5, ["param2"] = 8, ["y"] = 10, ["param1"] = 93, ["z"] = 10, ["name"] = "stones:stair_5"}, {["x"] = 5, ["param2"] = 4, ["y"] = 10, ["param1"] = 78, ["z"] = 11, ["name"] = "stones:roch"}, {["x"] = 5, ["param2"] = 2, ["y"] = 11, ["param1"] = 14, ["z"] = 4, ["name"] = "stones:s_52hul"}, {["x"] = 5, ["param2"] = 9, ["y"] = 11, ["param1"] = 62, ["z"] = 7, ["name"] = "stones:brushrock_52ur"}, {["x"] = 5, ["param2"] = 5, ["y"] = 11, ["param1"] = 77, ["z"] = 8, ["name"] = "stones:vsect_2"}, {["x"] = 5, ["param2"] = 20, ["y"] = 11, ["param1"] = 77, ["z"] = 10, ["name"] = "stones:stair_5"}, {["x"] = 5, ["param2"] = 5, ["y"] = 11, ["param1"] = 62, ["z"] = 11, ["name"] = "stones:s_22"}, {["x"] = 5, ["param2"] = 11, ["y"] = 12, ["param1"] = 46, ["z"] = 7, ["name"] = "stones:s_52"}, {["x"] = 5, ["param2"] = 2, ["y"] = 12, ["param1"] = 61, ["z"] = 8, ["name"] = "stones:arch"}, {["x"] = 5, ["param2"] = 2, ["y"] = 12, ["param1"] = 77, ["z"] = 9, ["name"] = "stones:arch"}, {["x"] = 5, ["param2"] = 3, ["y"] = 12, ["param1"] = 61, ["z"] = 10, ["name"] = "stones:c8rc"}, {["x"] = 5, ["param2"] = 5, ["y"] = 12, ["param1"] = 46, ["z"] = 11, ["name"] = "stones:s_52"}, {["x"] = 5, ["param2"] = 11, ["y"] = 13, ["param1"] = 30, ["z"] = 7, ["name"] = "stones:s_52"}, {["x"] = 5, ["param2"] = 2, ["y"] = 13, ["param1"] = 45, ["z"] = 8, ["name"] = "stones:c8l7"}, {["x"] = 5, ["param2"] = 14, ["y"] = 13, ["param1"] = 62, ["z"] = 9, ["name"] = "stones:s_52l"}, {["x"] = 5, ["param2"] = 11, ["y"] = 13, ["param1"] = 46, ["z"] = 10, ["name"] = "stones:s_52r"}, {["x"] = 5, ["param2"] = 5, ["y"] = 13, ["param1"] = 30, ["z"] = 11, ["name"] = "stones:s_52r"}, {["x"] = 5, ["y"] = 14, ["param1"] = 14, ["z"] = 7, ["name"] = "stones:vsedr"}, {["x"] = 5, ["param2"] = 5, ["y"] = 14, ["param1"] = 30, ["z"] = 8, ["name"] = "stones:s_52pl"}, {["x"] = 6, ["y"] = 7, ["param1"] = 46, ["z"] = 3, ["name"] = "stones:diagstep"}, {["x"] = 6, ["y"] = 7, ["param1"] = 62, ["z"] = 4, ["name"] = "stones:diagsteps"}, {["x"] = 6, ["param2"] = 2, ["y"] = 7, ["param1"] = 77, ["z"] = 5, ["name"] = "stones:brushrock_3"}, {["x"] = 6, ["param2"] = 2, ["y"] = 7, ["param1"] = 93, ["z"] = 6, ["name"] = "stones:brush"}, {["x"] = 6, ["y"] = 7, ["param1"] = 109, ["z"] = 7, ["name"] = "stones:brush"}, {["x"] = 6, ["param2"] = 1, ["y"] = 7, ["param1"] = 125, ["z"] = 8, ["name"] = "stones:brushrock_1"}, {["x"] = 6, ["param2"] = 11, ["y"] = 8, ["param1"] = 46, ["z"] = 4, ["name"] = "stones:s_2"}, {["x"] = 6, ["param2"] = 18, ["y"] = 8, ["param1"] = 62, ["z"] = 5, ["name"] = "stones:s_52u"}, {["x"] = 6, ["param2"] = 16, ["y"] = 8, ["param1"] = 110, ["z"] = 8, ["name"] = "stones:s_222"}, {["x"] = 6, ["param2"] = 16, ["y"] = 8, ["param1"] = 125, ["z"] = 9, ["name"] = "stones:brushrock_527l"}, {["x"] = 6, ["param2"] = 3, ["y"] = 8, ["param1"] = 108, ["z"] = 10, ["name"] = "stones:brushrock_0"}, {["x"] = 6, ["param2"] = 3, ["y"] = 8, ["param1"] = 92, ["z"] = 11, ["name"] = "stones:brushrock_0"}, {["x"] = 6, ["param2"] = 18, ["y"] = 8, ["param1"] = 77, ["z"] = 12, ["name"] = "stones:brushrock_52ur"}, {["x"] = 6, ["param2"] = 18, ["y"] = 8, ["param1"] = 61, ["z"] = 13, ["name"] = "stones:s_52"}, {["x"] = 6, ["param2"] = 18, ["y"] = 8, ["param1"] = 62, ["z"] = 14, ["name"] = "stones:s_52"}, {["x"] = 6, ["param2"] = 11, ["y"] = 9, ["param1"] = 30, ["z"] = 4, ["name"] = "stones:s_2"}, {["x"] = 6, ["param2"] = 18, ["y"] = 9, ["param1"] = 46, ["z"] = 5, ["name"] = "stones:s_52u"}, {["x"] = 6, ["param2"] = 12, ["y"] = 9, ["param1"] = 62, ["z"] = 12, ["name"] = "stones:s_52l"}, {["x"] = 6, ["param2"] = 12, ["y"] = 9, ["param1"] = 61, ["z"] = 13, ["name"] = "stones:sku2_l"}, {["x"] = 6, ["param2"] = 18, ["y"] = 9, ["param1"] = 78, ["z"] = 14, ["name"] = "stones:s_52"}, {["x"] = 6, ["param2"] = 9, ["y"] = 9, ["param1"] = 94, ["z"] = 19, ["name"] = "stones:brushrock_52ur"}, {["x"] = 6, ["param2"] = 3, ["y"] = 9, ["param1"] = 78, ["z"] = 20, ["name"] = "stones:brush"}, {["x"] = 6, ["param2"] = 7, ["y"] = 9, ["param1"] = 62, ["z"] = 21, ["name"] = "stones:brushrock_52ur"}, {["x"] = 6, ["param2"] = 11, ["y"] = 10, ["param1"] = 14, ["z"] = 4, ["name"] = "stones:s_2"}, {["x"] = 6, ["param2"] = 18, ["y"] = 10, ["param1"] = 30, ["z"] = 5, ["name"] = "stones:s_52u"}, {["x"] = 6, ["param2"] = 3, ["y"] = 10, ["param1"] = 46, ["z"] = 6, ["name"] = "stones:arschor"}, {["x"] = 6, ["param2"] = 1, ["y"] = 10, ["param1"] = 61, ["z"] = 7, ["name"] = "stones:arco"}, {["x"] = 6, ["param2"] = 2, ["y"] = 10, ["param1"] = 77, ["z"] = 8, ["name"] = "stones:arcshol"}, {["x"] = 6, ["y"] = 10, ["param1"] = 77, ["z"] = 10, ["name"] = "stones:arcshil"}, {["x"] = 6, ["y"] = 10, ["param1"] = 62, ["z"] = 11, ["name"] = "stones:arschor"}, {["x"] = 6, ["param2"] = 12, ["y"] = 11, ["param1"] = 14, ["z"] = 4, ["name"] = "stones:s_2"}, {["x"] = 6, ["param2"] = 18, ["y"] = 11, ["param1"] = 14, ["z"] = 5, ["name"] = "stones:s_52u"}, {["x"] = 6, ["param2"] = 16, ["y"] = 11, ["param1"] = 30, ["z"] = 6, ["name"] = "stones:brushrock_52ul"}, {["x"] = 6, ["param2"] = 3, ["y"] = 11, ["param1"] = 46, ["z"] = 7, ["name"] = "stones:brushrock_8"}, {["x"] = 6, ["param2"] = 2, ["y"] = 11, ["param1"] = 61, ["z"] = 8, ["name"] = "stones:brushrock_4"}, {["x"] = 6, ["param2"] = 22, ["y"] = 11, ["param1"] = 77, ["z"] = 9, ["name"] = "stones:diagsteps_52rh"}, {["x"] = 6, ["param2"] = 20, ["y"] = 11, ["param1"] = 61, ["z"] = 10, ["name"] = "stones:diagsteps_52rh"}, {["x"] = 6, ["param2"] = 5, ["y"] = 11, ["param1"] = 62, ["z"] = 11, ["name"] = "stones:s_52u"}, {["x"] = 6, ["param2"] = 4, ["y"] = 12, ["param1"] = 31, ["z"] = 7, ["name"] = "stones:shrub"}, {["x"] = 6, ["param2"] = 2, ["y"] = 12, ["param1"] = 46, ["z"] = 8, ["name"] = "stones:c8l6"}, {["x"] = 6, ["param2"] = 3, ["y"] = 12, ["param1"] = 62, ["z"] = 9, ["name"] = "stones:diagsteps_52lh"}, {["x"] = 6, ["param2"] = 14, ["y"] = 12, ["param1"] = 46, ["z"] = 10, ["name"] = "stones:s_52ul"}, {["x"] = 6, ["param2"] = 3, ["y"] = 12, ["param1"] = 46, ["z"] = 11, ["name"] = "stones:c8rb"}, {["x"] = 6, ["param2"] = 5, ["y"] = 13, ["param1"] = 30, ["z"] = 8, ["name"] = "stones:sku2_r"}, {["x"] = 6, ["param2"] = 3, ["y"] = 13, ["param1"] = 30, ["z"] = 11, ["name"] = "stones:dias52d"}, {["x"] = 7, ["param2"] = 12, ["y"] = 7, ["param1"] = 46, ["z"] = 4, ["name"] = "stones:s_52r"}, {["x"] = 7, ["y"] = 7, ["param1"] = 62, ["z"] = 5, ["name"] = "stones:diagsteps_13"}, {["x"] = 7, ["param2"] = 12, ["y"] = 7, ["param1"] = 78, ["z"] = 6, ["name"] = "stones:brushrock_527r"}, {["x"] = 7, ["param2"] = 2, ["y"] = 7, ["param1"] = 94, ["z"] = 7, ["name"] = "stones:brushrock_2"}, {["x"] = 7, ["y"] = 7, ["param1"] = 110, ["z"] = 8, ["name"] = "stones:rock"}, {["x"] = 7, ["param2"] = 12, ["y"] = 8, ["param1"] = 46, ["z"] = 5, ["name"] = "stones:s_52"}, {["x"] = 7, ["param2"] = 8, ["y"] = 8, ["param1"] = 93, ["z"] = 8, ["name"] = "runes:hui"}, {["x"] = 7, ["param2"] = 2, ["y"] = 8, ["param1"] = 109, ["z"] = 9, ["name"] = "stones:brushrock_8"}, {["x"] = 7, ["param2"] = 3, ["y"] = 8, ["param1"] = 93, ["z"] = 10, ["name"] = "stones:brushrock_5"}, {["x"] = 7, ["param2"] = 1, ["y"] = 8, ["param1"] = 77, ["z"] = 11, ["name"] = "stones:brushrock_0"}, {["x"] = 7, ["param2"] = 2, ["y"] = 8, ["param1"] = 61, ["z"] = 12, ["name"] = "stones:brushrock_8"}, {["x"] = 7, ["y"] = 8, ["param1"] = 61, ["z"] = 13, ["name"] = "stones:brushrock_2"}, {["x"] = 7, ["y"] = 8, ["param1"] = 77, ["z"] = 14, ["name"] = "stones:brushrock_3"}, {["x"] = 7, ["param2"] = 18, ["y"] = 8, ["param1"] = 62, ["z"] = 15, ["name"] = "stones:s_52"}, {["x"] = 7, ["param2"] = 12, ["y"] = 9, ["param1"] = 30, ["z"] = 5, ["name"] = "stones:s_52"}, {["x"] = 7, ["y"] = 9, ["param1"] = 77, ["z"] = 8, ["name"] = "stones:rock"}, {["x"] = 7, ["param2"] = 5, ["y"] = 9, ["param1"] = 92, ["z"] = 9, ["name"] = "stones:s_22"}, {["x"] = 7, ["param2"] = 12, ["y"] = 9, ["param1"] = 93, ["z"] = 14, ["name"] = "stones:s_52"}, {["x"] = 7, ["param2"] = 12, ["y"] = 9, ["param1"] = 78, ["z"] = 15, ["name"] = "stones:sku2_l"}, {["x"] = 7, ["param2"] = 18, ["y"] = 9, ["param1"] = 62, ["z"] = 16, ["name"] = "stones:s_52l"}, {["x"] = 7, ["param2"] = 9, ["y"] = 9, ["param1"] = 62, ["z"] = 18, ["name"] = "stones:s_52"}, {["x"] = 7, ["param2"] = 3, ["y"] = 9, ["param1"] = 78, ["z"] = 19, ["name"] = "stones:brushrock_2"}, {["x"] = 7, ["param2"] = 1, ["y"] = 9, ["param1"] = 62, ["z"] = 20, ["name"] = "stones:brushrock_2"}, {["x"] = 7, ["param2"] = 7, ["y"] = 9, ["param1"] = 46, ["z"] = 21, ["name"] = "stones:s_52"}, {["x"] = 7, ["param2"] = 12, ["y"] = 10, ["param1"] = 14, ["z"] = 5, ["name"] = "stones:s_52"}, {["x"] = 7, ["param2"] = 3, ["y"] = 10, ["param1"] = 30, ["z"] = 6, ["name"] = "stones:arschol"}, {["x"] = 7, ["param2"] = 1, ["y"] = 10, ["param1"] = 45, ["z"] = 7, ["name"] = "stones:arch"}, {["x"] = 7, ["y"] = 10, ["param1"] = 61, ["z"] = 8, ["name"] = "stones:rock"}, {["x"] = 7, ["param2"] = 5, ["y"] = 10, ["param1"] = 76, ["z"] = 9, ["name"] = "stones:s_22"}, {["x"] = 7, ["param2"] = 2, ["y"] = 10, ["param1"] = 61, ["z"] = 11, ["name"] = "stones:arschor"}, {["x"] = 7, ["param2"] = 2, ["y"] = 10, ["param1"] = 78, ["z"] = 12, ["name"] = "stones:arcshil"}, {["x"] = 7, ["param2"] = 12, ["y"] = 11, ["param1"] = 14, ["z"] = 5, ["name"] = "stones:s_52"}, {["x"] = 7, ["param2"] = 12, ["y"] = 11, ["param1"] = 14, ["z"] = 6, ["name"] = "stones:brushrock_52ur"}, {["x"] = 7, ["param2"] = 2, ["y"] = 11, ["param1"] = 30, ["z"] = 7, ["name"] = "stones:brushrock_2"}, {["x"] = 7, ["param2"] = 1, ["y"] = 11, ["param1"] = 45, ["z"] = 8, ["name"] = "stones:brushrock_1"}, {["x"] = 7, ["param2"] = 22, ["y"] = 11, ["param1"] = 61, ["z"] = 9, ["name"] = "stones:s_21u"}, {["x"] = 7, ["y"] = 11, ["param1"] = 62, ["z"] = 10, ["name"] = "stones:diagsteps_52z"}, {["x"] = 7, ["param2"] = 3, ["y"] = 11, ["param1"] = 77, ["z"] = 11, ["name"] = "stones:c8l1"}, {["x"] = 7, ["param2"] = 5, ["y"] = 11, ["param1"] = 94, ["z"] = 12, ["name"] = "stones:s_52"}, {["x"] = 7, ["param2"] = 11, ["y"] = 12, ["param1"] = 30, ["z"] = 8, ["name"] = "stones:s_52"}, {["x"] = 7, ["param2"] = 2, ["y"] = 12, ["param1"] = 46, ["z"] = 9, ["name"] = "stones:c8l5"}, {["x"] = 7, ["param2"] = 11, ["y"] = 12, ["param1"] = 62, ["z"] = 11, ["name"] = "stones:s_52r"}, {["x"] = 7, ["param2"] = 5, ["y"] = 12, ["param1"] = 78, ["z"] = 12, ["name"] = "stones:s_52r"}, {["x"] = 7, ["y"] = 13, ["param1"] = 14, ["z"] = 8, ["name"] = "stones:vsedr"}, {["x"] = 7, ["param2"] = 5, ["y"] = 13, ["param1"] = 30, ["z"] = 9, ["name"] = "stones:s_52pl"}, {["x"] = 8, ["param2"] = 12, ["y"] = 7, ["param1"] = 62, ["z"] = 6, ["name"] = "stones:s_52r"}, {["x"] = 8, ["y"] = 7, ["param1"] = 78, ["z"] = 7, ["name"] = "stones:diagsteps_13"}, {["x"] = 8, ["param2"] = 3, ["y"] = 7, ["param1"] = 94, ["z"] = 8, ["name"] = "stones:c8l1"}, {["x"] = 8, ["param2"] = 6, ["y"] = 7, ["param1"] = 110, ["z"] = 9, ["name"] = "stones:aset"}, {["x"] = 8, ["param2"] = 14, ["y"] = 8, ["param1"] = 78, ["z"] = 8, ["name"] = "stones:s_52"}, {["x"] = 8, ["param2"] = 11, ["y"] = 8, ["param1"] = 93, ["z"] = 9, ["name"] = "stones:s_52u"}, {["x"] = 8, ["param2"] = 14, ["y"] = 8, ["param1"] = 77, ["z"] = 10, ["name"] = "stones:s_52u"}, {["x"] = 8, ["param2"] = 12, ["y"] = 8, ["param1"] = 93, ["z"] = 11, ["name"] = "stones:s_52u"}, {["x"] = 8, ["y"] = 8, ["param1"] = 77, ["z"] = 12, ["name"] = "stones:brushrock_4"}, {["x"] = 8, ["param2"] = 1, ["y"] = 8, ["param1"] = 77, ["z"] = 13, ["name"] = "stones:brush"}, {["x"] = 8, ["param2"] = 1, ["y"] = 8, ["param1"] = 93, ["z"] = 14, ["name"] = "stones:brush"}, {["x"] = 8, ["y"] = 8, ["param1"] = 78, ["z"] = 15, ["name"] = "stones:brushrock_2"}, {["x"] = 8, ["param2"] = 18, ["y"] = 8, ["param1"] = 61, ["z"] = 16, ["name"] = "stones:brushrock_52ur"}, {["x"] = 8, ["param2"] = 14, ["y"] = 9, ["param1"] = 62, ["z"] = 8, ["name"] = "stones:s_52"}, {["x"] = 8, ["param2"] = 1, ["y"] = 9, ["param1"] = 77, ["z"] = 9, ["name"] = "stones:c8rb"}, {["x"] = 8, ["param2"] = 1, ["y"] = 9, ["param1"] = 60, ["z"] = 10, ["name"] = "stones:diagsteps_31"}, {["x"] = 8, ["y"] = 9, ["param1"] = 76, ["z"] = 11, ["name"] = "stones:s_21u"}, {["x"] = 8, ["param2"] = 5, ["y"] = 9, ["param1"] = 76, ["z"] = 12, ["name"] = "stones:s_52u"}, {["x"] = 8, ["param2"] = 12, ["y"] = 9, ["param1"] = 78, ["z"] = 16, ["name"] = "stones:s_52l"}, {["x"] = 8, ["y"] = 9, ["param1"] = 62, ["z"] = 17, ["name"] = "stones:c8lf"}, {["x"] = 8, ["y"] = 9, ["param1"] = 46, ["z"] = 18, ["name"] = "stones:brushrock_21"}, {["x"] = 8, ["param2"] = 3, ["y"] = 9, ["param1"] = 62, ["z"] = 19, ["name"] = "stones:brush"}, {["x"] = 8, ["param2"] = 7, ["y"] = 9, ["param1"] = 46, ["z"] = 20, ["name"] = "stones:brushrock_52ur"}, {["x"] = 8, ["param2"] = 1, ["y"] = 10, ["param1"] = 30, ["z"] = 7, ["name"] = "stones:arcshir"}, {["x"] = 8, ["param2"] = 14, ["y"] = 10, ["param1"] = 46, ["z"] = 8, ["name"] = "stones:s_52"}, {["x"] = 8, ["param2"] = 5, ["y"] = 10, ["param1"] = 61, ["z"] = 9, ["name"] = "stones:sku2_r"}, {["x"] = 8, ["param2"] = 16, ["y"] = 10, ["param1"] = 61, ["z"] = 10, ["name"] = "stones:s_52"}, {["x"] = 8, ["y"] = 10, ["param1"] = 77, ["z"] = 11, ["name"] = "stones:s_21"}, {["x"] = 8, ["param2"] = 3, ["y"] = 10, ["param1"] = 93, ["z"] = 12, ["name"] = "stones:c8ra"}, {["x"] = 8, ["param2"] = 12, ["y"] = 11, ["param1"] = 30, ["z"] = 7, ["name"] = "stones:s_52"}, {["x"] = 8, ["param2"] = 14, ["y"] = 11, ["param1"] = 46, ["z"] = 8, ["name"] = "stones:s_52"}, {["x"] = 8, ["param2"] = 2, ["y"] = 11, ["param1"] = 61, ["z"] = 9, ["name"] = "stones:c8l4"}, {["x"] = 8, ["param2"] = 14, ["y"] = 11, ["param1"] = 78, ["z"] = 10, ["name"] = "stones:s_52ul"}, {["x"] = 8, ["param2"] = 14, ["y"] = 11, ["param1"] = 94, ["z"] = 11, ["name"] = "stones:s_52l"}, {["x"] = 8, ["param2"] = 5, ["y"] = 11, ["param1"] = 109, ["z"] = 12, ["name"] = "stones:sku2_r"}, {["x"] = 8, ["param2"] = 5, ["y"] = 12, ["param1"] = 46, ["z"] = 9, ["name"] = "stones:sku2_r"}, {["x"] = 8, ["param2"] = 3, ["y"] = 12, ["param1"] = 94, ["z"] = 12, ["name"] = "stones:dias52d"}, {["x"] = 9, ["param2"] = 11, ["y"] = 8, ["param1"] = 77, ["z"] = 12, ["name"] = "stones:s_2"}, {["x"] = 9, ["param2"] = 2, ["y"] = 8, ["param1"] = 93, ["z"] = 13, ["name"] = "stones:brushrock_1"}, {["x"] = 9, ["param2"] = 1, ["y"] = 8, ["param1"] = 109, ["z"] = 14, ["name"] = "stones:brush"}, {["x"] = 9, ["param2"] = 1, ["y"] = 8, ["param1"] = 94, ["z"] = 15, ["name"] = "stones:brush"}, {["x"] = 9, ["param2"] = 1, ["y"] = 8, ["param1"] = 77, ["z"] = 16, ["name"] = "stones:brushrock_2"}, {["x"] = 9, ["param2"] = 11, ["y"] = 9, ["param1"] = 62, ["z"] = 9, ["name"] = "stones:s_52"}, {["x"] = 9, ["y"] = 9, ["param1"] = 61, ["z"] = 10, ["name"] = "stones:rock"}, {["x"] = 9, ["y"] = 9, ["param1"] = 77, ["z"] = 11, ["name"] = "stones:rock"}, {["x"] = 9, ["y"] = 9, ["param1"] = 93, ["z"] = 12, ["name"] = "stones:rock"}, {["x"] = 9, ["param2"] = 5, ["y"] = 9, ["param1"] = 109, ["z"] = 13, ["name"] = "stones:s_252r"}, {["x"] = 9, ["param2"] = 9, ["y"] = 9, ["param1"] = 94, ["z"] = 16, ["name"] = "stones:s_52r"}, {["x"] = 9, ["param2"] = 9, ["y"] = 9, ["param1"] = 78, ["z"] = 17, ["name"] = "stones:brushrock_527r"}, {["x"] = 9, ["y"] = 9, ["param1"] = 62, ["z"] = 18, ["name"] = "stones:brush"}, {["x"] = 9, ["param2"] = 1, ["y"] = 9, ["param1"] = 46, ["z"] = 19, ["name"] = "stones:brushrock_2"}, {["x"] = 9, ["param2"] = 7, ["y"] = 9, ["param1"] = 62, ["z"] = 20, ["name"] = "stones:s_52"}, {["x"] = 9, ["param2"] = 11, ["y"] = 10, ["param1"] = 62, ["z"] = 9, ["name"] = "stones:s_52r"}, {["x"] = 9, ["param2"] = 2, ["y"] = 10, ["param1"] = 77, ["z"] = 10, ["name"] = "stones:c8l3"}, {["x"] = 9, ["param2"] = 3, ["y"] = 10, ["param1"] = 94, ["z"] = 11, ["name"] = "stones:diagsteps_52lh"}, {["x"] = 9, ["param2"] = 3, ["y"] = 10, ["param1"] = 110, ["z"] = 12, ["name"] = "stones:c8r9"}, {["x"] = 9, ["param2"] = 5, ["y"] = 10, ["param1"] = 125, ["z"] = 13, ["name"] = "stones:s_52"}, {["x"] = 9, ["param2"] = 11, ["y"] = 11, ["param1"] = 78, ["z"] = 9, ["name"] = "stones:s_52r"}, {["x"] = 9, ["param2"] = 5, ["y"] = 11, ["param1"] = 94, ["z"] = 10, ["name"] = "stones:s_52r"}, {["x"] = 9, ["y"] = 11, ["param1"] = 126, ["z"] = 12, ["name"] = "stones:vsedr"}, {["x"] = 9, ["y"] = 11, ["param1"] = 141, ["z"] = 13, ["name"] = "stones:vsebr"}, {["x"] = 9, ["y"] = 12, ["param1"] = 62, ["z"] = 9, ["name"] = "stones:vsedr"}, {["x"] = 9, ["param2"] = 5, ["y"] = 12, ["param1"] = 78, ["z"] = 10, ["name"] = "stones:s_52pl"}, {["x"] = 10, ["param2"] = 11, ["y"] = 8, ["param1"] = 109, ["z"] = 13, ["name"] = "stones:s_2"}, {["x"] = 10, ["param2"] = 2, ["y"] = 8, ["param1"] = 125, ["z"] = 14, ["name"] = "stones:brushrock_3"}, {["x"] = 10, ["param2"] = 1, ["y"] = 8, ["param1"] = 110, ["z"] = 15, ["name"] = "stones:brushrock_2"}, {["x"] = 10, ["param2"] = 11, ["y"] = 9, ["param1"] = 78, ["z"] = 10, ["name"] = "stones:s_52u"}, {["x"] = 10, ["param2"] = 1, ["y"] = 9, ["param1"] = 93, ["z"] = 11, ["name"] = "stones:brushrock_4"}, {["x"] = 10, ["param2"] = 1, ["y"] = 9, ["param1"] = 110, ["z"] = 12, ["name"] = "stones:brushrock_5"}, {["x"] = 10, ["param2"] = 5, ["y"] = 9, ["param1"] = 125, ["z"] = 13, ["name"] = "stones:brushrock_527l"}, {["x"] = 10, ["param2"] = 18, ["y"] = 9, ["param1"] = 141, ["z"] = 14, ["name"] = "stones:s_52ur"}, {["x"] = 10, ["param2"] = 1, ["y"] = 9, ["param1"] = 126, ["z"] = 15, ["name"] = "stones:diagsteps_31"}, {["x"] = 10, ["param2"] = 1, ["y"] = 9, ["param1"] = 109, ["z"] = 16, ["name"] = "stones:brushrock_4"}, {["x"] = 10, ["param2"] = 3, ["y"] = 9, ["param1"] = 94, ["z"] = 17, ["name"] = "stones:brushrock_8"}, {["x"] = 10, ["param2"] = 3, ["y"] = 9, ["param1"] = 78, ["z"] = 18, ["name"] = "stones:brushrock_5"}, {["x"] = 10, ["param2"] = 14, ["y"] = 9, ["param1"] = 62, ["z"] = 19, ["name"] = "stones:brushrock_22"}, {["x"] = 10, ["param2"] = 2, ["y"] = 10, ["param1"] = 94, ["z"] = 10, ["name"] = "stones:c8l2"}, {["x"] = 10, ["param2"] = 14, ["y"] = 10, ["param1"] = 110, ["z"] = 11, ["name"] = "stones:s_52l"}, {["x"] = 10, ["param2"] = 3, ["y"] = 10, ["param1"] = 142, ["z"] = 13, ["name"] = "stones:dias52d"}, {["x"] = 10, ["param2"] = 7, ["y"] = 10, ["param1"] = 126, ["z"] = 16, ["name"] = "stones:panel"}, {["x"] = 10, ["param2"] = 3, ["y"] = 11, ["param1"] = 110, ["z"] = 10, ["name"] = "stones:dias52d"}, {["x"] = 10, ["param2"] = 8, ["y"] = 11, ["param1"] = 158, ["z"] = 15, ["name"] = "stones:s_52l"}, {["x"] = 10, ["param2"] = 4, ["y"] = 11, ["param1"] = 142, ["z"] = 16, ["name"] = "stones:s_52l"}, {["x"] = 10, ["param2"] = 12, ["y"] = 12, ["param1"] = 142, ["z"] = 15, ["name"] = "stones:s_52hul"}, {["x"] = 10, ["y"] = 13, ["param1"] = 126, ["z"] = 15, ["name"] = "stones:plot"}, {["x"] = 10, ["param2"] = 4, ["y"] = 14, ["param1"] = 111, ["z"] = 15, ["name"] = "stones:shrub"}, {["x"] = 11, ["param2"] = 8, ["y"] = 9, ["param1"] = 94, ["z"] = 10, ["name"] = "stones:roch"}, {["x"] = 11, ["param2"] = 2, ["y"] = 9, ["param1"] = 110, ["z"] = 11, ["name"] = "stones:brush"}, {["x"] = 11, ["y"] = 9, ["param1"] = 125, ["z"] = 12, ["name"] = "stones:brush"}, {["x"] = 11, ["y"] = 9, ["param1"] = 140, ["z"] = 13, ["name"] = "stones:brushrock_8"}, {["x"] = 11, ["param2"] = 3, ["y"] = 9, ["param1"] = 157, ["z"] = 14, ["name"] = "stones:brushrock_0"}, {["x"] = 11, ["param2"] = 1, ["y"] = 9, ["param1"] = 142, ["z"] = 15, ["name"] = "stones:brushrock_5"}, {["x"] = 11, ["param2"] = 3, ["y"] = 9, ["param1"] = 126, ["z"] = 16, ["name"] = "stones:brushrock_5"}, {["x"] = 11, ["param2"] = 14, ["y"] = 9, ["param1"] = 110, ["z"] = 17, ["name"] = "stones:brushrock_52ul"}, {["x"] = 11, ["param2"] = 14, ["y"] = 9, ["param1"] = 94, ["z"] = 18, ["name"] = "stones:s_52"}, {["x"] = 11, ["param2"] = 21, ["y"] = 10, ["param1"] = 110, ["z"] = 10, ["name"] = "stones:stair_half_l"}, {["x"] = 12, ["param2"] = 11, ["y"] = 9, ["param1"] = 110, ["z"] = 10, ["name"] = "stones:s_52"}, {["x"] = 12, ["y"] = 9, ["param1"] = 125, ["z"] = 11, ["name"] = "stones:brushrock_5"}, {["x"] = 12, ["param2"] = 2, ["y"] = 9, ["param1"] = 142, ["z"] = 12, ["name"] = "stones:brush"}, {["x"] = 12, ["y"] = 9, ["param1"] = 157, ["z"] = 13, ["name"] = "stones:brush"}, {["x"] = 12, ["param2"] = 1, ["y"] = 9, ["param1"] = 173, ["z"] = 14, ["name"] = "stones:brushrock_8"}, {["x"] = 12, ["param2"] = 14, ["y"] = 9, ["param1"] = 158, ["z"] = 15, ["name"] = "stones:brushrock_52ul"}, {["x"] = 12, ["param2"] = 14, ["y"] = 9, ["param1"] = 142, ["z"] = 16, ["name"] = "stones:s_52"}, {["x"] = 12, ["param2"] = 11, ["y"] = 10, ["param1"] = 126, ["z"] = 10, ["name"] = "stones:s_52r"}, {["x"] = 12, ["param2"] = 5, ["y"] = 10, ["param1"] = 142, ["z"] = 11, ["name"] = "stones:s_52r"}}