5:return {{["x"] = 0, ["param2"] = 17, ["y"] = 5, ["param1"] = 174, ["z"] = 11, ["name"] = "stones:s_52"}, {["x"] = 0, ["param2"] = 17, ["y"] = 5, ["param1"] = 190, ["z"] = 12, ["name"] = "stones:s_52"}, {["x"] = 0, ["param2"] = 17, ["y"] = 5, ["param1"] = 206, ["z"] = 13, ["name"] = "stones:s_52"}, {["x"] = 0, ["param2"] = 17, ["y"] = 6, ["param1"] = 174, ["z"] = 10, ["name"] = "stones:s_52"}, {["x"] = 0, ["param2"] = 17, ["y"] = 6, ["param1"] = 190, ["z"] = 11, ["name"] = "stones:s_52u"}, {["x"] = 0, ["param2"] = 16, ["y"] = 6, ["param1"] = 206, ["z"] = 12, ["name"] = "stones:roch"}, {["x"] = 0, ["param2"] = 17, ["y"] = 6, ["param1"] = 222, ["z"] = 13, ["name"] = "stones:s_52u"}, {["x"] = 0, ["param2"] = 16, ["y"] = 7, ["param1"] = 158, ["z"] = 10, ["name"] = "stones:roch"}, {["x"] = 0, ["param2"] = 14, ["y"] = 7, ["param1"] = 174, ["z"] = 11, ["name"] = "stones:s_52u"}, {["x"] = 0, ["param2"] = 15, ["y"] = 7, ["param1"] = 190, ["z"] = 12, ["name"] = "stones:panel"}, {["x"] = 0, ["y"] = 7, ["param1"] = 206, ["z"] = 13, ["name"] = "stones:rock"}, {["x"] = 0, ["param2"] = 3, ["y"] = 7, ["param1"] = 189, ["z"] = 14, ["name"] = "stones:arch"}, {["x"] = 0, ["param2"] = 1, ["y"] = 8, ["param1"] = 126, ["z"] = 4, ["name"] = "stones:arch"}, {["x"] = 0, ["y"] = 8, ["z"] = 5, ["name"] = "stones:rubble"}, {["x"] = 0, ["param2"] = 2, ["y"] = 8, ["param1"] = 126, ["z"] = 6, ["name"] = "stones:rush"}, {["x"] = 0, ["y"] = 8, ["z"] = 7, ["name"] = "stones:rubble"}, {["x"] = 0, ["y"] = 8, ["z"] = 8, ["name"] = "stones:rubble"}, {["x"] = 0, ["y"] = 8, ["z"] = 9, ["name"] = "stones:rubble"}, {["x"] = 0, ["y"] = 8, ["z"] = 10, ["name"] = "stones:rubble"}, {["x"] = 0, ["y"] = 8, ["param1"] = 157, ["z"] = 11, ["name"] = "stones:rock"}, {["x"] = 0, ["y"] = 8, ["param1"] = 173, ["z"] = 12, ["name"] = "stones:rock"}, {["x"] = 0, ["y"] = 8, ["param1"] = 189, ["z"] = 13, ["name"] = "stones:rock"}, {["x"] = 0, ["param2"] = 1, ["y"] = 8, ["param1"] = 172, ["z"] = 14, ["name"] = "stones:rush"}, {["x"] = 0, ["param2"] = 1, ["y"] = 8, ["param1"] = 156, ["z"] = 15, ["name"] = "stones:rush"}, {["x"] = 0, ["y"] = 8, ["param1"] = 139, ["z"] = 16, ["name"] = "stones:rush"}, {["x"] = 0, ["y"] = 8, ["param1"] = 154, ["z"] = 17, ["name"] = "stones:rush"}, {["x"] = 0, ["y"] = 8, ["param1"] = 170, ["z"] = 18, ["name"] = "stones:rush"}, {["x"] = 0, ["y"] = 8, ["param1"] = 153, ["z"] = 19, ["name"] = "stones:rush"}, {["x"] = 0, ["y"] = 8, ["param1"] = 136, ["z"] = 20, ["name"] = "stones:flat_4"}, {["x"] = 0, ["y"] = 8, ["z"] = 21, ["name"] = "stones:rubble"}, {["x"] = 0, ["param2"] = 17, ["y"] = 8, ["param1"] = 104, ["z"] = 22, ["name"] = "stones:s_2"}, {["x"] = 0, ["param2"] = 2, ["y"] = 9, ["param1"] = 126, ["z"] = 4, ["name"] = "stones:brushrock_0"}, {["x"] = 0, ["param2"] = 2, ["y"] = 9, ["param1"] = 141, ["z"] = 5, ["name"] = "stones:brush"}, {["x"] = 0, ["param2"] = 1, ["y"] = 9, ["param1"] = 142, ["z"] = 6, ["name"] = "stones:brush"}, {["x"] = 0, ["y"] = 9, ["param1"] = 157, ["z"] = 7, ["name"] = "stones:rock"}, {["x"] = 0, ["y"] = 9, ["param1"] = 140, ["z"] = 8, ["name"] = "stones:rock"}, {["x"] = 0, ["y"] = 9, ["param1"] = 124, ["z"] = 9, ["name"] = "stones:rock"}, {["x"] = 0, ["y"] = 9, ["param1"] = 140, ["z"] = 10, ["name"] = "stones:rock"}, {["x"] = 0, ["param2"] = 2, ["y"] = 9, ["param1"] = 140, ["z"] = 11, ["name"] = "stones:brushrock_c"}, {["x"] = 0, ["param2"] = 2, ["y"] = 9, ["param1"] = 156, ["z"] = 12, ["name"] = "stones:brush"}, {["x"] = 0, ["y"] = 9, ["param1"] = 172, ["z"] = 13, ["name"] = "stones:brush"}, {["x"] = 0, ["param2"] = 1, ["y"] = 9, ["param1"] = 156, ["z"] = 14, ["name"] = "stones:brush"}, {["x"] = 0, ["param2"] = 2, ["y"] = 9, ["param1"] = 141, ["z"] = 15, ["name"] = "stones:brush"}, {["x"] = 0, ["y"] = 9, ["param1"] = 156, ["z"] = 16, ["name"] = "stones:brush"}, {["x"] = 0, ["param2"] = 3, ["y"] = 9, ["param1"] = 171, ["z"] = 17, ["name"] = "stones:brushrock_0"}, {["x"] = 0, ["param2"] = 3, ["y"] = 9, ["param1"] = 187, ["z"] = 18, ["name"] = "stones:brushrock_0"}, {["x"] = 0, ["param2"] = 3, ["y"] = 9, ["param1"] = 170, ["z"] = 19, ["name"] = "stones:brushrock_0"}, {["x"] = 0, ["param2"] = 1, ["y"] = 9, ["param1"] = 153, ["z"] = 20, ["name"] = "stones:brushrock_5"}, {["x"] = 0, ["y"] = 9, ["param1"] = 138, ["z"] = 21, ["name"] = "stones:brushrock_8"}, {["x"] = 0, ["param2"] = 3, ["y"] = 9, ["param1"] = 121, ["z"] = 22, ["name"] = "stones:brushrock_0"}, {["x"] = 0, ["param2"] = 6, ["y"] = 10, ["param1"] = 110, ["z"] = 4, ["name"] = "stones:panel"}, {["x"] = 0, ["y"] = 10, ["param1"] = 142, ["z"] = 7, ["name"] = "stones:panel"}, {["x"] = 0, ["y"] = 10, ["param1"] = 125, ["z"] = 8, ["name"] = "stones:rock"}, {["x"] = 0, ["param2"] = 6, ["y"] = 10, ["param1"] = 156, ["z"] = 17, ["name"] = "stones:stair_half_r"}, {["x"] = 0, ["param2"] = 6, ["y"] = 10, ["param1"] = 172, ["z"] = 18, ["name"] = "stones:stair_half_r"}, {["x"] = 0, ["param2"] = 6, ["y"] = 10, ["param1"] = 156, ["z"] = 19, ["name"] = "stones:stair_half_r"}, {["x"] = 0, ["param2"] = 7, ["y"] = 10, ["param1"] = 140, ["z"] = 20, ["name"] = "stones:panel"}, {["x"] = 0, ["param2"] = 6, ["y"] = 10, ["param1"] = 108, ["z"] = 22, ["name"] = "stones:stair_half_r"}, {["x"] = 0, ["y"] = 11, ["param1"] = 110, ["z"] = 8, ["name"] = "stones:panel"}, {["x"] = 0, ["param2"] = 3, ["y"] = 11, ["param1"] = 93, ["z"] = 9, ["name"] = "stones:arch"}, {["x"] = 0, ["y"] = 11, ["param1"] = 109, ["z"] = 10, ["name"] = "stones:arco"}, {["x"] = 0, ["param2"] = 3, ["y"] = 11, ["param1"] = 109, ["z"] = 11, ["name"] = "stones:arco"}, {["x"] = 0, ["param2"] = 1, ["y"] = 12, ["param1"] = 94, ["z"] = 10, ["name"] = "stones:cish"}, {["x"] = 0, ["param2"] = 1, ["y"] = 12, ["param1"] = 94, ["z"] = 11, ["name"] = "stones:diagsteps_8l"}, {["x"] = 0, ["param2"] = 19, ["y"] = 12, ["param1"] = 110, ["z"] = 12, ["name"] = "stones:arch"}, {["x"] = 1, ["param2"] = 17, ["y"] = 5, ["param1"] = 173, ["z"] = 10, ["name"] = "stones:s_52u"}, {["x"] = 1, ["y"] = 5, ["param1"] = 189, ["z"] = 11, ["name"] = "stones:rock"}, {["x"] = 1, ["y"] = 5, ["param1"] = 205, ["z"] = 12, ["name"] = "stones:rock"}, {["x"] = 1, ["y"] = 5, ["param1"] = 221, ["z"] = 13, ["name"] = "stones:rock"}, {["x"] = 1, ["y"] = 6, ["param1"] = 189, ["z"] = 10, ["name"] = "stones:rock"}, {["x"] = 1, ["param2"] = 4, ["y"] = 6, ["param1"] = 205, ["z"] = 11, ["name"] = "stones:roch"}, {["x"] = 1, ["y"] = 6, ["param1"] = 238, ["z"] = 13, ["name"] = "tool:dice"}, {["x"] = 1, ["param2"] = 4, ["y"] = 6, ["param1"] = 221, ["z"] = 14, ["name"] = "stones:flat_1"}, {["x"] = 1, ["param2"] = 1, ["y"] = 7, ["param1"] = 158, ["z"] = 9, ["name"] = "stones:arch"}, {["x"] = 1, ["param2"] = 2, ["y"] = 7, ["param1"] = 173, ["z"] = 10, ["name"] = "runes:bu"}, {["x"] = 1, ["param2"] = 9, ["y"] = 7, ["param1"] = 222, ["z"] = 13, ["name"] = "stones:flat_3a"}, {["x"] = 1, ["param2"] = 3, ["y"] = 7, ["param1"] = 205, ["z"] = 14, ["name"] = "stones:arch"}, {["x"] = 1, ["param2"] = 8, ["y"] = 8, ["param1"] = 142, ["z"] = 4, ["name"] = "stones:s_2"}, {["x"] = 1, ["y"] = 8, ["z"] = 5, ["name"] = "stones:rubble"}, {["x"] = 1, ["y"] = 8, ["z"] = 6, ["name"] = "stones:rubble"}, {["x"] = 1, ["y"] = 8, ["param1"] = 126, ["z"] = 7, ["name"] = "stones:rock"}, {["x"] = 1, ["y"] = 8, ["param1"] = 126, ["z"] = 8, ["name"] = "stones:rock"}, {["x"] = 1, ["y"] = 8, ["param1"] = 141, ["z"] = 9, ["name"] = "stones:rock"}, {["x"] = 1, ["y"] = 8, ["param1"] = 157, ["z"] = 10, ["name"] = "stones:rock"}, {["x"] = 1, ["param2"] = 3, ["y"] = 8, ["param1"] = 174, ["z"] = 11, ["name"] = "stones:arch"}, {["x"] = 1, ["param2"] = 1, ["y"] = 8, ["param1"] = 190, ["z"] = 12, ["name"] = "stones:arch"}, {["x"] = 1, ["param2"] = 21, ["y"] = 8, ["param1"] = 205, ["z"] = 13, ["name"] = "stones:flat_3a"}, {["x"] = 1, ["param2"] = 1, ["y"] = 8, ["param1"] = 188, ["z"] = 14, ["name"] = "stones:flat_4"}, {["x"] = 1, ["param2"] = 1, ["y"] = 8, ["param1"] = 171, ["z"] = 15, ["name"] = "stones:flat_4"}, {["x"] = 1, ["param2"] = 1, ["y"] = 8, ["param1"] = 154, ["z"] = 16, ["name"] = "stones:flat_4"}, {["x"] = 1, ["param2"] = 1, ["y"] = 8, ["param1"] = 138, ["z"] = 17, ["name"] = "stones:flat_4"}, {["x"] = 1, ["param2"] = 1, ["y"] = 8, ["param1"] = 154, ["z"] = 18, ["name"] = "stones:flat_4"}, {["x"] = 1, ["param2"] = 1, ["y"] = 8, ["param1"] = 138, ["z"] = 19, ["name"] = "stones:flat_4"}, {["x"] = 1, ["param2"] = 3, ["y"] = 8, ["param1"] = 121, ["z"] = 20, ["name"] = "stones:flat_1"}, {["x"] = 1, ["param2"] = 3, ["y"] = 8, ["param1"] = 106, ["z"] = 21, ["name"] = "stones:flat_4"}, {["x"] = 1, ["y"] = 8, ["param1"] = 89, ["z"] = 22, ["name"] = "stones:flat_1"}, {["x"] = 1, ["param2"] = 2, ["y"] = 9, ["param1"] = 126, ["z"] = 4, ["name"] = "stones:brushrock_0"}, {["x"] = 1, ["param2"] = 2, ["y"] = 9, ["param1"] = 125, ["z"] = 5, ["name"] = "stones:brush"}, {["x"] = 1, ["param2"] = 1, ["y"] = 9, ["param1"] = 125, ["z"] = 6, ["name"] = "stones:brush"}, {["x"] = 1, ["y"] = 9, ["param1"] = 141, ["z"] = 7, ["name"] = "stones:rock"}, {["x"] = 1, ["y"] = 9, ["param1"] = 125, ["z"] = 8, ["name"] = "stones:rock"}, {["x"] = 1, ["y"] = 9, ["param1"] = 124, ["z"] = 9, ["name"] = "stones:rock"}, {["x"] = 1, ["y"] = 9, ["param1"] = 140, ["z"] = 10, ["name"] = "stones:rock"}, {["x"] = 1, ["param2"] = 1, ["y"] = 9, ["param1"] = 157, ["z"] = 11, ["name"] = "stones:brushrock_c"}, {["x"] = 1, ["param2"] = 2, ["y"] = 9, ["param1"] = 173, ["z"] = 12, ["name"] = "stones:brush"}, {["x"] = 1, ["y"] = 9, ["param1"] = 188, ["z"] = 13, ["name"] = "stones:brush"}, {["x"] = 1, ["param2"] = 3, ["y"] = 9, ["param1"] = 171, ["z"] = 14, ["name"] = "stones:brushrock_5"}, {["x"] = 1, ["param2"] = 2, ["y"] = 9, ["param1"] = 156, ["z"] = 15, ["name"] = "stones:brushrock_2"}, {["x"] = 1, ["y"] = 9, ["param1"] = 139, ["z"] = 16, ["name"] = "stones:brush"}, {["x"] = 1, ["param2"] = 1, ["y"] = 9, ["param1"] = 154, ["z"] = 17, ["name"] = "stones:brush"}, {["x"] = 1, ["y"] = 9, ["param1"] = 170, ["z"] = 18, ["name"] = "stones:brush"}, {["x"] = 1, ["param2"] = 1, ["y"] = 9, ["param1"] = 155, ["z"] = 19, ["name"] = "stones:brush"}, {["x"] = 1, ["y"] = 9, ["param1"] = 138, ["z"] = 20, ["name"] = "stones:brush"}, {["x"] = 1, ["param2"] = 1, ["y"] = 9, ["param1"] = 123, ["z"] = 21, ["name"] = "stones:brush"}, {["x"] = 1, ["param2"] = 2, ["y"] = 9, ["param1"] = 106, ["z"] = 22, ["name"] = "stones:brush"}, {["x"] = 1, ["param2"] = 15, ["y"] = 10, ["param1"] = 110, ["z"] = 4, ["name"] = "stones:stair_half_l"}, {["x"] = 1, ["y"] = 10, ["param1"] = 126, ["z"] = 7, ["name"] = "stones:panel"}, {["x"] = 1, ["y"] = 10, ["param1"] = 109, ["z"] = 8, ["name"] = "stones:rock"}, {["x"] = 1, ["param2"] = 18, ["y"] = 10, ["param1"] = 108, ["z"] = 9, ["name"] = "stones:s_52ur"}, {["x"] = 1, ["param2"] = 18, ["y"] = 10, ["param1"] = 123, ["z"] = 10, ["name"] = "stones:s_52r"}, {["x"] = 1, ["y"] = 11, ["param1"] = 94, ["z"] = 8, ["name"] = "stones:panel"}, {["x"] = 1, ["param2"] = 2, ["y"] = 11, ["param1"] = 93, ["z"] = 9, ["name"] = "stones:arci"}, {["x"] = 1, ["param2"] = 2, ["y"] = 11, ["param1"] = 108, ["z"] = 10, ["name"] = "stones:arch"}, {["x"] = 1, ["param2"] = 2, ["y"] = 11, ["param1"] = 124, ["z"] = 11, ["name"] = "stones:arco"}, {["x"] = 1, ["param2"] = 16, ["y"] = 12, ["param1"] = 78, ["z"] = 9, ["name"] = "stones:brushrock_22"}, {["x"] = 1, ["param2"] = 3, ["y"] = 12, ["param1"] = 93, ["z"] = 10, ["name"] = "stones:brushrock_0"}, {["x"] = 1, ["y"] = 12, ["param1"] = 109, ["z"] = 11, ["name"] = "stones:brushrock_3"}, {["x"] = 1, ["param2"] = 10, ["y"] = 12, ["param1"] = 125, ["z"] = 12, ["name"] = "stones:arch"}, {["x"] = 2, ["y"] = 5, ["param1"] = 158, ["z"] = 10, ["name"] = "stones:rock"}, {["x"] = 2, ["y"] = 5, ["param1"] = 173, ["z"] = 11, ["name"] = "stones:rock"}, {["x"] = 2, ["y"] = 5, ["param1"] = 190, ["z"] = 12, ["name"] = "stones:rock"}, {["x"] = 2, ["param2"] = 21, ["y"] = 5, ["param1"] = 205, ["z"] = 13, ["name"] = "stones:s_52u"}, {["x"] = 2, ["param2"] = 2, ["y"] = 6, ["param1"] = 174, ["z"] = 10, ["name"] = "stones:s_21"}, {["x"] = 2, ["param2"] = 7, ["y"] = 6, ["param1"] = 190, ["z"] = 11, ["name"] = "stones:s_22"}, {["x"] = 2, ["y"] = 6, ["param1"] = 222, ["z"] = 13, ["name"] = "stones:rock"}, {["x"] = 2, ["param2"] = 2, ["y"] = 7, ["param1"] = 158, ["z"] = 10, ["name"] = "stones:s_21"}, {["x"] = 2, ["param2"] = 3, ["y"] = 7, ["param1"] = 206, ["z"] = 13, ["name"] = "stones:s_21"}, {["x"] = 2, ["param2"] = 3, ["y"] = 7, ["param1"] = 189, ["z"] = 14, ["name"] = "stones:arch"}, {["x"] = 2, ["param2"] = 8, ["y"] = 8, ["param1"] = 126, ["z"] = 4, ["name"] = "stones:aset"}, {["x"] = 2, ["param2"] = 15, ["y"] = 8, ["param1"] = 142, ["z"] = 5, ["name"] = "stones:s_2"}, {["x"] = 2, ["param2"] = 15, ["y"] = 8, ["param1"] = 126, ["z"] = 6, ["name"] = "stones:s_2"}, {["x"] = 2, ["param2"] = 22, ["y"] = 8, ["param1"] = 110, ["z"] = 7, ["name"] = "stones:aset"}, {["x"] = 2, ["param2"] = 2, ["y"] = 8, ["param1"] = 141, ["z"] = 10, ["name"] = "stones:s_21"}, {["x"] = 2, ["param2"] = 3, ["y"] = 8, ["param1"] = 158, ["z"] = 11, ["name"] = "stones:arsh"}, {["x"] = 2, ["param2"] = 7, ["y"] = 8, ["param1"] = 174, ["z"] = 12, ["name"] = "stones:arsh"}, {["x"] = 2, ["param2"] = 3, ["y"] = 8, ["param1"] = 189, ["z"] = 13, ["name"] = "stones:s_21"}, {["x"] = 2, ["y"] = 8, ["param1"] = 172, ["z"] = 14, ["name"] = "stones:rock"}, {["x"] = 2, ["y"] = 8, ["param1"] = 155, ["z"] = 15, ["name"] = "stones:rock"}, {["x"] = 2, ["y"] = 8, ["param1"] = 138, ["z"] = 16, ["name"] = "stones:rock"}, {["x"] = 2, ["param2"] = 15, ["y"] = 8, ["param1"] = 123, ["z"] = 17, ["name"] = "stones:s_2"}, {["x"] = 2, ["param2"] = 21, ["y"] = 8, ["param1"] = 140, ["z"] = 18, ["name"] = "stones:s_52"}, {["x"] = 2, ["param2"] = 15, ["y"] = 8, ["param1"] = 124, ["z"] = 19, ["name"] = "stones:s_2"}, {["x"] = 2, ["param2"] = 21, ["y"] = 8, ["param1"] = 108, ["z"] = 20, ["name"] = "stones:s_52"}, {["x"] = 2, ["param2"] = 15, ["y"] = 8, ["param1"] = 92, ["z"] = 21, ["name"] = "stones:s_2"}, {["x"] = 2, ["param2"] = 21, ["y"] = 8, ["param1"] = 76, ["z"] = 22, ["name"] = "stones:s_52"}, {["x"] = 2, ["param2"] = 11, ["y"] = 9, ["param1"] = 109, ["z"] = 4, ["name"] = "stones:brushrock_22"}, {["x"] = 2, ["param2"] = 1, ["y"] = 9, ["param1"] = 125, ["z"] = 5, ["name"] = "stones:brushrock_0"}, {["x"] = 2, ["param2"] = 1, ["y"] = 9, ["param1"] = 109, ["z"] = 6, ["name"] = "stones:brushrock_0"}, {["x"] = 2, ["param2"] = 7, ["y"] = 9, ["param1"] = 125, ["z"] = 7, ["name"] = "stones:s_2"}, {["x"] = 2, ["param2"] = 11, ["y"] = 9, ["param1"] = 109, ["z"] = 8, ["name"] = "stones:s_2"}, {["x"] = 2, ["y"] = 9, ["param1"] = 109, ["z"] = 9, ["name"] = "stones:rock"}, {["x"] = 2, ["y"] = 9, ["param1"] = 124, ["z"] = 10, ["name"] = "stones:rock"}, {["x"] = 2, ["param2"] = 6, ["y"] = 9, ["param1"] = 141, ["z"] = 11, ["name"] = "stones:s_21"}, {["x"] = 2, ["param2"] = 6, ["y"] = 9, ["param1"] = 157, ["z"] = 12, ["name"] = "stones:s_21"}, {["x"] = 2, ["y"] = 9, ["param1"] = 172, ["z"] = 13, ["name"] = "stones:rock"}, {["x"] = 2, ["param2"] = 3, ["y"] = 9, ["param1"] = 155, ["z"] = 14, ["name"] = "stones:diagsteps_31"}, {["x"] = 2, ["y"] = 9, ["param1"] = 139, ["z"] = 15, ["name"] = "stones:diagsteps_13"}, {["x"] = 2, ["param2"] = 2, ["y"] = 9, ["param1"] = 122, ["z"] = 16, ["name"] = "stones:brushrock_3"}, {["x"] = 2, ["param2"] = 1, ["y"] = 9, ["param1"] = 138, ["z"] = 17, ["name"] = "stones:brushrock_0"}, {["x"] = 2, ["param2"] = 1, ["y"] = 9, ["param1"] = 153, ["z"] = 18, ["name"] = "stones:brushrock_0"}, {["x"] = 2, ["param2"] = 1, ["y"] = 9, ["param1"] = 140, ["z"] = 19, ["name"] = "stones:brushrock_0"}, {["x"] = 2, ["param2"] = 1, ["y"] = 9, ["param1"] = 124, ["z"] = 20, ["name"] = "stones:brushrock_0"}, {["x"] = 2, ["param2"] = 1, ["y"] = 9, ["param1"] = 108, ["z"] = 21, ["name"] = "stones:brushrock_0"}, {["x"] = 2, ["param2"] = 1, ["y"] = 9, ["param1"] = 92, ["z"] = 22, ["name"] = "stones:brushrock_0"}, {["x"] = 2, ["param2"] = 18, ["y"] = 10, ["param1"] = 94, ["z"] = 4, ["name"] = "stones:sku_202"}, {["x"] = 2, ["param2"] = 6, ["y"] = 10, ["param1"] = 110, ["z"] = 5, ["name"] = "stones:stair_half_l"}, {["x"] = 2, ["param2"] = 8, ["y"] = 10, ["param1"] = 93, ["z"] = 6, ["name"] = "stones:stair_half_r"}, {["x"] = 2, ["param2"] = 11, ["y"] = 10, ["param1"] = 109, ["z"] = 7, ["name"] = "stones:s_52l"}, {["x"] = 2, ["y"] = 10, ["param1"] = 93, ["z"] = 8, ["name"] = "stones:rock"}, {["x"] = 2, ["param2"] = 1, ["y"] = 10, ["param1"] = 92, ["z"] = 9, ["name"] = "stones:roch"}, {["x"] = 2, ["y"] = 10, ["param1"] = 107, ["z"] = 10, ["name"] = "stones:rock"}, {["x"] = 2, ["y"] = 10, ["param1"] = 155, ["z"] = 13, ["name"] = "stones:rock"}, {["x"] = 2, ["param2"] = 18, ["y"] = 10, ["param1"] = 107, ["z"] = 16, ["name"] = "stones:s_52u"}, {["x"] = 2, ["param2"] = 4, ["y"] = 10, ["param1"] = 122, ["z"] = 17, ["name"] = "stones:estruk"}, {["x"] = 2, ["param2"] = 4, ["y"] = 10, ["param1"] = 137, ["z"] = 18, ["name"] = "stones:estruk"}, {["x"] = 2, ["param2"] = 4, ["y"] = 10, ["param1"] = 124, ["z"] = 19, ["name"] = "stones:estruk"}, {["x"] = 2, ["param2"] = 4, ["y"] = 10, ["param1"] = 108, ["z"] = 20, ["name"] = "stones:estruk"}, {["x"] = 2, ["param2"] = 4, ["y"] = 10, ["param1"] = 92, ["z"] = 21, ["name"] = "stones:estruk"}, {["x"] = 2, ["param2"] = 4, ["y"] = 10, ["param1"] = 76, ["z"] = 22, ["name"] = "stones:estruk"}, {["x"] = 2, ["y"] = 11, ["param1"] = 78, ["z"] = 6, ["name"] = "stones:s_22r"}, {["x"] = 2, ["y"] = 11, ["param1"] = 94, ["z"] = 7, ["name"] = "stones:sku2_r"}, {["x"] = 2, ["y"] = 11, ["param1"] = 78, ["z"] = 8, ["name"] = "stones:rock"}, {["x"] = 2, ["y"] = 11, ["param1"] = 77, ["z"] = 9, ["name"] = "stones:rock"}, {["x"] = 2, ["y"] = 11, ["param1"] = 92, ["z"] = 10, ["name"] = "stones:rock"}, {["x"] = 2, ["param2"] = 3, ["y"] = 11, ["param1"] = 108, ["z"] = 11, ["name"] = "stones:arch"}, {["x"] = 2, ["param2"] = 1, ["y"] = 11, ["param1"] = 124, ["z"] = 12, ["name"] = "stones:arch"}, {["x"] = 2, ["y"] = 11, ["param1"] = 140, ["z"] = 13, ["name"] = "stones:rock"}, {["x"] = 2, ["param2"] = 3, ["y"] = 11, ["param1"] = 123, ["z"] = 14, ["name"] = "stones:arch"}, {["x"] = 2, ["param2"] = 1, ["y"] = 11, ["param1"] = 107, ["z"] = 15, ["name"] = "stones:arch"}, {["x"] = 2, ["param2"] = 18, ["y"] = 11, ["param1"] = 90, ["z"] = 16, ["name"] = "stones:s_52u"}, {["x"] = 2, ["param2"] = 13, ["y"] = 12, ["param1"] = 62, ["z"] = 8, ["name"] = "stones:cis"}, {["x"] = 2, ["param2"] = 2, ["y"] = 12, ["param1"] = 62, ["z"] = 9, ["name"] = "stones:brushrock_0"}, {["x"] = 2, ["param2"] = 1, ["y"] = 12, ["param1"] = 77, ["z"] = 10, ["name"] = "stones:brush"}, {["x"] = 2, ["param2"] = 2, ["y"] = 12, ["param1"] = 93, ["z"] = 11, ["name"] = "stones:brushrock_2"}, {["x"] = 2, ["y"] = 12, ["param1"] = 109, ["z"] = 12, ["name"] = "stones:brushrock_2"}, {["x"] = 2, ["param2"] = 3, ["y"] = 12, ["param1"] = 125, ["z"] = 13, ["name"] = "stones:brushrock_0"}, {["x"] = 2, ["param2"] = 3, ["y"] = 12, ["param1"] = 108, ["z"] = 14, ["name"] = "stones:brushrock_0"}, {["x"] = 2, ["param2"] = 3, ["y"] = 12, ["param1"] = 92, ["z"] = 15, ["name"] = "stones:brushrock_0"}, {["x"] = 2, ["param2"] = 18, ["y"] = 12, ["param1"] = 76, ["z"] = 16, ["name"] = "stones:brushrock_52ur"}, {["x"] = 2, ["param2"] = 5, ["y"] = 12, ["param1"] = 92, ["z"] = 17, ["name"] = "stones:s_22"}, {["x"] = 2, ["param2"] = 4, ["y"] = 13, ["param1"] = 62, ["z"] = 10, ["name"] = "stones:sku2_r"}, {["x"] = 2, ["param2"] = 6, ["y"] = 14, ["param1"] = 46, ["z"] = 10, ["name"] = "stones:sku2_l"}, {["x"] = 2, ["y"] = 15, ["param1"] = 30, ["z"] = 10, ["name"] = "stones:s_22r"}, {["x"] = 2, ["param2"] = 18, ["y"] = 15, ["param1"] = 46, ["z"] = 11, ["name"] = "stones:s_52r"}, {["x"] = 3, ["param2"] = 16, ["y"] = 5, ["param1"] = 126, ["z"] = 8, ["name"] = "stones:s_52"}, {["x"] = 3, ["param2"] = 16, ["y"] = 5, ["param1"] = 126, ["z"] = 9, ["name"] = "stones:s_52u"}, {["x"] = 3, ["y"] = 5, ["param1"] = 141, ["z"] = 10, ["name"] = "stones:rock"}, {["x"] = 3, ["y"] = 5, ["param1"] = 156, ["z"] = 11, ["name"] = "stones:rock"}, {["x"] = 3, ["y"] = 5, ["param1"] = 173, ["z"] = 12, ["name"] = "stones:rock"}, {["x"] = 3, ["param2"] = 21, ["y"] = 5, ["param1"] = 188, ["z"] = 13, ["name"] = "stones:s_52"}, {["x"] = 3, ["param2"] = 5, ["y"] = 6, ["param1"] = 157, ["z"] = 10, ["name"] = "stones:sku2_r"}, {["x"] = 3, ["param2"] = 1, ["y"] = 6, ["param1"] = 190, ["z"] = 12, ["name"] = "stones:diagstep"}, {["x"] = 3, ["y"] = 6, ["param1"] = 205, ["z"] = 13, ["name"] = "stones:rock"}, {["x"] = 3, ["y"] = 7, ["param1"] = 189, ["z"] = 13, ["name"] = "stones:panel"}, {["x"] = 3, ["param2"] = 3, ["y"] = 7, ["param1"] = 172, ["z"] = 14, ["name"] = "stones:arch"}, {["x"] = 3, ["meta"] = {["fields"] = {["shadows:gen"] = "13516"}, ["inventory"] = {}}, ["param2"] = 11, ["y"] = 8, ["param1"] = 155, ["z"] = 14, ["name"] = "stones:s_52l"}, {["x"] = 3, ["y"] = 8, ["param1"] = 139, ["z"] = 15, ["name"] = "stones:diagstep_7"}, {["x"] = 3, ["param2"] = 3, ["y"] = 8, ["param1"] = 123, ["z"] = 16, ["name"] = "stones:cis"}, {["x"] = 3, ["param2"] = 9, ["y"] = 9, ["param1"] = 93, ["z"] = 0, ["name"] = "stones:panel"}, {["x"] = 3, ["param2"] = 16, ["y"] = 9, ["param1"] = 77, ["z"] = 1, ["name"] = "stones:roch"}, {["x"] = 3, ["param2"] = 16, ["y"] = 9, ["param1"] = 61, ["z"] = 2, ["name"] = "stones:brushrock_52ul"}, {["x"] = 3, ["param2"] = 3, ["y"] = 9, ["param1"] = 77, ["z"] = 3, ["name"] = "stones:brushrock_0"}, {["x"] = 3, ["param2"] = 5, ["y"] = 9, ["param1"] = 92, ["z"] = 4, ["name"] = "stones:brushrock_22"}, {["x"] = 3, ["param2"] = 16, ["y"] = 9, ["param1"] = 108, ["z"] = 7, ["name"] = "stones:s_52l"}, {["x"] = 3, ["param2"] = 16, ["y"] = 9, ["param1"] = 92, ["z"] = 8, ["name"] = "stones:s_52ul"}, {["x"] = 3, ["y"] = 9, ["param1"] = 92, ["z"] = 9, ["name"] = "stones:roch"}, {["x"] = 3, ["y"] = 9, ["param1"] = 107, ["z"] = 10, ["name"] = "stones:sku"}, {["x"] = 3, ["param2"] = 20, ["y"] = 9, ["param1"] = 124, ["z"] = 11, ["name"] = "stones:roch"}, {["x"] = 3, ["param2"] = 7, ["y"] = 9, ["param1"] = 140, ["z"] = 12, ["name"] = "stones:s_52ul"}, {["x"] = 3, ["param2"] = 16, ["y"] = 9, ["param1"] = 122, ["z"] = 15, ["name"] = "stones:s_52"}, {["x"] = 3, ["param2"] = 3, ["y"] = 9, ["param1"] = 108, ["z"] = 16, ["name"] = "stones:cis"}, {["x"] = 3, ["param2"] = 9, ["y"] = 10, ["param1"] = 109, ["z"] = 0, ["name"] = "stones:panel"}, {["x"] = 3, ["param2"] = 20, ["y"] = 10, ["param1"] = 93, ["z"] = 1, ["name"] = "stones:stair_half_l"}, {["x"] = 3, ["param2"] = 14, ["y"] = 10, ["param1"] = 77, ["z"] = 2, ["name"] = "stones:sku2_r"}, {["x"] = 3, ["param2"] = 8, ["y"] = 10, ["param1"] = 61, ["z"] = 3, ["name"] = "stones:stair_half_l"}, {["x"] = 3, ["param2"] = 12, ["y"] = 10, ["param1"] = 77, ["z"] = 4, ["name"] = "stones:sku_202"}, {["x"] = 3, ["param2"] = 16, ["y"] = 10, ["param1"] = 76, ["z"] = 6, ["name"] = "stones:s_52l"}, {["x"] = 3, ["param2"] = 14, ["y"] = 10, ["param1"] = 92, ["z"] = 7, ["name"] = "stones:sku2_l"}, {["x"] = 3, ["param2"] = 14, ["y"] = 10, ["param1"] = 76, ["z"] = 8, ["name"] = "stones:s_52l"}, {["x"] = 3, ["param2"] = 9, ["y"] = 10, ["param1"] = 123, ["z"] = 12, ["name"] = "stones:s_52l"}, {["x"] = 3, ["param2"] = 7, ["y"] = 10, ["param1"] = 139, ["z"] = 13, ["name"] = "stones:s_52l"}, {["x"] = 3, ["param2"] = 3, ["y"] = 10, ["param1"] = 92, ["z"] = 16, ["name"] = "stones:cis"}, {["x"] = 3, ["y"] = 11, ["param1"] = 60, ["z"] = 9, ["name"] = "stones:arch"}, {["x"] = 3, ["y"] = 11, ["param1"] = 75, ["z"] = 10, ["name"] = "stones:arch"}, {["x"] = 3, ["param2"] = 3, ["y"] = 11, ["param1"] = 91, ["z"] = 11, ["name"] = "stones:arco"}, {["x"] = 3, ["y"] = 11, ["param1"] = 107, ["z"] = 12, ["name"] = "stones:arco"}, {["x"] = 3, ["y"] = 11, ["param1"] = 123, ["z"] = 13, ["name"] = "stones:arch"}, {["x"] = 3, ["param2"] = 3, ["y"] = 11, ["param1"] = 106, ["z"] = 14, ["name"] = "stones:arco"}, {["x"] = 3, ["param2"] = 1, ["y"] = 11, ["param1"] = 90, ["z"] = 15, ["name"] = "stones:arch"}, {["x"] = 3, ["param2"] = 3, ["y"] = 11, ["param1"] = 73, ["z"] = 16, ["name"] = "stones:cis"}, {["x"] = 3, ["y"] = 12, ["param1"] = 45, ["z"] = 9, ["name"] = "stones:brushrock_4"}, {["x"] = 3, ["param2"] = 1, ["y"] = 12, ["param1"] = 60, ["z"] = 10, ["name"] = "stones:brush"}, {["x"] = 3, ["y"] = 12, ["param1"] = 76, ["z"] = 11, ["name"] = "stones:brushrock_2"}, {["x"] = 3, ["param2"] = 2, ["y"] = 12, ["param1"] = 92, ["z"] = 12, ["name"] = "stones:brushrock_11"}, {["x"] = 3, ["param2"] = 2, ["y"] = 12, ["param1"] = 108, ["z"] = 13, ["name"] = "stones:brushrock_2"}, {["x"] = 3, ["param2"] = 1, ["y"] = 12, ["param1"] = 91, ["z"] = 14, ["name"] = "stones:brush"}, {["x"] = 3, ["param2"] = 1, ["y"] = 12, ["param1"] = 76, ["z"] = 15, ["name"] = "stones:brush"}, {["x"] = 3, ["y"] = 12, ["param1"] = 60, ["z"] = 16, ["name"] = "stones:brushrock_c"}, {["x"] = 3, ["param2"] = 7, ["y"] = 12, ["param1"] = 76, ["z"] = 17, ["name"] = "stones:s_52"}, {["x"] = 3, ["param2"] = 12, ["y"] = 15, ["param1"] = 29, ["z"] = 11, ["name"] = "stones:s_52r"}, {["x"] = 3, ["param2"] = 12, ["y"] = 15, ["param1"] = 46, ["z"] = 12, ["name"] = "stones:sku2_r"}, {["x"] = 3, ["param2"] = 5, ["y"] = 15, ["param1"] = 62, ["z"] = 13, ["name"] = "stones:s_22l"}, {["x"] = 4, ["param2"] = 16, ["y"] = 5, ["param1"] = 125, ["z"] = 7, ["name"] = "stones:brushrock_22"}, {["x"] = 4, ["param2"] = 1, ["y"] = 5, ["param1"] = 109, ["z"] = 8, ["name"] = "stones:brushrock_5"}, {["x"] = 4, ["y"] = 5, ["param1"] = 109, ["z"] = 9, ["name"] = "stones:brush"}, {["x"] = 4, ["y"] = 5, ["param1"] = 124, ["z"] = 10, ["name"] = "stones:brushrock_1"}, {["x"] = 4, ["y"] = 5, ["param1"] = 139, ["z"] = 11, ["name"] = "stones:rock"}, {["x"] = 4, ["param2"] = 3, ["y"] = 5, ["param1"] = 156, ["z"] = 12, ["name"] = "stones:brushrock_0"}, {["x"] = 4, ["param2"] = 5, ["y"] = 5, ["param1"] = 173, ["z"] = 13, ["name"] = "stones:brushrock_22"}, {["x"] = 4, ["param2"] = 1, ["y"] = 6, ["param1"] = 125, ["z"] = 9, ["name"] = "stones:diaq"}, {["x"] = 4, ["param2"] = 11, ["y"] = 6, ["param1"] = 140, ["z"] = 10, ["name"] = "stones:s_22"}, {["x"] = 4, ["y"] = 6, ["param1"] = 156, ["z"] = 11, ["name"] = "stones:rock"}, {["x"] = 4, ["param2"] = 15, ["y"] = 6, ["param1"] = 173, ["z"] = 12, ["name"] = "stones:s_52"}, {["x"] = 4, ["param2"] = 15, ["y"] = 6, ["param1"] = 190, ["z"] = 13, ["name"] = "stones:s_52"}, {["x"] = 4, ["param2"] = 1, ["y"] = 7, ["param1"] = 109, ["z"] = 9, ["name"] = "stones:diaq"}, {["x"] = 4, ["param2"] = 19, ["y"] = 7, ["param1"] = 141, ["z"] = 11, ["name"] = "stones:diagsteps_52rh"}, {["x"] = 4, ["y"] = 7, ["param1"] = 157, ["z"] = 12, ["name"] = "stones:s_52ul"}, {["x"] = 4, ["param2"] = 12, ["y"] = 7, ["param1"] = 174, ["z"] = 13, ["name"] = "stones:roch"}, {["x"] = 4, ["param2"] = 3, ["y"] = 7, ["param1"] = 157, ["z"] = 14, ["name"] = "stones:arsh"}, {["x"] = 4, ["param2"] = 1, ["y"] = 8, ["param1"] = 92, ["z"] = 9, ["name"] = "stones:diaq"}, {["x"] = 4, ["param2"] = 16, ["y"] = 8, ["param1"] = 124, ["z"] = 11, ["name"] = "stones:roch"}, {["x"] = 4, ["param2"] = 13, ["y"] = 8, ["param1"] = 157, ["z"] = 13, ["name"] = "stones:diagstep"}, {["x"] = 4, ["param2"] = 12, ["y"] = 8, ["param1"] = 140, ["z"] = 14, ["name"] = "stones:roch"}, {["x"] = 4, ["param2"] = 14, ["y"] = 8, ["param1"] = 124, ["z"] = 15, ["name"] = "stones:s_52"}, {["x"] = 4, ["param2"] = 8, ["y"] = 9, ["param1"] = 108, ["z"] = 0, ["name"] = "stones:roch"}, {["x"] = 4, ["param2"] = 2, ["y"] = 9, ["param1"] = 92, ["z"] = 1, ["name"] = "stones:brush"}, {["x"] = 4, ["y"] = 9, ["param1"] = 76, ["z"] = 2, ["name"] = "stones:brush"}, {["x"] = 4, ["param2"] = 3, ["y"] = 9, ["param1"] = 60, ["z"] = 3, ["name"] = "stones:brush"}, {["x"] = 4, ["param2"] = 1, ["y"] = 9, ["param1"] = 75, ["z"] = 4, ["name"] = "stones:brushrock_3"}, {["x"] = 4, ["param2"] = 16, ["y"] = 9, ["param1"] = 91, ["z"] = 5, ["name"] = "stones:s_52l"}, {["x"] = 4, ["param2"] = 16, ["y"] = 9, ["param1"] = 75, ["z"] = 6, ["name"] = "stones:s_52ul"}, {["x"] = 4, ["y"] = 9, ["param1"] = 91, ["z"] = 7, ["name"] = "stones:roch"}, {["x"] = 4, ["y"] = 9, ["param1"] = 76, ["z"] = 8, ["name"] = "stones:roch"}, {["x"] = 4, ["y"] = 9, ["param1"] = 75, ["z"] = 9, ["name"] = "stones:roch"}, {["x"] = 4, ["y"] = 9, ["param1"] = 91, ["z"] = 10, ["name"] = "stones:sku"}, {["x"] = 4, ["param2"] = 17, ["y"] = 9, ["param1"] = 107, ["z"] = 11, ["name"] = "stones:stair_2"}, {["x"] = 4, ["param2"] = 7, ["y"] = 9, ["param1"] = 123, ["z"] = 12, ["name"] = "stones:s_52l"}, {["x"] = 4, ["param2"] = 13, ["y"] = 9, ["param1"] = 124, ["z"] = 14, ["name"] = "stones:diagstep"}, {["x"] = 4, ["param2"] = 14, ["y"] = 9, ["param1"] = 108, ["z"] = 15, ["name"] = "stones:s_52"}, {["x"] = 4, ["param2"] = 8, ["y"] = 10, ["param1"] = 124, ["z"] = 0, ["name"] = "stones:panel"}, {["x"] = 4, ["param2"] = 17, ["y"] = 10, ["param1"] = 60, ["z"] = 4, ["name"] = "stones:stair_half_l"}, {["x"] = 4, ["param2"] = 14, ["y"] = 10, ["param1"] = 76, ["z"] = 5, ["name"] = "stones:sku2_l"}, {["x"] = 4, ["param2"] = 14, ["y"] = 10, ["param1"] = 60, ["z"] = 6, ["name"] = "stones:s_52l"}, {["x"] = 4, ["param2"] = 16, ["y"] = 10, ["param1"] = 91, ["z"] = 11, ["name"] = "stones:s_52r"}, {["x"] = 4, ["param2"] = 9, ["y"] = 10, ["param1"] = 107, ["z"] = 12, ["name"] = "stones:sku_202"}, {["x"] = 4, ["param2"] = 2, ["y"] = 11, ["param1"] = 44, ["z"] = 9, ["name"] = "stones:arch"}, {["x"] = 4, ["param2"] = 2, ["y"] = 11, ["param1"] = 58, ["z"] = 10, ["name"] = "stones:arch"}, {["x"] = 4, ["param2"] = 2, ["y"] = 11, ["param1"] = 74, ["z"] = 11, ["name"] = "stones:arch"}, {["x"] = 4, ["param2"] = 2, ["y"] = 11, ["param1"] = 90, ["z"] = 12, ["name"] = "stones:arco"}, {["x"] = 4, ["y"] = 12, ["param1"] = 28, ["z"] = 9, ["name"] = "stones:rock"}, {["x"] = 4, ["y"] = 12, ["param1"] = 43, ["z"] = 10, ["name"] = "stones:rock"}, {["x"] = 4, ["param2"] = 2, ["y"] = 12, ["param1"] = 58, ["z"] = 11, ["name"] = "stones:brushrock_3"}, {["x"] = 4, ["param2"] = 1, ["y"] = 12, ["param1"] = 76, ["z"] = 12, ["name"] = "stones:brushrock_0"}, {["x"] = 4, ["param2"] = 14, ["y"] = 12, ["param1"] = 92, ["z"] = 13, ["name"] = "stones:s_52u"}, {["x"] = 4, ["param2"] = 15, ["y"] = 12, ["param1"] = 76, ["z"] = 14, ["name"] = "stones:vr_2"}, {["x"] = 4, ["param2"] = 12, ["y"] = 12, ["param1"] = 60, ["z"] = 15, ["name"] = "stones:asect_2"}, {["x"] = 4, ["param2"] = 14, ["y"] = 12, ["param1"] = 44, ["z"] = 16, ["name"] = "stones:s_52"}, {["x"] = 4, ["param2"] = 15, ["y"] = 13, ["param1"] = 76, ["z"] = 13, ["name"] = "stones:sku2_l"}, {["x"] = 4, ["param2"] = 13, ["y"] = 14, ["param1"] = 60, ["z"] = 13, ["name"] = "stones:sku2_r"}, {["x"] = 4, ["param2"] = 3, ["y"] = 15, ["param1"] = 45, ["z"] = 13, ["name"] = "stones:s_22l"}, {["x"] = 5, ["param2"] = 11, ["y"] = 5, ["param1"] = 109, ["z"] = 7, ["name"] = "stones:brushrock_52ul"}, {["x"] = 5, ["param2"] = 3, ["y"] = 5, ["param1"] = 109, ["z"] = 8, ["name"] = "stones:brush"}, {["x"] = 5, ["param2"] = 2, ["y"] = 5, ["param1"] = 124, ["z"] = 9, ["name"] = "stones:brushrock_4"}, {["x"] = 5, ["param2"] = 1, ["y"] = 5, ["param1"] = 139, ["z"] = 10, ["name"] = "stones:plot"}, {["x"] = 5, ["param2"] = 3, ["y"] = 5, ["param1"] = 156, ["z"] = 11, ["name"] = "stones:brushrock_3"}, {["x"] = 5, ["param2"] = 3, ["y"] = 5, ["param1"] = 141, ["z"] = 12, ["name"] = "stones:brush"}, {["x"] = 5, ["param2"] = 7, ["y"] = 5, ["param1"] = 156, ["z"] = 13, ["name"] = "stones:brushrock_52ur"}, {["x"] = 5, ["param2"] = 11, ["y"] = 6, ["param1"] = 141, ["z"] = 9, ["name"] = "stones:s_52u"}, {["x"] = 5, ["param2"] = 7, ["y"] = 6, ["param1"] = 173, ["z"] = 11, ["name"] = "stones:s_52u"}, {["x"] = 5, ["param2"] = 11, ["y"] = 7, ["param1"] = 126, ["z"] = 9, ["name"] = "stones:s_52u"}, {["x"] = 5, ["param2"] = 7, ["y"] = 7, ["param1"] = 158, ["z"] = 11, ["name"] = "stones:s_52u"}, {["x"] = 5, ["param2"] = 11, ["y"] = 8, ["param1"] = 109, ["z"] = 9, ["name"] = "stones:s_52u"}, {["x"] = 5, ["param2"] = 4, ["y"] = 8, ["param1"] = 124, ["z"] = 10, ["name"] = "stones:cis"}, {["x"] = 5, ["param2"] = 7, ["y"] = 8, ["param1"] = 141, ["z"] = 11, ["name"] = "stones:s_52u"}, {["x"] = 5, ["param2"] = 11, ["y"] = 9, ["param1"] = 123, ["z"] = 0, ["name"] = "stones:panel"}, {["x"] = 5, ["param2"] = 12, ["y"] = 9, ["param1"] = 107, ["z"] = 1, ["name"] = "stones:brushrock_52ur"}, {["x"] = 5, ["param2"] = 1, ["y"] = 9, ["param1"] = 91, ["z"] = 2, ["name"] = "stones:brushrock_0"}, {["x"] = 5, ["param2"] = 14, ["y"] = 9, ["param1"] = 75, ["z"] = 3, ["name"] = "stones:brushrock_527l"}, {["x"] = 5, ["param2"] = 3, ["y"] = 9, ["param1"] = 60, ["z"] = 4, ["name"] = "stones:diagsteps_52lh"}, {["x"] = 5, ["y"] = 9, ["param1"] = 75, ["z"] = 5, ["name"] = "stones:roch"}, {["x"] = 5, ["param2"] = 2, ["y"] = 9, ["param1"] = 59, ["z"] = 6, ["name"] = "stones:roch"}, {["x"] = 5, ["param2"] = 14, ["y"] = 9, ["param1"] = 76, ["z"] = 7, ["name"] = "stones:s_52ul"}, {["x"] = 5, ["param2"] = 14, ["y"] = 9, ["param1"] = 76, ["z"] = 8, ["name"] = "stones:s_52l"}, {["x"] = 5, ["param2"] = 11, ["y"] = 9, ["param1"] = 92, ["z"] = 9, ["name"] = "stones:s_52u"}, {["x"] = 5, ["param2"] = 7, ["y"] = 9, ["param1"] = 124, ["z"] = 11, ["name"] = "stones:s_52u"}, {["x"] = 5, ["param2"] = 11, ["y"] = 10, ["param1"] = 140, ["z"] = 0, ["name"] = "stones:panel"}, {["x"] = 5, ["param2"] = 12, ["y"] = 10, ["param1"] = 124, ["z"] = 1, ["name"] = "stones:sku2_l"}, {["x"] = 5, ["param2"] = 5, ["y"] = 10, ["param1"] = 108, ["z"] = 2, ["name"] = "stones:panel"}, {["x"] = 5, ["param2"] = 11, ["y"] = 10, ["param1"] = 76, ["z"] = 9, ["name"] = "stones:s_52u"}, {["x"] = 5, ["param2"] = 22, ["y"] = 10, ["param1"] = 92, ["z"] = 10, ["name"] = "stones:sku2_l"}, {["x"] = 5, ["param2"] = 7, ["y"] = 10, ["param1"] = 108, ["z"] = 11, ["name"] = "stones:s_52u"}, {["x"] = 5, ["param2"] = 11, ["y"] = 11, ["param1"] = 60, ["z"] = 9, ["name"] = "stones:s_52u"}, {["x"] = 5, ["y"] = 11, ["param1"] = 76, ["z"] = 10, ["name"] = "stones:arch"}, {["x"] = 5, ["param2"] = 7, ["y"] = 11, ["param1"] = 92, ["z"] = 11, ["name"] = "stones:s_52u"}, {["x"] = 5, ["param2"] = 11, ["y"] = 12, ["param1"] = 44, ["z"] = 9, ["name"] = "stones:s_52u"}, {["x"] = 5, ["y"] = 12, ["param1"] = 58, ["z"] = 10, ["name"] = "stones:rock"}, {["x"] = 5, ["param2"] = 7, ["y"] = 12, ["param1"] = 76, ["z"] = 11, ["name"] = "stones:s_52u"}, {["x"] = 5, ["param2"] = 8, ["y"] = 13, ["param1"] = 28, ["z"] = 9, ["name"] = "stones:s_52r"}, {["x"] = 5, ["param2"] = 4, ["y"] = 13, ["param1"] = 44, ["z"] = 10, ["name"] = "stones:estruk"}, {["x"] = 5, ["param2"] = 6, ["y"] = 13, ["param1"] = 60, ["z"] = 11, ["name"] = "stones:s_52l"}, {["x"] = 5, ["param2"] = 1, ["y"] = 14, ["param1"] = 12, ["z"] = 9, ["name"] = "stones:s_22l"}, {["x"] = 5, ["param2"] = 19, ["y"] = 14, ["param1"] = 44, ["z"] = 11, ["name"] = "stones:s_22l"}, {["x"] = 6, ["param2"] = 11, ["y"] = 5, ["param1"] = 108, ["z"] = 7, ["name"] = "stones:s_52"}, {["x"] = 6, ["param2"] = 1, ["y"] = 5, ["param1"] = 124, ["z"] = 8, ["name"] = "stones:brushrock_c"}, {["x"] = 6, ["param2"] = 2, ["y"] = 5, ["param1"] = 139, ["z"] = 9, ["name"] = "stones:brush"}, {["x"] = 6, ["y"] = 5, ["param1"] = 156, ["z"] = 10, ["name"] = "stones:brush"}, {["x"] = 6, ["y"] = 5, ["param1"] = 172, ["z"] = 11, ["name"] = "stones:brush"}, {["x"] = 6, ["y"] = 5, ["param1"] = 156, ["z"] = 12, ["name"] = "stones:brushrock_c"}, {["x"] = 6, ["param2"] = 7, ["y"] = 5, ["param1"] = 140, ["z"] = 13, ["name"] = "stones:s_52"}, {["x"] = 6, ["param2"] = 16, ["y"] = 9, ["param1"] = 90, ["z"] = 1, ["name"] = "stones:s_52l"}, {["x"] = 6, ["param2"] = 16, ["y"] = 9, ["param1"] = 74, ["z"] = 2, ["name"] = "stones:s_52ul"}, {["x"] = 6, ["param2"] = 3, ["y"] = 9, ["param1"] = 59, ["z"] = 3, ["name"] = "stones:roch"}, {["x"] = 6, ["param2"] = 2, ["y"] = 9, ["param1"] = 43, ["z"] = 4, ["name"] = "stones:roch"}, {["x"] = 6, ["param2"] = 1, ["y"] = 9, ["param1"] = 59, ["z"] = 5, ["name"] = "stones:diagsteps_52lh"}, {["x"] = 6, ["param2"] = 16, ["y"] = 9, ["param1"] = 59, ["z"] = 6, ["name"] = "stones:brushrock_527l"}, {["x"] = 6, ["param2"] = 5, ["y"] = 9, ["param1"] = 76, ["z"] = 7, ["name"] = "stones:brushrock_22"}, {["x"] = 6, ["param2"] = 16, ["y"] = 10, ["param1"] = 124, ["z"] = 0, ["name"] = "stones:s_52l"}, {["x"] = 6, ["param2"] = 14, ["y"] = 10, ["param1"] = 108, ["z"] = 1, ["name"] = "stones:sku2_l"}, {["x"] = 6, ["param2"] = 7, ["y"] = 10, ["param1"] = 92, ["z"] = 2, ["name"] = "stones:s_22r"}, {["x"] = 6, ["param2"] = 16, ["y"] = 10, ["param1"] = 44, ["z"] = 5, ["name"] = "stones:s_52l"}, {["x"] = 6, ["param2"] = 14, ["y"] = 10, ["param1"] = 44, ["z"] = 6, ["name"] = "stones:sku2_l"}, {["x"] = 7, ["param2"] = 12, ["y"] = 5, ["param1"] = 140, ["z"] = 8, ["name"] = "stones:s_52"}, {["x"] = 7, ["param2"] = 12, ["y"] = 5, ["param1"] = 156, ["z"] = 9, ["name"] = "stones:brushrock_52ur"}, {["x"] = 7, ["param2"] = 1, ["y"] = 5, ["param1"] = 172, ["z"] = 10, ["name"] = "stones:brushrock_0"}, {["x"] = 7, ["param2"] = 14, ["y"] = 5, ["param1"] = 188, ["z"] = 11, ["name"] = "stones:brushrock_52ul"}, {["x"] = 7, ["param2"] = 14, ["y"] = 5, ["param1"] = 172, ["z"] = 12, ["name"] = "stones:s_52"}, {["x"] = 7, ["param2"] = 16, ["y"] = 9, ["param1"] = 90, ["z"] = 0, ["name"] = "stones:s_52ul"}, {["x"] = 7, ["y"] = 9, ["param1"] = 75, ["z"] = 1, ["name"] = "stones:roch"}, {["x"] = 7, ["param2"] = 2, ["y"] = 9, ["param1"] = 58, ["z"] = 2, ["name"] = "stones:roch"}, {["x"] = 7, ["param2"] = 14, ["y"] = 9, ["param1"] = 42, ["z"] = 3, ["name"] = "stones:s_52ul"}, {["x"] = 7, ["param2"] = 14, ["y"] = 9, ["param1"] = 42, ["z"] = 4, ["name"] = "stones:s_52l"}, {["x"] = 7, ["param2"] = 12, ["y"] = 9, ["param1"] = 60, ["z"] = 5, ["name"] = "stones:s_52"}, {["x"] = 7, ["param2"] = 3, ["y"] = 9, ["param1"] = 76, ["z"] = 6, ["name"] = "stones:brushrock_21"}, {["x"] = 7, ["param2"] = 7, ["y"] = 9, ["param1"] = 92, ["z"] = 7, ["name"] = "stones:brushrock_52ur"}, {["x"] = 7, ["param2"] = 14, ["y"] = 10, ["param1"] = 108, ["z"] = 0, ["name"] = "stones:s_52l"}, {["x"] = 7, ["param2"] = 16, ["y"] = 10, ["param1"] = 60, ["z"] = 3, ["name"] = "stones:s_52l"}, {["x"] = 7, ["param2"] = 14, ["y"] = 10, ["param1"] = 44, ["z"] = 4, ["name"] = "stones:sku2_l"}, {["x"] = 7, ["param2"] = 14, ["y"] = 10, ["param1"] = 44, ["z"] = 5, ["name"] = "stones:s_52l"}, {["x"] = 8, ["y"] = 9, ["param1"] = 76, ["z"] = 0, ["name"] = "stones:roch"}, {["x"] = 8, ["param2"] = 14, ["y"] = 9, ["param1"] = 76, ["z"] = 1, ["name"] = "stones:s_52ul"}, {["x"] = 8, ["param2"] = 14, ["y"] = 9, ["param1"] = 59, ["z"] = 2, ["name"] = "stones:s_52l"}, {["x"] = 8, ["param2"] = 11, ["y"] = 9, ["param1"] = 60, ["z"] = 6, ["name"] = "stones:s_22"}, {["x"] = 8, ["param2"] = 7, ["y"] = 9, ["param1"] = 76, ["z"] = 7, ["name"] = "stones:s_22"}, {["x"] = 8, ["param2"] = 9, ["y"] = 10, ["param1"] = 77, ["z"] = 1, ["name"] = "stones:s_22r"}, {["x"] = 8, ["param2"] = 14, ["y"] = 10, ["param1"] = 60, ["z"] = 2, ["name"] = "stones:sku2_l"}, {["x"] = 8, ["param2"] = 14, ["y"] = 10, ["param1"] = 44, ["z"] = 3, ["name"] = "stones:s_52l"}, {["x"] = 9, ["param2"] = 16, ["y"] = 9, ["param1"] = 76, ["z"] = 0, ["name"] = "stones:brushrock_527l"}, {["x"] = 9, ["param2"] = 3, ["y"] = 9, ["param1"] = 93, ["z"] = 1, ["name"] = "stones:brushrock_0"}, {["x"] = 9, ["param2"] = 5, ["y"] = 9, ["param1"] = 76, ["z"] = 2, ["name"] = "stones:brushrock_22"}, {["x"] = 9, ["param2"] = 11, ["y"] = 10, ["param1"] = 78, ["z"] = 1, ["name"] = "stones:panel"}, {["x"] = 9, ["param2"] = 12, ["y"] = 10, ["param1"] = 61, ["z"] = 2, ["name"] = "stones:sku_202"}, {["x"] = 10, ["y"] = 9, ["param1"] = 93, ["z"] = 0, ["name"] = "stones:brush"}, {["x"] = 10, ["y"] = 9, ["param1"] = 110, ["z"] = 1, ["name"] = "stones:brush"}, {["x"] = 10, ["y"] = 9, ["param1"] = 93, ["z"] = 2, ["name"] = "stones:brushrock_0"}, {["x"] = 10, ["param2"] = 8, ["y"] = 10, ["param1"] = 78, ["z"] = 2, ["name"] = "stones:panel"}, {["x"] = 11, ["y"] = 9, ["param1"] = 108, ["z"] = 0, ["name"] = "stones:brush"}, {["x"] = 11, ["param2"] = 1, ["y"] = 9, ["param1"] = 125, ["z"] = 1, ["name"] = "stones:brush"}, {["x"] = 11, ["param2"] = 7, ["y"] = 9, ["param1"] = 108, ["z"] = 2, ["name"] = "stones:brushrock_52ur"}, {["x"] = 11, ["param2"] = 7, ["y"] = 10, ["param1"] = 93, ["z"] = 2, ["name"] = "stones:sku2_l"}, {["x"] = 12, ["param2"] = 3, ["y"] = 9, ["param1"] = 123, ["z"] = 0, ["name"] = "stones:brushrock_21"}, {["x"] = 12, ["param2"] = 2, ["y"] = 9, ["param1"] = 140, ["z"] = 1, ["name"] = "stones:brushrock_21"}, {["x"] = 12, ["param2"] = 7, ["y"] = 9, ["param1"] = 123, ["z"] = 2, ["name"] = "stones:panel"}, {["x"] = 12, ["param2"] = 12, ["y"] = 10, ["param1"] = 108, ["z"] = 0, ["name"] = "stones:sku_202"}, {["x"] = 12, ["param2"] = 7, ["y"] = 10, ["param1"] = 125, ["z"] = 1, ["name"] = "stones:sku_202"}, {["x"] = 12, ["param2"] = 7, ["y"] = 10, ["param1"] = 108, ["z"] = 2, ["name"] = "stones:panel"}, {["x"] = 13, ["param2"] = 11, ["y"] = 9, ["param1"] = 140, ["z"] = 0, ["name"] = "stones:s_22"}, {["x"] = 13, ["param2"] = 7, ["y"] = 9, ["param1"] = 156, ["z"] = 1, ["name"] = "stones:s_22"}, {["x"] = 13, ["param2"] = 11, ["y"] = 10, ["param1"] = 124, ["z"] = 0, ["name"] = "stones:s_22"}, {["x"] = 13, ["param2"] = 7, ["y"] = 10, ["param1"] = 140, ["z"] = 1, ["name"] = "stones:s_22"}}