5:return {{["x"] = 0, ["param2"] = 20, ["y"] = 5, ["param1"] = 105, ["z"] = 18, ["name"] = "stones:diagstep"}, {["x"] = 0, ["param2"] = 20, ["y"] = 5, ["param1"] = 89, ["z"] = 19, ["name"] = "stones:roch"}, {["x"] = 0, ["param2"] = 20, ["y"] = 5, ["param1"] = 71, ["z"] = 20, ["name"] = "stones:roch"}, {["x"] = 0, ["param2"] = 14, ["y"] = 5, ["param1"] = 54, ["z"] = 21, ["name"] = "stones:s_52ur"}, {["x"] = 0, ["param2"] = 15, ["y"] = 5, ["param1"] = 69, ["z"] = 22, ["name"] = "stones:micro"}, {["x"] = 0, ["param2"] = 16, ["y"] = 6, ["param1"] = 108, ["z"] = 17, ["name"] = "stones:s_22r"}, {["x"] = 0, ["param2"] = 9, ["y"] = 6, ["param1"] = 92, ["z"] = 18, ["name"] = "stones:sku_202"}, {["x"] = 0, ["param2"] = 7, ["y"] = 6, ["param1"] = 71, ["z"] = 21, ["name"] = "stones:sku_202"}, {["x"] = 0, ["param2"] = 7, ["y"] = 6, ["param1"] = 86, ["z"] = 22, ["name"] = "stones:panel"}, {["x"] = 0, ["param2"] = 7, ["y"] = 7, ["param1"] = 71, ["z"] = 22, ["name"] = "stones:panel"}, {["x"] = 0, ["param2"] = 7, ["y"] = 8, ["param1"] = 55, ["z"] = 22, ["name"] = "stones:panel"}, {["x"] = 0, ["param2"] = 9, ["y"] = 9, ["param1"] = 12, ["z"] = 20, ["name"] = "stones:s_52"}, {["x"] = 0, ["param2"] = 2, ["y"] = 9, ["param1"] = 25, ["z"] = 21, ["name"] = "stones:diagsteps_52rh"}, {["x"] = 0, ["param2"] = 1, ["y"] = 9, ["param1"] = 41, ["z"] = 22, ["name"] = "stones:roch"}, {["x"] = 0, ["param2"] = 2, ["y"] = 9, ["param1"] = 57, ["z"] = 23, ["name"] = "stones:panel"}, {["x"] = 0, ["param2"] = 9, ["y"] = 10, ["param1"] = 12, ["z"] = 20, ["name"] = "stones:s_52r"}, {["x"] = 0, ["param2"] = 7, ["y"] = 10, ["param1"] = 28, ["z"] = 21, ["name"] = "stones:s_52r"}, {["x"] = 0, ["param2"] = 7, ["y"] = 10, ["param1"] = 60, ["z"] = 23, ["name"] = "stones:sku2_r"}, {["x"] = 1, ["param2"] = 9, ["y"] = 5, ["param1"] = 121, ["z"] = 16, ["name"] = "stones:micro"}, {["x"] = 1, ["param2"] = 16, ["y"] = 5, ["param1"] = 105, ["z"] = 17, ["name"] = "stones:s_52ur"}, {["x"] = 1, ["param2"] = 20, ["y"] = 5, ["param1"] = 89, ["z"] = 18, ["name"] = "stones:roch"}, {["x"] = 1, ["param2"] = 20, ["y"] = 5, ["param1"] = 73, ["z"] = 19, ["name"] = "stones:roch"}, {["x"] = 1, ["param2"] = 22, ["y"] = 5, ["param1"] = 55, ["z"] = 20, ["name"] = "stones:diagstep"}, {["x"] = 1, ["param2"] = 9, ["y"] = 6, ["param1"] = 108, ["z"] = 16, ["name"] = "stones:panel"}, {["x"] = 1, ["param2"] = 9, ["y"] = 6, ["param1"] = 92, ["z"] = 17, ["name"] = "stones:sku_202"}, {["x"] = 1, ["param2"] = 7, ["y"] = 6, ["param1"] = 41, ["z"] = 20, ["name"] = "stones:sku_202"}, {["x"] = 1, ["param2"] = 14, ["y"] = 6, ["param1"] = 55, ["z"] = 21, ["name"] = "stones:s_22r"}, {["x"] = 1, ["param2"] = 9, ["y"] = 9, ["param1"] = 9, ["z"] = 20, ["name"] = "stones:s_52ur"}, {["x"] = 1, ["param2"] = 7, ["y"] = 9, ["param1"] = 9, ["z"] = 21, ["name"] = "stones:estruk"}, {["x"] = 1, ["y"] = 9, ["param1"] = 25, ["z"] = 22, ["name"] = "stones:diagsteps_52rh"}, {["x"] = 1, ["param2"] = 7, ["y"] = 9, ["param1"] = 41, ["z"] = 23, ["name"] = "stones:s_52"}, {["x"] = 1, ["param2"] = 7, ["y"] = 10, ["param1"] = 12, ["z"] = 20, ["name"] = "stones:sku2_r"}, {["x"] = 1, ["param2"] = 9, ["y"] = 10, ["param1"] = 28, ["z"] = 22, ["name"] = "stones:s_52r"}, {["x"] = 1, ["param2"] = 7, ["y"] = 10, ["param1"] = 44, ["z"] = 23, ["name"] = "stones:s_52r"}, {["x"] = 2, ["param2"] = 9, ["y"] = 5, ["param1"] = 105, ["z"] = 16, ["name"] = "stones:s_52ul"}, {["x"] = 2, ["param2"] = 20, ["y"] = 5, ["param1"] = 89, ["z"] = 17, ["name"] = "stones:roch"}, {["x"] = 2, ["param2"] = 21, ["y"] = 5, ["param1"] = 73, ["z"] = 18, ["name"] = "stones:s_221"}, {["x"] = 2, ["param2"] = 14, ["y"] = 5, ["param1"] = 55, ["z"] = 19, ["name"] = "stones:s_52r"}, {["x"] = 2, ["param2"] = 16, ["y"] = 6, ["param1"] = 76, ["z"] = 15, ["name"] = "stones:s_22r"}, {["x"] = 2, ["param2"] = 9, ["y"] = 6, ["param1"] = 92, ["z"] = 16, ["name"] = "stones:sku_202"}, {["x"] = 2, ["param2"] = 7, ["y"] = 6, ["param1"] = 41, ["z"] = 19, ["name"] = "stones:sku_202"}, {["x"] = 2, ["param2"] = 14, ["y"] = 6, ["param1"] = 23, ["z"] = 20, ["name"] = "stones:s_22r"}, {["x"] = 2, ["param2"] = 9, ["y"] = 9, ["param1"] = 12, ["z"] = 19, ["name"] = "stones:s_52"}, {["x"] = 2, ["param2"] = 2, ["y"] = 9, ["param1"] = 9, ["z"] = 20, ["name"] = "stones:diagsteps_52rh"}, {["x"] = 2, ["param2"] = 9, ["y"] = 9, ["param1"] = 9, ["z"] = 21, ["name"] = "stones:estruk"}, {["x"] = 2, ["param2"] = 7, ["y"] = 9, ["param1"] = 9, ["z"] = 22, ["name"] = "stones:s_52ur"}, {["x"] = 2, ["param2"] = 9, ["y"] = 10, ["param1"] = 12, ["z"] = 19, ["name"] = "stones:s_52r"}, {["x"] = 2, ["param2"] = 7, ["y"] = 10, ["param1"] = 12, ["z"] = 20, ["name"] = "stones:s_52r"}, {["x"] = 2, ["param2"] = 7, ["y"] = 10, ["param1"] = 12, ["z"] = 22, ["name"] = "stones:sku2_r"}, {["x"] = 3, ["param2"] = 20, ["y"] = 5, ["param1"] = 73, ["z"] = 15, ["name"] = "stones:diagstep"}, {["x"] = 3, ["param2"] = 20, ["y"] = 5, ["param1"] = 89, ["z"] = 16, ["name"] = "stones:roch"}, {["x"] = 3, ["param2"] = 21, ["y"] = 5, ["param1"] = 73, ["z"] = 17, ["name"] = "stones:s_221"}, {["x"] = 3, ["param2"] = 14, ["y"] = 5, ["param1"] = 57, ["z"] = 18, ["name"] = "stones:s_22r"}, {["x"] = 3, ["param2"] = 16, ["y"] = 6, ["param1"] = 44, ["z"] = 14, ["name"] = "stones:s_22r"}, {["x"] = 3, ["param2"] = 9, ["y"] = 6, ["param1"] = 60, ["z"] = 15, ["name"] = "stones:sku_202"}, {["x"] = 3, ["param2"] = 7, ["y"] = 6, ["param1"] = 44, ["z"] = 18, ["name"] = "stones:sku_202"}, {["x"] = 3, ["param2"] = 14, ["y"] = 6, ["param1"] = 25, ["z"] = 19, ["name"] = "stones:s_22r"}, {["x"] = 3, ["y"] = 9, ["param1"] = 9, ["z"] = 19, ["name"] = "stones:panel"}, {["x"] = 3, ["param2"] = 1, ["y"] = 9, ["param1"] = 9, ["z"] = 20, ["name"] = "stones:roch"}, {["x"] = 3, ["y"] = 9, ["param1"] = 9, ["z"] = 21, ["name"] = "stones:diagsteps_52rh"}, {["x"] = 3, ["param2"] = 7, ["y"] = 9, ["param1"] = 25, ["z"] = 22, ["name"] = "stones:s_52"}, {["x"] = 3, ["param2"] = 7, ["y"] = 10, ["param1"] = 12, ["z"] = 19, ["name"] = "stones:sku2_r"}, {["x"] = 3, ["param2"] = 9, ["y"] = 10, ["param1"] = 12, ["z"] = 21, ["name"] = "stones:s_52r"}, {["x"] = 3, ["param2"] = 7, ["y"] = 10, ["param1"] = 12, ["z"] = 22, ["name"] = "stones:s_52r"}, {["x"] = 4, ["param2"] = 9, ["y"] = 5, ["param1"] = 41, ["z"] = 14, ["name"] = "stones:s_52l"}, {["x"] = 4, ["param2"] = 20, ["y"] = 5, ["param1"] = 57, ["z"] = 15, ["name"] = "stones:roch"}, {["x"] = 4, ["param2"] = 20, ["y"] = 5, ["param1"] = 73, ["z"] = 16, ["name"] = "stones:roch"}, {["x"] = 4, ["param2"] = 7, ["y"] = 5, ["param1"] = 57, ["z"] = 17, ["name"] = "stones:s_52l"}, {["x"] = 4, ["param2"] = 16, ["y"] = 6, ["param1"] = 60, ["z"] = 13, ["name"] = "stones:s_22r"}, {["x"] = 4, ["param2"] = 9, ["y"] = 6, ["param1"] = 44, ["z"] = 14, ["name"] = "stones:sku_202"}, {["x"] = 4, ["param2"] = 7, ["y"] = 6, ["param1"] = 44, ["z"] = 17, ["name"] = "stones:sku_202"}, {["x"] = 4, ["param2"] = 14, ["y"] = 6, ["param1"] = 25, ["z"] = 18, ["name"] = "stones:s_22r"}, {["x"] = 4, ["param2"] = 9, ["y"] = 9, ["param1"] = 9, ["z"] = 19, ["name"] = "stones:s_52ur"}, {["x"] = 4, ["param2"] = 1, ["y"] = 9, ["param1"] = 9, ["z"] = 20, ["name"] = "stones:roch"}, {["x"] = 4, ["param2"] = 7, ["y"] = 9, ["param1"] = 25, ["z"] = 21, ["name"] = "stones:s_52r"}, {["x"] = 4, ["param2"] = 9, ["y"] = 10, ["param1"] = 12, ["z"] = 18, ["name"] = "stones:s_52r"}, {["x"] = 4, ["param2"] = 7, ["y"] = 10, ["param1"] = 12, ["z"] = 19, ["name"] = "stones:s_52r"}, {["x"] = 4, ["param2"] = 7, ["y"] = 10, ["param1"] = 12, ["z"] = 21, ["name"] = "stones:sku2_r"}, {["x"] = 5, ["param2"] = 16, ["y"] = 5, ["param1"] = 57, ["z"] = 13, ["name"] = "stones:s_22r"}, {["x"] = 5, ["param2"] = 23, ["y"] = 5, ["param1"] = 41, ["z"] = 14, ["name"] = "stones:s_221"}, {["x"] = 5, ["param2"] = 20, ["y"] = 5, ["param1"] = 41, ["z"] = 15, ["name"] = "stones:roch"}, {["x"] = 5, ["param2"] = 22, ["y"] = 5, ["param1"] = 57, ["z"] = 16, ["name"] = "stones:diagstep"}, {["x"] = 5, ["param2"] = 16, ["y"] = 6, ["param1"] = 92, ["z"] = 12, ["name"] = "stones:s_22r"}, {["x"] = 5, ["param2"] = 9, ["y"] = 6, ["param1"] = 76, ["z"] = 13, ["name"] = "stones:sku_202"}, {["x"] = 5, ["param2"] = 7, ["y"] = 6, ["param1"] = 44, ["z"] = 16, ["name"] = "stones:sku_202"}, {["x"] = 5, ["param2"] = 14, ["y"] = 6, ["param1"] = 28, ["z"] = 17, ["name"] = "stones:s_22r"}, {["x"] = 5, ["param2"] = 9, ["y"] = 9, ["param1"] = 9, ["z"] = 18, ["name"] = "stones:s_52r"}, {["x"] = 5, ["param2"] = 1, ["y"] = 9, ["param1"] = 9, ["z"] = 19, ["name"] = "stones:roch"}, {["x"] = 5, ["param2"] = 7, ["y"] = 9, ["param1"] = 25, ["z"] = 20, ["name"] = "stones:s_52ur"}, {["x"] = 5, ["param2"] = 7, ["y"] = 10, ["param1"] = 12, ["z"] = 18, ["name"] = "stones:sku2_r"}, {["x"] = 5, ["param2"] = 9, ["y"] = 10, ["param1"] = 12, ["z"] = 20, ["name"] = "stones:s_52r"}, {["x"] = 5, ["param2"] = 7, ["y"] = 10, ["param1"] = 28, ["z"] = 21, ["name"] = "stones:s_52r"}, {["x"] = 6, ["param2"] = 16, ["y"] = 5, ["param1"] = 89, ["z"] = 12, ["name"] = "stones:s_52r"}, {["x"] = 6, ["param2"] = 23, ["y"] = 5, ["param1"] = 73, ["z"] = 13, ["name"] = "stones:s_221"}, {["x"] = 6, ["param2"] = 21, ["y"] = 5, ["param1"] = 57, ["z"] = 14, ["name"] = "stones:roch"}, {["x"] = 6, ["param2"] = 7, ["y"] = 5, ["param1"] = 41, ["z"] = 15, ["name"] = "stones:s_52ul"}, {["x"] = 6, ["param2"] = 16, ["y"] = 6, ["param1"] = 124, ["z"] = 11, ["name"] = "stones:s_22r"}, {["x"] = 6, ["param2"] = 9, ["y"] = 6, ["param1"] = 108, ["z"] = 12, ["name"] = "stones:sku_202"}, {["x"] = 6, ["param2"] = 7, ["y"] = 6, ["param1"] = 60, ["z"] = 15, ["name"] = "stones:sku_202"}, {["x"] = 6, ["param2"] = 14, ["y"] = 6, ["param1"] = 44, ["z"] = 16, ["name"] = "stones:s_22r"}, {["x"] = 6, ["param2"] = 9, ["y"] = 9, ["param1"] = 25, ["z"] = 18, ["name"] = "stones:s_52ur"}, {["x"] = 6, ["param2"] = 1, ["y"] = 9, ["param1"] = 25, ["z"] = 19, ["name"] = "stones:roch"}, {["x"] = 6, ["param2"] = 7, ["y"] = 9, ["param1"] = 41, ["z"] = 20, ["name"] = "stones:s_52r"}, {["x"] = 6, ["param2"] = 9, ["y"] = 10, ["param1"] = 28, ["z"] = 17, ["name"] = "stones:s_52r"}, {["x"] = 6, ["param2"] = 7, ["y"] = 10, ["param1"] = 12, ["z"] = 18, ["name"] = "stones:s_52r"}, {["x"] = 6, ["param2"] = 7, ["y"] = 10, ["param1"] = 28, ["z"] = 20, ["name"] = "stones:sku2_r"}, {["x"] = 7, ["param2"] = 20, ["y"] = 5, ["param1"] = 121, ["z"] = 11, ["name"] = "stones:diagstep"}, {["x"] = 7, ["param2"] = 20, ["y"] = 5, ["param1"] = 105, ["z"] = 12, ["name"] = "stones:roch"}, {["x"] = 7, ["param2"] = 20, ["y"] = 5, ["param1"] = 89, ["z"] = 13, ["name"] = "stones:roch"}, {["x"] = 7, ["param2"] = 14, ["y"] = 5, ["param1"] = 73, ["z"] = 14, ["name"] = "stones:s_52ur"}, {["x"] = 7, ["param2"] = 15, ["y"] = 5, ["param1"] = 57, ["z"] = 15, ["name"] = "stones:micro"}, {["x"] = 7, ["param2"] = 16, ["y"] = 6, ["param1"] = 156, ["z"] = 10, ["name"] = "stones:s_22r"}, {["x"] = 7, ["param2"] = 9, ["y"] = 6, ["param1"] = 140, ["z"] = 11, ["name"] = "stones:sku_202"}, {["x"] = 7, ["param2"] = 7, ["y"] = 6, ["param1"] = 92, ["z"] = 14, ["name"] = "stones:sku_202"}, {["x"] = 7, ["param2"] = 7, ["y"] = 6, ["param1"] = 76, ["z"] = 15, ["name"] = "stones:panel"}, {["x"] = 7, ["param2"] = 9, ["y"] = 9, ["param1"] = 57, ["z"] = 17, ["name"] = "stones:s_52r"}, {["x"] = 7, ["param2"] = 2, ["y"] = 9, ["param1"] = 41, ["z"] = 18, ["name"] = "stones:roch"}, {["x"] = 7, ["param2"] = 7, ["y"] = 9, ["param1"] = 41, ["z"] = 19, ["name"] = "stones:s_52ur"}, {["x"] = 7, ["param2"] = 7, ["y"] = 10, ["param1"] = 44, ["z"] = 17, ["name"] = "stones:sku2_r"}, {["x"] = 7, ["param2"] = 9, ["y"] = 10, ["param1"] = 28, ["z"] = 19, ["name"] = "stones:s_52r"}, {["x"] = 7, ["param2"] = 7, ["y"] = 10, ["param1"] = 44, ["z"] = 20, ["name"] = "stones:s_52r"}, {["x"] = 8, ["param2"] = 9, ["y"] = 5, ["param1"] = 170, ["z"] = 9, ["name"] = "stones:micro"}, {["x"] = 8, ["param2"] = 16, ["y"] = 5, ["param1"] = 153, ["z"] = 10, ["name"] = "stones:s_52ur"}, {["x"] = 8, ["param2"] = 20, ["y"] = 5, ["param1"] = 137, ["z"] = 11, ["name"] = "stones:roch"}, {["x"] = 8, ["param2"] = 20, ["y"] = 5, ["param1"] = 121, ["z"] = 12, ["name"] = "stones:roch"}, {["x"] = 8, ["param2"] = 22, ["y"] = 5, ["param1"] = 105, ["z"] = 13, ["name"] = "stones:diagstep"}, {["x"] = 8, ["param2"] = 9, ["y"] = 6, ["param1"] = 187, ["z"] = 9, ["name"] = "stones:panel"}, {["x"] = 8, ["param2"] = 9, ["y"] = 6, ["param1"] = 170, ["z"] = 10, ["name"] = "stones:sku_202"}, {["x"] = 8, ["param2"] = 7, ["y"] = 6, ["param1"] = 124, ["z"] = 13, ["name"] = "stones:sku_202"}, {["x"] = 8, ["param2"] = 14, ["y"] = 6, ["param1"] = 108, ["z"] = 14, ["name"] = "stones:s_22r"}, {["x"] = 8, ["param2"] = 8, ["y"] = 7, ["param1"] = 204, ["z"] = 9, ["name"] = "stones:s_52ur"}, {["x"] = 8, ["param2"] = 10, ["y"] = 8, ["param1"] = 221, ["z"] = 9, ["name"] = "stones:spikle"}, {["x"] = 8, ["param2"] = 9, ["y"] = 9, ["param1"] = 73, ["z"] = 17, ["name"] = "stones:s_52ur"}, {["x"] = 8, ["param2"] = 1, ["y"] = 9, ["param1"] = 57, ["z"] = 18, ["name"] = "stones:roch"}, {["x"] = 8, ["param2"] = 7, ["y"] = 9, ["param1"] = 57, ["z"] = 19, ["name"] = "stones:s_52r"}, {["x"] = 8, ["param2"] = 9, ["y"] = 10, ["param1"] = 76, ["z"] = 16, ["name"] = "stones:s_52r"}, {["x"] = 8, ["param2"] = 7, ["y"] = 10, ["param1"] = 60, ["z"] = 17, ["name"] = "stones:s_52r"}, {["x"] = 8, ["param2"] = 7, ["y"] = 10, ["param1"] = 44, ["z"] = 19, ["name"] = "stones:sku2_r"}, {["x"] = 9, ["param2"] = 9, ["y"] = 5, ["param1"] = 187, ["z"] = 9, ["name"] = "stones:s_52ul"}, {["x"] = 9, ["param2"] = 20, ["y"] = 5, ["param1"] = 170, ["z"] = 10, ["name"] = "stones:roch"}, {["x"] = 9, ["param2"] = 21, ["y"] = 5, ["param1"] = 153, ["z"] = 11, ["name"] = "stones:s_221"}, {["x"] = 9, ["param2"] = 14, ["y"] = 5, ["param1"] = 137, ["z"] = 12, ["name"] = "stones:s_52r"}, {["x"] = 9, ["param2"] = 16, ["y"] = 6, ["param1"] = 188, ["z"] = 8, ["name"] = "stones:s_22r"}, {["x"] = 9, ["param2"] = 9, ["y"] = 6, ["param1"] = 204, ["z"] = 9, ["name"] = "stones:sku_202"}, {["x"] = 9, ["param2"] = 7, ["y"] = 6, ["param1"] = 156, ["z"] = 12, ["name"] = "stones:sku_202"}, {["x"] = 9, ["param2"] = 14, ["y"] = 6, ["param1"] = 140, ["z"] = 13, ["name"] = "stones:s_22r"}, {["x"] = 9, ["param2"] = 13, ["y"] = 8, ["param1"] = 238, ["z"] = 9, ["name"] = "stones:estamp"}, {["x"] = 9, ["param2"] = 9, ["y"] = 9, ["param1"] = 105, ["z"] = 16, ["name"] = "stones:s_52r"}, {["x"] = 9, ["param2"] = 2, ["y"] = 9, ["param1"] = 89, ["z"] = 17, ["name"] = "stones:roch"}, {["x"] = 9, ["param2"] = 7, ["y"] = 9, ["param1"] = 73, ["z"] = 18, ["name"] = "stones:s_52ur"}, {["x"] = 9, ["param2"] = 7, ["y"] = 10, ["param1"] = 92, ["z"] = 16, ["name"] = "stones:sku2_r"}, {["x"] = 9, ["param2"] = 9, ["y"] = 10, ["param1"] = 60, ["z"] = 18, ["name"] = "stones:s_52r"}, {["x"] = 9, ["param2"] = 7, ["y"] = 10, ["param1"] = 44, ["z"] = 19, ["name"] = "stones:s_52r"}, {["x"] = 10, ["param2"] = 20, ["y"] = 5, ["param1"] = 153, ["z"] = 8, ["name"] = "stones:diagstep"}, {["x"] = 10, ["param2"] = 20, ["y"] = 5, ["param1"] = 170, ["z"] = 9, ["name"] = "stones:roch"}, {["x"] = 10, ["param2"] = 21, ["y"] = 5, ["param1"] = 153, ["z"] = 10, ["name"] = "stones:s_221"}, {["x"] = 10, ["param2"] = 14, ["y"] = 5, ["param1"] = 137, ["z"] = 11, ["name"] = "stones:s_22r"}, {["x"] = 10, ["param2"] = 16, ["y"] = 6, ["param1"] = 156, ["z"] = 7, ["name"] = "stones:s_22r"}, {["x"] = 10, ["param2"] = 9, ["y"] = 6, ["param1"] = 172, ["z"] = 8, ["name"] = "stones:sku_202"}, {["x"] = 10, ["param2"] = 7, ["y"] = 6, ["param1"] = 156, ["z"] = 11, ["name"] = "stones:sku_202"}, {["x"] = 10, ["param2"] = 14, ["y"] = 6, ["param1"] = 140, ["z"] = 12, ["name"] = "stones:s_22r"}, {["x"] = 10, ["param2"] = 9, ["y"] = 9, ["param1"] = 89, ["z"] = 16, ["name"] = "stones:s_52ur"}, {["x"] = 10, ["param2"] = 2, ["y"] = 9, ["param1"] = 73, ["z"] = 17, ["name"] = "stones:roch"}, {["x"] = 10, ["param2"] = 7, ["y"] = 9, ["param1"] = 57, ["z"] = 18, ["name"] = "stones:s_52r"}, {["x"] = 10, ["param2"] = 9, ["y"] = 10, ["param1"] = 92, ["z"] = 15, ["name"] = "stones:s_52r"}, {["x"] = 10, ["param2"] = 7, ["y"] = 10, ["param1"] = 76, ["z"] = 16, ["name"] = "stones:s_52r"}, {["x"] = 10, ["param2"] = 7, ["y"] = 10, ["param1"] = 44, ["z"] = 18, ["name"] = "stones:sku2_r"}, {["x"] = 11, ["param2"] = 20, ["y"] = 5, ["param1"] = 121, ["z"] = 7, ["name"] = "stones:diagstep"}, {["x"] = 11, ["param2"] = 20, ["y"] = 5, ["param1"] = 137, ["z"] = 8, ["name"] = "stones:roch"}, {["x"] = 11, ["param2"] = 20, ["y"] = 5, ["param1"] = 153, ["z"] = 9, ["name"] = "stones:roch"}, {["x"] = 11, ["param2"] = 7, ["y"] = 5, ["param1"] = 137, ["z"] = 10, ["name"] = "stones:s_52l"}, {["x"] = 11, ["param2"] = 16, ["y"] = 6, ["param1"] = 124, ["z"] = 6, ["name"] = "stones:s_22r"}, {["x"] = 11, ["param2"] = 9, ["y"] = 6, ["param1"] = 140, ["z"] = 7, ["name"] = "stones:sku_202"}, {["x"] = 11, ["param2"] = 7, ["y"] = 6, ["param1"] = 156, ["z"] = 10, ["name"] = "stones:sku_202"}, {["x"] = 11, ["param2"] = 14, ["y"] = 6, ["param1"] = 140, ["z"] = 11, ["name"] = "stones:s_22r"}, {["x"] = 11, ["param2"] = 9, ["y"] = 9, ["param1"] = 89, ["z"] = 15, ["name"] = "stones:s_52r"}, {["x"] = 11, ["param2"] = 2, ["y"] = 9, ["param1"] = 73, ["z"] = 16, ["name"] = "stones:roch"}, {["x"] = 11, ["param2"] = 7, ["y"] = 9, ["param1"] = 57, ["z"] = 17, ["name"] = "stones:s_52ur"}, {["x"] = 11, ["param2"] = 7, ["y"] = 10, ["param1"] = 76, ["z"] = 15, ["name"] = "stones:sku2_r"}, {["x"] = 11, ["param2"] = 9, ["y"] = 10, ["param1"] = 44, ["z"] = 17, ["name"] = "stones:s_52r"}, {["x"] = 11, ["param2"] = 7, ["y"] = 10, ["param1"] = 28, ["z"] = 18, ["name"] = "stones:s_52r"}, {["x"] = 12, ["param2"] = 20, ["y"] = 5, ["param1"] = 92, ["z"] = 6, ["name"] = "stones:diagstep"}, {["x"] = 12, ["param2"] = 20, ["y"] = 5, ["param1"] = 105, ["z"] = 7, ["name"] = "stones:roch"}, {["x"] = 12, ["param2"] = 20, ["y"] = 5, ["param1"] = 121, ["z"] = 8, ["name"] = "stones:roch"}, {["x"] = 12, ["param2"] = 22, ["y"] = 5, ["param1"] = 137, ["z"] = 9, ["name"] = "stones:diagstep"}, {["x"] = 12, ["param2"] = 9, ["y"] = 6, ["param1"] = 108, ["z"] = 6, ["name"] = "stones:sku_202"}, {["x"] = 12, ["param2"] = 7, ["y"] = 6, ["param1"] = 156, ["z"] = 9, ["name"] = "stones:sku_202"}, {["x"] = 12, ["param2"] = 14, ["y"] = 6, ["param1"] = 140, ["z"] = 10, ["name"] = "stones:s_22r"}, {["x"] = 12, ["param2"] = 9, ["y"] = 9, ["param1"] = 92, ["z"] = 14, ["name"] = "stones:s_52"}, {["x"] = 12, ["param2"] = 2, ["y"] = 9, ["param1"] = 73, ["z"] = 15, ["name"] = "stones:diagsteps_52rh"}, {["x"] = 12, ["param2"] = 1, ["y"] = 9, ["param1"] = 57, ["z"] = 16, ["name"] = "stones:roch"}, {["x"] = 12, ["param2"] = 2, ["y"] = 9, ["param1"] = 41, ["z"] = 17, ["name"] = "stones:panel"}, {["x"] = 12, ["param2"] = 9, ["y"] = 10, ["param1"] = 76, ["z"] = 14, ["name"] = "stones:s_52r"}, {["x"] = 12, ["param2"] = 7, ["y"] = 10, ["param1"] = 60, ["z"] = 15, ["name"] = "stones:s_52r"}, {["x"] = 12, ["param2"] = 7, ["y"] = 10, ["param1"] = 28, ["z"] = 17, ["name"] = "stones:sku2_r"}, {["x"] = 13, ["param2"] = 20, ["y"] = 5, ["param1"] = 76, ["z"] = 6, ["name"] = "stones:roch"}, {["x"] = 13, ["param2"] = 20, ["y"] = 5, ["param1"] = 92, ["z"] = 7, ["name"] = "stones:roch"}, {["x"] = 13, ["param2"] = 22, ["y"] = 5, ["param1"] = 108, ["z"] = 8, ["name"] = "stones:diagstep"}, {["x"] = 13, ["param2"] = 7, ["y"] = 6, ["param1"] = 124, ["z"] = 8, ["name"] = "stones:sku_202"}, {["x"] = 13, ["param2"] = 14, ["y"] = 6, ["param1"] = 140, ["z"] = 9, ["name"] = "stones:s_22r"}, {["x"] = 13, ["param2"] = 9, ["y"] = 9, ["param1"] = 73, ["z"] = 14, ["name"] = "stones:s_52ur"}, {["x"] = 13, ["param2"] = 7, ["y"] = 9, ["param1"] = 57, ["z"] = 15, ["name"] = "stones:estruk"}, {["x"] = 13, ["y"] = 9, ["param1"] = 41, ["z"] = 16, ["name"] = "stones:diagsteps_52rh"}, {["x"] = 13, ["param2"] = 7, ["y"] = 9, ["param1"] = 25, ["z"] = 17, ["name"] = "stones:s_52"}, {["x"] = 13, ["param2"] = 7, ["y"] = 10, ["param1"] = 60, ["z"] = 14, ["name"] = "stones:sku2_r"}, {["x"] = 13, ["param2"] = 9, ["y"] = 10, ["param1"] = 28, ["z"] = 16, ["name"] = "stones:s_52r"}, {["x"] = 13, ["param2"] = 7, ["y"] = 10, ["param1"] = 12, ["z"] = 17, ["name"] = "stones:s_52r"}, {["x"] = 14, ["param2"] = 9, ["y"] = 9, ["param1"] = 76, ["z"] = 13, ["name"] = "stones:s_52"}, {["x"] = 14, ["param2"] = 2, ["y"] = 9, ["param1"] = 57, ["z"] = 14, ["name"] = "stones:diagsteps_52rh"}, {["x"] = 14, ["param2"] = 9, ["y"] = 9, ["param1"] = 41, ["z"] = 15, ["name"] = "stones:estruk"}, {["x"] = 14, ["param2"] = 7, ["y"] = 9, ["param1"] = 25, ["z"] = 16, ["name"] = "stones:s_52ur"}, {["x"] = 14, ["param2"] = 9, ["y"] = 10, ["param1"] = 60, ["z"] = 13, ["name"] = "stones:s_52r"}, {["x"] = 14, ["param2"] = 7, ["y"] = 10, ["param1"] = 44, ["z"] = 14, ["name"] = "stones:s_52r"}, {["x"] = 14, ["param2"] = 7, ["y"] = 10, ["param1"] = 12, ["z"] = 16, ["name"] = "stones:sku2_r"}, {["x"] = 15, ["y"] = 9, ["param1"] = 57, ["z"] = 13, ["name"] = "stones:panel"}, {["x"] = 15, ["param2"] = 1, ["y"] = 9, ["param1"] = 41, ["z"] = 14, ["name"] = "stones:roch"}, {["x"] = 15, ["y"] = 9, ["param1"] = 25, ["z"] = 15, ["name"] = "stones:diagsteps_52rh"}, {["x"] = 15, ["param2"] = 7, ["y"] = 9, ["param1"] = 9, ["z"] = 16, ["name"] = "stones:s_52"}, {["x"] = 15, ["param2"] = 7, ["y"] = 10, ["param1"] = 44, ["z"] = 13, ["name"] = "stones:sku2_r"}, {["x"] = 15, ["param2"] = 9, ["y"] = 10, ["param1"] = 12, ["z"] = 15, ["name"] = "stones:s_52r"}, {["x"] = 15, ["param2"] = 7, ["y"] = 10, ["param1"] = 12, ["z"] = 16, ["name"] = "stones:s_52r"}, {["x"] = 16, ["param2"] = 9, ["y"] = 9, ["param1"] = 41, ["z"] = 13, ["name"] = "stones:s_52ur"}, {["x"] = 16, ["param2"] = 1, ["y"] = 9, ["param1"] = 25, ["z"] = 14, ["name"] = "stones:roch"}, {["x"] = 16, ["param2"] = 7, ["y"] = 9, ["param1"] = 9, ["z"] = 15, ["name"] = "stones:s_52r"}, {["x"] = 16, ["param2"] = 9, ["y"] = 10, ["param1"] = 44, ["z"] = 12, ["name"] = "stones:s_52r"}, {["x"] = 16, ["param2"] = 7, ["y"] = 10, ["param1"] = 28, ["z"] = 13, ["name"] = "stones:s_52r"}, {["x"] = 16, ["param2"] = 7, ["y"] = 10, ["param1"] = 12, ["z"] = 15, ["name"] = "stones:sku2_r"}, {["x"] = 17, ["param2"] = 9, ["y"] = 9, ["param1"] = 41, ["z"] = 12, ["name"] = "stones:s_52r"}, {["x"] = 17, ["param2"] = 1, ["y"] = 9, ["param1"] = 25, ["z"] = 13, ["name"] = "stones:roch"}, {["x"] = 17, ["param2"] = 7, ["y"] = 9, ["param1"] = 9, ["z"] = 14, ["name"] = "stones:s_52ur"}, {["x"] = 17, ["param2"] = 7, ["y"] = 10, ["param1"] = 28, ["z"] = 12, ["name"] = "stones:sku2_r"}, {["x"] = 17, ["param2"] = 9, ["y"] = 10, ["param1"] = 12, ["z"] = 14, ["name"] = "stones:s_52r"}, {["x"] = 17, ["param2"] = 7, ["y"] = 10, ["param1"] = 12, ["z"] = 15, ["name"] = "stones:s_52r"}, {["x"] = 18, ["param2"] = 9, ["y"] = 9, ["param1"] = 25, ["z"] = 12, ["name"] = "stones:s_52ur"}, {["x"] = 18, ["param2"] = 1, ["y"] = 9, ["param1"] = 9, ["z"] = 13, ["name"] = "stones:roch"}, {["x"] = 18, ["param2"] = 7, ["y"] = 9, ["param1"] = 9, ["z"] = 14, ["name"] = "stones:s_52r"}, {["x"] = 18, ["param2"] = 9, ["y"] = 10, ["param1"] = 28, ["z"] = 11, ["name"] = "stones:s_52r"}, {["x"] = 18, ["param2"] = 7, ["y"] = 10, ["param1"] = 12, ["z"] = 12, ["name"] = "stones:s_52r"}, {["x"] = 18, ["param2"] = 7, ["y"] = 10, ["param1"] = 12, ["z"] = 14, ["name"] = "stones:sku2_r"}, {["x"] = 19, ["param2"] = 9, ["y"] = 9, ["param1"] = 25, ["z"] = 11, ["name"] = "stones:s_52r"}, {["x"] = 19, ["param2"] = 2, ["y"] = 9, ["param1"] = 9, ["z"] = 12, ["name"] = "stones:roch"}, {["x"] = 19, ["param2"] = 7, ["y"] = 9, ["param1"] = 9, ["z"] = 13, ["name"] = "stones:s_52ur"}, {["x"] = 19, ["param2"] = 7, ["y"] = 10, ["param1"] = 12, ["z"] = 11, ["name"] = "stones:sku2_r"}, {["x"] = 19, ["param2"] = 9, ["y"] = 10, ["param1"] = 12, ["z"] = 13, ["name"] = "stones:s_52r"}, {["x"] = 19, ["param2"] = 7, ["y"] = 10, ["param1"] = 12, ["z"] = 14, ["name"] = "stones:s_52r"}, {["x"] = 20, ["param2"] = 9, ["y"] = 9, ["param1"] = 9, ["z"] = 11, ["name"] = "stones:s_52ur"}, {["x"] = 20, ["param2"] = 1, ["y"] = 9, ["param1"] = 9, ["z"] = 12, ["name"] = "stones:roch"}, {["x"] = 20, ["param2"] = 7, ["y"] = 9, ["param1"] = 9, ["z"] = 13, ["name"] = "stones:s_52r"}, {["x"] = 20, ["param2"] = 9, ["y"] = 10, ["param1"] = 12, ["z"] = 10, ["name"] = "stones:s_52r"}, {["x"] = 20, ["param2"] = 7, ["y"] = 10, ["param1"] = 12, ["z"] = 11, ["name"] = "stones:s_52r"}, {["x"] = 20, ["param2"] = 7, ["y"] = 10, ["param1"] = 12, ["z"] = 13, ["name"] = "stones:sku2_r"}, {["x"] = 21, ["param2"] = 9, ["y"] = 9, ["param1"] = 9, ["z"] = 10, ["name"] = "stones:s_52r"}, {["x"] = 21, ["param2"] = 2, ["y"] = 9, ["param1"] = 9, ["z"] = 11, ["name"] = "stones:roch"}, {["x"] = 21, ["param2"] = 7, ["y"] = 9, ["param1"] = 9, ["z"] = 12, ["name"] = "stones:s_52ur"}, {["x"] = 21, ["param2"] = 7, ["y"] = 10, ["param1"] = 12, ["z"] = 10, ["name"] = "stones:sku2_r"}, {["x"] = 21, ["param2"] = 9, ["y"] = 10, ["param1"] = 12, ["z"] = 12, ["name"] = "stones:s_52r"}, {["x"] = 21, ["param2"] = 7, ["y"] = 10, ["param1"] = 12, ["z"] = 13, ["name"] = "stones:s_52r"}, {["x"] = 22, ["param2"] = 9, ["y"] = 9, ["param1"] = 9, ["z"] = 10, ["name"] = "stones:s_52ur"}, {["x"] = 22, ["param2"] = 2, ["y"] = 9, ["param1"] = 9, ["z"] = 11, ["name"] = "stones:roch"}, {["x"] = 22, ["param2"] = 7, ["y"] = 9, ["param1"] = 9, ["z"] = 12, ["name"] = "stones:s_52r"}, {["x"] = 22, ["param2"] = 9, ["y"] = 10, ["param1"] = 12, ["z"] = 9, ["name"] = "stones:s_52r"}, {["x"] = 22, ["param2"] = 7, ["y"] = 10, ["param1"] = 12, ["z"] = 10, ["name"] = "stones:s_52r"}, {["x"] = 22, ["param2"] = 7, ["y"] = 10, ["param1"] = 12, ["z"] = 12, ["name"] = "stones:sku2_r"}, {["x"] = 23, ["param2"] = 9, ["y"] = 9, ["param1"] = 9, ["z"] = 9, ["name"] = "stones:s_52r"}, {["x"] = 23, ["param2"] = 2, ["y"] = 9, ["param1"] = 9, ["z"] = 10, ["name"] = "stones:roch"}, {["x"] = 23, ["param2"] = 7, ["y"] = 9, ["param1"] = 9, ["z"] = 11, ["name"] = "stones:s_52ur"}, {["x"] = 23, ["param2"] = 7, ["y"] = 10, ["param1"] = 12, ["z"] = 9, ["name"] = "stones:sku2_r"}, {["x"] = 23, ["param2"] = 9, ["y"] = 10, ["param1"] = 12, ["z"] = 11, ["name"] = "stones:s_52r"}, {["x"] = 23, ["param2"] = 7, ["y"] = 10, ["param1"] = 12, ["z"] = 12, ["name"] = "stones:s_52r"}, {["x"] = 24, ["param2"] = 9, ["y"] = 9, ["param1"] = 12, ["z"] = 8, ["name"] = "stones:s_52"}, {["x"] = 24, ["param2"] = 2, ["y"] = 9, ["param1"] = 9, ["z"] = 9, ["name"] = "stones:diagsteps_52rh"}, {["x"] = 24, ["param2"] = 1, ["y"] = 9, ["param1"] = 9, ["z"] = 10, ["name"] = "stones:roch"}, {["x"] = 24, ["param2"] = 2, ["y"] = 9, ["param1"] = 9, ["z"] = 11, ["name"] = "stones:panel"}, {["x"] = 24, ["param2"] = 9, ["y"] = 10, ["param1"] = 12, ["z"] = 8, ["name"] = "stones:s_52r"}, {["x"] = 24, ["param2"] = 7, ["y"] = 10, ["param1"] = 12, ["z"] = 9, ["name"] = "stones:s_52r"}, {["x"] = 24, ["param2"] = 7, ["y"] = 10, ["param1"] = 12, ["z"] = 11, ["name"] = "stones:sku2_r"}, {["x"] = 25, ["param2"] = 9, ["y"] = 9, ["param1"] = 9, ["z"] = 8, ["name"] = "stones:s_52ur"}, {["x"] = 25, ["param2"] = 7, ["y"] = 9, ["param1"] = 9, ["z"] = 9, ["name"] = "stones:estruk"}, {["x"] = 25, ["y"] = 9, ["param1"] = 9, ["z"] = 10, ["name"] = "stones:diagsteps_52rh"}, {["x"] = 25, ["param2"] = 7, ["y"] = 9, ["param1"] = 9, ["z"] = 11, ["name"] = "stones:s_52"}, {["x"] = 25, ["param2"] = 7, ["y"] = 10, ["param1"] = 12, ["z"] = 8, ["name"] = "stones:sku2_r"}, {["x"] = 25, ["param2"] = 9, ["y"] = 10, ["param1"] = 12, ["z"] = 10, ["name"] = "stones:s_52r"}, {["x"] = 25, ["param2"] = 7, ["y"] = 10, ["param1"] = 12, ["z"] = 11, ["name"] = "stones:s_52r"}, {["x"] = 26, ["param2"] = 9, ["y"] = 9, ["param1"] = 12, ["z"] = 7, ["name"] = "stones:s_52"}, {["x"] = 26, ["param2"] = 2, ["y"] = 9, ["param1"] = 9, ["z"] = 8, ["name"] = "stones:diagsteps_52rh"}, {["x"] = 26, ["param2"] = 9, ["y"] = 9, ["param1"] = 9, ["z"] = 9, ["name"] = "stones:estruk"}, {["x"] = 26, ["param2"] = 7, ["y"] = 9, ["param1"] = 9, ["z"] = 10, ["name"] = "stones:s_52ur"}, {["x"] = 26, ["param2"] = 9, ["y"] = 10, ["param1"] = 12, ["z"] = 7, ["name"] = "stones:s_52r"}, {["x"] = 26, ["param2"] = 7, ["y"] = 10, ["param1"] = 12, ["z"] = 8, ["name"] = "stones:s_52r"}, {["x"] = 26, ["param2"] = 7, ["y"] = 10, ["param1"] = 12, ["z"] = 10, ["name"] = "stones:sku2_r"}, {["x"] = 27, ["y"] = 9, ["param1"] = 9, ["z"] = 7, ["name"] = "stones:panel"}, {["x"] = 27, ["param2"] = 1, ["y"] = 9, ["param1"] = 9, ["z"] = 8, ["name"] = "stones:roch"}, {["x"] = 27, ["y"] = 9, ["param1"] = 9, ["z"] = 9, ["name"] = "stones:diagsteps_52rh"}, {["x"] = 27, ["param2"] = 7, ["y"] = 9, ["param1"] = 9, ["z"] = 10, ["name"] = "stones:s_52"}, {["x"] = 27, ["param2"] = 7, ["y"] = 10, ["param1"] = 12, ["z"] = 7, ["name"] = "stones:sku2_r"}, {["x"] = 27, ["param2"] = 9, ["y"] = 10, ["param1"] = 12, ["z"] = 9, ["name"] = "stones:s_52r"}, {["x"] = 27, ["param2"] = 7, ["y"] = 10, ["param1"] = 12, ["z"] = 10, ["name"] = "stones:s_52r"}, {["x"] = 28, ["param2"] = 9, ["y"] = 9, ["param1"] = 9, ["z"] = 7, ["name"] = "stones:s_52ur"}, {["x"] = 28, ["param2"] = 1, ["y"] = 9, ["param1"] = 9, ["z"] = 8, ["name"] = "stones:roch"}, {["x"] = 28, ["param2"] = 7, ["y"] = 9, ["param1"] = 9, ["z"] = 9, ["name"] = "stones:s_52r"}, {["x"] = 28, ["param2"] = 9, ["y"] = 10, ["param1"] = 12, ["z"] = 6, ["name"] = "stones:s_52r"}, {["x"] = 28, ["param2"] = 7, ["y"] = 10, ["param1"] = 12, ["z"] = 7, ["name"] = "stones:s_52r"}, {["x"] = 28, ["param2"] = 7, ["y"] = 10, ["param1"] = 12, ["z"] = 9, ["name"] = "stones:sku2_r"}, {["x"] = 29, ["param2"] = 9, ["y"] = 9, ["param1"] = 9, ["z"] = 6, ["name"] = "stones:s_52r"}, {["x"] = 29, ["param2"] = 1, ["y"] = 9, ["param1"] = 9, ["z"] = 7, ["name"] = "stones:roch"}, {["x"] = 29, ["param2"] = 7, ["y"] = 9, ["param1"] = 9, ["z"] = 8, ["name"] = "stones:s_52ur"}, {["x"] = 29, ["param2"] = 7, ["y"] = 10, ["param1"] = 12, ["z"] = 6, ["name"] = "stones:sku2_r"}, {["x"] = 29, ["param2"] = 9, ["y"] = 10, ["param1"] = 12, ["z"] = 8, ["name"] = "stones:s_52r"}, {["x"] = 29, ["param2"] = 7, ["y"] = 10, ["param1"] = 12, ["z"] = 9, ["name"] = "stones:s_52r"}, {["x"] = 30, ["param2"] = 9, ["y"] = 9, ["param1"] = 9, ["z"] = 6, ["name"] = "stones:s_52ur"}, {["x"] = 30, ["param2"] = 1, ["y"] = 9, ["param1"] = 9, ["z"] = 7, ["name"] = "stones:roch"}, {["x"] = 30, ["param2"] = 7, ["y"] = 9, ["param1"] = 9, ["z"] = 8, ["name"] = "stones:s_52r"}, {["x"] = 30, ["param2"] = 9, ["y"] = 10, ["param1"] = 12, ["z"] = 5, ["name"] = "stones:s_52r"}, {["x"] = 30, ["param2"] = 7, ["y"] = 10, ["param1"] = 12, ["z"] = 6, ["name"] = "stones:s_52r"}, {["x"] = 30, ["param2"] = 7, ["y"] = 10, ["param1"] = 12, ["z"] = 8, ["name"] = "stones:sku2_r"}, {["x"] = 31, ["param2"] = 9, ["y"] = 9, ["param1"] = 9, ["z"] = 5, ["name"] = "stones:s_52r"}, {["x"] = 31, ["param2"] = 2, ["y"] = 9, ["param1"] = 9, ["z"] = 6, ["name"] = "stones:roch"}, {["x"] = 31, ["param2"] = 7, ["y"] = 9, ["param1"] = 9, ["z"] = 7, ["name"] = "stones:s_52ur"}, {["x"] = 31, ["param2"] = 7, ["y"] = 10, ["param1"] = 12, ["z"] = 5, ["name"] = "stones:sku2_r"}, {["x"] = 31, ["param2"] = 9, ["y"] = 10, ["param1"] = 12, ["z"] = 7, ["name"] = "stones:s_52r"}, {["x"] = 31, ["param2"] = 7, ["y"] = 10, ["param1"] = 12, ["z"] = 8, ["name"] = "stones:s_52r"}, {["x"] = 32, ["param2"] = 9, ["y"] = 9, ["param1"] = 9, ["z"] = 5, ["name"] = "stones:s_52ur"}, {["x"] = 32, ["param2"] = 1, ["y"] = 9, ["param1"] = 9, ["z"] = 6, ["name"] = "stones:roch"}, {["x"] = 32, ["param2"] = 7, ["y"] = 9, ["param1"] = 9, ["z"] = 7, ["name"] = "stones:s_52r"}, {["x"] = 32, ["param2"] = 9, ["y"] = 10, ["param1"] = 12, ["z"] = 4, ["name"] = "stones:s_52r"}, {["x"] = 32, ["param2"] = 7, ["y"] = 10, ["param1"] = 12, ["z"] = 5, ["name"] = "stones:s_52r"}, {["x"] = 32, ["param2"] = 7, ["y"] = 10, ["param1"] = 12, ["z"] = 7, ["name"] = "stones:sku2_r"}, {["x"] = 33, ["param2"] = 9, ["y"] = 9, ["param1"] = 9, ["z"] = 4, ["name"] = "stones:s_52r"}, {["x"] = 33, ["param2"] = 2, ["y"] = 9, ["param1"] = 9, ["z"] = 5, ["name"] = "stones:roch"}, {["x"] = 33, ["param2"] = 7, ["y"] = 9, ["param1"] = 9, ["z"] = 6, ["name"] = "stones:s_52ur"}, {["x"] = 33, ["param2"] = 7, ["y"] = 10, ["param1"] = 12, ["z"] = 4, ["name"] = "stones:sku2_r"}, {["x"] = 33, ["param2"] = 9, ["y"] = 10, ["param1"] = 12, ["z"] = 6, ["name"] = "stones:s_52r"}, {["x"] = 33, ["param2"] = 7, ["y"] = 10, ["param1"] = 12, ["z"] = 7, ["name"] = "stones:s_52r"}, {["x"] = 34, ["param2"] = 9, ["y"] = 9, ["param1"] = 9, ["z"] = 4, ["name"] = "stones:s_52ur"}, {["x"] = 34, ["param2"] = 2, ["y"] = 9, ["param1"] = 9, ["z"] = 5, ["name"] = "stones:roch"}, {["x"] = 34, ["param2"] = 7, ["y"] = 9, ["param1"] = 9, ["z"] = 6, ["name"] = "stones:s_52r"}, {["x"] = 34, ["param2"] = 9, ["y"] = 10, ["param1"] = 12, ["z"] = 3, ["name"] = "stones:s_52r"}, {["x"] = 34, ["param2"] = 7, ["y"] = 10, ["param1"] = 12, ["z"] = 4, ["name"] = "stones:s_52r"}, {["x"] = 34, ["param2"] = 7, ["y"] = 10, ["param1"] = 12, ["z"] = 6, ["name"] = "stones:sku2_r"}, {["x"] = 35, ["param2"] = 9, ["y"] = 9, ["param1"] = 9, ["z"] = 3, ["name"] = "stones:s_52r"}, {["x"] = 35, ["param2"] = 2, ["y"] = 9, ["param1"] = 9, ["z"] = 4, ["name"] = "stones:roch"}, {["x"] = 35, ["param2"] = 7, ["y"] = 9, ["param1"] = 9, ["z"] = 5, ["name"] = "stones:s_52ur"}, {["x"] = 35, ["param2"] = 7, ["y"] = 10, ["param1"] = 12, ["z"] = 3, ["name"] = "stones:sku2_r"}, {["x"] = 35, ["param2"] = 9, ["y"] = 10, ["param1"] = 12, ["z"] = 5, ["name"] = "stones:s_52r"}, {["x"] = 35, ["param2"] = 7, ["y"] = 10, ["param1"] = 12, ["z"] = 6, ["name"] = "stones:s_52r"}, {["x"] = 36, ["param2"] = 9, ["y"] = 9, ["param1"] = 12, ["z"] = 2, ["name"] = "stones:s_52"}, {["x"] = 36, ["param2"] = 2, ["y"] = 9, ["param1"] = 9, ["z"] = 3, ["name"] = "stones:diagsteps_52rh"}, {["x"] = 36, ["param2"] = 1, ["y"] = 9, ["param1"] = 9, ["z"] = 4, ["name"] = "stones:roch"}, {["x"] = 36, ["param2"] = 2, ["y"] = 9, ["param1"] = 9, ["z"] = 5, ["name"] = "stones:panel"}, {["x"] = 36, ["param2"] = 9, ["y"] = 10, ["param1"] = 12, ["z"] = 2, ["name"] = "stones:s_52r"}, {["x"] = 36, ["param2"] = 7, ["y"] = 10, ["param1"] = 12, ["z"] = 3, ["name"] = "stones:s_52r"}, {["x"] = 36, ["param2"] = 7, ["y"] = 10, ["param1"] = 12, ["z"] = 5, ["name"] = "stones:sku2_r"}, {["x"] = 37, ["param2"] = 9, ["y"] = 9, ["param1"] = 9, ["z"] = 2, ["name"] = "stones:s_52ur"}, {["x"] = 37, ["param2"] = 7, ["y"] = 9, ["param1"] = 9, ["z"] = 3, ["name"] = "stones:estruk"}, {["x"] = 37, ["y"] = 9, ["param1"] = 9, ["z"] = 4, ["name"] = "stones:diagsteps_52rh"}, {["x"] = 37, ["param2"] = 7, ["y"] = 9, ["param1"] = 9, ["z"] = 5, ["name"] = "stones:s_52"}, {["x"] = 37, ["param2"] = 7, ["y"] = 10, ["param1"] = 12, ["z"] = 2, ["name"] = "stones:sku2_r"}, {["x"] = 37, ["param2"] = 9, ["y"] = 10, ["param1"] = 12, ["z"] = 4, ["name"] = "stones:s_52r"}, {["x"] = 37, ["param2"] = 7, ["y"] = 10, ["param1"] = 12, ["z"] = 5, ["name"] = "stones:s_52r"}, {["x"] = 38, ["param2"] = 9, ["y"] = 9, ["param1"] = 12, ["z"] = 1, ["name"] = "stones:s_52"}, {["x"] = 38, ["param2"] = 2, ["y"] = 9, ["param1"] = 9, ["z"] = 2, ["name"] = "stones:diagsteps_52rh"}, {["x"] = 38, ["param2"] = 9, ["y"] = 9, ["param1"] = 9, ["z"] = 3, ["name"] = "stones:estruk"}, {["x"] = 38, ["param2"] = 7, ["y"] = 9, ["param1"] = 9, ["z"] = 4, ["name"] = "stones:s_52ur"}, {["x"] = 38, ["param2"] = 9, ["y"] = 10, ["param1"] = 12, ["z"] = 1, ["name"] = "stones:s_52r"}, {["x"] = 38, ["param2"] = 7, ["y"] = 10, ["param1"] = 12, ["z"] = 2, ["name"] = "stones:s_52r"}, {["x"] = 38, ["param2"] = 7, ["y"] = 10, ["param1"] = 12, ["z"] = 4, ["name"] = "stones:sku2_r"}, {["x"] = 39, ["y"] = 9, ["param1"] = 9, ["z"] = 1, ["name"] = "stones:panel"}, {["x"] = 39, ["param2"] = 1, ["y"] = 9, ["param1"] = 9, ["z"] = 2, ["name"] = "stones:roch"}, {["x"] = 39, ["y"] = 9, ["param1"] = 9, ["z"] = 3, ["name"] = "stones:diagsteps_52rh"}, {["x"] = 39, ["param2"] = 7, ["y"] = 9, ["param1"] = 9, ["z"] = 4, ["name"] = "stones:s_52"}, {["x"] = 39, ["param2"] = 7, ["y"] = 10, ["param1"] = 12, ["z"] = 1, ["name"] = "stones:sku2_r"}, {["x"] = 39, ["param2"] = 9, ["y"] = 10, ["param1"] = 12, ["z"] = 3, ["name"] = "stones:s_52r"}, {["x"] = 39, ["param2"] = 7, ["y"] = 10, ["param1"] = 12, ["z"] = 4, ["name"] = "stones:s_52r"}, {["x"] = 40, ["param2"] = 9, ["y"] = 9, ["param1"] = 9, ["z"] = 1, ["name"] = "stones:s_52ur"}, {["x"] = 40, ["param2"] = 1, ["y"] = 9, ["param1"] = 9, ["z"] = 2, ["name"] = "stones:roch"}, {["x"] = 40, ["param2"] = 7, ["y"] = 9, ["param1"] = 9, ["z"] = 3, ["name"] = "stones:s_52r"}, {["x"] = 40, ["param2"] = 9, ["y"] = 10, ["param1"] = 12, ["z"] = 0, ["name"] = "stones:s_52r"}, {["x"] = 40, ["param2"] = 7, ["y"] = 10, ["param1"] = 12, ["z"] = 1, ["name"] = "stones:s_52r"}, {["x"] = 40, ["param2"] = 7, ["y"] = 10, ["param1"] = 12, ["z"] = 3, ["name"] = "stones:sku2_r"}, {["x"] = 41, ["param2"] = 9, ["y"] = 9, ["param1"] = 12, ["z"] = 0, ["name"] = "stones:s_52r"}, {["x"] = 41, ["param2"] = 1, ["y"] = 9, ["param1"] = 9, ["z"] = 1, ["name"] = "stones:roch"}, {["x"] = 41, ["param2"] = 7, ["y"] = 9, ["param1"] = 9, ["z"] = 2, ["name"] = "stones:s_52ur"}, {["x"] = 41, ["param2"] = 7, ["y"] = 10, ["param1"] = 12, ["z"] = 0, ["name"] = "stones:sku2_r"}, {["x"] = 41, ["param2"] = 9, ["y"] = 10, ["param1"] = 12, ["z"] = 2, ["name"] = "stones:s_52r"}, {["x"] = 41, ["param2"] = 7, ["y"] = 10, ["param1"] = 12, ["z"] = 3, ["name"] = "stones:s_52r"}, {["x"] = 42, ["param2"] = 9, ["y"] = 9, ["param1"] = 12, ["z"] = 0, ["name"] = "stones:s_52ur"}, {["x"] = 42, ["param2"] = 1, ["y"] = 9, ["param1"] = 12, ["z"] = 1, ["name"] = "stones:roch"}, {["x"] = 42, ["param2"] = 7, ["y"] = 9, ["param1"] = 12, ["z"] = 2, ["name"] = "stones:s_52r"}, {["x"] = 42, ["param2"] = 7, ["y"] = 10, ["param1"] = 12, ["z"] = 0, ["name"] = "stones:s_52r"}, {["x"] = 42, ["param2"] = 7, ["y"] = 10, ["param1"] = 12, ["z"] = 2, ["name"] = "stones:sku2_r"}}