5:return {{["x"] = 0, ["param2"] = 2, ["y"] = 0, ["param1"] = 44, ["z"] = 0, ["name"] = "stones:spircol_8"}, {["x"] = 0, ["y"] = 0, ["param1"] = 109, ["z"] = 4, ["name"] = "stones:rock"}, {["x"] = 0, ["y"] = 1, ["param1"] = 125, ["z"] = 4, ["name"] = "stones:rock"}, {["x"] = 0, ["param2"] = 22, ["y"] = 1, ["param1"] = 142, ["z"] = 5, ["name"] = "stones:s_52l"}, {["x"] = 0, ["param2"] = 13, ["y"] = 2, ["param1"] = 142, ["z"] = 4, ["name"] = "stones:flat_4"}, {["x"] = 0, ["y"] = 2, ["param1"] = 158, ["z"] = 5, ["name"] = "stones:s_52l"}, {["x"] = 0, ["param2"] = 12, ["y"] = 2, ["param1"] = 174, ["z"] = 6, ["name"] = "stones:sku2_r"}, {["x"] = 0, ["param2"] = 5, ["y"] = 2, ["param1"] = 190, ["z"] = 7, ["name"] = "stones:s_22l"}, {["x"] = 0, ["param2"] = 1, ["y"] = 3, ["param1"] = 126, ["z"] = 4, ["name"] = "runes:lit_ke"}, {["x"] = 1, ["param2"] = 19, ["y"] = 2, ["param1"] = 174, ["z"] = 5, ["name"] = "stones:s_52l"}, {["x"] = 1, ["param2"] = 1, ["y"] = 2, ["param1"] = 206, ["z"] = 7, ["name"] = "stones:s_52ur"}, {["x"] = 2, ["y"] = 0, ["param1"] = 187, ["z"] = 7, ["name"] = "stones:rock"}, {["x"] = 2, ["y"] = 1, ["param1"] = 204, ["z"] = 7, ["name"] = "stones:rock"}, {["x"] = 2, ["param2"] = 15, ["y"] = 2, ["param1"] = 189, ["z"] = 5, ["name"] = "stones:s_52l"}, {["x"] = 2, ["y"] = 2, ["param1"] = 221, ["z"] = 7, ["name"] = "stones:rock"}, {["x"] = 2, ["param2"] = 4, ["y"] = 2, ["param1"] = 238, ["z"] = 8, ["name"] = "stones:estamp"}, {["x"] = 2, ["param2"] = 15, ["y"] = 3, ["param1"] = 174, ["z"] = 5, ["name"] = "stones:sku2_l"}, {["x"] = 2, ["y"] = 3, ["param1"] = 206, ["z"] = 7, ["name"] = "stones:rock"}, {["x"] = 2, ["param2"] = 19, ["y"] = 4, ["param1"] = 158, ["z"] = 5, ["name"] = "stones:s_52l"}, {["x"] = 2, ["y"] = 4, ["param1"] = 190, ["z"] = 7, ["name"] = "stones:pyra_2"}, {["x"] = 2, ["param2"] = 17, ["y"] = 5, ["param1"] = 142, ["z"] = 5, ["name"] = "stones:s_52r"}, {["x"] = 2, ["param2"] = 19, ["y"] = 6, ["param1"] = 126, ["z"] = 5, ["name"] = "stones:s_52l"}, {["x"] = 3, ["param2"] = 9, ["y"] = 0, ["param1"] = 78, ["z"] = 1, ["name"] = "stones:s_2"}, {["x"] = 3, ["param2"] = 18, ["y"] = 0, ["param1"] = 93, ["z"] = 2, ["name"] = "stones:s_52u"}, {["x"] = 3, ["param2"] = 5, ["y"] = 0, ["param1"] = 109, ["z"] = 3, ["name"] = "stones:s_22"}, {["x"] = 3, ["param2"] = 16, ["y"] = 1, ["param1"] = 94, ["z"] = 1, ["name"] = "stones:brushrock_22"}, {["x"] = 3, ["param2"] = 18, ["y"] = 1, ["param1"] = 109, ["z"] = 2, ["name"] = "stones:brushrock_52ur"}, {["x"] = 3, ["param2"] = 18, ["y"] = 1, ["param1"] = 125, ["z"] = 3, ["name"] = "stones:s_22"}, {["x"] = 3, ["param2"] = 21, ["y"] = 4, ["param1"] = 142, ["z"] = 5, ["name"] = "stones:s_52ur"}, {["x"] = 3, ["param2"] = 22, ["y"] = 5, ["param1"] = 126, ["z"] = 5, ["name"] = "stones:arsh"}, {["x"] = 3, ["param2"] = 18, ["y"] = 6, ["param1"] = 110, ["z"] = 5, ["name"] = "stones:arsh"}, {["x"] = 3, ["param2"] = 1, ["y"] = 7, ["param1"] = 94, ["z"] = 5, ["name"] = "stones:s_52r"}, {["x"] = 4, ["y"] = 0, ["param1"] = 78, ["z"] = 1, ["name"] = "stones:rock"}, {["x"] = 4, ["y"] = 0, ["param1"] = 77, ["z"] = 2, ["name"] = "stones:rock"}, {["x"] = 4, ["param2"] = 5, ["y"] = 0, ["param1"] = 94, ["z"] = 3, ["name"] = "stones:s_52u"}, {["x"] = 4, ["y"] = 1, ["param1"] = 94, ["z"] = 1, ["name"] = "stones:brushrock_4"}, {["x"] = 4, ["param2"] = 1, ["y"] = 1, ["param1"] = 93, ["z"] = 2, ["name"] = "runes:lit_hui"}, {["x"] = 4, ["param2"] = 5, ["y"] = 1, ["param1"] = 110, ["z"] = 3, ["name"] = "stones:brushrock_52ul"}, {["x"] = 4, ["param2"] = 16, ["y"] = 2, ["param1"] = 190, ["z"] = 9, ["name"] = "stones:s_52r"}, {["x"] = 4, ["param2"] = 5, ["y"] = 2, ["param1"] = 173, ["z"] = 10, ["name"] = "stones:s_22r"}, {["x"] = 4, ["param2"] = 23, ["y"] = 4, ["param1"] = 126, ["z"] = 5, ["name"] = "stones:s_52ul"}, {["x"] = 4, ["param2"] = 14, ["y"] = 5, ["param1"] = 110, ["z"] = 5, ["name"] = "stones:arsh"}, {["x"] = 4, ["param2"] = 2, ["y"] = 6, ["param1"] = 94, ["z"] = 5, ["name"] = "stones:arsh"}, {["x"] = 4, ["param2"] = 3, ["y"] = 7, ["param1"] = 78, ["z"] = 5, ["name"] = "stones:s_52l"}, {["x"] = 5, ["param2"] = 12, ["y"] = 0, ["param1"] = 94, ["z"] = 1, ["name"] = "stones:s_52"}, {["x"] = 5, ["param2"] = 12, ["y"] = 0, ["param1"] = 77, ["z"] = 2, ["name"] = "stones:s_52u"}, {["x"] = 5, ["param2"] = 14, ["y"] = 0, ["param1"] = 78, ["z"] = 3, ["name"] = "stones:s_2"}, {["x"] = 5, ["param2"] = 19, ["y"] = 0, ["param1"] = 110, ["z"] = 5, ["name"] = "stones:s_52u"}, {["x"] = 5, ["param2"] = 1, ["y"] = 0, ["param1"] = 156, ["z"] = 8, ["name"] = "stones:s_22l"}, {["x"] = 5, ["param2"] = 5, ["y"] = 0, ["param1"] = 124, ["z"] = 10, ["name"] = "stones:sku"}, {["x"] = 5, ["param2"] = 12, ["y"] = 1, ["param1"] = 110, ["z"] = 1, ["name"] = "stones:s_52"}, {["x"] = 5, ["param2"] = 12, ["y"] = 1, ["param1"] = 93, ["z"] = 2, ["name"] = "stones:brushrock_52ur"}, {["x"] = 5, ["param2"] = 14, ["y"] = 1, ["param1"] = 94, ["z"] = 3, ["name"] = "stones:brushrock_22"}, {["x"] = 5, ["param2"] = 19, ["y"] = 1, ["param1"] = 126, ["z"] = 5, ["name"] = "stones:s_52"}, {["x"] = 5, ["param2"] = 5, ["y"] = 1, ["param1"] = 140, ["z"] = 10, ["name"] = "stones:sku"}, {["x"] = 5, ["param2"] = 17, ["y"] = 2, ["param1"] = 142, ["z"] = 5, ["name"] = "stones:s_52r"}, {["x"] = 5, ["y"] = 2, ["param1"] = 158, ["z"] = 6, ["name"] = "runes:nbdx4"}, {["x"] = 5, ["y"] = 2, ["param1"] = 174, ["z"] = 7, ["name"] = "runes:nbdx1"}, {["x"] = 5, ["param2"] = 16, ["y"] = 2, ["param1"] = 190, ["z"] = 8, ["name"] = "stones:brushrock_52ul"}, {["x"] = 5, ["param2"] = 1, ["y"] = 2, ["param1"] = 174, ["z"] = 9, ["name"] = "stones:brushrock_5"}, {["x"] = 5, ["param2"] = 5, ["y"] = 2, ["param1"] = 157, ["z"] = 10, ["name"] = "stones:brushrock_52ul"}, {["x"] = 5, ["param2"] = 13, ["y"] = 3, ["param1"] = 126, ["z"] = 5, ["name"] = "stones:sku2_r"}, {["x"] = 5, ["param2"] = 4, ["y"] = 3, ["param1"] = 159, ["z"] = 9, ["name"] = "stones:shrub"}, {["x"] = 5, ["param2"] = 13, ["y"] = 4, ["param1"] = 110, ["z"] = 5, ["name"] = "stones:s_52r"}, {["x"] = 5, ["param2"] = 15, ["y"] = 5, ["param1"] = 94, ["z"] = 5, ["name"] = "stones:s_52l"}, {["x"] = 5, ["param2"] = 13, ["y"] = 6, ["param1"] = 78, ["z"] = 5, ["name"] = "stones:s_52r"}, {["x"] = 6, ["param2"] = 1, ["y"] = 0, ["param1"] = 140, ["z"] = 8, ["name"] = "stones:s_52ul"}, {["x"] = 6, ["param2"] = 1, ["y"] = 0, ["param1"] = 124, ["z"] = 9, ["name"] = "stones:s_52r"}, {["x"] = 6, ["y"] = 1, ["param1"] = 109, ["z"] = 5, ["name"] = "stones:arch"}, {["x"] = 6, ["param2"] = 3, ["y"] = 2, ["param1"] = 126, ["z"] = 5, ["name"] = "stones:stair_3_inner"}, {["x"] = 6, ["y"] = 2, ["param1"] = 142, ["z"] = 6, ["name"] = "runes:nbdx3"}, {["x"] = 6, ["y"] = 2, ["param1"] = 158, ["z"] = 7, ["name"] = "runes:nbdx2"}, {["x"] = 6, ["param2"] = 12, ["y"] = 2, ["param1"] = 174, ["z"] = 8, ["name"] = "stones:brushrock_52ur"}, {["x"] = 6, ["param2"] = 1, ["y"] = 2, ["param1"] = 158, ["z"] = 9, ["name"] = "stones:brushrock_0"}, {["x"] = 6, ["param2"] = 14, ["y"] = 2, ["param1"] = 141, ["z"] = 10, ["name"] = "stones:brushrock_22"}, {["x"] = 7, ["y"] = 0, ["param1"] = 77, ["z"] = 4, ["name"] = "default:blackpool"}, {["x"] = 7, ["y"] = 0, ["param1"] = 110, ["z"] = 7, ["name"] = "default:blackpool"}, {["x"] = 7, ["param2"] = 8, ["y"] = 0, ["param1"] = 125, ["z"] = 8, ["name"] = "stones:roch"}, {["x"] = 7, ["param2"] = 5, ["y"] = 0, ["param1"] = 109, ["z"] = 9, ["name"] = "stones:s_52u"}, {["x"] = 7, ["param2"] = 5, ["y"] = 1, ["param1"] = 125, ["z"] = 9, ["name"] = "stones:s_52u"}, {["x"] = 7, ["y"] = 2, ["param1"] = 109, ["z"] = 5, ["name"] = "stones:stair_3"}, {["x"] = 7, ["param2"] = 3, ["y"] = 2, ["param1"] = 141, ["z"] = 9, ["name"] = "stones:s_52u"}, {["x"] = 8, ["param2"] = 5, ["y"] = 0, ["param1"] = 126, ["z"] = 0, ["name"] = "stones:panel"}, {["x"] = 8, ["param2"] = 11, ["y"] = 0, ["param1"] = 110, ["z"] = 8, ["name"] = "stones:s_22"}, {["x"] = 8, ["param2"] = 14, ["y"] = 0, ["param1"] = 94, ["z"] = 9, ["name"] = "stones:s_52"}, {["x"] = 8, ["param2"] = 10, ["y"] = 1, ["param1"] = 142, ["z"] = 0, ["name"] = "stones:sku3_l"}, {["x"] = 8, ["param2"] = 2, ["y"] = 1, ["param1"] = 110, ["z"] = 4, ["name"] = "stones:arch"}, {["x"] = 8, ["param2"] = 2, ["y"] = 1, ["param1"] = 93, ["z"] = 5, ["name"] = "stones:arch"}, {["x"] = 8, ["param2"] = 14, ["y"] = 1, ["param1"] = 110, ["z"] = 9, ["name"] = "stones:s_52"}, {["x"] = 8, ["y"] = 2, ["param1"] = 158, ["z"] = 0, ["name"] = "stones:s_22l"}, {["x"] = 8, ["param2"] = 12, ["y"] = 2, ["param1"] = 174, ["z"] = 1, ["name"] = "stones:sku2_r"}, {["x"] = 8, ["param2"] = 18, ["y"] = 2, ["param1"] = 158, ["z"] = 2, ["name"] = "stones:s_52r"}, {["x"] = 8, ["param2"] = 3, ["y"] = 2, ["param1"] = 126, ["z"] = 4, ["name"] = "stones:stair_941"}, {["x"] = 8, ["y"] = 2, ["param1"] = 110, ["z"] = 5, ["name"] = "stones:stair_3_inner"}, {["x"] = 8, ["y"] = 2, ["param1"] = 110, ["z"] = 6, ["name"] = "stones:rock"}, {["x"] = 8, ["param2"] = 1, ["y"] = 2, ["param1"] = 142, ["z"] = 8, ["name"] = "stones:diagstep"}, {["x"] = 8, ["param2"] = 3, ["y"] = 2, ["param1"] = 126, ["z"] = 9, ["name"] = "stones:diagstep"}, {["x"] = 8, ["param2"] = 1, ["y"] = 3, ["param1"] = 110, ["z"] = 6, ["name"] = "stones:flat_4"}, {["x"] = 8, ["param2"] = 2, ["y"] = 4, ["param1"] = 126, ["z"] = 6, ["name"] = "stones:pyra"}, {["x"] = 9, ["param2"] = 13, ["y"] = 0, ["param1"] = 110, ["z"] = 4, ["name"] = "stones:s_52u"}, {["x"] = 9, ["param2"] = 13, ["y"] = 0, ["param1"] = 94, ["z"] = 5, ["name"] = "stones:s_52u"}, {["x"] = 9, ["param2"] = 3, ["y"] = 0, ["param1"] = 62, ["z"] = 10, ["name"] = "stones:spircol_8"}, {["x"] = 9, ["param2"] = 13, ["y"] = 1, ["param1"] = 126, ["z"] = 4, ["name"] = "stones:s_52"}, {["x"] = 9, ["param2"] = 13, ["y"] = 1, ["param1"] = 110, ["z"] = 5, ["name"] = "stones:s_52"}, {["x"] = 9, ["param2"] = 3, ["y"] = 1, ["param1"] = 78, ["z"] = 10, ["name"] = "stones:spircol_8"}, {["x"] = 9, ["param2"] = 4, ["y"] = 2, ["param1"] = 174, ["z"] = 2, ["name"] = "stones:stair_half_l"}, {["x"] = 9, ["y"] = 2, ["param1"] = 158, ["z"] = 3, ["name"] = "stones:sku3_r"}, {["x"] = 9, ["param2"] = 14, ["y"] = 2, ["param1"] = 142, ["z"] = 4, ["name"] = "stones:sku2_r"}, {["x"] = 9, ["param2"] = 14, ["y"] = 2, ["param1"] = 126, ["z"] = 5, ["name"] = "stones:s_52r"}, {["x"] = 9, ["param2"] = 12, ["y"] = 2, ["param1"] = 110, ["z"] = 6, ["name"] = "stones:s_52r"}, {["x"] = 9, ["param2"] = 12, ["y"] = 2, ["param1"] = 110, ["z"] = 7, ["name"] = "stones:s_52ur"}, {["x"] = 9, ["param2"] = 3, ["y"] = 2, ["param1"] = 126, ["z"] = 8, ["name"] = "stones:diagstep"}, {["x"] = 9, ["param2"] = 3, ["y"] = 2, ["param1"] = 94, ["z"] = 10, ["name"] = "stones:spircol_8"}, {["x"] = 9, ["param2"] = 6, ["y"] = 3, ["param1"] = 190, ["z"] = 2, ["name"] = "stones:sku3_l"}, {["x"] = 9, ["param2"] = 3, ["y"] = 3, ["param1"] = 78, ["z"] = 10, ["name"] = "stones:spircol_8"}, {["x"] = 9, ["param2"] = 9, ["y"] = 4, ["param1"] = 206, ["z"] = 2, ["name"] = "stones:panel"}, {["x"] = 9, ["param2"] = 3, ["y"] = 4, ["param1"] = 78, ["z"] = 10, ["name"] = "stones:spircol_8"}, {["x"] = 9, ["param2"] = 3, ["y"] = 5, ["param1"] = 62, ["z"] = 10, ["name"] = "stones:spircol_8"}, {["x"] = 9, ["param2"] = 3, ["y"] = 6, ["param1"] = 46, ["z"] = 10, ["name"] = "stones:spircol_8"}, {["x"] = 9, ["param2"] = 3, ["y"] = 7, ["param1"] = 30, ["z"] = 10, ["name"] = "stones:spircol_8"}}