5:return {{["x"] = 0, ["param2"] = 9, ["y"] = 0, ["param1"] = 126, ["z"] = 0, ["name"] = "stones:s_22"}, {["x"] = 0, ["param2"] = 16, ["y"] = 0, ["param1"] = 110, ["z"] = 1, ["name"] = "stones:s_52u"}, {["x"] = 0, ["y"] = 0, ["param1"] = 110, ["z"] = 2, ["name"] = "stones:rock"}, {["x"] = 0, ["param2"] = 18, ["y"] = 0, ["param1"] = 94, ["z"] = 3, ["name"] = "stones:s_52u"}, {["x"] = 0, ["param2"] = 5, ["y"] = 0, ["param1"] = 78, ["z"] = 4, ["name"] = "stones:s_22"}, {["x"] = 0, ["param2"] = 16, ["y"] = 1, ["param1"] = 126, ["z"] = 1, ["name"] = "stones:s_52"}, {["x"] = 0, ["param2"] = 16, ["y"] = 1, ["param1"] = 126, ["z"] = 2, ["name"] = "stones:roch"}, {["x"] = 0, ["param2"] = 18, ["y"] = 1, ["param1"] = 110, ["z"] = 3, ["name"] = "stones:s_52"}, {["x"] = 0, ["param2"] = 16, ["y"] = 2, ["param1"] = 142, ["z"] = 1, ["name"] = "stones:s_52"}, {["x"] = 0, ["param2"] = 16, ["y"] = 2, ["param1"] = 142, ["z"] = 2, ["name"] = "stones:roch"}, {["x"] = 0, ["param2"] = 18, ["y"] = 2, ["param1"] = 126, ["z"] = 3, ["name"] = "stones:s_52"}, {["x"] = 0, ["param2"] = 16, ["y"] = 3, ["param1"] = 142, ["z"] = 1, ["name"] = "stones:s_52"}, {["x"] = 0, ["param2"] = 16, ["y"] = 3, ["param1"] = 158, ["z"] = 2, ["name"] = "stones:roch"}, {["x"] = 0, ["param2"] = 18, ["y"] = 3, ["param1"] = 142, ["z"] = 3, ["name"] = "stones:s_52"}, {["x"] = 0, ["param2"] = 16, ["y"] = 4, ["param1"] = 158, ["z"] = 1, ["name"] = "stones:s_52"}, {["x"] = 0, ["param2"] = 16, ["y"] = 4, ["param1"] = 174, ["z"] = 2, ["name"] = "stones:roch"}, {["x"] = 0, ["param2"] = 18, ["y"] = 4, ["param1"] = 158, ["z"] = 3, ["name"] = "stones:s_52"}, {["x"] = 0, ["param2"] = 9, ["y"] = 5, ["param1"] = 158, ["z"] = 0, ["name"] = "stones:s_22l"}, {["x"] = 0, ["param2"] = 20, ["y"] = 5, ["param1"] = 174, ["z"] = 1, ["name"] = "stones:diagsteps_13"}, {["x"] = 0, ["param2"] = 23, ["y"] = 5, ["param1"] = 190, ["z"] = 2, ["name"] = "stones:stair_2"}, {["x"] = 0, ["param2"] = 23, ["y"] = 5, ["param1"] = 174, ["z"] = 3, ["name"] = "stones:diagsteps_31"}, {["x"] = 0, ["param2"] = 18, ["y"] = 5, ["param1"] = 158, ["z"] = 4, ["name"] = "stones:s_22l"}, {["x"] = 1, ["param2"] = 9, ["y"] = 0, ["param1"] = 141, ["z"] = 0, ["name"] = "stones:s_52u"}, {["x"] = 1, ["y"] = 0, ["param1"] = 125, ["z"] = 1, ["name"] = "stones:rock"}, {["x"] = 1, ["y"] = 0, ["param1"] = 125, ["z"] = 2, ["name"] = "stones:rock"}, {["x"] = 1, ["y"] = 0, ["param1"] = 109, ["z"] = 3, ["name"] = "stones:rock"}, {["x"] = 1, ["y"] = 0, ["param1"] = 93, ["z"] = 4, ["name"] = "stones:rock"}, {["x"] = 1, ["param2"] = 9, ["y"] = 1, ["param1"] = 158, ["z"] = 0, ["name"] = "stones:s_52"}, {["x"] = 1, ["param2"] = 22, ["y"] = 1, ["param1"] = 141, ["z"] = 1, ["name"] = "stones:spirdiag_r"}, {["x"] = 1, ["y"] = 1, ["param1"] = 125, ["z"] = 3, ["name"] = "stones:spircod"}, {["x"] = 1, ["param2"] = 5, ["y"] = 1, ["param1"] = 110, ["z"] = 4, ["name"] = "stones:s_52"}, {["x"] = 1, ["param2"] = 9, ["y"] = 2, ["param1"] = 174, ["z"] = 0, ["name"] = "stones:s_52"}, {["x"] = 1, ["param2"] = 3, ["y"] = 2, ["param1"] = 157, ["z"] = 1, ["name"] = "stones:spirdiag_r"}, {["x"] = 1, ["y"] = 2, ["param1"] = 157, ["z"] = 2, ["name"] = "stones:spirstax_r"}, {["x"] = 1, ["param2"] = 21, ["y"] = 2, ["param1"] = 141, ["z"] = 3, ["name"] = "stones:spirdiag_r"}, {["x"] = 1, ["param2"] = 5, ["y"] = 2, ["param1"] = 126, ["z"] = 4, ["name"] = "stones:s_52"}, {["x"] = 1, ["param2"] = 9, ["y"] = 3, ["param1"] = 158, ["z"] = 0, ["name"] = "stones:s_52"}, {["x"] = 1, ["param2"] = 3, ["y"] = 3, ["param1"] = 157, ["z"] = 1, ["name"] = "stones:spircod"}, {["x"] = 1, ["y"] = 3, ["param1"] = 157, ["z"] = 3, ["name"] = "stones:spirdiag_r"}, {["x"] = 1, ["param2"] = 2, ["y"] = 3, ["param1"] = 142, ["z"] = 4, ["name"] = "stones:diagsteps_31"}, {["x"] = 1, ["param2"] = 9, ["y"] = 4, ["param1"] = 158, ["z"] = 0, ["name"] = "stones:s_52"}, {["x"] = 1, ["param2"] = 3, ["y"] = 4, ["param1"] = 173, ["z"] = 1, ["name"] = "stones:spircod"}, {["x"] = 1, ["y"] = 4, ["param1"] = 173, ["z"] = 3, ["name"] = "stones:spircod"}, {["x"] = 1, ["param2"] = 5, ["y"] = 4, ["param1"] = 158, ["z"] = 4, ["name"] = "stones:s_52"}, {["x"] = 1, ["param2"] = 20, ["y"] = 5, ["param1"] = 174, ["z"] = 0, ["name"] = "stones:diagsteps_31"}, {["x"] = 1, ["param2"] = 22, ["y"] = 5, ["param1"] = 190, ["z"] = 1, ["name"] = "stones:spirdiag"}, {["x"] = 1, ["param2"] = 3, ["y"] = 5, ["param1"] = 205, ["z"] = 2, ["name"] = "stones:spirjoin_2l"}, {["x"] = 1, ["y"] = 5, ["param1"] = 189, ["z"] = 3, ["name"] = "stones:spircod"}, {["x"] = 1, ["param2"] = 23, ["y"] = 5, ["param1"] = 174, ["z"] = 4, ["name"] = "stones:diagsteps_13"}, {["x"] = 1, ["param2"] = 17, ["y"] = 6, ["param1"] = 222, ["z"] = 2, ["name"] = "stones:sku3_l"}, {["x"] = 1, ["param2"] = 5, ["y"] = 6, ["param1"] = 190, ["z"] = 4, ["name"] = "stones:s_22"}, {["x"] = 1, ["param2"] = 10, ["y"] = 7, ["param1"] = 206, ["z"] = 2, ["name"] = "stones:s_22r"}, {["x"] = 1, ["param2"] = 12, ["y"] = 7, ["param1"] = 190, ["z"] = 3, ["name"] = "stones:sku2_r"}, {["x"] = 1, ["param2"] = 5, ["y"] = 7, ["param1"] = 174, ["z"] = 4, ["name"] = "stones:s_22l"}, {["x"] = 2, ["y"] = 0, ["param1"] = 124, ["z"] = 0, ["name"] = "stones:rock"}, {["x"] = 2, ["y"] = 0, ["param1"] = 124, ["z"] = 1, ["name"] = "stones:rock"}, {["x"] = 2, ["y"] = 0, ["param1"] = 140, ["z"] = 2, ["name"] = "stones:rock"}, {["x"] = 2, ["y"] = 0, ["param1"] = 124, ["z"] = 3, ["name"] = "stones:rock"}, {["x"] = 2, ["y"] = 0, ["param1"] = 108, ["z"] = 4, ["name"] = "stones:rock"}, {["x"] = 2, ["y"] = 1, ["param1"] = 141, ["z"] = 0, ["name"] = "stones:s_22"}, {["x"] = 2, ["param2"] = 23, ["y"] = 1, ["param1"] = 140, ["z"] = 1, ["name"] = "stones:spirout_r"}, {["x"] = 2, ["y"] = 1, ["param1"] = 156, ["z"] = 2, ["name"] = "stones:spircol_8"}, {["x"] = 2, ["y"] = 2, ["param1"] = 172, ["z"] = 2, ["name"] = "stones:spircol_8"}, {["x"] = 2, ["param2"] = 15, ["y"] = 3, ["param1"] = 157, ["z"] = 0, ["name"] = "stones:s_52r"}, {["x"] = 2, ["param2"] = 1, ["y"] = 3, ["param1"] = 188, ["z"] = 2, ["name"] = "stones:spircol_8"}, {["x"] = 2, ["param2"] = 21, ["y"] = 3, ["param1"] = 172, ["z"] = 3, ["name"] = "stones:spirout_r"}, {["x"] = 2, ["param2"] = 2, ["y"] = 3, ["param1"] = 157, ["z"] = 4, ["name"] = "stones:roch"}, {["x"] = 2, ["param2"] = 15, ["y"] = 4, ["param1"] = 173, ["z"] = 0, ["name"] = "stones:s_52ur"}, {["x"] = 2, ["param2"] = 1, ["y"] = 4, ["param1"] = 205, ["z"] = 2, ["name"] = "stones:spircol_8"}, {["x"] = 2, ["param2"] = 8, ["y"] = 5, ["param1"] = 189, ["z"] = 0, ["name"] = "stones:stair_2"}, {["x"] = 2, ["param2"] = 3, ["y"] = 5, ["param1"] = 205, ["z"] = 1, ["name"] = "stones:spirout_r"}, {["x"] = 2, ["param2"] = 2, ["y"] = 5, ["param1"] = 222, ["z"] = 2, ["name"] = "stones:spircol_8"}, {["x"] = 2, ["param2"] = 20, ["y"] = 5, ["param1"] = 189, ["z"] = 4, ["name"] = "stones:roch"}, {["x"] = 2, ["y"] = 6, ["param1"] = 238, ["z"] = 2, ["name"] = "stones:estamp"}, {["x"] = 2, ["param2"] = 4, ["y"] = 7, ["param1"] = 189, ["z"] = 4, ["name"] = "stones:panel"}, {["x"] = 3, ["param2"] = 2, ["y"] = 0, ["param1"] = 109, ["z"] = 0, ["name"] = "stones:brushrock_4"}, {["x"] = 3, ["y"] = 0, ["param1"] = 109, ["z"] = 1, ["name"] = "stones:rock"}, {["x"] = 3, ["y"] = 0, ["param1"] = 125, ["z"] = 2, ["name"] = "stones:rock"}, {["x"] = 3, ["y"] = 0, ["param1"] = 109, ["z"] = 3, ["name"] = "stones:rock"}, {["x"] = 3, ["y"] = 0, ["param1"] = 93, ["z"] = 4, ["name"] = "stones:rock"}, {["x"] = 3, ["y"] = 1, ["param1"] = 126, ["z"] = 0, ["name"] = "stones:s_22l"}, {["x"] = 3, ["param2"] = 14, ["y"] = 1, ["param1"] = 125, ["z"] = 1, ["name"] = "stones:s_52l"}, {["x"] = 3, ["param2"] = 1, ["y"] = 1, ["param1"] = 125, ["z"] = 3, ["name"] = "stones:spircod"}, {["x"] = 3, ["param2"] = 7, ["y"] = 1, ["param1"] = 110, ["z"] = 4, ["name"] = "stones:s_52"}, {["x"] = 3, ["param2"] = 1, ["y"] = 2, ["param1"] = 141, ["z"] = 3, ["name"] = "stones:spircod"}, {["x"] = 3, ["param2"] = 7, ["y"] = 2, ["param1"] = 126, ["z"] = 4, ["name"] = "stones:s_52"}, {["x"] = 3, ["param2"] = 20, ["y"] = 3, ["param1"] = 157, ["z"] = 3, ["name"] = "stones:spirdiag_r"}, {["x"] = 3, ["param2"] = 3, ["y"] = 3, ["param1"] = 142, ["z"] = 4, ["name"] = "stones:diagsteps_13"}, {["x"] = 3, ["param2"] = 20, ["y"] = 4, ["param1"] = 173, ["z"] = 1, ["name"] = "stones:diagstep"}, {["x"] = 3, ["param2"] = 2, ["y"] = 4, ["param1"] = 190, ["z"] = 2, ["name"] = "stones:spirstax_r"}, {["x"] = 3, ["param2"] = 1, ["y"] = 4, ["param1"] = 173, ["z"] = 3, ["name"] = "stones:spirdiag_r"}, {["x"] = 3, ["param2"] = 7, ["y"] = 4, ["param1"] = 158, ["z"] = 4, ["name"] = "stones:s_52"}, {["x"] = 3, ["param2"] = 21, ["y"] = 5, ["param1"] = 174, ["z"] = 0, ["name"] = "stones:diagsteps_13"}, {["x"] = 3, ["param2"] = 2, ["y"] = 5, ["param1"] = 190, ["z"] = 1, ["name"] = "stones:spirdiag_r"}, {["x"] = 3, ["param2"] = 1, ["y"] = 5, ["param1"] = 190, ["z"] = 3, ["name"] = "stones:spircod"}, {["x"] = 3, ["param2"] = 22, ["y"] = 5, ["param1"] = 174, ["z"] = 4, ["name"] = "stones:diagsteps_31"}, {["x"] = 3, ["param2"] = 7, ["y"] = 6, ["param1"] = 190, ["z"] = 4, ["name"] = "stones:s_22"}, {["x"] = 3, ["param2"] = 14, ["y"] = 7, ["param1"] = 190, ["z"] = 3, ["name"] = "stones:sku_202"}, {["x"] = 3, ["param2"] = 14, ["y"] = 7, ["param1"] = 174, ["z"] = 4, ["name"] = "stones:s_22l"}, {["x"] = 4, ["param2"] = 7, ["y"] = 0, ["param1"] = 94, ["z"] = 0, ["name"] = "stones:brushrock_52ur"}, {["x"] = 4, ["param2"] = 12, ["y"] = 0, ["param1"] = 94, ["z"] = 1, ["name"] = "stones:s_52"}, {["x"] = 4, ["param2"] = 12, ["y"] = 0, ["param1"] = 110, ["z"] = 2, ["name"] = "stones:s_52u"}, {["x"] = 4, ["param2"] = 14, ["y"] = 0, ["param1"] = 94, ["z"] = 3, ["name"] = "stones:s_52u"}, {["x"] = 4, ["param2"] = 7, ["y"] = 0, ["param1"] = 78, ["z"] = 4, ["name"] = "stones:s_22"}, {["x"] = 4, ["param2"] = 11, ["y"] = 1, ["param1"] = 126, ["z"] = 2, ["name"] = "stones:panel"}, {["x"] = 4, ["param2"] = 14, ["y"] = 1, ["param1"] = 110, ["z"] = 3, ["name"] = "stones:s_52"}, {["x"] = 4, ["param2"] = 11, ["y"] = 2, ["param1"] = 142, ["z"] = 2, ["name"] = "stones:panel"}, {["x"] = 4, ["param2"] = 14, ["y"] = 2, ["param1"] = 126, ["z"] = 3, ["name"] = "stones:s_52"}, {["x"] = 4, ["param2"] = 11, ["y"] = 3, ["param1"] = 158, ["z"] = 2, ["name"] = "stones:panel"}, {["x"] = 4, ["param2"] = 14, ["y"] = 3, ["param1"] = 142, ["z"] = 3, ["name"] = "stones:s_52"}, {["x"] = 4, ["param2"] = 12, ["y"] = 4, ["param1"] = 158, ["z"] = 1, ["name"] = "stones:s_52l"}, {["x"] = 4, ["param2"] = 20, ["y"] = 4, ["param1"] = 174, ["z"] = 2, ["name"] = "stones:stair_half_r"}, {["x"] = 4, ["param2"] = 14, ["y"] = 4, ["param1"] = 158, ["z"] = 3, ["name"] = "stones:s_52"}, {["x"] = 4, ["param2"] = 11, ["y"] = 5, ["param1"] = 158, ["z"] = 0, ["name"] = "stones:s_22r"}, {["x"] = 4, ["param2"] = 21, ["y"] = 5, ["param1"] = 174, ["z"] = 1, ["name"] = "stones:diagsteps_31"}, {["x"] = 4, ["param2"] = 21, ["y"] = 5, ["param1"] = 190, ["z"] = 2, ["name"] = "stones:stair_2"}, {["x"] = 4, ["param2"] = 22, ["y"] = 5, ["param1"] = 174, ["z"] = 3, ["name"] = "stones:diagsteps_13"}, {["x"] = 4, ["param2"] = 14, ["y"] = 5, ["param1"] = 158, ["z"] = 4, ["name"] = "stones:s_22r"}, {["x"] = 4, ["y"] = 6, ["param1"] = 190, ["z"] = 1, ["name"] = "stones:s_22l"}, {["x"] = 4, ["y"] = 6, ["param1"] = 206, ["z"] = 2, ["name"] = "stones:sku_202"}, {["x"] = 4, ["y"] = 7, ["param1"] = 190, ["z"] = 2, ["name"] = "stones:s_22l"}, {["x"] = 4, ["param2"] = 14, ["y"] = 7, ["param1"] = 174, ["z"] = 3, ["name"] = "stones:s_22l"}}