5:return {{["x"] = 0, ["param2"] = 11, ["y"] = 0, ["param1"] = 78, ["z"] = 0, ["name"] = "stones:s_52r"}, {["x"] = 0, ["param2"] = 20, ["y"] = 0, ["param1"] = 94, ["z"] = 1, ["name"] = "stones:roch"}, {["x"] = 0, ["param2"] = 5, ["y"] = 0, ["param1"] = 77, ["z"] = 2, ["name"] = "stones:s_52ur"}, {["x"] = 0, ["param2"] = 5, ["y"] = 1, ["param1"] = 62, ["z"] = 0, ["name"] = "stones:sku2_l"}, {["x"] = 0, ["param2"] = 11, ["y"] = 1, ["param1"] = 62, ["z"] = 2, ["name"] = "stones:s_52l"}, {["x"] = 0, ["param2"] = 5, ["y"] = 1, ["param1"] = 46, ["z"] = 3, ["name"] = "stones:s_52l"}, {["x"] = 0, ["param2"] = 5, ["y"] = 2, ["param1"] = 46, ["z"] = 0, ["name"] = "stones:sku2_l"}, {["x"] = 0, ["param2"] = 11, ["y"] = 2, ["param1"] = 46, ["z"] = 2, ["name"] = "stones:s_52l"}, {["x"] = 0, ["param2"] = 5, ["y"] = 2, ["param1"] = 30, ["z"] = 3, ["name"] = "stones:s_52l"}, {["x"] = 1, ["param2"] = 11, ["y"] = 0, ["param1"] = 77, ["z"] = 1, ["name"] = "stones:s_52ur"}, {["x"] = 1, ["param2"] = 20, ["y"] = 0, ["param1"] = 62, ["z"] = 2, ["name"] = "stones:roch"}, {["x"] = 1, ["param2"] = 5, ["y"] = 0, ["param1"] = 46, ["z"] = 3, ["name"] = "stones:s_52ur"}, {["x"] = 1, ["param2"] = 11, ["y"] = 1, ["param1"] = 78, ["z"] = 0, ["name"] = "stones:s_52l"}, {["x"] = 1, ["param2"] = 5, ["y"] = 1, ["param1"] = 62, ["z"] = 1, ["name"] = "stones:s_52l"}, {["x"] = 1, ["param2"] = 5, ["y"] = 1, ["param1"] = 30, ["z"] = 3, ["name"] = "stones:sku"}, {["x"] = 1, ["param2"] = 11, ["y"] = 2, ["param1"] = 62, ["z"] = 0, ["name"] = "stones:s_52l"}, {["x"] = 1, ["param2"] = 5, ["y"] = 2, ["param1"] = 46, ["z"] = 1, ["name"] = "stones:s_52l"}, {["x"] = 1, ["param2"] = 5, ["y"] = 2, ["param1"] = 14, ["z"] = 3, ["name"] = "stones:sku2_l"}, {["x"] = 2, ["param2"] = 11, ["y"] = 0, ["param1"] = 94, ["z"] = 1, ["name"] = "stones:s_52r"}, {["x"] = 2, ["param2"] = 20, ["y"] = 0, ["param1"] = 78, ["z"] = 2, ["name"] = "stones:roch"}, {["x"] = 2, ["param2"] = 5, ["y"] = 0, ["param1"] = 61, ["z"] = 3, ["name"] = "stones:s_52ur"}, {["x"] = 2, ["param2"] = 5, ["y"] = 1, ["param1"] = 78, ["z"] = 1, ["name"] = "stones:sku2_l"}, {["x"] = 2, ["param2"] = 11, ["y"] = 1, ["param1"] = 46, ["z"] = 3, ["name"] = "stones:s_52r"}, {["x"] = 2, ["param2"] = 5, ["y"] = 1, ["param1"] = 30, ["z"] = 4, ["name"] = "stones:s_52r"}, {["x"] = 2, ["param2"] = 5, ["y"] = 2, ["param1"] = 62, ["z"] = 1, ["name"] = "stones:sku2_l"}, {["x"] = 3, ["param2"] = 11, ["y"] = 0, ["param1"] = 77, ["z"] = 2, ["name"] = "stones:s_52ur"}, {["x"] = 3, ["param2"] = 20, ["y"] = 0, ["param1"] = 62, ["z"] = 3, ["name"] = "stones:roch"}, {["x"] = 3, ["param2"] = 5, ["y"] = 0, ["param1"] = 45, ["z"] = 4, ["name"] = "stones:s_52ur"}, {["x"] = 3, ["param2"] = 11, ["y"] = 1, ["param1"] = 78, ["z"] = 1, ["name"] = "stones:s_52l"}, {["x"] = 3, ["param2"] = 5, ["y"] = 1, ["param1"] = 62, ["z"] = 2, ["name"] = "stones:s_52l"}, {["x"] = 3, ["param2"] = 5, ["y"] = 1, ["param1"] = 30, ["z"] = 4, ["name"] = "stones:sku"}, {["x"] = 3, ["param2"] = 11, ["y"] = 2, ["param1"] = 62, ["z"] = 1, ["name"] = "stones:s_52l"}, {["x"] = 3, ["param2"] = 5, ["y"] = 2, ["param1"] = 46, ["z"] = 2, ["name"] = "stones:s_52l"}, {["x"] = 3, ["param2"] = 5, ["y"] = 2, ["param1"] = 46, ["z"] = 4, ["name"] = "stones:sku2_l"}, {["x"] = 4, ["param2"] = 11, ["y"] = 0, ["param1"] = 94, ["z"] = 2, ["name"] = "stones:s_52r"}, {["x"] = 4, ["param2"] = 20, ["y"] = 0, ["param1"] = 78, ["z"] = 3, ["name"] = "stones:roch"}, {["x"] = 4, ["param2"] = 5, ["y"] = 0, ["param1"] = 61, ["z"] = 4, ["name"] = "stones:s_52ur"}, {["x"] = 4, ["param2"] = 5, ["y"] = 1, ["param1"] = 78, ["z"] = 2, ["name"] = "stones:sku2_l"}, {["x"] = 4, ["param2"] = 11, ["y"] = 1, ["param1"] = 46, ["z"] = 4, ["name"] = "stones:s_52l"}, {["x"] = 4, ["param2"] = 5, ["y"] = 1, ["param1"] = 62, ["z"] = 5, ["name"] = "stones:s_52l"}, {["x"] = 4, ["param2"] = 5, ["y"] = 2, ["param1"] = 62, ["z"] = 2, ["name"] = "stones:sku2_l"}, {["x"] = 4, ["param2"] = 11, ["y"] = 2, ["param1"] = 62, ["z"] = 4, ["name"] = "stones:s_52l"}, {["x"] = 4, ["param2"] = 5, ["y"] = 2, ["param1"] = 78, ["z"] = 5, ["name"] = "stones:s_52l"}}