5:return {{["x"] = 0, ["param2"] = 13, ["y"] = 8, ["param1"] = 110, ["z"] = 10, ["name"] = "stones:arschir"}, {["x"] = 0, ["param2"] = 13, ["y"] = 9, ["param1"] = 126, ["z"] = 10, ["name"] = "stones:arcshil"}, {["x"] = 0, ["param2"] = 11, ["y"] = 9, ["param1"] = 141, ["z"] = 11, ["name"] = "stones:brushrock_527l"}, {["x"] = 0, ["param2"] = 3, ["y"] = 9, ["param1"] = 157, ["z"] = 12, ["name"] = "stones:brush"}, {["x"] = 0, ["param2"] = 1, ["y"] = 9, ["param1"] = 173, ["z"] = 13, ["name"] = "stones:brushrock_8"}, {["x"] = 0, ["param2"] = 14, ["y"] = 9, ["param1"] = 189, ["z"] = 14, ["name"] = "stones:brushrock_22"}, {["x"] = 0, ["param2"] = 9, ["y"] = 9, ["param1"] = 126, ["z"] = 18, ["name"] = "stones:s_22"}, {["x"] = 0, ["param2"] = 16, ["y"] = 9, ["param1"] = 109, ["z"] = 19, ["name"] = "stones:s_52u"}, {["x"] = 0, ["y"] = 9, ["param1"] = 125, ["z"] = 20, ["name"] = "stones:rock"}, {["x"] = 0, ["param2"] = 18, ["y"] = 9, ["param1"] = 109, ["z"] = 21, ["name"] = "stones:s_52u"}, {["x"] = 0, ["param2"] = 5, ["y"] = 9, ["param1"] = 93, ["z"] = 22, ["name"] = "stones:s_22"}, {["x"] = 0, ["param2"] = 3, ["y"] = 10, ["param1"] = 158, ["z"] = 11, ["name"] = "stones:dias52d"}, {["x"] = 0, ["param2"] = 16, ["y"] = 10, ["param1"] = 125, ["z"] = 19, ["name"] = "stones:s_52"}, {["x"] = 0, ["param2"] = 16, ["y"] = 10, ["param1"] = 124, ["z"] = 20, ["name"] = "stones:roch"}, {["x"] = 0, ["param2"] = 18, ["y"] = 10, ["param1"] = 108, ["z"] = 21, ["name"] = "stones:s_52"}, {["x"] = 0, ["param2"] = 16, ["y"] = 11, ["param1"] = 141, ["z"] = 19, ["name"] = "stones:s_52"}, {["x"] = 0, ["param2"] = 16, ["y"] = 11, ["param1"] = 140, ["z"] = 20, ["name"] = "stones:roch"}, {["x"] = 0, ["param2"] = 18, ["y"] = 11, ["param1"] = 124, ["z"] = 21, ["name"] = "stones:s_52"}, {["x"] = 0, ["param2"] = 16, ["y"] = 12, ["param1"] = 141, ["z"] = 19, ["name"] = "stones:s_52"}, {["x"] = 0, ["param2"] = 16, ["y"] = 12, ["param1"] = 156, ["z"] = 20, ["name"] = "stones:roch"}, {["x"] = 0, ["param2"] = 18, ["y"] = 12, ["param1"] = 140, ["z"] = 21, ["name"] = "stones:s_52"}, {["x"] = 0, ["param2"] = 16, ["y"] = 13, ["param1"] = 157, ["z"] = 19, ["name"] = "stones:s_52"}, {["x"] = 0, ["param2"] = 16, ["y"] = 13, ["param1"] = 173, ["z"] = 20, ["name"] = "stones:roch"}, {["x"] = 0, ["param2"] = 18, ["y"] = 13, ["param1"] = 157, ["z"] = 21, ["name"] = "stones:s_52"}, {["x"] = 0, ["param2"] = 9, ["y"] = 14, ["param1"] = 158, ["z"] = 18, ["name"] = "stones:s_22l"}, {["x"] = 0, ["param2"] = 20, ["y"] = 14, ["param1"] = 174, ["z"] = 19, ["name"] = "stones:diagsteps_13"}, {["x"] = 0, ["param2"] = 23, ["y"] = 14, ["param1"] = 189, ["z"] = 20, ["name"] = "stones:stair_2"}, {["x"] = 0, ["param2"] = 23, ["y"] = 14, ["param1"] = 173, ["z"] = 21, ["name"] = "stones:diagsteps_31"}, {["x"] = 0, ["param2"] = 18, ["y"] = 14, ["param1"] = 157, ["z"] = 22, ["name"] = "stones:s_22l"}, {["x"] = 1, ["param2"] = 17, ["y"] = 8, ["param1"] = 110, ["z"] = 9, ["name"] = "stones:s_252l"}, {["x"] = 1, ["param2"] = 23, ["y"] = 8, ["param1"] = 126, ["z"] = 10, ["name"] = "stones:s_252l"}, {["x"] = 1, ["param2"] = 17, ["y"] = 8, ["param1"] = 190, ["z"] = 14, ["name"] = "stones:s_2"}, {["x"] = 1, ["param2"] = 9, ["y"] = 8, ["param1"] = 110, ["z"] = 19, ["name"] = "stones:s_2"}, {["x"] = 1, ["y"] = 8, ["param1"] = 126, ["z"] = 20, ["name"] = "stones:rock"}, {["x"] = 1, ["param2"] = 5, ["y"] = 8, ["param1"] = 110, ["z"] = 21, ["name"] = "stones:s_2"}, {["x"] = 1, ["y"] = 9, ["param1"] = 141, ["z"] = 10, ["name"] = "stones:s_52"}, {["x"] = 1, ["y"] = 9, ["param1"] = 157, ["z"] = 11, ["name"] = "stones:stair_2"}, {["x"] = 1, ["param2"] = 3, ["y"] = 9, ["param1"] = 173, ["z"] = 12, ["name"] = "stones:brush"}, {["x"] = 1, ["y"] = 9, ["param1"] = 189, ["z"] = 13, ["name"] = "stones:brushrock_0"}, {["x"] = 1, ["y"] = 9, ["param1"] = 206, ["z"] = 14, ["name"] = "stones:rock"}, {["x"] = 1, ["param2"] = 16, ["y"] = 9, ["param1"] = 189, ["z"] = 15, ["name"] = "stones:s_52"}, {["x"] = 1, ["param2"] = 16, ["y"] = 9, ["param1"] = 174, ["z"] = 16, ["name"] = "stones:roch"}, {["x"] = 1, ["param2"] = 18, ["y"] = 9, ["param1"] = 158, ["z"] = 17, ["name"] = "stones:s_52"}, {["x"] = 1, ["param2"] = 9, ["y"] = 9, ["param1"] = 141, ["z"] = 18, ["name"] = "stones:s_52u"}, {["x"] = 1, ["y"] = 9, ["param1"] = 125, ["z"] = 19, ["name"] = "stones:rock"}, {["x"] = 1, ["param2"] = 2, ["y"] = 9, ["param1"] = 141, ["z"] = 20, ["name"] = "stones:rush"}, {["x"] = 1, ["y"] = 9, ["param1"] = 125, ["z"] = 21, ["name"] = "stones:rock"}, {["x"] = 1, ["param2"] = 5, ["y"] = 9, ["param1"] = 109, ["z"] = 22, ["name"] = "stones:s_52u"}, {["x"] = 1, ["param2"] = 3, ["y"] = 10, ["param1"] = 222, ["z"] = 14, ["name"] = "stones:iso54"}, {["x"] = 1, ["param2"] = 9, ["y"] = 10, ["param1"] = 158, ["z"] = 18, ["name"] = "stones:s_52"}, {["x"] = 1, ["param2"] = 22, ["y"] = 10, ["param1"] = 141, ["z"] = 19, ["name"] = "stones:spirdiag_r"}, {["x"] = 1, ["y"] = 10, ["param1"] = 124, ["z"] = 21, ["name"] = "stones:spircod"}, {["x"] = 1, ["param2"] = 5, ["y"] = 10, ["param1"] = 108, ["z"] = 22, ["name"] = "stones:s_52"}, {["x"] = 1, ["param2"] = 3, ["y"] = 11, ["param1"] = 238, ["z"] = 14, ["name"] = "stones:isokar"}, {["x"] = 1, ["param2"] = 9, ["y"] = 11, ["param1"] = 174, ["z"] = 18, ["name"] = "stones:s_52"}, {["x"] = 1, ["param2"] = 3, ["y"] = 11, ["param1"] = 157, ["z"] = 19, ["name"] = "stones:spirdiag_r"}, {["x"] = 1, ["y"] = 11, ["param1"] = 156, ["z"] = 20, ["name"] = "stones:spirstax_r"}, {["x"] = 1, ["param2"] = 21, ["y"] = 11, ["param1"] = 139, ["z"] = 21, ["name"] = "stones:spirdiag_r"}, {["x"] = 1, ["param2"] = 5, ["y"] = 11, ["param1"] = 123, ["z"] = 22, ["name"] = "stones:s_52"}, {["x"] = 1, ["param2"] = 9, ["y"] = 12, ["param1"] = 158, ["z"] = 18, ["name"] = "stones:s_52"}, {["x"] = 1, ["param2"] = 3, ["y"] = 12, ["param1"] = 157, ["z"] = 19, ["name"] = "stones:spircod"}, {["x"] = 1, ["y"] = 12, ["param1"] = 155, ["z"] = 21, ["name"] = "stones:spirdiag_r"}, {["x"] = 1, ["param2"] = 2, ["y"] = 12, ["param1"] = 139, ["z"] = 22, ["name"] = "stones:diagsteps_31"}, {["x"] = 1, ["param2"] = 9, ["y"] = 13, ["param1"] = 158, ["z"] = 18, ["name"] = "stones:s_52"}, {["x"] = 1, ["param2"] = 3, ["y"] = 13, ["param1"] = 173, ["z"] = 19, ["name"] = "stones:spircod"}, {["x"] = 1, ["y"] = 13, ["param1"] = 172, ["z"] = 21, ["name"] = "stones:spircod"}, {["x"] = 1, ["param2"] = 5, ["y"] = 13, ["param1"] = 156, ["z"] = 22, ["name"] = "stones:s_52"}, {["x"] = 1, ["param2"] = 20, ["y"] = 14, ["param1"] = 174, ["z"] = 18, ["name"] = "stones:diagsteps_31"}, {["x"] = 1, ["param2"] = 22, ["y"] = 14, ["param1"] = 190, ["z"] = 19, ["name"] = "stones:spirdiag"}, {["x"] = 1, ["param2"] = 3, ["y"] = 14, ["param1"] = 205, ["z"] = 20, ["name"] = "stones:spirjoin_2l"}, {["x"] = 1, ["y"] = 14, ["param1"] = 188, ["z"] = 21, ["name"] = "stones:spircod"}, {["x"] = 1, ["param2"] = 23, ["y"] = 14, ["param1"] = 172, ["z"] = 22, ["name"] = "stones:diagsteps_13"}, {["x"] = 1, ["param2"] = 17, ["y"] = 15, ["param1"] = 222, ["z"] = 20, ["name"] = "stones:sku3_l"}, {["x"] = 1, ["param2"] = 5, ["y"] = 15, ["param1"] = 189, ["z"] = 22, ["name"] = "stones:s_22"}, {["x"] = 1, ["param2"] = 10, ["y"] = 16, ["param1"] = 206, ["z"] = 20, ["name"] = "stones:s_22r"}, {["x"] = 1, ["param2"] = 12, ["y"] = 16, ["param1"] = 190, ["z"] = 21, ["name"] = "stones:sku2_r"}, {["x"] = 1, ["param2"] = 5, ["y"] = 16, ["param1"] = 174, ["z"] = 22, ["name"] = "stones:s_22l"}, {["x"] = 2, ["param2"] = 16, ["y"] = 8, ["param1"] = 141, ["z"] = 8, ["name"] = "stones:brushrock_22"}, {["x"] = 2, ["param2"] = 1, ["y"] = 8, ["param1"] = 125, ["z"] = 9, ["name"] = "stones:brushrock_5"}, {["x"] = 2, ["param2"] = 3, ["y"] = 8, ["param1"] = 141, ["z"] = 10, ["name"] = "stones:brushrock_c"}, {["x"] = 2, ["param2"] = 5, ["y"] = 8, ["param1"] = 125, ["z"] = 11, ["name"] = "stones:s_2"}, {["x"] = 2, ["y"] = 8, ["param1"] = 173, ["z"] = 14, ["name"] = "stones:rock"}, {["x"] = 2, ["param2"] = 17, ["y"] = 8, ["param1"] = 157, ["z"] = 15, ["name"] = "stones:s_52u"}, {["x"] = 2, ["param2"] = 17, ["y"] = 8, ["param1"] = 141, ["z"] = 16, ["name"] = "stones:vr_2u"}, {["x"] = 2, ["param2"] = 18, ["y"] = 8, ["param1"] = 125, ["z"] = 17, ["name"] = "stones:s_52u"}, {["x"] = 2, ["param2"] = 16, ["y"] = 8, ["param1"] = 125, ["z"] = 18, ["name"] = "stones:s_52u"}, {["x"] = 2, ["y"] = 8, ["param1"] = 125, ["z"] = 19, ["name"] = "stones:rock"}, {["x"] = 2, ["y"] = 8, ["param1"] = 141, ["z"] = 20, ["name"] = "stones:rock"}, {["x"] = 2, ["y"] = 8, ["param1"] = 125, ["z"] = 21, ["name"] = "stones:rock"}, {["x"] = 2, ["param2"] = 17, ["y"] = 9, ["param1"] = 158, ["z"] = 10, ["name"] = "stones:arcshir"}, {["x"] = 2, ["param2"] = 9, ["y"] = 9, ["param1"] = 141, ["z"] = 11, ["name"] = "stones:brushrock_527r"}, {["x"] = 2, ["param2"] = 3, ["y"] = 9, ["param1"] = 157, ["z"] = 12, ["name"] = "stones:brush"}, {["x"] = 2, ["y"] = 9, ["param1"] = 174, ["z"] = 13, ["name"] = "stones:brushrock_8"}, {["x"] = 2, ["param2"] = 3, ["y"] = 9, ["param1"] = 190, ["z"] = 14, ["name"] = "stones:brushrock_0"}, {["x"] = 2, ["param2"] = 1, ["y"] = 9, ["param1"] = 174, ["z"] = 15, ["name"] = "stones:brushrock_5"}, {["x"] = 2, ["y"] = 9, ["param1"] = 158, ["z"] = 16, ["name"] = "stones:brush"}, {["x"] = 2, ["y"] = 9, ["param1"] = 142, ["z"] = 17, ["name"] = "stones:brushrock_2"}, {["x"] = 2, ["y"] = 9, ["param1"] = 141, ["z"] = 18, ["name"] = "stones:rock"}, {["x"] = 2, ["y"] = 9, ["param1"] = 140, ["z"] = 19, ["name"] = "stones:rock"}, {["x"] = 2, ["y"] = 9, ["param1"] = 156, ["z"] = 20, ["name"] = "stones:rock"}, {["x"] = 2, ["y"] = 9, ["param1"] = 140, ["z"] = 21, ["name"] = "stones:rock"}, {["x"] = 2, ["y"] = 9, ["param1"] = 124, ["z"] = 22, ["name"] = "stones:rock"}, {["x"] = 2, ["param2"] = 2, ["y"] = 10, ["param1"] = 157, ["z"] = 11, ["name"] = "stones:dias52b"}, {["x"] = 2, ["y"] = 10, ["param1"] = 142, ["z"] = 18, ["name"] = "stones:s_22"}, {["x"] = 2, ["param2"] = 23, ["y"] = 10, ["param1"] = 141, ["z"] = 19, ["name"] = "stones:spirout_r"}, {["x"] = 2, ["y"] = 10, ["param1"] = 156, ["z"] = 20, ["name"] = "stones:spircol_8"}, {["x"] = 2, ["param2"] = 6, ["y"] = 10, ["param1"] = 124, ["z"] = 22, ["name"] = "stones:panel"}, {["x"] = 2, ["y"] = 11, ["param1"] = 172, ["z"] = 20, ["name"] = "stones:spircol_8"}, {["x"] = 2, ["param2"] = 15, ["y"] = 12, ["param1"] = 158, ["z"] = 18, ["name"] = "stones:s_52r"}, {["x"] = 2, ["param2"] = 1, ["y"] = 12, ["param1"] = 188, ["z"] = 20, ["name"] = "stones:spircol_8"}, {["x"] = 2, ["param2"] = 21, ["y"] = 12, ["param1"] = 171, ["z"] = 21, ["name"] = "stones:spirout_r"}, {["x"] = 2, ["param2"] = 2, ["y"] = 12, ["param1"] = 156, ["z"] = 22, ["name"] = "stones:roch"}, {["x"] = 2, ["param2"] = 15, ["y"] = 13, ["param1"] = 174, ["z"] = 18, ["name"] = "stones:s_52ur"}, {["x"] = 2, ["param2"] = 1, ["y"] = 13, ["param1"] = 204, ["z"] = 20, ["name"] = "stones:spircol_8"}, {["x"] = 2, ["param2"] = 4, ["y"] = 13, ["param1"] = 172, ["z"] = 22, ["name"] = "stones:panel"}, {["x"] = 2, ["param2"] = 8, ["y"] = 14, ["param1"] = 190, ["z"] = 18, ["name"] = "stones:stair_2"}, {["x"] = 2, ["param2"] = 3, ["y"] = 14, ["param1"] = 206, ["z"] = 19, ["name"] = "stones:spirout_r"}, {["x"] = 2, ["param2"] = 2, ["y"] = 14, ["param1"] = 221, ["z"] = 20, ["name"] = "stones:spircol_8"}, {["x"] = 2, ["param2"] = 20, ["y"] = 14, ["param1"] = 188, ["z"] = 22, ["name"] = "stones:roch"}, {["x"] = 2, ["y"] = 15, ["param1"] = 238, ["z"] = 20, ["name"] = "stones:estamp"}, {["x"] = 2, ["param2"] = 4, ["y"] = 16, ["param1"] = 190, ["z"] = 22, ["name"] = "stones:panel"}, {["x"] = 3, ["param2"] = 2, ["y"] = 8, ["param1"] = 158, ["z"] = 8, ["name"] = "stones:brushrock_0"}, {["x"] = 3, ["param2"] = 1, ["y"] = 8, ["param1"] = 142, ["z"] = 9, ["name"] = "stones:brush"}, {["x"] = 3, ["y"] = 8, ["param1"] = 158, ["z"] = 10, ["name"] = "stones:brush"}, {["x"] = 3, ["param2"] = 2, ["y"] = 8, ["param1"] = 141, ["z"] = 11, ["name"] = "stones:brushrock_4"}, {["x"] = 3, ["param2"] = 9, ["y"] = 8, ["param1"] = 141, ["z"] = 13, ["name"] = "stones:r_2"}, {["x"] = 3, ["y"] = 8, ["z"] = 14, ["name"] = "stones:rubble"}, {["x"] = 3, ["y"] = 8, ["z"] = 15, ["name"] = "stones:rubble"}, {["x"] = 3, ["y"] = 8, ["z"] = 16, ["name"] = "stones:rubble"}, {["x"] = 3, ["y"] = 8, ["z"] = 17, ["name"] = "stones:rubble"}, {["x"] = 3, ["y"] = 8, ["z"] = 18, ["name"] = "stones:rubble"}, {["x"] = 3, ["y"] = 8, ["param1"] = 140, ["z"] = 19, ["name"] = "stones:rock"}, {["x"] = 3, ["y"] = 8, ["param1"] = 156, ["z"] = 20, ["name"] = "stones:rock"}, {["x"] = 3, ["y"] = 8, ["param1"] = 140, ["z"] = 21, ["name"] = "stones:rock"}, {["x"] = 3, ["param2"] = 11, ["y"] = 9, ["param1"] = 158, ["z"] = 11, ["name"] = "stones:brushrock_52ul"}, {["x"] = 3, ["param2"] = 3, ["y"] = 9, ["param1"] = 142, ["z"] = 12, ["name"] = "stones:brush"}, {["x"] = 3, ["param2"] = 2, ["y"] = 9, ["param1"] = 158, ["z"] = 13, ["name"] = "stones:brush"}, {["x"] = 3, ["param2"] = 1, ["y"] = 9, ["param1"] = 174, ["z"] = 14, ["name"] = "stones:brush"}, {["x"] = 3, ["y"] = 9, ["param1"] = 158, ["z"] = 15, ["name"] = "stones:brush"}, {["x"] = 3, ["y"] = 9, ["param1"] = 142, ["z"] = 16, ["name"] = "stones:brush"}, {["x"] = 3, ["y"] = 9, ["param1"] = 142, ["z"] = 17, ["name"] = "stones:brush"}, {["x"] = 3, ["param2"] = 2, ["y"] = 9, ["param1"] = 157, ["z"] = 18, ["name"] = "stones:brushrock_4"}, {["x"] = 3, ["y"] = 9, ["param1"] = 157, ["z"] = 19, ["name"] = "stones:rock"}, {["x"] = 3, ["y"] = 9, ["param1"] = 172, ["z"] = 20, ["name"] = "stones:rock"}, {["x"] = 3, ["y"] = 9, ["param1"] = 156, ["z"] = 21, ["name"] = "stones:rock"}, {["x"] = 3, ["param2"] = 7, ["y"] = 9, ["param1"] = 141, ["z"] = 22, ["name"] = "stones:s_52u"}, {["x"] = 3, ["param2"] = 5, ["y"] = 10, ["param1"] = 142, ["z"] = 11, ["name"] = "stones:sku2_r"}, {["x"] = 3, ["y"] = 10, ["param1"] = 142, ["z"] = 18, ["name"] = "stones:s_22l"}, {["x"] = 3, ["param2"] = 14, ["y"] = 10, ["param1"] = 142, ["z"] = 19, ["name"] = "stones:s_52l"}, {["x"] = 3, ["param2"] = 1, ["y"] = 10, ["param1"] = 140, ["z"] = 21, ["name"] = "stones:spircod"}, {["x"] = 3, ["param2"] = 7, ["y"] = 10, ["param1"] = 125, ["z"] = 22, ["name"] = "stones:s_52"}, {["x"] = 3, ["param2"] = 1, ["y"] = 11, ["param1"] = 140, ["z"] = 21, ["name"] = "stones:spircod"}, {["x"] = 3, ["param2"] = 7, ["y"] = 11, ["param1"] = 125, ["z"] = 22, ["name"] = "stones:s_52"}, {["x"] = 3, ["param2"] = 20, ["y"] = 12, ["param1"] = 156, ["z"] = 21, ["name"] = "stones:spirdiag_r"}, {["x"] = 3, ["param2"] = 3, ["y"] = 12, ["param1"] = 141, ["z"] = 22, ["name"] = "stones:diagsteps_13"}, {["x"] = 3, ["param2"] = 20, ["y"] = 13, ["param1"] = 173, ["z"] = 19, ["name"] = "stones:diagstep"}, {["x"] = 3, ["param2"] = 2, ["y"] = 13, ["param1"] = 188, ["z"] = 20, ["name"] = "stones:spirstax_r"}, {["x"] = 3, ["param2"] = 1, ["y"] = 13, ["param1"] = 171, ["z"] = 21, ["name"] = "stones:spirdiag_r"}, {["x"] = 3, ["param2"] = 7, ["y"] = 13, ["param1"] = 156, ["z"] = 22, ["name"] = "stones:s_52"}, {["x"] = 3, ["param2"] = 21, ["y"] = 14, ["param1"] = 174, ["z"] = 18, ["name"] = "stones:diagsteps_13"}, {["x"] = 3, ["param2"] = 2, ["y"] = 14, ["param1"] = 190, ["z"] = 19, ["name"] = "stones:spirdiag_r"}, {["x"] = 3, ["param2"] = 1, ["y"] = 14, ["param1"] = 188, ["z"] = 21, ["name"] = "stones:spircod"}, {["x"] = 3, ["param2"] = 22, ["y"] = 14, ["param1"] = 172, ["z"] = 22, ["name"] = "stones:diagsteps_31"}, {["x"] = 3, ["param2"] = 7, ["y"] = 15, ["param1"] = 189, ["z"] = 22, ["name"] = "stones:s_22"}, {["x"] = 3, ["param2"] = 14, ["y"] = 16, ["param1"] = 190, ["z"] = 21, ["name"] = "stones:sku_202"}, {["x"] = 3, ["param2"] = 14, ["y"] = 16, ["param1"] = 174, ["z"] = 22, ["name"] = "stones:s_22l"}, {["x"] = 4, ["param2"] = 11, ["y"] = 8, ["param1"] = 174, ["z"] = 8, ["name"] = "stones:brushrock_22"}, {["x"] = 4, ["param2"] = 2, ["y"] = 8, ["param1"] = 158, ["z"] = 9, ["name"] = "stones:brushrock_8"}, {["x"] = 4, ["param2"] = 3, ["y"] = 8, ["param1"] = 173, ["z"] = 10, ["name"] = "stones:brushrock_5"}, {["x"] = 4, ["param2"] = 14, ["y"] = 8, ["param1"] = 157, ["z"] = 11, ["name"] = "stones:brushrock_22"}, {["x"] = 4, ["y"] = 8, ["z"] = 13, ["name"] = "stones:rubble"}, {["x"] = 4, ["y"] = 8, ["param1"] = 141, ["z"] = 14, ["name"] = "stones:rush"}, {["x"] = 4, ["y"] = 8, ["param1"] = 125, ["z"] = 15, ["name"] = "stones:rush"}, {["x"] = 4, ["y"] = 8, ["param1"] = 125, ["z"] = 16, ["name"] = "stones:rush"}, {["x"] = 4, ["y"] = 8, ["param1"] = 141, ["z"] = 17, ["name"] = "stones:rush"}, {["x"] = 4, ["y"] = 8, ["z"] = 18, ["name"] = "stones:rubble"}, {["x"] = 4, ["y"] = 8, ["param1"] = 157, ["z"] = 19, ["name"] = "stones:rock"}, {["x"] = 4, ["y"] = 8, ["param1"] = 172, ["z"] = 20, ["name"] = "stones:rock"}, {["x"] = 4, ["param2"] = 7, ["y"] = 8, ["param1"] = 155, ["z"] = 21, ["name"] = "stones:s_2"}, {["x"] = 4, ["param2"] = 16, ["y"] = 9, ["param1"] = 190, ["z"] = 10, ["name"] = "stones:s_52"}, {["x"] = 4, ["y"] = 9, ["param1"] = 173, ["z"] = 11, ["name"] = "stones:brushrock_21"}, {["x"] = 4, ["param2"] = 1, ["y"] = 9, ["param1"] = 158, ["z"] = 12, ["name"] = "stones:brush"}, {["x"] = 4, ["param2"] = 2, ["y"] = 9, ["param1"] = 142, ["z"] = 13, ["name"] = "stones:brush"}, {["x"] = 4, ["y"] = 9, ["param1"] = 158, ["z"] = 14, ["name"] = "stones:brush"}, {["x"] = 4, ["y"] = 9, ["param1"] = 142, ["z"] = 15, ["name"] = "stones:brush"}, {["x"] = 4, ["param2"] = 1, ["y"] = 9, ["param1"] = 142, ["z"] = 16, ["name"] = "stones:brush"}, {["x"] = 4, ["y"] = 9, ["param1"] = 158, ["z"] = 17, ["name"] = "stones:brush"}, {["x"] = 4, ["param2"] = 7, ["y"] = 9, ["param1"] = 174, ["z"] = 18, ["name"] = "stones:brushrock_527r"}, {["x"] = 4, ["param2"] = 3, ["y"] = 9, ["param1"] = 174, ["z"] = 19, ["name"] = "stones:diagsteps_52rh"}, {["x"] = 4, ["param2"] = 3, ["y"] = 9, ["param1"] = 189, ["z"] = 20, ["name"] = "stones:s_21u"}, {["x"] = 4, ["param2"] = 14, ["y"] = 9, ["param1"] = 172, ["z"] = 21, ["name"] = "stones:s_52u"}, {["x"] = 4, ["param2"] = 7, ["y"] = 9, ["param1"] = 157, ["z"] = 22, ["name"] = "stones:s_22"}, {["x"] = 4, ["param2"] = 16, ["y"] = 10, ["param1"] = 174, ["z"] = 10, ["name"] = "stones:s_52r"}, {["x"] = 4, ["param2"] = 9, ["y"] = 10, ["param1"] = 158, ["z"] = 11, ["name"] = "stones:sku_202"}, {["x"] = 4, ["param2"] = 11, ["y"] = 10, ["param1"] = 174, ["z"] = 20, ["name"] = "stones:panel"}, {["x"] = 4, ["param2"] = 14, ["y"] = 10, ["param1"] = 157, ["z"] = 21, ["name"] = "stones:s_52"}, {["x"] = 4, ["param2"] = 11, ["y"] = 11, ["param1"] = 157, ["z"] = 20, ["name"] = "stones:panel"}, {["x"] = 4, ["param2"] = 14, ["y"] = 11, ["param1"] = 140, ["z"] = 21, ["name"] = "stones:s_52"}, {["x"] = 4, ["param2"] = 11, ["y"] = 12, ["param1"] = 156, ["z"] = 20, ["name"] = "stones:panel"}, {["x"] = 4, ["param2"] = 14, ["y"] = 12, ["param1"] = 140, ["z"] = 21, ["name"] = "stones:s_52"}, {["x"] = 4, ["param2"] = 12, ["y"] = 13, ["param1"] = 156, ["z"] = 19, ["name"] = "stones:s_52l"}, {["x"] = 4, ["param2"] = 20, ["y"] = 13, ["param1"] = 172, ["z"] = 20, ["name"] = "stones:stair_half_r"}, {["x"] = 4, ["param2"] = 14, ["y"] = 13, ["param1"] = 156, ["z"] = 21, ["name"] = "stones:s_52"}, {["x"] = 4, ["param2"] = 11, ["y"] = 14, ["param1"] = 157, ["z"] = 18, ["name"] = "stones:s_22r"}, {["x"] = 4, ["param2"] = 21, ["y"] = 14, ["param1"] = 173, ["z"] = 19, ["name"] = "stones:diagsteps_31"}, {["x"] = 4, ["param2"] = 21, ["y"] = 14, ["param1"] = 188, ["z"] = 20, ["name"] = "stones:stair_2"}, {["x"] = 4, ["param2"] = 22, ["y"] = 14, ["param1"] = 172, ["z"] = 21, ["name"] = "stones:diagsteps_13"}, {["x"] = 4, ["param2"] = 14, ["y"] = 14, ["param1"] = 156, ["z"] = 22, ["name"] = "stones:s_22r"}, {["x"] = 4, ["y"] = 15, ["param1"] = 188, ["z"] = 19, ["name"] = "stones:s_22l"}, {["x"] = 4, ["y"] = 15, ["param1"] = 204, ["z"] = 20, ["name"] = "stones:sku_202"}, {["x"] = 4, ["y"] = 16, ["param1"] = 188, ["z"] = 20, ["name"] = "stones:s_22l"}, {["x"] = 4, ["param2"] = 14, ["y"] = 16, ["param1"] = 173, ["z"] = 21, ["name"] = "stones:s_22l"}, {["x"] = 5, ["param2"] = 9, ["y"] = 8, ["param1"] = 189, ["z"] = 8, ["name"] = "stones:r_2"}, {["x"] = 5, ["y"] = 8, ["z"] = 9, ["name"] = "stones:rubble"}, {["x"] = 5, ["y"] = 8, ["z"] = 10, ["name"] = "stones:rubble"}, {["x"] = 5, ["param2"] = 5, ["y"] = 8, ["param1"] = 173, ["z"] = 11, ["name"] = "stones:r_2"}, {["x"] = 5, ["param2"] = 9, ["y"] = 8, ["param1"] = 157, ["z"] = 12, ["name"] = "stones:r_2"}, {["x"] = 5, ["y"] = 8, ["z"] = 13, ["name"] = "stones:rubble"}, {["x"] = 5, ["param2"] = 1, ["y"] = 8, ["param1"] = 125, ["z"] = 14, ["name"] = "stones:rush"}, {["x"] = 5, ["y"] = 8, ["param1"] = 125, ["z"] = 15, ["name"] = "stones:rush"}, {["x"] = 5, ["y"] = 8, ["param1"] = 141, ["z"] = 16, ["name"] = "stones:rush"}, {["x"] = 5, ["y"] = 8, ["param1"] = 157, ["z"] = 17, ["name"] = "stones:rush"}, {["x"] = 5, ["y"] = 8, ["z"] = 18, ["name"] = "stones:rubble"}, {["x"] = 5, ["y"] = 8, ["z"] = 19, ["name"] = "stones:rubble"}, {["x"] = 5, ["y"] = 8, ["z"] = 20, ["name"] = "stones:rubble"}, {["x"] = 5, ["param2"] = 16, ["y"] = 9, ["param1"] = 190, ["z"] = 7, ["name"] = "stones:s_52"}, {["x"] = 5, ["param2"] = 14, ["y"] = 9, ["param1"] = 206, ["z"] = 8, ["name"] = "stones:sku"}, {["x"] = 5, ["param2"] = 12, ["y"] = 9, ["param1"] = 190, ["z"] = 9, ["name"] = "stones:roch"}, {["x"] = 5, ["param2"] = 3, ["y"] = 9, ["param1"] = 206, ["z"] = 10, ["name"] = "stones:diagsteps_52rv"}, {["x"] = 5, ["param2"] = 12, ["y"] = 9, ["param1"] = 190, ["z"] = 11, ["name"] = "stones:brushrock_527r"}, {["x"] = 5, ["param2"] = 2, ["y"] = 9, ["param1"] = 174, ["z"] = 12, ["name"] = "stones:brushrock_8"}, {["x"] = 5, ["y"] = 9, ["param1"] = 158, ["z"] = 13, ["name"] = "stones:brush"}, {["x"] = 5, ["param2"] = 3, ["y"] = 9, ["param1"] = 142, ["z"] = 14, ["name"] = "stones:brush"}, {["x"] = 5, ["y"] = 9, ["param1"] = 142, ["z"] = 15, ["name"] = "stones:brush"}, {["x"] = 5, ["param2"] = 3, ["y"] = 9, ["param1"] = 158, ["z"] = 16, ["name"] = "stones:brushrock_5"}, {["x"] = 5, ["param2"] = 14, ["y"] = 9, ["param1"] = 174, ["z"] = 17, ["name"] = "stones:brushrock_527l"}, {["x"] = 5, ["param2"] = 14, ["y"] = 9, ["param1"] = 190, ["z"] = 18, ["name"] = "stones:s_222"}, {["x"] = 5, ["param2"] = 11, ["y"] = 9, ["param1"] = 204, ["z"] = 20, ["name"] = "stones:s_52"}, {["x"] = 5, ["param2"] = 5, ["y"] = 9, ["param1"] = 188, ["z"] = 21, ["name"] = "stones:s_52"}, {["x"] = 5, ["param2"] = 22, ["y"] = 10, ["param1"] = 174, ["z"] = 9, ["name"] = "stones:sku_202"}, {["x"] = 5, ["param2"] = 14, ["y"] = 10, ["param1"] = 190, ["z"] = 10, ["name"] = "stones:s_52r"}, {["x"] = 6, ["param2"] = 9, ["y"] = 8, ["param1"] = 174, ["z"] = 6, ["name"] = "stones:r_2"}, {["x"] = 6, ["y"] = 8, ["z"] = 7, ["name"] = "stones:rubble"}, {["x"] = 6, ["y"] = 8, ["z"] = 8, ["name"] = "stones:rubble"}, {["x"] = 6, ["y"] = 8, ["z"] = 9, ["name"] = "stones:rubble"}, {["x"] = 6, ["y"] = 8, ["z"] = 10, ["name"] = "stones:rubble"}, {["x"] = 6, ["y"] = 8, ["z"] = 11, ["name"] = "stones:rubble"}, {["x"] = 6, ["y"] = 8, ["z"] = 12, ["name"] = "stones:rubble"}, {["x"] = 6, ["param2"] = 2, ["y"] = 8, ["param1"] = 158, ["z"] = 13, ["name"] = "stones:rush"}, {["x"] = 6, ["y"] = 8, ["param1"] = 141, ["z"] = 14, ["name"] = "stones:rush"}, {["x"] = 6, ["y"] = 8, ["param1"] = 140, ["z"] = 15, ["name"] = "stones:rush"}, {["x"] = 6, ["y"] = 8, ["z"] = 16, ["name"] = "stones:rubble"}, {["x"] = 6, ["y"] = 8, ["z"] = 17, ["name"] = "stones:rubble"}, {["x"] = 6, ["y"] = 8, ["z"] = 18, ["name"] = "stones:rubble"}, {["x"] = 6, ["y"] = 8, ["z"] = 19, ["name"] = "stones:rubble"}, {["x"] = 6, ["y"] = 8, ["z"] = 20, ["name"] = "stones:rubble"}, {["x"] = 6, ["param2"] = 5, ["y"] = 8, ["param1"] = 188, ["z"] = 21, ["name"] = "stones:r_2"}, {["x"] = 6, ["param2"] = 7, ["y"] = 9, ["param1"] = 190, ["z"] = 6, ["name"] = "stones:sku_20"}, {["x"] = 6, ["param2"] = 14, ["y"] = 9, ["param1"] = 206, ["z"] = 7, ["name"] = "stones:s_52"}, {["x"] = 6, ["y"] = 9, ["param1"] = 206, ["z"] = 11, ["name"] = "stones:diagstep"}, {["x"] = 6, ["param2"] = 11, ["y"] = 9, ["param1"] = 189, ["z"] = 12, ["name"] = "stones:brushrock_2u"}, {["x"] = 6, ["param2"] = 2, ["y"] = 9, ["param1"] = 174, ["z"] = 13, ["name"] = "stones:brushrock_2"}, {["x"] = 6, ["param2"] = 3, ["y"] = 9, ["param1"] = 158, ["z"] = 14, ["name"] = "stones:brushrock_5"}, {["x"] = 6, ["param2"] = 14, ["y"] = 9, ["param1"] = 157, ["z"] = 15, ["name"] = "stones:brushrock_527l"}, {["x"] = 6, ["param2"] = 3, ["y"] = 9, ["param1"] = 174, ["z"] = 16, ["name"] = "stones:diagsteps_31"}, {["x"] = 6, ["param2"] = 14, ["y"] = 9, ["param1"] = 190, ["z"] = 17, ["name"] = "stones:s_52l"}, {["x"] = 6, ["param2"] = 5, ["y"] = 9, ["param1"] = 205, ["z"] = 21, ["name"] = "stones:sku"}, {["x"] = 7, ["param2"] = 9, ["y"] = 8, ["param1"] = 190, ["z"] = 5, ["name"] = "stones:r_2"}, {["x"] = 7, ["y"] = 8, ["z"] = 6, ["name"] = "stones:rubble"}, {["x"] = 7, ["y"] = 8, ["z"] = 7, ["name"] = "stones:rubble"}, {["x"] = 7, ["y"] = 8, ["z"] = 8, ["name"] = "stones:rubble"}, {["x"] = 7, ["y"] = 8, ["z"] = 9, ["name"] = "stones:rubble"}, {["x"] = 7, ["y"] = 8, ["z"] = 10, ["name"] = "stones:rubble"}, {["x"] = 7, ["y"] = 8, ["z"] = 11, ["name"] = "stones:rubble"}, {["x"] = 7, ["y"] = 8, ["z"] = 12, ["name"] = "stones:rubble"}, {["x"] = 7, ["param2"] = 1, ["y"] = 8, ["param1"] = 174, ["z"] = 13, ["name"] = "stones:rush"}, {["x"] = 7, ["param2"] = 1, ["y"] = 8, ["param1"] = 157, ["z"] = 14, ["name"] = "stones:rush"}, {["x"] = 7, ["y"] = 8, ["param1"] = 156, ["z"] = 15, ["name"] = "stones:rush"}, {["x"] = 7, ["y"] = 8, ["z"] = 16, ["name"] = "stones:rubble"}, {["x"] = 7, ["y"] = 8, ["z"] = 17, ["name"] = "stones:rubble"}, {["x"] = 7, ["y"] = 8, ["z"] = 18, ["name"] = "stones:rubble"}, {["x"] = 7, ["y"] = 8, ["z"] = 19, ["name"] = "stones:rubble"}, {["x"] = 7, ["y"] = 8, ["z"] = 20, ["name"] = "stones:rubble"}, {["x"] = 7, ["y"] = 8, ["z"] = 21, ["name"] = "stones:rubble"}, {["x"] = 7, ["param2"] = 7, ["y"] = 9, ["param1"] = 206, ["z"] = 5, ["name"] = "stones:sku_20"}, {["x"] = 7, ["param2"] = 7, ["y"] = 9, ["param1"] = 206, ["z"] = 6, ["name"] = "stones:s_22"}, {["x"] = 7, ["param2"] = 2, ["y"] = 9, ["param1"] = 238, ["z"] = 8, ["name"] = "stones:octa"}, {["x"] = 7, ["param2"] = 2, ["y"] = 9, ["param1"] = 238, ["z"] = 10, ["name"] = "stones:octa"}, {["x"] = 7, ["param2"] = 1, ["y"] = 9, ["param1"] = 205, ["z"] = 12, ["name"] = "stones:diagsteps_8r"}, {["x"] = 7, ["param2"] = 1, ["y"] = 9, ["param1"] = 189, ["z"] = 13, ["name"] = "stones:brushrock_4"}, {["x"] = 7, ["y"] = 9, ["param1"] = 173, ["z"] = 14, ["name"] = "stones:brushrock_3"}, {["x"] = 7, ["param2"] = 2, ["y"] = 9, ["param1"] = 173, ["z"] = 15, ["name"] = "stones:diagsteps"}, {["x"] = 7, ["y"] = 9, ["param1"] = 238, ["z"] = 20, ["name"] = "stones:octa"}, {["x"] = 7, ["param2"] = 11, ["y"] = 9, ["param1"] = 222, ["z"] = 21, ["name"] = "stones:s_52"}, {["x"] = 7, ["param2"] = 5, ["y"] = 9, ["param1"] = 205, ["z"] = 22, ["name"] = "stones:s_52"}, {["x"] = 7, ["param2"] = 7, ["y"] = 10, ["param1"] = 190, ["z"] = 12, ["name"] = "stones:sku_20"}, {["x"] = 7, ["param2"] = 4, ["y"] = 10, ["param1"] = 174, ["z"] = 13, ["name"] = "stones:s_52l"}, {["x"] = 7, ["param2"] = 10, ["y"] = 10, ["param1"] = 158, ["z"] = 14, ["name"] = "stones:s_52r"}, {["x"] = 7, ["param2"] = 11, ["y"] = 10, ["param1"] = 158, ["z"] = 15, ["name"] = "stones:sku_20"}, {["x"] = 8, ["y"] = 8, ["z"] = 5, ["name"] = "stones:rubble"}, {["x"] = 8, ["y"] = 8, ["z"] = 6, ["name"] = "stones:rubble"}, {["x"] = 8, ["y"] = 8, ["z"] = 7, ["name"] = "stones:rubble"}, {["x"] = 8, ["y"] = 8, ["z"] = 8, ["name"] = "stones:rubble"}, {["x"] = 8, ["y"] = 8, ["z"] = 9, ["name"] = "stones:rubble"}, {["x"] = 8, ["y"] = 8, ["z"] = 10, ["name"] = "stones:rubble"}, {["x"] = 8, ["y"] = 8, ["z"] = 11, ["name"] = "stones:rubble"}, {["x"] = 8, ["param2"] = 2, ["y"] = 8, ["param1"] = 174, ["z"] = 12, ["name"] = "stones:rush"}, {["x"] = 8, ["param2"] = 2, ["y"] = 8, ["param1"] = 158, ["z"] = 13, ["name"] = "stones:rush"}, {["x"] = 8, ["param2"] = 1, ["y"] = 8, ["param1"] = 157, ["z"] = 14, ["name"] = "stones:rush"}, {["x"] = 8, ["param2"] = 1, ["y"] = 8, ["param1"] = 172, ["z"] = 15, ["name"] = "stones:rush"}, {["x"] = 8, ["y"] = 8, ["z"] = 16, ["name"] = "stones:rubble"}, {["x"] = 8, ["y"] = 8, ["z"] = 17, ["name"] = "stones:rubble"}, {["x"] = 8, ["y"] = 8, ["z"] = 18, ["name"] = "stones:rubble"}, {["x"] = 8, ["y"] = 8, ["z"] = 19, ["name"] = "stones:rubble"}, {["x"] = 8, ["y"] = 8, ["z"] = 20, ["name"] = "stones:rubble"}, {["x"] = 8, ["y"] = 8, ["z"] = 21, ["name"] = "stones:rubble"}, {["x"] = 8, ["param2"] = 9, ["y"] = 9, ["param1"] = 206, ["z"] = 4, ["name"] = "stones:s_52"}, {["x"] = 8, ["param2"] = 7, ["y"] = 9, ["param1"] = 222, ["z"] = 5, ["name"] = "stones:s_52"}, {["x"] = 8, ["param2"] = 9, ["y"] = 9, ["param1"] = 206, ["z"] = 11, ["name"] = "stones:s_52"}, {["x"] = 8, ["param2"] = 2, ["y"] = 9, ["param1"] = 189, ["z"] = 12, ["name"] = "stones:brushrock_c"}, {["x"] = 8, ["param2"] = 3, ["y"] = 9, ["param1"] = 173, ["z"] = 13, ["name"] = "stones:brushrock_5"}, {["x"] = 8, ["param2"] = 2, ["y"] = 9, ["param1"] = 172, ["z"] = 14, ["name"] = "stones:brushrock_2"}, {["x"] = 8, ["param2"] = 2, ["y"] = 9, ["param1"] = 189, ["z"] = 15, ["name"] = "stones:brushrock_5"}, {["x"] = 8, ["param2"] = 5, ["y"] = 9, ["param1"] = 205, ["z"] = 16, ["name"] = "stones:s_52"}, {["x"] = 8, ["param2"] = 1, ["y"] = 9, ["param1"] = 238, ["z"] = 18, ["name"] = "stones:octa"}, {["x"] = 8, ["param2"] = 4, ["y"] = 9, ["param1"] = 188, ["z"] = 22, ["name"] = "stones:roch"}, {["x"] = 8, ["param2"] = 9, ["y"] = 10, ["param1"] = 190, ["z"] = 11, ["name"] = "stones:s_52l"}, {["x"] = 8, ["param2"] = 7, ["y"] = 10, ["param1"] = 174, ["z"] = 12, ["name"] = "stones:s_52l"}, {["x"] = 8, ["param2"] = 9, ["y"] = 10, ["param1"] = 157, ["z"] = 13, ["name"] = "stones:s_22"}, {["x"] = 8, ["param2"] = 5, ["y"] = 10, ["param1"] = 157, ["z"] = 14, ["name"] = "stones:s_22"}, {["x"] = 8, ["param2"] = 11, ["y"] = 10, ["param1"] = 174, ["z"] = 15, ["name"] = "stones:s_52r"}, {["x"] = 8, ["param2"] = 5, ["y"] = 10, ["param1"] = 189, ["z"] = 16, ["name"] = "stones:s_52r"}, {["x"] = 8, ["y"] = 11, ["param1"] = 142, ["z"] = 13, ["name"] = "runes:0bl"}, {["x"] = 8, ["y"] = 11, ["param1"] = 141, ["z"] = 14, ["name"] = "runes:0ul"}, {["x"] = 9, ["param2"] = 9, ["y"] = 8, ["param1"] = 206, ["z"] = 4, ["name"] = "stones:r_2"}, {["x"] = 9, ["y"] = 8, ["z"] = 5, ["name"] = "stones:rubble"}, {["x"] = 9, ["y"] = 8, ["z"] = 6, ["name"] = "stones:rubble"}, {["x"] = 9, ["y"] = 8, ["z"] = 7, ["name"] = "stones:rubble"}, {["x"] = 9, ["y"] = 8, ["z"] = 8, ["name"] = "stones:rubble"}, {["x"] = 9, ["y"] = 8, ["z"] = 9, ["name"] = "stones:rubble"}, {["x"] = 9, ["y"] = 8, ["z"] = 10, ["name"] = "stones:rubble"}, {["x"] = 9, ["y"] = 8, ["z"] = 11, ["name"] = "stones:rubble"}, {["x"] = 9, ["param2"] = 2, ["y"] = 8, ["param1"] = 190, ["z"] = 12, ["name"] = "stones:rush"}, {["x"] = 9, ["param2"] = 2, ["y"] = 8, ["param1"] = 174, ["z"] = 13, ["name"] = "stones:rush"}, {["x"] = 9, ["param2"] = 2, ["y"] = 8, ["param1"] = 157, ["z"] = 14, ["name"] = "stones:rush"}, {["x"] = 9, ["param2"] = 1, ["y"] = 8, ["param1"] = 172, ["z"] = 15, ["name"] = "stones:rush"}, {["x"] = 9, ["y"] = 8, ["z"] = 16, ["name"] = "stones:rubble"}, {["x"] = 9, ["y"] = 8, ["z"] = 17, ["name"] = "stones:rubble"}, {["x"] = 9, ["y"] = 8, ["z"] = 18, ["name"] = "stones:rubble"}, {["x"] = 9, ["y"] = 8, ["z"] = 19, ["name"] = "stones:rubble"}, {["x"] = 9, ["y"] = 8, ["z"] = 20, ["name"] = "stones:rubble"}, {["x"] = 9, ["param2"] = 4, ["y"] = 8, ["z"] = 21, ["name"] = "stones:rubble"}, {["x"] = 9, ["param2"] = 7, ["y"] = 9, ["param1"] = 222, ["z"] = 4, ["name"] = "stones:sku"}, {["x"] = 9, ["param2"] = 2, ["y"] = 9, ["param1"] = 238, ["z"] = 5, ["name"] = "stones:octa"}, {["x"] = 9, ["param2"] = 1, ["y"] = 9, ["param1"] = 238, ["z"] = 10, ["name"] = "stones:octa"}, {["x"] = 9, ["param2"] = 11, ["y"] = 9, ["param1"] = 222, ["z"] = 11, ["name"] = "stones:s_52"}, {["x"] = 9, ["y"] = 9, ["param1"] = 205, ["z"] = 12, ["name"] = "stones:brushrock_5"}, {["x"] = 9, ["y"] = 9, ["param1"] = 189, ["z"] = 13, ["name"] = "stones:brushrock_2"}, {["x"] = 9, ["param2"] = 1, ["y"] = 9, ["param1"] = 172, ["z"] = 14, ["name"] = "stones:brushrock_5"}, {["x"] = 9, ["param2"] = 1, ["y"] = 9, ["param1"] = 188, ["z"] = 15, ["name"] = "stones:brushrock_2"}, {["x"] = 9, ["param2"] = 7, ["y"] = 9, ["param1"] = 205, ["z"] = 16, ["name"] = "stones:s_52"}, {["x"] = 9, ["param2"] = 4, ["y"] = 9, ["param1"] = 188, ["z"] = 22, ["name"] = "stones:roch"}, {["x"] = 9, ["param2"] = 11, ["y"] = 10, ["param1"] = 206, ["z"] = 11, ["name"] = "stones:s_52r"}, {["x"] = 9, ["param2"] = 5, ["y"] = 10, ["param1"] = 190, ["z"] = 12, ["name"] = "stones:s_52r"}, {["x"] = 9, ["param2"] = 11, ["y"] = 10, ["param1"] = 173, ["z"] = 13, ["name"] = "stones:s_22"}, {["x"] = 9, ["param2"] = 7, ["y"] = 10, ["param1"] = 156, ["z"] = 14, ["name"] = "stones:s_22"}, {["x"] = 9, ["param2"] = 9, ["y"] = 10, ["param1"] = 173, ["z"] = 15, ["name"] = "stones:s_52l"}, {["x"] = 9, ["param2"] = 7, ["y"] = 10, ["param1"] = 189, ["z"] = 16, ["name"] = "stones:s_52l"}, {["x"] = 9, ["y"] = 11, ["param1"] = 158, ["z"] = 13, ["name"] = "runes:0br"}, {["x"] = 9, ["y"] = 11, ["param1"] = 141, ["z"] = 14, ["name"] = "runes:0ur"}, {["x"] = 10, ["y"] = 8, ["z"] = 4, ["name"] = "stones:rubble"}, {["x"] = 10, ["y"] = 8, ["z"] = 5, ["name"] = "stones:rubble"}, {["x"] = 10, ["y"] = 8, ["z"] = 6, ["name"] = "stones:rubble"}, {["x"] = 10, ["y"] = 8, ["z"] = 7, ["name"] = "stones:rubble"}, {["x"] = 10, ["y"] = 8, ["z"] = 8, ["name"] = "stones:rubble"}, {["x"] = 10, ["y"] = 8, ["z"] = 9, ["name"] = "stones:rubble"}, {["x"] = 10, ["y"] = 8, ["z"] = 10, ["name"] = "stones:rubble"}, {["x"] = 10, ["y"] = 8, ["z"] = 11, ["name"] = "stones:rubble"}, {["x"] = 10, ["y"] = 8, ["z"] = 12, ["name"] = "stones:rubble"}, {["x"] = 10, ["param2"] = 2, ["y"] = 8, ["param1"] = 158, ["z"] = 13, ["name"] = "stones:rush"}, {["x"] = 10, ["param2"] = 2, ["y"] = 8, ["param1"] = 173, ["z"] = 14, ["name"] = "stones:rush"}, {["x"] = 10, ["y"] = 8, ["z"] = 15, ["name"] = "stones:rubble"}, {["x"] = 10, ["y"] = 8, ["z"] = 16, ["name"] = "stones:rubble"}, {["x"] = 10, ["y"] = 8, ["z"] = 17, ["name"] = "stones:rubble"}, {["x"] = 10, ["y"] = 8, ["z"] = 18, ["name"] = "stones:rubble"}, {["x"] = 10, ["y"] = 8, ["z"] = 19, ["name"] = "stones:rubble"}, {["x"] = 10, ["y"] = 8, ["z"] = 20, ["name"] = "stones:rubble"}, {["x"] = 10, ["y"] = 8, ["z"] = 21, ["name"] = "stones:rubble"}, {["x"] = 10, ["param2"] = 4, ["y"] = 9, ["param1"] = 206, ["z"] = 4, ["name"] = "stones:roch"}, {["x"] = 10, ["param2"] = 1, ["y"] = 9, ["param1"] = 238, ["z"] = 7, ["name"] = "stones:octa"}, {["x"] = 10, ["param2"] = 11, ["y"] = 9, ["param1"] = 190, ["z"] = 12, ["name"] = "stones:brushrock_22"}, {["x"] = 10, ["param2"] = 2, ["y"] = 9, ["param1"] = 173, ["z"] = 13, ["name"] = "stones:brushrock_2"}, {["x"] = 10, ["param2"] = 3, ["y"] = 9, ["param1"] = 188, ["z"] = 14, ["name"] = "stones:brushrock_5"}, {["x"] = 10, ["param2"] = 14, ["y"] = 9, ["param1"] = 204, ["z"] = 15, ["name"] = "stones:brushrock_22"}, {["x"] = 10, ["param2"] = 2, ["y"] = 9, ["param1"] = 238, ["z"] = 17, ["name"] = "stones:octa"}, {["x"] = 10, ["param2"] = 1, ["y"] = 9, ["param1"] = 238, ["z"] = 20, ["name"] = "stones:octa"}, {["x"] = 10, ["param2"] = 4, ["y"] = 9, ["param1"] = 204, ["z"] = 22, ["name"] = "stones:roch"}, {["x"] = 10, ["param2"] = 5, ["y"] = 10, ["param1"] = 174, ["z"] = 12, ["name"] = "stones:sku_20"}, {["x"] = 10, ["param2"] = 5, ["y"] = 10, ["param1"] = 157, ["z"] = 13, ["name"] = "stones:s_22"}, {["x"] = 10, ["param2"] = 9, ["y"] = 10, ["param1"] = 172, ["z"] = 14, ["name"] = "stones:s_22"}, {["x"] = 10, ["param2"] = 16, ["y"] = 10, ["param1"] = 188, ["z"] = 15, ["name"] = "stones:sku_20"}, {["x"] = 11, ["param2"] = 12, ["y"] = 8, ["param1"] = 174, ["z"] = 4, ["name"] = "stones:r_2"}, {["x"] = 11, ["y"] = 8, ["z"] = 5, ["name"] = "stones:rubble"}, {["x"] = 11, ["y"] = 8, ["z"] = 6, ["name"] = "stones:rubble"}, {["x"] = 11, ["y"] = 8, ["z"] = 7, ["name"] = "stones:rubble"}, {["x"] = 11, ["y"] = 8, ["z"] = 8, ["name"] = "stones:rubble"}, {["x"] = 11, ["y"] = 8, ["z"] = 9, ["name"] = "stones:rubble"}, {["x"] = 11, ["y"] = 8, ["z"] = 10, ["name"] = "stones:rubble"}, {["x"] = 11, ["y"] = 8, ["z"] = 11, ["name"] = "stones:rubble"}, {["x"] = 11, ["y"] = 8, ["z"] = 12, ["name"] = "stones:rubble"}, {["x"] = 11, ["y"] = 8, ["z"] = 13, ["name"] = "stones:rubble"}, {["x"] = 11, ["y"] = 8, ["z"] = 14, ["name"] = "stones:rubble"}, {["x"] = 11, ["y"] = 8, ["z"] = 15, ["name"] = "stones:rubble"}, {["x"] = 11, ["y"] = 8, ["z"] = 16, ["name"] = "stones:rubble"}, {["x"] = 11, ["y"] = 8, ["z"] = 17, ["name"] = "stones:rubble"}, {["x"] = 11, ["y"] = 8, ["z"] = 18, ["name"] = "stones:rubble"}, {["x"] = 11, ["y"] = 8, ["z"] = 19, ["name"] = "stones:rubble"}, {["x"] = 11, ["y"] = 8, ["z"] = 20, ["name"] = "stones:rubble"}, {["x"] = 11, ["y"] = 8, ["z"] = 21, ["name"] = "stones:rubble"}, {["x"] = 11, ["param2"] = 6, ["y"] = 8, ["param1"] = 169, ["z"] = 22, ["name"] = "stones:s_52"}, {["x"] = 11, ["param2"] = 5, ["y"] = 9, ["param1"] = 190, ["z"] = 4, ["name"] = "stones:sku_20"}, {["x"] = 11, ["param2"] = 16, ["y"] = 9, ["param1"] = 205, ["z"] = 5, ["name"] = "stones:roch"}, {["x"] = 11, ["param2"] = 16, ["y"] = 9, ["param1"] = 205, ["z"] = 6, ["name"] = "stones:roch"}, {["x"] = 11, ["param2"] = 16, ["y"] = 9, ["param1"] = 221, ["z"] = 7, ["name"] = "stones:roch"}, {["x"] = 11, ["param2"] = 16, ["y"] = 9, ["param1"] = 205, ["z"] = 8, ["name"] = "stones:roch"}, {["x"] = 11, ["param2"] = 18, ["y"] = 9, ["param1"] = 189, ["z"] = 9, ["name"] = "stones:s_52"}, {["x"] = 11, ["param2"] = 9, ["y"] = 9, ["param1"] = 173, ["z"] = 12, ["name"] = "stones:s_252r"}, {["x"] = 11, ["param2"] = 21, ["y"] = 9, ["param1"] = 156, ["z"] = 13, ["name"] = "stones:diagsteps_52rh"}, {["x"] = 11, ["param2"] = 23, ["y"] = 9, ["param1"] = 171, ["z"] = 14, ["name"] = "stones:diagsteps_52rh"}, {["x"] = 11, ["param2"] = 18, ["y"] = 9, ["param1"] = 187, ["z"] = 15, ["name"] = "stones:s_252r"}, {["x"] = 11, ["param2"] = 4, ["y"] = 9, ["param1"] = 188, ["z"] = 22, ["name"] = "stones:roch"}, {["x"] = 11, ["param2"] = 16, ["y"] = 10, ["param1"] = 190, ["z"] = 5, ["name"] = "stones:s_52r"}, {["x"] = 11, ["param2"] = 6, ["y"] = 10, ["param1"] = 190, ["z"] = 6, ["name"] = "stones:stair_half_l"}, {["x"] = 11, ["param2"] = 17, ["y"] = 10, ["param1"] = 206, ["z"] = 7, ["name"] = "stones:panel"}, {["x"] = 11, ["param2"] = 8, ["y"] = 10, ["param1"] = 190, ["z"] = 8, ["name"] = "stones:stair_half_r"}, {["x"] = 11, ["param2"] = 18, ["y"] = 10, ["param1"] = 174, ["z"] = 9, ["name"] = "stones:s_52l"}, {["x"] = 11, ["param2"] = 9, ["y"] = 10, ["param1"] = 157, ["z"] = 12, ["name"] = "stones:s_2"}, {["x"] = 11, ["param2"] = 7, ["y"] = 10, ["param1"] = 140, ["z"] = 13, ["name"] = "stones:s_52"}, {["x"] = 11, ["param2"] = 11, ["y"] = 10, ["param1"] = 155, ["z"] = 14, ["name"] = "stones:s_22"}, {["x"] = 11, ["param2"] = 11, ["y"] = 10, ["param1"] = 172, ["z"] = 15, ["name"] = "stones:sku_20"}, {["x"] = 11, ["param2"] = 16, ["y"] = 11, ["param1"] = 141, ["z"] = 12, ["name"] = "stones:vsect"}, {["x"] = 11, ["param2"] = 7, ["y"] = 11, ["param1"] = 124, ["z"] = 13, ["name"] = "stones:s_52pr"}, {["x"] = 12, ["param2"] = 9, ["y"] = 8, ["param1"] = 158, ["z"] = 4, ["name"] = "stones:aset"}, {["x"] = 12, ["y"] = 8, ["z"] = 5, ["name"] = "stones:rubble"}, {["x"] = 12, ["y"] = 8, ["param1"] = 174, ["z"] = 6, ["name"] = "stones:rush"}, {["x"] = 12, ["y"] = 8, ["param1"] = 190, ["z"] = 7, ["name"] = "stones:rush"}, {["x"] = 12, ["param2"] = 3, ["y"] = 8, ["param1"] = 174, ["z"] = 8, ["name"] = "stones:rush"}, {["x"] = 12, ["param2"] = 3, ["y"] = 8, ["param1"] = 158, ["z"] = 9, ["name"] = "stones:rush"}, {["x"] = 12, ["y"] = 8, ["z"] = 10, ["name"] = "stones:rubble"}, {["x"] = 12, ["y"] = 8, ["z"] = 11, ["name"] = "stones:rubble"}, {["x"] = 12, ["y"] = 8, ["z"] = 12, ["name"] = "stones:rubble"}, {["x"] = 12, ["y"] = 8, ["z"] = 13, ["name"] = "stones:rubble"}, {["x"] = 12, ["param2"] = 2, ["y"] = 8, ["param1"] = 157, ["z"] = 14, ["name"] = "stones:rush"}, {["x"] = 12, ["y"] = 8, ["param1"] = 172, ["z"] = 15, ["name"] = "stones:rush"}, {["x"] = 12, ["y"] = 8, ["z"] = 16, ["name"] = "stones:rubble"}, {["x"] = 12, ["y"] = 8, ["z"] = 17, ["name"] = "stones:rubble"}, {["x"] = 12, ["y"] = 8, ["z"] = 18, ["name"] = "stones:rubble"}, {["x"] = 12, ["y"] = 8, ["z"] = 19, ["name"] = "stones:rubble"}, {["x"] = 12, ["y"] = 8, ["z"] = 20, ["name"] = "stones:rubble"}, {["x"] = 12, ["y"] = 8, ["z"] = 21, ["name"] = "stones:rubble"}, {["x"] = 12, ["param2"] = 16, ["y"] = 9, ["param1"] = 174, ["z"] = 4, ["name"] = "stones:brushrock_22"}, {["x"] = 12, ["param2"] = 1, ["y"] = 9, ["param1"] = 189, ["z"] = 5, ["name"] = "stones:brushrock_5"}, {["x"] = 12, ["param2"] = 2, ["y"] = 9, ["param1"] = 189, ["z"] = 6, ["name"] = "stones:brush"}, {["x"] = 12, ["param2"] = 2, ["y"] = 9, ["param1"] = 206, ["z"] = 7, ["name"] = "stones:brush"}, {["x"] = 12, ["param2"] = 3, ["y"] = 9, ["param1"] = 190, ["z"] = 8, ["name"] = "stones:brush"}, {["x"] = 12, ["y"] = 9, ["param1"] = 173, ["z"] = 9, ["name"] = "stones:brushrock_2"}, {["x"] = 12, ["param2"] = 18, ["y"] = 9, ["param1"] = 189, ["z"] = 10, ["name"] = "stones:brushrock_52ur"}, {["x"] = 12, ["param2"] = 23, ["y"] = 9, ["param1"] = 173, ["z"] = 11, ["name"] = "stones:diagsteps_52rv"}, {["x"] = 12, ["param2"] = 17, ["y"] = 9, ["param1"] = 156, ["z"] = 12, ["name"] = "stones:stair_2"}, {["x"] = 12, ["param2"] = 23, ["y"] = 9, ["param1"] = 156, ["z"] = 13, ["name"] = "stones:s_21u"}, {["x"] = 12, ["param2"] = 3, ["y"] = 9, ["param1"] = 172, ["z"] = 14, ["name"] = "stones:brushrock_3"}, {["x"] = 12, ["y"] = 9, ["param1"] = 188, ["z"] = 15, ["name"] = "stones:brushrock_1"}, {["x"] = 12, ["param2"] = 5, ["y"] = 9, ["param1"] = 204, ["z"] = 16, ["name"] = "stones:s_52"}, {["x"] = 12, ["param2"] = 1, ["y"] = 9, ["param1"] = 238, ["z"] = 18, ["name"] = "stones:octa"}, {["x"] = 12, ["param2"] = 9, ["y"] = 9, ["param1"] = 188, ["z"] = 21, ["name"] = "stones:s_52"}, {["x"] = 12, ["param2"] = 7, ["y"] = 9, ["param1"] = 172, ["z"] = 22, ["name"] = "stones:s_52"}, {["x"] = 12, ["param2"] = 7, ["y"] = 10, ["param1"] = 158, ["z"] = 4, ["name"] = "stones:sku_202"}, {["x"] = 12, ["param2"] = 14, ["y"] = 10, ["param1"] = 174, ["z"] = 5, ["name"] = "stones:s_52r"}, {["x"] = 12, ["param2"] = 12, ["y"] = 10, ["param1"] = 158, ["z"] = 9, ["name"] = "stones:s_52l"}, {["x"] = 12, ["param2"] = 12, ["y"] = 10, ["param1"] = 173, ["z"] = 10, ["name"] = "stones:sku2_l"}, {["x"] = 12, ["param2"] = 16, ["y"] = 10, ["param1"] = 157, ["z"] = 11, ["name"] = "stones:s_52u"}, {["x"] = 12, ["param2"] = 3, ["y"] = 10, ["param1"] = 140, ["z"] = 12, ["name"] = "stones:diagsteps_8r"}, {["x"] = 12, ["param2"] = 11, ["y"] = 10, ["param1"] = 173, ["z"] = 15, ["name"] = "stones:s_52r"}, {["x"] = 12, ["param2"] = 5, ["y"] = 10, ["param1"] = 188, ["z"] = 16, ["name"] = "stones:s_52r"}, {["x"] = 12, ["param2"] = 9, ["y"] = 11, ["param1"] = 141, ["z"] = 11, ["name"] = "stones:s_2"}, {["x"] = 12, ["param2"] = 7, ["y"] = 11, ["param1"] = 124, ["z"] = 12, ["name"] = "stones:s_2"}, {["x"] = 12, ["param2"] = 9, ["y"] = 12, ["param1"] = 125, ["z"] = 11, ["name"] = "stones:s_2"}, {["x"] = 12, ["param2"] = 4, ["y"] = 12, ["param1"] = 109, ["z"] = 12, ["name"] = "stones:vsect"}, {["x"] = 12, ["param2"] = 9, ["y"] = 13, ["param1"] = 110, ["z"] = 11, ["name"] = "stones:panel"}, {["x"] = 12, ["y"] = 14, ["param1"] = 94, ["z"] = 11, ["name"] = "stones:s_22r"}, {["x"] = 12, ["param2"] = 1, ["y"] = 14, ["param1"] = 78, ["z"] = 12, ["name"] = "stones:panel"}, {["x"] = 12, ["param2"] = 18, ["y"] = 14, ["param1"] = 78, ["z"] = 13, ["name"] = "stones:s_52r"}, {["x"] = 13, ["param2"] = 8, ["y"] = 8, ["param1"] = 142, ["z"] = 4, ["name"] = "stones:s_2"}, {["x"] = 13, ["y"] = 8, ["z"] = 5, ["name"] = "stones:rubble"}, {["x"] = 13, ["param2"] = 3, ["y"] = 8, ["param1"] = 158, ["z"] = 6, ["name"] = "stones:rush"}, {["x"] = 13, ["param2"] = 3, ["y"] = 8, ["param1"] = 174, ["z"] = 7, ["name"] = "stones:rush"}, {["x"] = 13, ["param2"] = 3, ["y"] = 8, ["param1"] = 158, ["z"] = 8, ["name"] = "stones:rush"}, {["x"] = 13, ["param2"] = 3, ["y"] = 8, ["param1"] = 142, ["z"] = 9, ["name"] = "stones:rush"}, {["x"] = 13, ["param2"] = 3, ["y"] = 8, ["param1"] = 158, ["z"] = 10, ["name"] = "stones:rush"}, {["x"] = 13, ["y"] = 8, ["param1"] = 142, ["z"] = 11, ["name"] = "stones:rock"}, {["x"] = 13, ["y"] = 8, ["param1"] = 142, ["z"] = 12, ["name"] = "stones:rock"}, {["x"] = 13, ["y"] = 8, ["param1"] = 158, ["z"] = 13, ["name"] = "stones:rock"}, {["x"] = 13, ["y"] = 8, ["param1"] = 141, ["z"] = 14, ["name"] = "stones:rush"}, {["x"] = 13, ["y"] = 8, ["param1"] = 156, ["z"] = 15, ["name"] = "stones:rush"}, {["x"] = 13, ["y"] = 8, ["z"] = 16, ["name"] = "stones:rubble"}, {["x"] = 13, ["y"] = 8, ["z"] = 17, ["name"] = "stones:rubble"}, {["x"] = 13, ["y"] = 8, ["z"] = 18, ["name"] = "stones:rubble"}, {["x"] = 13, ["y"] = 8, ["z"] = 19, ["name"] = "stones:rubble"}, {["x"] = 13, ["y"] = 8, ["z"] = 20, ["name"] = "stones:rubble"}, {["x"] = 13, ["y"] = 8, ["z"] = 21, ["name"] = "stones:rubble"}, {["x"] = 13, ["param2"] = 2, ["y"] = 9, ["param1"] = 158, ["z"] = 4, ["name"] = "stones:brushrock_0"}, {["x"] = 13, ["param2"] = 2, ["y"] = 9, ["param1"] = 173, ["z"] = 5, ["name"] = "stones:brush"}, {["x"] = 13, ["param2"] = 2, ["y"] = 9, ["param1"] = 174, ["z"] = 6, ["name"] = "stones:brush"}, {["x"] = 13, ["param2"] = 3, ["y"] = 9, ["param1"] = 189, ["z"] = 7, ["name"] = "stones:brush"}, {["x"] = 13, ["param2"] = 2, ["y"] = 9, ["param1"] = 173, ["z"] = 8, ["name"] = "stones:brush"}, {["x"] = 13, ["param2"] = 3, ["y"] = 9, ["param1"] = 157, ["z"] = 9, ["name"] = "stones:brush"}, {["x"] = 13, ["param2"] = 3, ["y"] = 9, ["param1"] = 173, ["z"] = 10, ["name"] = "stones:brush"}, {["x"] = 13, ["y"] = 9, ["param1"] = 157, ["z"] = 11, ["name"] = "stones:rock"}, {["x"] = 13, ["y"] = 9, ["param1"] = 141, ["z"] = 12, ["name"] = "stones:rock"}, {["x"] = 13, ["y"] = 9, ["param1"] = 141, ["z"] = 13, ["name"] = "stones:rock"}, {["x"] = 13, ["y"] = 9, ["param1"] = 156, ["z"] = 14, ["name"] = "stones:brushrock_4"}, {["x"] = 13, ["param2"] = 1, ["y"] = 9, ["param1"] = 173, ["z"] = 15, ["name"] = "stones:brush"}, {["x"] = 13, ["param2"] = 5, ["y"] = 9, ["param1"] = 188, ["z"] = 16, ["name"] = "stones:brushrock_52ul"}, {["x"] = 13, ["param2"] = 20, ["y"] = 9, ["param1"] = 172, ["z"] = 21, ["name"] = "stones:diagsteps_52lv"}, {["x"] = 13, ["param2"] = 15, ["y"] = 10, ["param1"] = 142, ["z"] = 4, ["name"] = "stones:stair_half_l"}, {["x"] = 13, ["param2"] = 8, ["y"] = 10, ["param1"] = 140, ["z"] = 11, ["name"] = "runes:hui"}, {["x"] = 13, ["param2"] = 2, ["y"] = 10, ["param1"] = 124, ["z"] = 12, ["name"] = "stones:diagsteps"}, {["x"] = 13, ["param2"] = 1, ["y"] = 10, ["param1"] = 124, ["z"] = 13, ["name"] = "stones:diagsteps_8l"}, {["x"] = 13, ["param2"] = 2, ["y"] = 10, ["param1"] = 141, ["z"] = 14, ["name"] = "stones:diaq"}, {["x"] = 13, ["param2"] = 5, ["y"] = 10, ["param1"] = 173, ["z"] = 16, ["name"] = "stones:sku2_r"}, {["x"] = 13, ["param2"] = 9, ["y"] = 10, ["param1"] = 156, ["z"] = 21, ["name"] = "stones:panel"}, {["x"] = 13, ["param2"] = 20, ["y"] = 11, ["param1"] = 141, ["z"] = 10, ["name"] = "stones:aset_2"}, {["x"] = 13, ["param2"] = 3, ["y"] = 11, ["param1"] = 125, ["z"] = 11, ["name"] = "stones:diagsteps_8r"}, {["x"] = 13, ["param2"] = 9, ["y"] = 11, ["param1"] = 108, ["z"] = 13, ["name"] = "stones:s_2"}, {["x"] = 13, ["param2"] = 2, ["y"] = 11, ["param1"] = 124, ["z"] = 14, ["name"] = "stones:diaq"}, {["x"] = 13, ["param2"] = 9, ["y"] = 12, ["param1"] = 126, ["z"] = 10, ["name"] = "stones:s_2"}, {["x"] = 13, ["param2"] = 7, ["y"] = 12, ["param1"] = 110, ["z"] = 11, ["name"] = "stones:s_2"}, {["x"] = 13, ["param2"] = 9, ["y"] = 12, ["param1"] = 93, ["z"] = 13, ["name"] = "stones:s_2"}, {["x"] = 13, ["param2"] = 22, ["y"] = 12, ["param1"] = 108, ["z"] = 14, ["name"] = "stones:diaq"}, {["x"] = 13, ["y"] = 13, ["param1"] = 78, ["z"] = 13, ["name"] = "stones:diaq"}, {["x"] = 13, ["param2"] = 2, ["y"] = 13, ["param1"] = 93, ["z"] = 14, ["name"] = "stones:diaq"}, {["x"] = 13, ["y"] = 14, ["param1"] = 62, ["z"] = 13, ["name"] = "stones:diagstep"}, {["x"] = 13, ["param2"] = 2, ["y"] = 14, ["param1"] = 77, ["z"] = 14, ["name"] = "stones:diagstep_2"}, {["x"] = 14, ["param2"] = 1, ["y"] = 8, ["param1"] = 126, ["z"] = 4, ["name"] = "stones:arch"}, {["x"] = 14, ["y"] = 8, ["z"] = 5, ["name"] = "stones:rubble"}, {["x"] = 14, ["param2"] = 2, ["y"] = 8, ["param1"] = 142, ["z"] = 6, ["name"] = "stones:rush"}, {["x"] = 14, ["y"] = 8, ["z"] = 7, ["name"] = "stones:rubble"}, {["x"] = 14, ["y"] = 8, ["z"] = 8, ["name"] = "stones:rubble"}, {["x"] = 14, ["param2"] = 3, ["y"] = 8, ["param1"] = 126, ["z"] = 9, ["name"] = "stones:rush"}, {["x"] = 14, ["param2"] = 3, ["y"] = 8, ["param1"] = 142, ["z"] = 10, ["name"] = "stones:rush"}, {["x"] = 14, ["y"] = 8, ["param1"] = 142, ["z"] = 11, ["name"] = "stones:rock"}, {["x"] = 14, ["y"] = 8, ["param1"] = 158, ["z"] = 12, ["name"] = "stones:rock"}, {["x"] = 14, ["y"] = 8, ["param1"] = 174, ["z"] = 13, ["name"] = "stones:rock"}, {["x"] = 14, ["param2"] = 1, ["y"] = 8, ["param1"] = 157, ["z"] = 14, ["name"] = "stones:rush"}, {["x"] = 14, ["y"] = 8, ["param1"] = 141, ["z"] = 15, ["name"] = "stones:rush"}, {["x"] = 14, ["y"] = 8, ["param1"] = 156, ["z"] = 16, ["name"] = "stones:rush"}, {["x"] = 14, ["y"] = 8, ["z"] = 17, ["name"] = "stones:rubble"}, {["x"] = 14, ["y"] = 8, ["z"] = 18, ["name"] = "stones:rubble"}, {["x"] = 14, ["y"] = 8, ["z"] = 19, ["name"] = "stones:rubble"}, {["x"] = 14, ["y"] = 8, ["z"] = 20, ["name"] = "stones:rubble"}, {["x"] = 14, ["y"] = 8, ["z"] = 21, ["name"] = "stones:rubble"}, {["x"] = 14, ["param2"] = 2, ["y"] = 9, ["param1"] = 142, ["z"] = 4, ["name"] = "stones:brushrock_0"}, {["x"] = 14, ["param2"] = 3, ["y"] = 9, ["param1"] = 157, ["z"] = 5, ["name"] = "stones:brush"}, {["x"] = 14, ["param2"] = 1, ["y"] = 9, ["param1"] = 158, ["z"] = 6, ["name"] = "stones:brush"}, {["x"] = 14, ["param2"] = 1, ["y"] = 9, ["param1"] = 173, ["z"] = 7, ["name"] = "stones:brushrock_3"}, {["x"] = 14, ["y"] = 9, ["param1"] = 156, ["z"] = 8, ["name"] = "stones:rock"}, {["x"] = 14, ["param2"] = 2, ["y"] = 9, ["param1"] = 141, ["z"] = 9, ["name"] = "stones:brushrock_3"}, {["x"] = 14, ["param2"] = 3, ["y"] = 9, ["param1"] = 157, ["z"] = 10, ["name"] = "stones:brushrock_4"}, {["x"] = 14, ["y"] = 9, ["param1"] = 141, ["z"] = 11, ["name"] = "stones:rock"}, {["x"] = 14, ["y"] = 9, ["param1"] = 141, ["z"] = 12, ["name"] = "stones:rock"}, {["x"] = 14, ["y"] = 9, ["param1"] = 157, ["z"] = 13, ["name"] = "stones:rock"}, {["x"] = 14, ["param2"] = 2, ["y"] = 9, ["param1"] = 141, ["z"] = 14, ["name"] = "stones:brushrock_c"}, {["x"] = 14, ["param2"] = 1, ["y"] = 9, ["param1"] = 158, ["z"] = 15, ["name"] = "stones:brush"}, {["x"] = 14, ["param2"] = 2, ["y"] = 9, ["param1"] = 173, ["z"] = 16, ["name"] = "stones:brushrock_5"}, {["x"] = 14, ["param2"] = 5, ["y"] = 9, ["param1"] = 188, ["z"] = 17, ["name"] = "stones:s_52"}, {["x"] = 14, ["param2"] = 16, ["y"] = 9, ["param1"] = 188, ["z"] = 19, ["name"] = "stones:s_52l"}, {["x"] = 14, ["param2"] = 1, ["y"] = 9, ["param1"] = 172, ["z"] = 20, ["name"] = "stones:s_52hul"}, {["x"] = 14, ["param2"] = 5, ["y"] = 9, ["param1"] = 155, ["z"] = 21, ["name"] = "runes:ke"}, {["x"] = 14, ["param2"] = 5, ["y"] = 9, ["param1"] = 138, ["z"] = 22, ["name"] = "stones:s_52"}, {["x"] = 14, ["param2"] = 6, ["y"] = 10, ["param1"] = 126, ["z"] = 4, ["name"] = "stones:panel"}, {["x"] = 14, ["param2"] = 4, ["y"] = 10, ["param1"] = 142, ["z"] = 5, ["name"] = "stones:shrub"}, {["x"] = 14, ["param2"] = 9, ["y"] = 10, ["param1"] = 158, ["z"] = 7, ["name"] = "stones:s_52r"}, {["x"] = 14, ["y"] = 10, ["param1"] = 141, ["z"] = 8, ["name"] = "stones:rock"}, {["x"] = 14, ["param2"] = 8, ["y"] = 10, ["param1"] = 124, ["z"] = 11, ["name"] = "stones:vr"}, {["x"] = 14, ["y"] = 10, ["param1"] = 124, ["z"] = 12, ["name"] = "stones:rock"}, {["x"] = 14, ["param2"] = 2, ["y"] = 10, ["param1"] = 141, ["z"] = 13, ["name"] = "stones:plot"}, {["x"] = 14, ["param2"] = 11, ["y"] = 10, ["param1"] = 158, ["z"] = 16, ["name"] = "stones:s_52r"}, {["x"] = 14, ["param2"] = 5, ["y"] = 10, ["param1"] = 173, ["z"] = 17, ["name"] = "stones:s_52r"}, {["x"] = 14, ["param2"] = 11, ["y"] = 10, ["param1"] = 140, ["z"] = 21, ["name"] = "stones:s_52r"}, {["x"] = 14, ["param2"] = 5, ["y"] = 10, ["param1"] = 124, ["z"] = 22, ["name"] = "stones:s_52r"}, {["x"] = 14, ["param2"] = 13, ["y"] = 11, ["param1"] = 126, ["z"] = 8, ["name"] = "stones:stair_5"}, {["x"] = 14, ["param2"] = 3, ["y"] = 11, ["param1"] = 109, ["z"] = 9, ["name"] = "stones:arch"}, {["x"] = 14, ["param2"] = 7, ["y"] = 11, ["param1"] = 125, ["z"] = 10, ["name"] = "stones:arch"}, {["x"] = 14, ["param2"] = 2, ["y"] = 11, ["param1"] = 109, ["z"] = 11, ["name"] = "stones:diagsteps"}, {["x"] = 14, ["param2"] = 1, ["y"] = 11, ["param1"] = 109, ["z"] = 12, ["name"] = "stones:diagsteps_8l"}, {["x"] = 14, ["param2"] = 4, ["y"] = 11, ["param1"] = 125, ["z"] = 13, ["name"] = "stones:shrub"}, {["x"] = 14, ["param2"] = 13, ["y"] = 12, ["param1"] = 110, ["z"] = 8, ["name"] = "stones:cish"}, {["x"] = 14, ["param2"] = 12, ["y"] = 12, ["param1"] = 94, ["z"] = 9, ["name"] = "stones:roch"}, {["x"] = 14, ["param2"] = 7, ["y"] = 12, ["param1"] = 110, ["z"] = 10, ["name"] = "stones:s_22"}, {["x"] = 14, ["param2"] = 9, ["y"] = 12, ["param1"] = 94, ["z"] = 12, ["name"] = "stones:s_2"}, {["x"] = 14, ["param2"] = 7, ["y"] = 12, ["param1"] = 110, ["z"] = 13, ["name"] = "stones:s_2"}}