5:return {{["x"] = 0, ["param2"] = 16, ["y"] = 3, ["param1"] = 103, ["z"] = 7, ["name"] = "stones:s_52"}, {["x"] = 0, ["param2"] = 16, ["y"] = 3, ["param1"] = 89, ["z"] = 8, ["name"] = "stones:brushrock_52ul"}, {["x"] = 0, ["param2"] = 5, ["y"] = 3, ["param1"] = 73, ["z"] = 9, ["name"] = "stones:brushrock_22"}, {["x"] = 1, ["param2"] = 16, ["y"] = 3, ["param1"] = 105, ["z"] = 6, ["name"] = "stones:brushrock_22"}, {["x"] = 1, ["param2"] = 1, ["y"] = 3, ["param1"] = 88, ["z"] = 7, ["name"] = "stones:brushrock_5"}, {["x"] = 1, ["y"] = 3, ["param1"] = 71, ["z"] = 8, ["name"] = "stones:brush"}, {["x"] = 1, ["y"] = 3, ["param1"] = 55, ["z"] = 9, ["name"] = "stones:brushrock_0"}, {["x"] = 1, ["param2"] = 4, ["y"] = 4, ["param1"] = 55, ["z"] = 8, ["name"] = "stones:shrub"}, {["x"] = 1, ["param2"] = 8, ["y"] = 4, ["param1"] = 39, ["z"] = 9, ["name"] = "stones:roch"}, {["x"] = 1, ["param2"] = 19, ["y"] = 5, ["param1"] = 25, ["z"] = 9, ["name"] = "stones:s_52ur"}, {["x"] = 1, ["param2"] = 19, ["y"] = 6, ["param1"] = 12, ["z"] = 9, ["name"] = "stones:s_22r"}, {["x"] = 2, ["param2"] = 11, ["y"] = 3, ["param1"] = 90, ["z"] = 6, ["name"] = "stones:brushrock_52ul"}, {["x"] = 2, ["param2"] = 3, ["y"] = 3, ["param1"] = 73, ["z"] = 7, ["name"] = "stones:brushrock_5"}, {["x"] = 2, ["param2"] = 1, ["y"] = 3, ["param1"] = 56, ["z"] = 8, ["name"] = "stones:brushrock_0"}, {["x"] = 2, ["param2"] = 14, ["y"] = 3, ["param1"] = 39, ["z"] = 9, ["name"] = "stones:brushrock_22"}, {["x"] = 2, ["param2"] = 16, ["y"] = 4, ["param1"] = 56, ["z"] = 7, ["name"] = "stones:s_52"}, {["x"] = 2, ["param2"] = 16, ["y"] = 4, ["param1"] = 39, ["z"] = 8, ["name"] = "stones:roch"}, {["x"] = 2, ["param2"] = 9, ["y"] = 4, ["param1"] = 23, ["z"] = 9, ["name"] = "stones:sku_20"}, {["x"] = 2, ["param2"] = 16, ["y"] = 5, ["param1"] = 39, ["z"] = 7, ["name"] = "stones:s_52"}, {["x"] = 2, ["param2"] = 16, ["y"] = 5, ["param1"] = 23, ["z"] = 8, ["name"] = "stones:roch"}, {["x"] = 2, ["param2"] = 9, ["y"] = 5, ["param1"] = 9, ["z"] = 9, ["name"] = "stones:sku_20"}, {["x"] = 2, ["param2"] = 17, ["y"] = 6, ["param1"] = 23, ["z"] = 7, ["name"] = "stones:vr_2"}, {["x"] = 2, ["param2"] = 18, ["y"] = 6, ["param1"] = 9, ["z"] = 8, ["name"] = "stones:s_221"}, {["x"] = 2, ["param2"] = 16, ["y"] = 6, ["param1"] = 12, ["z"] = 9, ["name"] = "stones:sku_202"}, {["x"] = 2, ["param2"] = 17, ["y"] = 7, ["param1"] = 25, ["z"] = 6, ["name"] = "stones:diagstep"}, {["x"] = 2, ["param2"] = 18, ["y"] = 7, ["param1"] = 9, ["z"] = 7, ["name"] = "stones:s_221"}, {["x"] = 2, ["param2"] = 4, ["y"] = 7, ["param1"] = 12, ["z"] = 8, ["name"] = "stones:s_22r"}, {["x"] = 2, ["param2"] = 20, ["y"] = 8, ["param1"] = 25, ["z"] = 5, ["name"] = "stones:s_52l"}, {["x"] = 2, ["param2"] = 18, ["y"] = 8, ["param1"] = 9, ["z"] = 6, ["name"] = "stones:s_221"}, {["x"] = 2, ["param2"] = 4, ["y"] = 8, ["param1"] = 12, ["z"] = 7, ["name"] = "stones:s_22r"}, {["x"] = 2, ["param2"] = 16, ["y"] = 9, ["param1"] = 57, ["z"] = 4, ["name"] = "stones:s_52"}, {["x"] = 2, ["param2"] = 18, ["y"] = 9, ["param1"] = 44, ["z"] = 5, ["name"] = "stones:s_221"}, {["x"] = 2, ["param2"] = 4, ["y"] = 9, ["param1"] = 28, ["z"] = 6, ["name"] = "stones:s_22r"}, {["x"] = 3, ["param2"] = 11, ["y"] = 3, ["param1"] = 75, ["z"] = 6, ["name"] = "stones:s_52"}, {["x"] = 3, ["y"] = 3, ["param1"] = 58, ["z"] = 7, ["name"] = "stones:rock"}, {["x"] = 3, ["param2"] = 5, ["y"] = 3, ["param1"] = 41, ["z"] = 8, ["name"] = "stones:s_52"}, {["x"] = 3, ["param2"] = 16, ["y"] = 4, ["param1"] = 92, ["z"] = 4, ["name"] = "stones:flat_1"}, {["x"] = 3, ["param2"] = 7, ["y"] = 4, ["param1"] = 41, ["z"] = 7, ["name"] = "stones:s_21u"}, {["x"] = 3, ["param2"] = 7, ["y"] = 5, ["param1"] = 24, ["z"] = 7, ["name"] = "stones:c8r1"}, {["x"] = 3, ["param2"] = 13, ["y"] = 5, ["param1"] = 9, ["z"] = 8, ["name"] = "stones:s_52pr"}, {["x"] = 3, ["y"] = 6, ["param1"] = 7, ["z"] = 7, ["name"] = "stones:rock"}, {["x"] = 3, ["param2"] = 4, ["y"] = 6, ["param1"] = 12, ["z"] = 8, ["name"] = "stones:s_252l"}, {["x"] = 3, ["param2"] = 8, ["y"] = 7, ["param1"] = 9, ["z"] = 6, ["name"] = "stones:s_2"}, {["x"] = 3, ["param2"] = 2, ["y"] = 7, ["param1"] = 12, ["z"] = 7, ["name"] = "stones:stair_3"}, {["x"] = 3, ["param2"] = 17, ["y"] = 8, ["param1"] = 87, ["z"] = 0, ["name"] = "stones:s_2"}, {["x"] = 3, ["param2"] = 23, ["y"] = 8, ["param1"] = 71, ["z"] = 1, ["name"] = "stones:s_52"}, {["x"] = 3, ["param2"] = 17, ["y"] = 8, ["param1"] = 56, ["z"] = 2, ["name"] = "stones:s_2"}, {["x"] = 3, ["param2"] = 23, ["y"] = 8, ["param1"] = 41, ["z"] = 3, ["name"] = "stones:s_52"}, {["x"] = 3, ["param2"] = 17, ["y"] = 8, ["param1"] = 24, ["z"] = 4, ["name"] = "stones:s_2"}, {["x"] = 3, ["param2"] = 20, ["y"] = 8, ["param1"] = 9, ["z"] = 5, ["name"] = "stones:s_3"}, {["x"] = 3, ["param2"] = 2, ["y"] = 8, ["param1"] = 12, ["z"] = 6, ["name"] = "stones:stair_2"}, {["x"] = 3, ["param2"] = 3, ["y"] = 9, ["param1"] = 105, ["z"] = 0, ["name"] = "stones:brushrock_0"}, {["x"] = 3, ["param2"] = 3, ["y"] = 9, ["param1"] = 89, ["z"] = 1, ["name"] = "stones:brushrock_0"}, {["x"] = 3, ["param2"] = 3, ["y"] = 9, ["param1"] = 73, ["z"] = 2, ["name"] = "stones:brushrock_0"}, {["x"] = 3, ["param2"] = 3, ["y"] = 9, ["param1"] = 57, ["z"] = 3, ["name"] = "stones:brushrock_0"}, {["x"] = 3, ["param2"] = 1, ["y"] = 9, ["param1"] = 41, ["z"] = 4, ["name"] = "stones:brushrock_5"}, {["x"] = 3, ["param2"] = 2, ["y"] = 9, ["param1"] = 28, ["z"] = 5, ["name"] = "stones:stair_3"}, {["x"] = 3, ["param2"] = 6, ["y"] = 10, ["param1"] = 92, ["z"] = 0, ["name"] = "stones:stair_half_r"}, {["x"] = 3, ["param2"] = 8, ["y"] = 10, ["param1"] = 76, ["z"] = 1, ["name"] = "stones:stair_half_l"}, {["x"] = 3, ["param2"] = 8, ["y"] = 10, ["param1"] = 60, ["z"] = 2, ["name"] = "stones:stair_half_l"}, {["x"] = 3, ["param2"] = 8, ["y"] = 10, ["param1"] = 41, ["z"] = 3, ["name"] = "stones:stair_half_l"}, {["x"] = 3, ["param2"] = 15, ["y"] = 11, ["param1"] = 28, ["z"] = 3, ["name"] = "stones:sku"}, {["x"] = 3, ["param2"] = 1, ["y"] = 12, ["param1"] = 12, ["z"] = 3, ["name"] = "stones:s_22"}, {["x"] = 4, ["y"] = 3, ["param1"] = 93, ["z"] = 4, ["name"] = "stones:rock"}, {["x"] = 4, ["param2"] = 2, ["y"] = 3, ["param1"] = 43, ["z"] = 7, ["name"] = "stones:brushrock_0"}, {["x"] = 4, ["param2"] = 5, ["y"] = 3, ["param1"] = 26, ["z"] = 8, ["name"] = "stones:brushrock_52ul"}, {["x"] = 4, ["param2"] = 8, ["y"] = 4, ["param1"] = 94, ["z"] = 3, ["name"] = "stones:flat_1"}, {["x"] = 4, ["y"] = 4, ["param1"] = 77, ["z"] = 4, ["name"] = "default:flo"}, {["x"] = 4, ["param2"] = 4, ["y"] = 4, ["param1"] = 60, ["z"] = 5, ["name"] = "stones:flat_1"}, {["x"] = 4, ["param2"] = 4, ["y"] = 4, ["param1"] = 26, ["z"] = 7, ["name"] = "stones:roch"}, {["x"] = 4, ["param2"] = 5, ["y"] = 5, ["param1"] = 60, ["z"] = 4, ["name"] = "stones:flat_4"}, {["x"] = 4, ["param2"] = 4, ["y"] = 5, ["param1"] = 9, ["z"] = 7, ["name"] = "stones:roch"}, {["x"] = 4, ["param2"] = 12, ["y"] = 6, ["param1"] = 43, ["z"] = 4, ["name"] = "stones:flat_3a"}, {["x"] = 4, ["param2"] = 7, ["y"] = 6, ["param1"] = 9, ["z"] = 7, ["name"] = "stones:s_221"}, {["x"] = 4, ["param2"] = 12, ["y"] = 7, ["param1"] = 26, ["z"] = 4, ["name"] = "stones:flat_3a"}, {["x"] = 4, ["param2"] = 13, ["y"] = 7, ["param1"] = 9, ["z"] = 7, ["name"] = "stones:s_22r"}, {["x"] = 4, ["param2"] = 3, ["y"] = 8, ["param1"] = 73, ["z"] = 0, ["name"] = "stones:flat_4"}, {["x"] = 4, ["param2"] = 3, ["y"] = 8, ["param1"] = 56, ["z"] = 1, ["name"] = "stones:flat_4"}, {["x"] = 4, ["param2"] = 1, ["y"] = 8, ["param1"] = 41, ["z"] = 2, ["name"] = "stones:flat_3a"}, {["x"] = 4, ["param2"] = 3, ["y"] = 8, ["param1"] = 26, ["z"] = 3, ["name"] = "stones:flat_4"}, {["x"] = 4, ["param2"] = 9, ["y"] = 8, ["param1"] = 9, ["z"] = 4, ["name"] = "stones:flat_2"}, {["x"] = 4, ["param2"] = 15, ["y"] = 8, ["param1"] = 9, ["z"] = 5, ["name"] = "stones:s_3"}, {["x"] = 4, ["param2"] = 4, ["y"] = 8, ["param1"] = 12, ["z"] = 6, ["name"] = "stones:stair_2p"}, {["x"] = 4, ["y"] = 9, ["param1"] = 89, ["z"] = 0, ["name"] = "stones:brush"}, {["x"] = 4, ["param2"] = 2, ["y"] = 9, ["param1"] = 73, ["z"] = 1, ["name"] = "stones:brush"}, {["x"] = 4, ["param2"] = 2, ["y"] = 9, ["param1"] = 57, ["z"] = 2, ["name"] = "stones:brush"}, {["x"] = 4, ["param2"] = 2, ["y"] = 9, ["param1"] = 41, ["z"] = 3, ["name"] = "stones:brush"}, {["x"] = 4, ["param2"] = 2, ["y"] = 9, ["param1"] = 25, ["z"] = 4, ["name"] = "stones:brush"}, {["x"] = 4, ["param2"] = 2, ["y"] = 9, ["param1"] = 12, ["z"] = 5, ["name"] = "stones:stair_3"}, {["x"] = 4, ["y"] = 12, ["param1"] = 12, ["z"] = 3, ["name"] = "stones:roch"}, {["x"] = 5, ["param2"] = 2, ["y"] = 3, ["param1"] = 28, ["z"] = 7, ["name"] = "stones:brushrock_0"}, {["x"] = 5, ["param2"] = 2, ["y"] = 3, ["param1"] = 11, ["z"] = 8, ["name"] = "stones:brushrock_5"}, {["x"] = 5, ["param2"] = 5, ["y"] = 3, ["param1"] = 10, ["z"] = 9, ["name"] = "stones:s_52"}, {["x"] = 5, ["param2"] = 12, ["y"] = 4, ["param1"] = 62, ["z"] = 4, ["name"] = "stones:flat_1"}, {["x"] = 5, ["param2"] = 4, ["y"] = 4, ["param1"] = 11, ["z"] = 7, ["name"] = "stones:roch"}, {["x"] = 5, ["param2"] = 4, ["y"] = 5, ["param1"] = 12, ["z"] = 7, ["name"] = "stones:roch"}, {["x"] = 5, ["param2"] = 2, ["y"] = 6, ["param1"] = 12, ["z"] = 7, ["name"] = "stones:panel"}, {["x"] = 5, ["param2"] = 21, ["y"] = 8, ["param1"] = 60, ["z"] = 0, ["name"] = "stones:s_2"}, {["x"] = 5, ["param2"] = 21, ["y"] = 8, ["param1"] = 41, ["z"] = 1, ["name"] = "stones:s_52"}, {["x"] = 5, ["param2"] = 15, ["y"] = 8, ["param1"] = 25, ["z"] = 2, ["name"] = "stones:s_2"}, {["x"] = 5, ["param2"] = 21, ["y"] = 8, ["param1"] = 9, ["z"] = 3, ["name"] = "stones:s_52"}, {["x"] = 5, ["param2"] = 1, ["y"] = 9, ["param1"] = 76, ["z"] = 0, ["name"] = "stones:brushrock_0"}, {["x"] = 5, ["param2"] = 1, ["y"] = 9, ["param1"] = 60, ["z"] = 1, ["name"] = "stones:brushrock_0"}, {["x"] = 5, ["param2"] = 1, ["y"] = 9, ["param1"] = 41, ["z"] = 2, ["name"] = "stones:brushrock_0"}, {["x"] = 5, ["param2"] = 1, ["y"] = 9, ["param1"] = 25, ["z"] = 3, ["name"] = "stones:brushrock_0"}, {["x"] = 5, ["param2"] = 2, ["y"] = 9, ["param1"] = 9, ["z"] = 4, ["name"] = "stones:brushrock_2"}, {["x"] = 5, ["y"] = 9, ["param1"] = 9, ["z"] = 5, ["name"] = "stones:brushrock_2"}, {["x"] = 5, ["param2"] = 18, ["y"] = 9, ["param1"] = 12, ["z"] = 6, ["name"] = "stones:brushrock_52ur"}, {["x"] = 5, ["param2"] = 18, ["y"] = 9, ["param1"] = 12, ["z"] = 7, ["name"] = "stones:s_52"}, {["x"] = 5, ["param2"] = 4, ["y"] = 10, ["param1"] = 60, ["z"] = 0, ["name"] = "stones:estruk"}, {["x"] = 5, ["param2"] = 4, ["y"] = 10, ["param1"] = 44, ["z"] = 1, ["name"] = "stones:estruk"}, {["x"] = 5, ["param2"] = 4, ["y"] = 10, ["param1"] = 28, ["z"] = 2, ["name"] = "stones:estruk"}, {["x"] = 5, ["param2"] = 16, ["y"] = 10, ["param1"] = 9, ["z"] = 3, ["name"] = "stones:roch"}, {["x"] = 5, ["param2"] = 13, ["y"] = 11, ["param1"] = 12, ["z"] = 3, ["name"] = "stones:sku"}, {["x"] = 5, ["param2"] = 3, ["y"] = 12, ["param1"] = 12, ["z"] = 3, ["name"] = "stones:s_22"}, {["x"] = 6, ["param2"] = 2, ["y"] = 3, ["param1"] = 11, ["z"] = 7, ["name"] = "stones:brushrock_0"}, {["x"] = 6, ["param2"] = 3, ["y"] = 3, ["param1"] = 10, ["z"] = 8, ["name"] = "stones:brush"}, {["x"] = 6, ["param2"] = 4, ["y"] = 3, ["param1"] = 9, ["z"] = 9, ["name"] = "stones:roch"}, {["x"] = 6, ["param2"] = 20, ["y"] = 4, ["param1"] = 28, ["z"] = 5, ["name"] = "stones:plot"}, {["x"] = 6, ["param2"] = 4, ["y"] = 4, ["param1"] = 12, ["z"] = 7, ["name"] = "stones:roch"}, {["x"] = 6, ["param2"] = 20, ["y"] = 5, ["param1"] = 44, ["z"] = 3, ["name"] = "stones:s_52r"}, {["x"] = 6, ["param2"] = 22, ["y"] = 5, ["param1"] = 28, ["z"] = 4, ["name"] = "stones:s_52l"}, {["x"] = 6, ["param2"] = 5, ["y"] = 5, ["param1"] = 13, ["z"] = 5, ["name"] = "stones:s_52hur"}, {["x"] = 6, ["param2"] = 4, ["y"] = 5, ["param1"] = 13, ["z"] = 7, ["name"] = "stones:roch"}, {["x"] = 6, ["param2"] = 4, ["y"] = 6, ["param1"] = 44, ["z"] = 2, ["name"] = "stones:sku_202"}, {["x"] = 6, ["param2"] = 2, ["y"] = 6, ["param1"] = 28, ["z"] = 3, ["name"] = "stones:s_52r"}, {["x"] = 6, ["y"] = 6, ["param1"] = 12, ["z"] = 4, ["name"] = "stones:s_52l"}, {["x"] = 6, ["param2"] = 2, ["y"] = 6, ["param1"] = 12, ["z"] = 5, ["name"] = "stones:s_22r"}, {["x"] = 6, ["param2"] = 1, ["y"] = 6, ["param1"] = 12, ["z"] = 7, ["name"] = "stones:s_52ur"}, {["x"] = 6, ["param2"] = 8, ["y"] = 7, ["param1"] = 12, ["z"] = 1, ["name"] = "stones:s_52l"}, {["x"] = 6, ["param2"] = 4, ["y"] = 7, ["param1"] = 28, ["z"] = 2, ["name"] = "stones:s_52l"}, {["x"] = 6, ["param2"] = 10, ["y"] = 8, ["param1"] = 28, ["z"] = 1, ["name"] = "stones:s_52r"}, {["x"] = 6, ["param2"] = 6, ["y"] = 8, ["param1"] = 12, ["z"] = 2, ["name"] = "stones:s_52r"}, {["x"] = 6, ["param2"] = 22, ["y"] = 9, ["param1"] = 28, ["z"] = 2, ["name"] = "stones:sku_202"}, {["x"] = 6, ["param2"] = 22, ["y"] = 9, ["param1"] = 12, ["z"] = 3, ["name"] = "stones:s_52l"}, {["x"] = 6, ["param2"] = 12, ["y"] = 9, ["param1"] = 12, ["z"] = 4, ["name"] = "stones:s_52"}, {["x"] = 6, ["param2"] = 12, ["y"] = 9, ["param1"] = 12, ["z"] = 5, ["name"] = "stones:brushrock_52ur"}, {["x"] = 6, ["param2"] = 2, ["y"] = 9, ["param1"] = 12, ["z"] = 6, ["name"] = "stones:brushrock_8"}, {["x"] = 6, ["y"] = 9, ["param1"] = 9, ["z"] = 7, ["name"] = "stones:brushrock_2"}, {["x"] = 6, ["param2"] = 3, ["y"] = 9, ["param1"] = 9, ["z"] = 8, ["name"] = "stones:brushrock_0"}, {["x"] = 6, ["param2"] = 18, ["y"] = 9, ["param1"] = 25, ["z"] = 9, ["name"] = "stones:brushrock_52ur"}, {["x"] = 6, ["param2"] = 18, ["y"] = 9, ["param1"] = 41, ["z"] = 10, ["name"] = "stones:s_52"}, {["x"] = 6, ["y"] = 10, ["param1"] = 12, ["z"] = 3, ["name"] = "stones:s_52l"}, {["x"] = 6, ["param2"] = 22, ["y"] = 10, ["param1"] = 12, ["z"] = 4, ["name"] = "stones:sku2_l"}, {["x"] = 6, ["param2"] = 12, ["y"] = 10, ["param1"] = 12, ["z"] = 5, ["name"] = "stones:sku2_l"}, {["x"] = 6, ["param2"] = 5, ["y"] = 10, ["param1"] = 12, ["z"] = 6, ["name"] = "stones:s_22r"}, {["x"] = 6, ["param2"] = 11, ["y"] = 10, ["param1"] = 28, ["z"] = 8, ["name"] = "stones:panel"}, {["x"] = 6, ["param2"] = 12, ["y"] = 10, ["param1"] = 44, ["z"] = 9, ["name"] = "stones:sku2_l"}, {["x"] = 6, ["param2"] = 18, ["y"] = 10, ["param1"] = 60, ["z"] = 10, ["name"] = "stones:s_52l"}, {["x"] = 7, ["param2"] = 9, ["y"] = 3, ["param1"] = 12, ["z"] = 6, ["name"] = "stones:s_52"}, {["x"] = 7, ["param2"] = 3, ["y"] = 3, ["param1"] = 10, ["z"] = 7, ["name"] = "stones:brushrock_2"}, {["x"] = 7, ["param2"] = 2, ["y"] = 3, ["param1"] = 9, ["z"] = 8, ["name"] = "stones:brush"}, {["x"] = 7, ["param2"] = 4, ["y"] = 3, ["param1"] = 24, ["z"] = 9, ["name"] = "stones:roch"}, {["x"] = 7, ["param2"] = 18, ["y"] = 5, ["param1"] = 12, ["z"] = 7, ["name"] = "stones:arsh"}, {["x"] = 7, ["param2"] = 4, ["y"] = 6, ["param1"] = 11, ["z"] = 7, ["name"] = "stones:roch"}, {["x"] = 7, ["y"] = 9, ["param1"] = 12, ["z"] = 6, ["name"] = "stones:brushrock_4"}, {["x"] = 7, ["param2"] = 1, ["y"] = 9, ["param1"] = 9, ["z"] = 7, ["name"] = "stones:brush"}, {["x"] = 7, ["y"] = 9, ["param1"] = 28, ["z"] = 8, ["name"] = "stones:brush"}, {["x"] = 7, ["param2"] = 3, ["y"] = 9, ["param1"] = 44, ["z"] = 9, ["name"] = "stones:brush"}, {["x"] = 7, ["y"] = 9, ["param1"] = 57, ["z"] = 10, ["name"] = "stones:brushrock_2"}, {["x"] = 7, ["param2"] = 5, ["y"] = 9, ["param1"] = 41, ["z"] = 11, ["name"] = "stones:brushrock_22"}, {["x"] = 7, ["param2"] = 15, ["y"] = 10, ["param1"] = 12, ["z"] = 6, ["name"] = "stones:stair_half_l"}, {["x"] = 7, ["param2"] = 12, ["y"] = 10, ["param1"] = 76, ["z"] = 10, ["name"] = "stones:s_52l"}, {["x"] = 7, ["param2"] = 12, ["y"] = 10, ["param1"] = 60, ["z"] = 11, ["name"] = "stones:sku_202"}, {["x"] = 8, ["param2"] = 8, ["y"] = 3, ["param1"] = 12, ["z"] = 6, ["name"] = "stones:roch"}, {["x"] = 8, ["param2"] = 2, ["y"] = 3, ["param1"] = 9, ["z"] = 7, ["name"] = "stones:brushrock_8"}, {["x"] = 8, ["param2"] = 2, ["y"] = 3, ["param1"] = 24, ["z"] = 8, ["name"] = "stones:brush"}, {["x"] = 8, ["param2"] = 4, ["y"] = 3, ["param1"] = 39, ["z"] = 9, ["name"] = "stones:roch"}, {["x"] = 8, ["param2"] = 9, ["y"] = 4, ["param1"] = 12, ["z"] = 6, ["name"] = "stones:s_22"}, {["x"] = 8, ["param2"] = 5, ["y"] = 4, ["param1"] = 10, ["z"] = 7, ["name"] = "stones:s_22"}, {["x"] = 8, ["param2"] = 9, ["y"] = 5, ["param1"] = 12, ["z"] = 6, ["name"] = "stones:s_22"}, {["x"] = 8, ["param2"] = 5, ["y"] = 5, ["param1"] = 11, ["z"] = 7, ["name"] = "stones:s_22"}, {["x"] = 8, ["param2"] = 1, ["y"] = 5, ["param1"] = 10, ["z"] = 8, ["name"] = "stones:arschil"}, {["x"] = 8, ["param2"] = 9, ["y"] = 6, ["param1"] = 12, ["z"] = 6, ["name"] = "stones:s_22"}, {["x"] = 8, ["param2"] = 1, ["y"] = 6, ["param1"] = 10, ["z"] = 7, ["name"] = "stones:s_21"}, {["x"] = 8, ["param2"] = 18, ["y"] = 6, ["param1"] = 9, ["z"] = 8, ["name"] = "stones:s_52"}, {["x"] = 8, ["param2"] = 9, ["y"] = 7, ["param1"] = 12, ["z"] = 6, ["name"] = "stones:s_22"}, {["x"] = 8, ["param2"] = 19, ["y"] = 7, ["param1"] = 9, ["z"] = 7, ["name"] = "stones:s_3"}, {["x"] = 8, ["param2"] = 19, ["y"] = 7, ["param1"] = 9, ["z"] = 8, ["name"] = "stones:vsect_2"}, {["x"] = 8, ["param2"] = 9, ["y"] = 8, ["param1"] = 12, ["z"] = 6, ["name"] = "stones:s_222"}, {["x"] = 8, ["param2"] = 23, ["y"] = 8, ["param1"] = 9, ["z"] = 7, ["name"] = "stones:diagsteps_31"}, {["x"] = 8, ["param2"] = 17, ["y"] = 8, ["param1"] = 25, ["z"] = 8, ["name"] = "stones:panel"}, {["x"] = 8, ["param2"] = 18, ["y"] = 8, ["param1"] = 41, ["z"] = 9, ["name"] = "stones:s_52l"}, {["x"] = 8, ["param2"] = 2, ["y"] = 9, ["param1"] = 12, ["z"] = 6, ["name"] = "stones:s_21u"}, {["x"] = 8, ["param2"] = 12, ["y"] = 9, ["param1"] = 25, ["z"] = 7, ["name"] = "stones:brushrock_527r"}, {["x"] = 8, ["param2"] = 1, ["y"] = 9, ["param1"] = 44, ["z"] = 8, ["name"] = "stones:brushrock_0"}, {["x"] = 8, ["param2"] = 2, ["y"] = 9, ["param1"] = 60, ["z"] = 9, ["name"] = "stones:brushrock_2"}, {["x"] = 8, ["param2"] = 3, ["y"] = 9, ["param1"] = 76, ["z"] = 10, ["name"] = "stones:brush"}, {["x"] = 8, ["param2"] = 2, ["y"] = 9, ["param1"] = 57, ["z"] = 11, ["name"] = "stones:brushrock_5"}, {["x"] = 8, ["param2"] = 5, ["y"] = 9, ["param1"] = 73, ["z"] = 12, ["name"] = "stones:s_52"}, {["x"] = 8, ["param2"] = 3, ["y"] = 10, ["param1"] = 28, ["z"] = 6, ["name"] = "stones:sku2_l"}, {["x"] = 8, ["param2"] = 11, ["y"] = 10, ["param1"] = 76, ["z"] = 11, ["name"] = "stones:s_52r"}, {["x"] = 8, ["param2"] = 5, ["y"] = 10, ["param1"] = 60, ["z"] = 12, ["name"] = "stones:s_52r"}, {["x"] = 9, ["y"] = 3, ["z"] = 6, ["name"] = "stones:rock"}, {["x"] = 9, ["param2"] = 2, ["y"] = 3, ["param1"] = 25, ["z"] = 7, ["name"] = "stones:brushrock_0"}, {["x"] = 9, ["param2"] = 3, ["y"] = 3, ["param1"] = 41, ["z"] = 8, ["name"] = "stones:brush"}, {["x"] = 9, ["param2"] = 5, ["y"] = 3, ["param1"] = 55, ["z"] = 9, ["name"] = "stones:s_52u"}, {["x"] = 9, ["y"] = 4, ["z"] = 6, ["name"] = "stones:rock"}, {["x"] = 9, ["param2"] = 4, ["y"] = 4, ["param1"] = 12, ["z"] = 7, ["name"] = "stones:roch"}, {["x"] = 9, ["param2"] = 5, ["y"] = 4, ["param1"] = 41, ["z"] = 9, ["name"] = "stones:s_52u"}, {["x"] = 9, ["y"] = 5, ["z"] = 6, ["name"] = "stones:rock"}, {["x"] = 9, ["param2"] = 4, ["y"] = 5, ["param1"] = 12, ["z"] = 7, ["name"] = "stones:vr_2"}, {["x"] = 9, ["param2"] = 1, ["y"] = 5, ["param1"] = 12, ["z"] = 8, ["name"] = "stones:arcshir"}, {["x"] = 9, ["param2"] = 12, ["y"] = 5, ["param1"] = 25, ["z"] = 9, ["name"] = "stones:sku_20"}, {["x"] = 9, ["param2"] = 2, ["y"] = 6, ["param1"] = 12, ["z"] = 6, ["name"] = "stones:s_21"}, {["x"] = 9, ["param2"] = 7, ["y"] = 6, ["param1"] = 12, ["z"] = 7, ["name"] = "stones:s_22"}, {["x"] = 9, ["param2"] = 12, ["y"] = 6, ["param1"] = 12, ["z"] = 8, ["name"] = "stones:s_52"}, {["x"] = 9, ["param2"] = 12, ["y"] = 6, ["param1"] = 25, ["z"] = 9, ["name"] = "stones:sku_20"}, {["x"] = 9, ["param2"] = 7, ["y"] = 7, ["param1"] = 12, ["z"] = 6, ["name"] = "stones:s_52u"}, {["x"] = 9, ["param2"] = 12, ["y"] = 7, ["param1"] = 12, ["z"] = 7, ["name"] = "stones:s_52"}, {["x"] = 9, ["param2"] = 12, ["y"] = 7, ["param1"] = 28, ["z"] = 8, ["name"] = "stones:roch"}, {["x"] = 9, ["param2"] = 12, ["y"] = 7, ["param1"] = 44, ["z"] = 9, ["name"] = "stones:sku"}, {["x"] = 9, ["param2"] = 18, ["y"] = 7, ["param1"] = 57, ["z"] = 10, ["name"] = "stones:s_52"}, {["x"] = 9, ["param2"] = 7, ["y"] = 8, ["param1"] = 12, ["z"] = 6, ["name"] = "stones:s_52u"}, {["x"] = 9, ["param2"] = 12, ["y"] = 8, ["param1"] = 44, ["z"] = 8, ["name"] = "stones:s_52"}, {["x"] = 9, ["param2"] = 12, ["y"] = 8, ["param1"] = 60, ["z"] = 9, ["name"] = "stones:s_52u"}, {["x"] = 9, ["param2"] = 18, ["y"] = 8, ["param1"] = 76, ["z"] = 10, ["name"] = "stones:s_52u"}, {["x"] = 9, ["param2"] = 5, ["y"] = 8, ["param1"] = 57, ["z"] = 11, ["name"] = "stones:s_22"}, {["x"] = 9, ["param2"] = 2, ["y"] = 9, ["param1"] = 28, ["z"] = 6, ["name"] = "stones:diagsteps_52rv"}, {["x"] = 9, ["param2"] = 13, ["y"] = 9, ["param1"] = 76, ["z"] = 9, ["name"] = "stones:s_252l"}, {["x"] = 9, ["param2"] = 12, ["y"] = 9, ["param1"] = 92, ["z"] = 10, ["name"] = "stones:brushrock_527r"}, {["x"] = 9, ["param2"] = 2, ["y"] = 9, ["param1"] = 76, ["z"] = 11, ["name"] = "stones:brushrock_8"}, {["x"] = 9, ["param2"] = 1, ["y"] = 9, ["param1"] = 89, ["z"] = 12, ["name"] = "stones:brushrock_21"}, {["x"] = 9, ["param2"] = 5, ["y"] = 9, ["param1"] = 73, ["z"] = 13, ["name"] = "stones:s_22"}, {["x"] = 9, ["param2"] = 3, ["y"] = 10, ["param1"] = 44, ["z"] = 6, ["name"] = "stones:s_52l"}, {["x"] = 9, ["param2"] = 18, ["y"] = 10, ["param1"] = 76, ["z"] = 12, ["name"] = "stones:sku_202"}, {["x"] = 9, ["param2"] = 5, ["y"] = 10, ["param1"] = 60, ["z"] = 13, ["name"] = "stones:s_22"}, {["x"] = 10, ["param2"] = 9, ["y"] = 3, ["param1"] = 28, ["z"] = 6, ["name"] = "stones:brushrock_52ur"}, {["x"] = 10, ["param2"] = 2, ["y"] = 3, ["param1"] = 44, ["z"] = 7, ["name"] = "stones:brush"}, {["x"] = 10, ["param2"] = 3, ["y"] = 3, ["param1"] = 60, ["z"] = 8, ["name"] = "stones:brush"}, {["x"] = 10, ["y"] = 3, ["param1"] = 73, ["z"] = 9, ["name"] = "stones:brushrock_2"}, {["x"] = 10, ["param2"] = 3, ["y"] = 3, ["param1"] = 89, ["z"] = 10, ["name"] = "stones:brushrock_0"}, {["x"] = 10, ["param2"] = 5, ["y"] = 3, ["param1"] = 105, ["z"] = 11, ["name"] = "stones:brushrock_22"}, {["x"] = 10, ["param2"] = 12, ["y"] = 4, ["param1"] = 60, ["z"] = 9, ["name"] = "stones:s_52"}, {["x"] = 10, ["param2"] = 12, ["y"] = 4, ["param1"] = 76, ["z"] = 10, ["name"] = "stones:roch"}, {["x"] = 10, ["param2"] = 12, ["y"] = 4, ["param1"] = 92, ["z"] = 11, ["name"] = "stones:sku"}, {["x"] = 10, ["param2"] = 11, ["y"] = 5, ["param1"] = 44, ["z"] = 9, ["name"] = "stones:s_22"}, {["x"] = 10, ["param2"] = 7, ["y"] = 5, ["param1"] = 60, ["z"] = 10, ["name"] = "stones:panel"}, {["x"] = 10, ["param2"] = 12, ["y"] = 5, ["param1"] = 76, ["z"] = 11, ["name"] = "stones:sku"}, {["x"] = 10, ["param2"] = 11, ["y"] = 6, ["param1"] = 44, ["z"] = 9, ["name"] = "stones:s_22"}, {["x"] = 10, ["param2"] = 12, ["y"] = 6, ["param1"] = 60, ["z"] = 10, ["name"] = "stones:roch"}, {["x"] = 10, ["param2"] = 12, ["y"] = 6, ["param1"] = 60, ["z"] = 11, ["name"] = "stones:sku"}, {["x"] = 10, ["param2"] = 12, ["y"] = 7, ["param1"] = 76, ["z"] = 10, ["name"] = "stones:s_52"}, {["x"] = 10, ["param2"] = 3, ["y"] = 7, ["param1"] = 57, ["z"] = 11, ["name"] = "stones:s_21"}, {["x"] = 10, ["param2"] = 11, ["y"] = 8, ["param1"] = 76, ["z"] = 11, ["name"] = "stones:s_52u"}, {["x"] = 10, ["param2"] = 11, ["y"] = 9, ["param1"] = 92, ["z"] = 11, ["name"] = "stones:brushrock_52ul"}, {["x"] = 10, ["y"] = 9, ["param1"] = 105, ["z"] = 12, ["name"] = "stones:brush"}, {["x"] = 10, ["param2"] = 1, ["y"] = 9, ["param1"] = 89, ["z"] = 13, ["name"] = "stones:brushrock_21"}, {["x"] = 10, ["param2"] = 5, ["y"] = 9, ["param1"] = 73, ["z"] = 14, ["name"] = "stones:s_22"}, {["x"] = 10, ["param2"] = 18, ["y"] = 10, ["param1"] = 76, ["z"] = 13, ["name"] = "stones:sku_202"}, {["x"] = 10, ["param2"] = 5, ["y"] = 10, ["param1"] = 60, ["z"] = 14, ["name"] = "stones:s_22r"}, {["x"] = 11, ["param2"] = 11, ["y"] = 3, ["param1"] = 44, ["z"] = 6, ["name"] = "stones:brushrock_22"}, {["x"] = 11, ["param2"] = 1, ["y"] = 3, ["param1"] = 60, ["z"] = 7, ["name"] = "stones:brushrock_0"}, {["x"] = 11, ["param2"] = 2, ["y"] = 3, ["param1"] = 76, ["z"] = 8, ["name"] = "stones:brushrock_2"}, {["x"] = 11, ["param2"] = 1, ["y"] = 3, ["param1"] = 92, ["z"] = 9, ["name"] = "stones:brush"}, {["x"] = 11, ["param2"] = 1, ["y"] = 3, ["param1"] = 108, ["z"] = 10, ["name"] = "stones:brushrock_8"}, {["x"] = 11, ["param2"] = 14, ["y"] = 3, ["param1"] = 124, ["z"] = 11, ["name"] = "stones:brushrock_22"}, {["x"] = 11, ["param2"] = 15, ["y"] = 7, ["param1"] = 76, ["z"] = 11, ["name"] = "stones:s_52r"}, {["x"] = 11, ["param2"] = 11, ["y"] = 8, ["param1"] = 92, ["z"] = 11, ["name"] = "stones:panel"}, {["x"] = 11, ["param2"] = 11, ["y"] = 9, ["param1"] = 108, ["z"] = 11, ["name"] = "stones:panel"}, {["x"] = 11, ["param2"] = 3, ["y"] = 9, ["param1"] = 121, ["z"] = 12, ["name"] = "stones:brushrock_21"}, {["x"] = 11, ["y"] = 9, ["param1"] = 105, ["z"] = 13, ["name"] = "stones:brush"}, {["x"] = 11, ["param2"] = 1, ["y"] = 9, ["param1"] = 89, ["z"] = 14, ["name"] = "stones:brushrock_21"}, {["x"] = 11, ["param2"] = 11, ["y"] = 10, ["param1"] = 124, ["z"] = 11, ["name"] = "stones:panel"}, {["x"] = 11, ["param2"] = 12, ["y"] = 10, ["param1"] = 108, ["z"] = 12, ["name"] = "stones:sku_202"}, {["x"] = 11, ["param2"] = 18, ["y"] = 10, ["param1"] = 76, ["z"] = 14, ["name"] = "stones:sku_202"}, {["x"] = 12, ["param2"] = 12, ["y"] = 3, ["param1"] = 92, ["z"] = 8, ["name"] = "stones:s_52"}, {["x"] = 12, ["param2"] = 12, ["y"] = 3, ["param1"] = 108, ["z"] = 9, ["name"] = "stones:brushrock_52ur"}, {["x"] = 12, ["param2"] = 14, ["y"] = 3, ["param1"] = 124, ["z"] = 10, ["name"] = "stones:brushrock_22"}, {["x"] = 12, ["param2"] = 11, ["y"] = 9, ["param1"] = 140, ["z"] = 12, ["name"] = "stones:s_22"}, {["x"] = 12, ["param2"] = 3, ["y"] = 9, ["param1"] = 124, ["z"] = 13, ["name"] = "stones:brushrock_21"}, {["x"] = 12, ["param2"] = 1, ["y"] = 9, ["param1"] = 108, ["z"] = 14, ["name"] = "stones:brush"}, {["x"] = 12, ["param2"] = 11, ["y"] = 10, ["param1"] = 124, ["z"] = 12, ["name"] = "stones:s_22r"}, {["x"] = 12, ["param2"] = 12, ["y"] = 10, ["param1"] = 108, ["z"] = 13, ["name"] = "stones:sku_202"}}