5:return {{["x"] = 1, ["param2"] = 16, ["y"] = 8, ["param1"] = 60, ["z"] = 6, ["name"] = "stones:s_52"}, {["x"] = 1, ["param2"] = 16, ["y"] = 8, ["param1"] = 45, ["z"] = 7, ["name"] = "stones:brushrock_52ul"}, {["x"] = 1, ["param2"] = 3, ["y"] = 8, ["param1"] = 45, ["z"] = 8, ["name"] = "stones:brushrock_0"}, {["x"] = 1, ["param2"] = 18, ["y"] = 8, ["param1"] = 62, ["z"] = 9, ["name"] = "stones:brushrock_52ur"}, {["x"] = 1, ["param2"] = 5, ["y"] = 8, ["param1"] = 78, ["z"] = 10, ["name"] = "stones:panel"}, {["x"] = 1, ["param2"] = 16, ["y"] = 9, ["param1"] = 76, ["z"] = 6, ["name"] = "stones:s_52r"}, {["x"] = 1, ["param2"] = 14, ["y"] = 9, ["param1"] = 60, ["z"] = 7, ["name"] = "stones:sku2_r"}, {["x"] = 1, ["param2"] = 22, ["y"] = 9, ["param1"] = 61, ["z"] = 8, ["name"] = "stones:stair_half_l"}, {["x"] = 1, ["param2"] = 12, ["y"] = 9, ["param1"] = 78, ["z"] = 9, ["name"] = "stones:sku2_l"}, {["x"] = 1, ["param2"] = 5, ["y"] = 9, ["param1"] = 94, ["z"] = 10, ["name"] = "stones:panel"}, {["x"] = 2, ["param2"] = 16, ["y"] = 8, ["param1"] = 43, ["z"] = 4, ["name"] = "stones:s_52"}, {["x"] = 2, ["param2"] = 16, ["y"] = 8, ["param1"] = 60, ["z"] = 5, ["name"] = "stones:brushrock_52ul"}, {["x"] = 2, ["param2"] = 1, ["y"] = 8, ["param1"] = 77, ["z"] = 6, ["name"] = "stones:brushrock_5"}, {["x"] = 2, ["param2"] = 3, ["y"] = 8, ["param1"] = 62, ["z"] = 7, ["name"] = "stones:brush"}, {["x"] = 2, ["param2"] = 3, ["y"] = 8, ["param1"] = 46, ["z"] = 8, ["name"] = "stones:brush"}, {["x"] = 2, ["param2"] = 3, ["y"] = 8, ["param1"] = 46, ["z"] = 9, ["name"] = "stones:brush"}, {["x"] = 2, ["param2"] = 5, ["y"] = 8, ["param1"] = 62, ["z"] = 10, ["name"] = "stones:brushrock_52ul"}, {["x"] = 2, ["param2"] = 16, ["y"] = 9, ["param1"] = 60, ["z"] = 4, ["name"] = "stones:s_52r"}, {["x"] = 2, ["param2"] = 14, ["y"] = 9, ["param1"] = 76, ["z"] = 5, ["name"] = "stones:sku2_r"}, {["x"] = 2, ["param2"] = 14, ["y"] = 9, ["param1"] = 92, ["z"] = 6, ["name"] = "stones:s_52r"}, {["x"] = 2, ["param2"] = 5, ["y"] = 9, ["param1"] = 78, ["z"] = 10, ["name"] = "stones:sku2_r"}, {["x"] = 3, ["param2"] = 9, ["y"] = 8, ["param1"] = 28, ["z"] = 2, ["name"] = "stones:panel"}, {["x"] = 3, ["param2"] = 16, ["y"] = 8, ["param1"] = 42, ["z"] = 3, ["name"] = "stones:brushrock_52ul"}, {["x"] = 3, ["param2"] = 1, ["y"] = 8, ["param1"] = 59, ["z"] = 4, ["name"] = "stones:brushrock_5"}, {["x"] = 3, ["param2"] = 3, ["y"] = 8, ["param1"] = 76, ["z"] = 5, ["name"] = "stones:brush"}, {["x"] = 3, ["param2"] = 1, ["y"] = 8, ["param1"] = 93, ["z"] = 6, ["name"] = "stones:brush"}, {["x"] = 3, ["y"] = 8, ["param1"] = 78, ["z"] = 7, ["name"] = "stones:brush"}, {["x"] = 3, ["y"] = 8, ["param1"] = 62, ["z"] = 8, ["name"] = "stones:brush"}, {["x"] = 3, ["y"] = 8, ["param1"] = 46, ["z"] = 9, ["name"] = "stones:brush"}, {["x"] = 3, ["y"] = 8, ["param1"] = 46, ["z"] = 10, ["name"] = "stones:brushrock_0"}, {["x"] = 3, ["param2"] = 9, ["y"] = 9, ["param1"] = 44, ["z"] = 2, ["name"] = "stones:panel"}, {["x"] = 3, ["param2"] = 14, ["y"] = 9, ["param1"] = 60, ["z"] = 3, ["name"] = "stones:sku2_r"}, {["x"] = 3, ["param2"] = 14, ["y"] = 9, ["param1"] = 76, ["z"] = 4, ["name"] = "stones:s_52r"}, {["x"] = 3, ["param2"] = 17, ["y"] = 9, ["param1"] = 61, ["z"] = 10, ["name"] = "stones:stair_half_l"}, {["x"] = 4, ["param2"] = 9, ["y"] = 8, ["param1"] = 41, ["z"] = 2, ["name"] = "stones:brushrock_52ur"}, {["x"] = 4, ["param2"] = 2, ["y"] = 8, ["param1"] = 60, ["z"] = 3, ["name"] = "stones:brush"}, {["x"] = 4, ["param2"] = 3, ["y"] = 8, ["param1"] = 76, ["z"] = 4, ["name"] = "stones:brush"}, {["x"] = 4, ["param2"] = 2, ["y"] = 8, ["param1"] = 92, ["z"] = 5, ["name"] = "stones:brush"}, {["x"] = 4, ["param2"] = 1, ["y"] = 8, ["param1"] = 109, ["z"] = 6, ["name"] = "stones:brush"}, {["x"] = 4, ["param2"] = 1, ["y"] = 8, ["param1"] = 94, ["z"] = 7, ["name"] = "stones:brush"}, {["x"] = 4, ["param2"] = 1, ["y"] = 8, ["param1"] = 77, ["z"] = 8, ["name"] = "stones:brush"}, {["x"] = 4, ["param2"] = 1, ["y"] = 8, ["param1"] = 62, ["z"] = 9, ["name"] = "stones:brush"}, {["x"] = 4, ["param2"] = 7, ["y"] = 8, ["param1"] = 46, ["z"] = 10, ["name"] = "stones:brushrock_52ur"}, {["x"] = 4, ["param2"] = 7, ["y"] = 9, ["param1"] = 60, ["z"] = 2, ["name"] = "stones:sku2_l"}, {["x"] = 4, ["param2"] = 7, ["y"] = 9, ["param1"] = 61, ["z"] = 10, ["name"] = "stones:sku2_l"}, {["x"] = 4, ["param2"] = 17, ["y"] = 10, ["param1"] = 93, ["z"] = 9, ["name"] = "stones:s_22l"}, {["x"] = 4, ["param2"] = 19, ["y"] = 11, ["param1"] = 110, ["z"] = 9, ["name"] = "stones:s_52r"}, {["x"] = 5, ["param2"] = 9, ["y"] = 8, ["param1"] = 44, ["z"] = 1, ["name"] = "stones:s_52"}, {["x"] = 5, ["param2"] = 3, ["y"] = 8, ["param1"] = 57, ["z"] = 2, ["name"] = "stones:brushrock_2"}, {["x"] = 5, ["param2"] = 1, ["y"] = 8, ["param1"] = 76, ["z"] = 3, ["name"] = "stones:brush"}, {["x"] = 5, ["param2"] = 3, ["y"] = 8, ["param1"] = 92, ["z"] = 4, ["name"] = "stones:brush"}, {["x"] = 5, ["param2"] = 1, ["y"] = 8, ["param1"] = 108, ["z"] = 5, ["name"] = "stones:brushrock_8"}, {["x"] = 5, ["param2"] = 3, ["y"] = 8, ["param1"] = 124, ["z"] = 6, ["name"] = "stones:brushrock_4"}, {["x"] = 5, ["param2"] = 2, ["y"] = 8, ["param1"] = 109, ["z"] = 7, ["name"] = "stones:brushrock_3"}, {["x"] = 5, ["param2"] = 1, ["y"] = 8, ["param1"] = 93, ["z"] = 8, ["name"] = "stones:brushrock_0"}, {["x"] = 5, ["param2"] = 14, ["y"] = 8, ["param1"] = 78, ["z"] = 9, ["name"] = "stones:brushrock_52ul"}, {["x"] = 5, ["param2"] = 7, ["y"] = 8, ["param1"] = 62, ["z"] = 10, ["name"] = "stones:panel"}, {["x"] = 5, ["param2"] = 9, ["y"] = 9, ["param1"] = 60, ["z"] = 1, ["name"] = "stones:s_52l"}, {["x"] = 5, ["param2"] = 7, ["y"] = 9, ["param1"] = 76, ["z"] = 2, ["name"] = "stones:s_52l"}, {["x"] = 5, ["param2"] = 16, ["y"] = 9, ["param1"] = 140, ["z"] = 6, ["name"] = "stones:s_52l"}, {["x"] = 5, ["param2"] = 18, ["y"] = 9, ["param1"] = 124, ["z"] = 7, ["name"] = "stones:s_52r"}, {["x"] = 5, ["param2"] = 6, ["y"] = 9, ["param1"] = 109, ["z"] = 8, ["name"] = "stones:sku_202"}, {["x"] = 5, ["param2"] = 14, ["y"] = 9, ["param1"] = 93, ["z"] = 9, ["name"] = "stones:sku2_r"}, {["x"] = 5, ["param2"] = 7, ["y"] = 9, ["param1"] = 78, ["z"] = 10, ["name"] = "stones:panel"}, {["x"] = 5, ["param2"] = 9, ["y"] = 10, ["param1"] = 124, ["z"] = 8, ["name"] = "stones:s_22r"}, {["x"] = 5, ["param2"] = 9, ["y"] = 10, ["param1"] = 109, ["z"] = 9, ["name"] = "stones:skud_202r"}, {["x"] = 5, ["param2"] = 15, ["y"] = 11, ["param1"] = 126, ["z"] = 9, ["name"] = "stones:s_52r"}, {["x"] = 5, ["param2"] = 11, ["y"] = 12, ["param1"] = 110, ["z"] = 9, ["name"] = "stones:panel"}, {["x"] = 5, ["param2"] = 12, ["y"] = 13, ["param1"] = 94, ["z"] = 9, ["name"] = "stones:s_52hul"}, {["x"] = 5, ["y"] = 14, ["param1"] = 78, ["z"] = 9, ["name"] = "stones:plot"}, {["x"] = 5, ["param2"] = 4, ["y"] = 15, ["param1"] = 62, ["z"] = 9, ["name"] = "stones:shrub"}, {["x"] = 6, ["param2"] = 11, ["y"] = 8, ["param1"] = 60, ["z"] = 1, ["name"] = "stones:panel"}, {["x"] = 6, ["param2"] = 3, ["y"] = 8, ["param1"] = 73, ["z"] = 2, ["name"] = "stones:brushrock_21"}, {["x"] = 6, ["param2"] = 1, ["y"] = 8, ["param1"] = 92, ["z"] = 3, ["name"] = "stones:brush"}, {["x"] = 6, ["param2"] = 3, ["y"] = 8, ["param1"] = 108, ["z"] = 4, ["name"] = "stones:brushrock_5"}, {["x"] = 6, ["param2"] = 14, ["y"] = 8, ["param1"] = 123, ["z"] = 5, ["name"] = "stones:brushrock_22"}, {["x"] = 6, ["param2"] = 11, ["y"] = 9, ["param1"] = 76, ["z"] = 1, ["name"] = "stones:panel"}, {["x"] = 6, ["param2"] = 12, ["y"] = 9, ["param1"] = 92, ["z"] = 2, ["name"] = "stones:sku_202"}, {["x"] = 6, ["param2"] = 16, ["y"] = 9, ["param1"] = 140, ["z"] = 5, ["name"] = "stones:s_222"}, {["x"] = 6, ["param2"] = 16, ["y"] = 9, ["param1"] = 156, ["z"] = 6, ["name"] = "stones:brushrock_527l"}, {["x"] = 6, ["param2"] = 18, ["y"] = 9, ["param1"] = 140, ["z"] = 7, ["name"] = "stones:brushrock_527r"}, {["x"] = 6, ["param2"] = 1, ["y"] = 9, ["param1"] = 125, ["z"] = 8, ["name"] = "stones:stair_half_r"}, {["x"] = 6, ["param2"] = 1, ["y"] = 10, ["param1"] = 141, ["z"] = 8, ["name"] = "stones:sku3_r"}, {["x"] = 7, ["param2"] = 17, ["y"] = 7, ["param1"] = 90, ["z"] = 3, ["name"] = "stones:s_2"}, {["x"] = 7, ["param2"] = 15, ["y"] = 8, ["param1"] = 92, ["z"] = 2, ["name"] = "stones:estruk"}, {["x"] = 7, ["param2"] = 3, ["y"] = 8, ["param1"] = 108, ["z"] = 3, ["name"] = "stones:stair_3"}, {["x"] = 7, ["param2"] = 14, ["y"] = 8, ["param1"] = 123, ["z"] = 4, ["name"] = "stones:s_52"}, {["x"] = 7, ["param2"] = 15, ["y"] = 9, ["param1"] = 108, ["z"] = 2, ["name"] = "stones:estruk"}, {["x"] = 7, ["param2"] = 11, ["y"] = 9, ["param1"] = 157, ["z"] = 5, ["name"] = "stones:s_252r"}, {["x"] = 7, ["y"] = 9, ["param1"] = 173, ["z"] = 6, ["name"] = "stones:brushrock_5"}, {["x"] = 7, ["y"] = 9, ["param1"] = 156, ["z"] = 7, ["name"] = "stones:brush"}, {["x"] = 7, ["param2"] = 4, ["y"] = 9, ["param1"] = 140, ["z"] = 8, ["name"] = "stones:roch"}, {["x"] = 7, ["param2"] = 6, ["y"] = 10, ["param1"] = 157, ["z"] = 8, ["name"] = "stones:panel"}, {["x"] = 8, ["param2"] = 17, ["y"] = 6, ["param1"] = 89, ["z"] = 2, ["name"] = "stones:s_52l"}, {["x"] = 8, ["param2"] = 17, ["y"] = 6, ["param1"] = 89, ["z"] = 3, ["name"] = "stones:s_2"}, {["x"] = 8, ["param2"] = 18, ["y"] = 6, ["param1"] = 106, ["z"] = 4, ["name"] = "stones:s_52"}, {["x"] = 8, ["param2"] = 13, ["y"] = 7, ["param1"] = 92, ["z"] = 2, ["name"] = "stones:sku2_l"}, {["x"] = 8, ["param2"] = 3, ["y"] = 7, ["param1"] = 108, ["z"] = 3, ["name"] = "stones:stair_3"}, {["x"] = 8, ["param2"] = 13, ["y"] = 8, ["param1"] = 108, ["z"] = 2, ["name"] = "stones:s_52l"}, {["x"] = 8, ["y"] = 9, ["param1"] = 189, ["z"] = 6, ["name"] = "stones:brushrock_4"}, {["x"] = 8, ["param2"] = 3, ["y"] = 9, ["param1"] = 173, ["z"] = 7, ["name"] = "stones:brush"}, {["x"] = 8, ["param2"] = 1, ["y"] = 9, ["param1"] = 157, ["z"] = 8, ["name"] = "stones:brushrock_21"}, {["x"] = 8, ["param2"] = 5, ["y"] = 9, ["param1"] = 140, ["z"] = 9, ["name"] = "stones:panel"}, {["x"] = 8, ["param2"] = 16, ["y"] = 10, ["param1"] = 174, ["z"] = 4, ["name"] = "stones:s_52"}, {["x"] = 8, ["param2"] = 16, ["y"] = 10, ["param1"] = 190, ["z"] = 5, ["name"] = "stones:s_52u"}, {["x"] = 8, ["param2"] = 6, ["y"] = 10, ["param1"] = 206, ["z"] = 6, ["name"] = "stones:s_252l"}, {["x"] = 8, ["param2"] = 18, ["y"] = 10, ["param1"] = 174, ["z"] = 8, ["name"] = "stones:sku_202"}, {["x"] = 8, ["param2"] = 5, ["y"] = 10, ["param1"] = 157, ["z"] = 9, ["name"] = "stones:panel"}, {["x"] = 9, ["param2"] = 9, ["y"] = 6, ["param1"] = 92, ["z"] = 1, ["name"] = "stones:s_22"}, {["x"] = 9, ["y"] = 6, ["param1"] = 92, ["z"] = 2, ["name"] = "stones:brushrock_21"}, {["x"] = 9, ["param2"] = 3, ["y"] = 6, ["param1"] = 108, ["z"] = 3, ["name"] = "stones:brush"}, {["x"] = 9, ["y"] = 6, ["param1"] = 123, ["z"] = 4, ["name"] = "stones:brushrock_2"}, {["x"] = 9, ["param2"] = 5, ["y"] = 6, ["param1"] = 138, ["z"] = 5, ["name"] = "stones:brushrock_22"}, {["x"] = 9, ["param2"] = 16, ["y"] = 9, ["param1"] = 157, ["z"] = 3, ["name"] = "stones:s_22r"}, {["x"] = 9, ["param2"] = 16, ["y"] = 9, ["param1"] = 173, ["z"] = 4, ["name"] = "stones:s_52ur"}, {["x"] = 9, ["param2"] = 20, ["y"] = 9, ["param1"] = 189, ["z"] = 5, ["name"] = "stones:roch"}, {["x"] = 9, ["param2"] = 6, ["y"] = 9, ["param1"] = 205, ["z"] = 6, ["name"] = "stones:s_21"}, {["x"] = 9, ["y"] = 9, ["param1"] = 189, ["z"] = 7, ["name"] = "stones:brushrock_5"}, {["x"] = 9, ["param2"] = 1, ["y"] = 9, ["param1"] = 174, ["z"] = 8, ["name"] = "stones:brush"}, {["x"] = 9, ["param2"] = 5, ["y"] = 9, ["param1"] = 157, ["z"] = 9, ["name"] = "stones:brushrock_52ul"}, {["x"] = 9, ["param2"] = 16, ["y"] = 10, ["param1"] = 174, ["z"] = 3, ["name"] = "stones:brushrock_22"}, {["x"] = 9, ["param2"] = 1, ["y"] = 10, ["param1"] = 190, ["z"] = 4, ["name"] = "stones:brushrock_5"}, {["x"] = 9, ["param2"] = 2, ["y"] = 10, ["param1"] = 206, ["z"] = 5, ["name"] = "stones:brushrock_5"}, {["x"] = 9, ["param2"] = 4, ["y"] = 10, ["param1"] = 222, ["z"] = 6, ["name"] = "runes:hui"}, {["x"] = 9, ["param2"] = 5, ["y"] = 10, ["param1"] = 172, ["z"] = 9, ["name"] = "stones:sku2_r"}, {["x"] = 9, ["y"] = 11, ["param1"] = 239, ["z"] = 6, ["name"] = "tool:dice"}, {["x"] = 10, ["param2"] = 9, ["y"] = 6, ["param1"] = 108, ["z"] = 1, ["name"] = "stones:brushrock_52ur"}, {["x"] = 10, ["param2"] = 2, ["y"] = 6, ["param1"] = 92, ["z"] = 2, ["name"] = "stones:brush"}, {["x"] = 10, ["param2"] = 3, ["y"] = 6, ["param1"] = 92, ["z"] = 3, ["name"] = "stones:brush"}, {["x"] = 10, ["param2"] = 2, ["y"] = 6, ["param1"] = 106, ["z"] = 4, ["name"] = "stones:brush"}, {["x"] = 10, ["y"] = 6, ["param1"] = 122, ["z"] = 5, ["name"] = "stones:brushrock_0"}, {["x"] = 10, ["param2"] = 17, ["y"] = 8, ["param1"] = 172, ["z"] = 6, ["name"] = "stones:s_52"}, {["x"] = 10, ["param2"] = 17, ["y"] = 8, ["param1"] = 156, ["z"] = 7, ["name"] = "stones:s_52r"}, {["x"] = 10, ["param2"] = 8, ["y"] = 9, ["param1"] = 140, ["z"] = 3, ["name"] = "stones:panel"}, {["x"] = 10, ["param2"] = 20, ["y"] = 9, ["param1"] = 157, ["z"] = 4, ["name"] = "stones:roch"}, {["x"] = 10, ["param2"] = 20, ["y"] = 9, ["param1"] = 173, ["z"] = 5, ["name"] = "stones:roch"}, {["x"] = 10, ["param2"] = 5, ["y"] = 9, ["param1"] = 189, ["z"] = 6, ["name"] = "stones:s_21"}, {["x"] = 10, ["param2"] = 2, ["y"] = 9, ["param1"] = 173, ["z"] = 7, ["name"] = "stones:brushrock_0"}, {["x"] = 10, ["param2"] = 1, ["y"] = 9, ["param1"] = 157, ["z"] = 8, ["name"] = "stones:brush"}, {["x"] = 10, ["y"] = 9, ["param1"] = 140, ["z"] = 9, ["name"] = "stones:brushrock_0"}, {["x"] = 10, ["param2"] = 2, ["y"] = 10, ["param1"] = 157, ["z"] = 3, ["name"] = "stones:brushrock_0"}, {["x"] = 10, ["param2"] = 2, ["y"] = 10, ["param1"] = 174, ["z"] = 4, ["name"] = "stones:brush"}, {["x"] = 10, ["param2"] = 3, ["y"] = 10, ["param1"] = 190, ["z"] = 5, ["name"] = "stones:brush"}, {["x"] = 10, ["param2"] = 2, ["y"] = 10, ["param1"] = 206, ["z"] = 6, ["name"] = "stones:stair_3"}, {["x"] = 10, ["param2"] = 8, ["y"] = 10, ["param1"] = 156, ["z"] = 9, ["name"] = "stones:panel"}, {["x"] = 11, ["param2"] = 2, ["y"] = 6, ["param1"] = 124, ["z"] = 1, ["name"] = "stones:brushrock_0"}, {["x"] = 11, ["param2"] = 3, ["y"] = 6, ["param1"] = 108, ["z"] = 2, ["name"] = "stones:brush"}, {["x"] = 11, ["param2"] = 2, ["y"] = 6, ["param1"] = 92, ["z"] = 3, ["name"] = "stones:brush"}, {["x"] = 11, ["y"] = 6, ["param1"] = 92, ["z"] = 4, ["name"] = "stones:brush"}, {["x"] = 11, ["param2"] = 1, ["y"] = 6, ["param1"] = 106, ["z"] = 5, ["name"] = "stones:brushrock_3"}, {["x"] = 11, ["param2"] = 2, ["y"] = 6, ["param1"] = 122, ["z"] = 6, ["name"] = "stones:cis"}, {["x"] = 11, ["param2"] = 9, ["y"] = 7, ["param1"] = 124, ["z"] = 5, ["name"] = "stones:s_52r"}, {["x"] = 11, ["param2"] = 2, ["y"] = 7, ["param1"] = 139, ["z"] = 6, ["name"] = "stones:cis"}, {["x"] = 11, ["y"] = 8, ["param1"] = 156, ["z"] = 6, ["name"] = "stones:s_52hul"}, {["x"] = 11, ["param2"] = 5, ["y"] = 8, ["param1"] = 140, ["z"] = 7, ["name"] = "stones:s_52u"}, {["x"] = 11, ["param2"] = 11, ["y"] = 9, ["param1"] = 124, ["z"] = 3, ["name"] = "stones:s_22r"}, {["x"] = 11, ["param2"] = 15, ["y"] = 9, ["param1"] = 140, ["z"] = 4, ["name"] = "stones:panel"}, {["x"] = 11, ["param2"] = 14, ["y"] = 9, ["param1"] = 157, ["z"] = 5, ["name"] = "stones:s_52r"}, {["x"] = 11, ["param2"] = 15, ["y"] = 9, ["param1"] = 173, ["z"] = 6, ["name"] = "stones:s_52"}, {["x"] = 11, ["param2"] = 2, ["y"] = 9, ["param1"] = 157, ["z"] = 7, ["name"] = "stones:brushrock_0"}, {["x"] = 11, ["param2"] = 3, ["y"] = 9, ["param1"] = 140, ["z"] = 8, ["name"] = "stones:brush"}, {["x"] = 11, ["param2"] = 1, ["y"] = 9, ["param1"] = 123, ["z"] = 9, ["name"] = "stones:brushrock_3"}, {["x"] = 11, ["param2"] = 16, ["y"] = 9, ["param1"] = 106, ["z"] = 10, ["name"] = "stones:s_52l"}, {["x"] = 11, ["param2"] = 11, ["y"] = 10, ["param1"] = 140, ["z"] = 3, ["name"] = "stones:brushrock_22"}, {["x"] = 11, ["param2"] = 1, ["y"] = 10, ["param1"] = 157, ["z"] = 4, ["name"] = "stones:brushrock_0"}, {["x"] = 11, ["param2"] = 14, ["y"] = 10, ["param1"] = 174, ["z"] = 5, ["name"] = "stones:brushrock_52ul"}, {["x"] = 11, ["param2"] = 14, ["y"] = 10, ["param1"] = 190, ["z"] = 6, ["name"] = "stones:diagstep"}, {["x"] = 11, ["param2"] = 17, ["y"] = 10, ["param1"] = 140, ["z"] = 9, ["name"] = "stones:stair_half_l"}, {["x"] = 11, ["param2"] = 14, ["y"] = 10, ["param1"] = 124, ["z"] = 10, ["name"] = "stones:sku2_l"}, {["x"] = 12, ["param2"] = 2, ["y"] = 6, ["param1"] = 140, ["z"] = 1, ["name"] = "stones:brushrock_0"}, {["x"] = 12, ["param2"] = 2, ["y"] = 6, ["param1"] = 124, ["z"] = 2, ["name"] = "stones:brush"}, {["x"] = 12, ["param2"] = 2, ["y"] = 6, ["param1"] = 108, ["z"] = 3, ["name"] = "stones:brush"}, {["x"] = 12, ["param2"] = 1, ["y"] = 6, ["param1"] = 92, ["z"] = 4, ["name"] = "stones:brushrock_2"}, {["x"] = 12, ["y"] = 6, ["param1"] = 91, ["z"] = 5, ["name"] = "stones:rock"}, {["x"] = 12, ["y"] = 6, ["param1"] = 106, ["z"] = 6, ["name"] = "stones:rock"}, {["x"] = 12, ["param2"] = 18, ["y"] = 6, ["param1"] = 89, ["z"] = 7, ["name"] = "stones:s_52r"}, {["x"] = 12, ["param2"] = 1, ["y"] = 7, ["param1"] = 108, ["z"] = 5, ["name"] = "stones:diagsteps_13"}, {["x"] = 12, ["param2"] = 1, ["y"] = 7, ["param1"] = 123, ["z"] = 6, ["name"] = "stones:rock"}, {["x"] = 12, ["param2"] = 9, ["y"] = 8, ["param1"] = 140, ["z"] = 6, ["name"] = "stones:s_52ur"}, {["x"] = 12, ["y"] = 8, ["param1"] = 123, ["z"] = 7, ["name"] = "stones:diagstep_7"}, {["x"] = 12, ["param2"] = 18, ["y"] = 8, ["param1"] = 106, ["z"] = 8, ["name"] = "stones:s_52r"}, {["x"] = 12, ["param2"] = 11, ["y"] = 9, ["param1"] = 140, ["z"] = 7, ["name"] = "stones:brushrock_22"}, {["x"] = 12, ["param2"] = 14, ["y"] = 9, ["param1"] = 124, ["z"] = 8, ["name"] = "stones:brushrock_527l"}, {["x"] = 12, ["param2"] = 3, ["y"] = 9, ["param1"] = 108, ["z"] = 9, ["name"] = "stones:diagsteps_52lh"}, {["x"] = 12, ["y"] = 9, ["param1"] = 92, ["z"] = 10, ["name"] = "stones:roch"}, {["x"] = 12, ["param2"] = 11, ["y"] = 10, ["param1"] = 140, ["z"] = 4, ["name"] = "stones:s_52"}, {["x"] = 12, ["param2"] = 5, ["y"] = 10, ["param1"] = 157, ["z"] = 5, ["name"] = "stones:s_52"}, {["x"] = 13, ["param2"] = 16, ["y"] = 5, ["param1"] = 72, ["z"] = 7, ["name"] = "stones:s_52l"}, {["x"] = 13, ["param2"] = 18, ["y"] = 5, ["param1"] = 55, ["z"] = 8, ["name"] = "stones:s_52r"}, {["x"] = 13, ["param2"] = 11, ["y"] = 6, ["param1"] = 156, ["z"] = 1, ["name"] = "stones:brushrock_22"}, {["x"] = 13, ["param2"] = 2, ["y"] = 6, ["param1"] = 140, ["z"] = 2, ["name"] = "stones:brushrock_2"}, {["x"] = 13, ["param2"] = 3, ["y"] = 6, ["param1"] = 124, ["z"] = 3, ["name"] = "stones:brushrock_5"}, {["x"] = 13, ["param2"] = 14, ["y"] = 6, ["param1"] = 108, ["z"] = 4, ["name"] = "stones:brushrock_22"}, {["x"] = 13, ["y"] = 6, ["param1"] = 90, ["z"] = 5, ["name"] = "stones:cis"}, {["x"] = 13, ["y"] = 6, ["param1"] = 90, ["z"] = 6, ["name"] = "stones:rock"}, {["x"] = 13, ["param2"] = 18, ["y"] = 6, ["param1"] = 73, ["z"] = 7, ["name"] = "stones:estruk"}, {["x"] = 13, ["param2"] = 18, ["y"] = 6, ["param1"] = 72, ["z"] = 8, ["name"] = "stones:s_52r"}, {["x"] = 13, ["y"] = 7, ["param1"] = 92, ["z"] = 5, ["name"] = "stones:cis"}, {["x"] = 13, ["y"] = 7, ["param1"] = 107, ["z"] = 6, ["name"] = "stones:rock"}, {["x"] = 13, ["param2"] = 9, ["y"] = 7, ["param1"] = 90, ["z"] = 7, ["name"] = "stones:estruk"}, {["x"] = 13, ["param2"] = 2, ["y"] = 7, ["param1"] = 73, ["z"] = 8, ["name"] = "stones:diagstep"}, {["x"] = 13, ["y"] = 8, ["param1"] = 108, ["z"] = 5, ["name"] = "stones:cis"}, {["x"] = 13, ["param2"] = 1, ["y"] = 8, ["param1"] = 123, ["z"] = 6, ["name"] = "stones:diagstep_7"}, {["x"] = 13, ["param2"] = 3, ["y"] = 8, ["param1"] = 106, ["z"] = 7, ["name"] = "stones:diagsteps"}, {["x"] = 13, ["param2"] = 18, ["y"] = 8, ["param1"] = 89, ["z"] = 8, ["name"] = "stones:estruk"}, {["x"] = 13, ["y"] = 9, ["param1"] = 124, ["z"] = 5, ["name"] = "stones:cis"}, {["x"] = 13, ["param2"] = 5, ["y"] = 9, ["param1"] = 140, ["z"] = 6, ["name"] = "stones:s_252r"}, {["x"] = 13, ["param2"] = 1, ["y"] = 9, ["param1"] = 123, ["z"] = 7, ["name"] = "stones:diagstep"}, {["x"] = 13, ["y"] = 9, ["param1"] = 106, ["z"] = 8, ["name"] = "stones:roch"}, {["x"] = 13, ["y"] = 9, ["param1"] = 90, ["z"] = 9, ["name"] = "stones:roch"}, {["x"] = 13, ["param2"] = 1, ["y"] = 9, ["param1"] = 75, ["z"] = 10, ["name"] = "stones:diagsteps_52lh"}, {["x"] = 13, ["y"] = 10, ["param1"] = 140, ["z"] = 5, ["name"] = "stones:cis"}, {["x"] = 13, ["param2"] = 5, ["y"] = 10, ["param1"] = 157, ["z"] = 6, ["name"] = "stones:s_52"}, {["x"] = 14, ["param2"] = 2, ["y"] = 3, ["param1"] = 204, ["z"] = 2, ["name"] = "stones:sku_202"}, {["x"] = 14, ["param2"] = 16, ["y"] = 3, ["param1"] = 187, ["z"] = 3, ["name"] = "stones:sku3_r"}, {["x"] = 14, ["param2"] = 12, ["y"] = 3, ["param1"] = 170, ["z"] = 4, ["name"] = "stones:sku_202"}, {["x"] = 14, ["param2"] = 8, ["y"] = 4, ["param1"] = 172, ["z"] = 1, ["name"] = "stones:s_52r"}, {["x"] = 14, ["param2"] = 4, ["y"] = 4, ["param1"] = 187, ["z"] = 2, ["name"] = "stones:s_52r"}, {["x"] = 14, ["y"] = 4, ["param1"] = 102, ["z"] = 7, ["name"] = "runes:nbdx4"}, {["x"] = 14, ["y"] = 4, ["param1"] = 86, ["z"] = 8, ["name"] = "runes:nbdx1"}, {["x"] = 14, ["param2"] = 4, ["y"] = 5, ["param1"] = 187, ["z"] = 1, ["name"] = "stones:sku2_r"}, {["x"] = 14, ["param2"] = 9, ["y"] = 5, ["param1"] = 104, ["z"] = 6, ["name"] = "stones:s_52r"}, {["x"] = 14, ["param2"] = 19, ["y"] = 5, ["param1"] = 87, ["z"] = 7, ["name"] = "stones:arsh"}, {["x"] = 14, ["param2"] = 4, ["y"] = 5, ["param1"] = 70, ["z"] = 8, ["name"] = "stones:arsh"}, {["x"] = 14, ["param2"] = 5, ["y"] = 5, ["param1"] = 87, ["z"] = 9, ["name"] = "stones:s_52l"}, {["x"] = 14, ["param2"] = 1, ["y"] = 6, ["param1"] = 188, ["z"] = 0, ["name"] = "stones:arsh"}, {["x"] = 14, ["param2"] = 4, ["y"] = 6, ["param1"] = 170, ["z"] = 1, ["name"] = "stones:s_52r"}, {["x"] = 14, ["param2"] = 12, ["y"] = 6, ["param1"] = 153, ["z"] = 2, ["name"] = "stones:s_52"}, {["x"] = 14, ["param2"] = 14, ["y"] = 6, ["param1"] = 140, ["z"] = 3, ["name"] = "stones:s_52"}, {["x"] = 14, ["param2"] = 11, ["y"] = 6, ["param1"] = 89, ["z"] = 6, ["name"] = "stones:s_52ul"}, {["x"] = 14, ["param2"] = 19, ["y"] = 6, ["param1"] = 72, ["z"] = 7, ["name"] = "stones:arsh"}, {["x"] = 14, ["param2"] = 4, ["y"] = 6, ["param1"] = 87, ["z"] = 8, ["name"] = "stones:arsh"}, {["x"] = 14, ["param2"] = 5, ["y"] = 6, ["param1"] = 104, ["z"] = 9, ["name"] = "stones:s_52l"}, {["x"] = 14, ["param2"] = 17, ["y"] = 7, ["param1"] = 172, ["z"] = 0, ["name"] = "stones:s_52u"}, {["x"] = 14, ["param2"] = 9, ["y"] = 7, ["param1"] = 92, ["z"] = 6, ["name"] = "stones:s_52r"}, {["x"] = 14, ["param2"] = 19, ["y"] = 7, ["param1"] = 73, ["z"] = 7, ["name"] = "stones:arsh"}, {["x"] = 14, ["param2"] = 4, ["y"] = 7, ["param1"] = 72, ["z"] = 8, ["name"] = "stones:arsh"}, {["x"] = 14, ["param2"] = 5, ["y"] = 7, ["param1"] = 89, ["z"] = 9, ["name"] = "stones:s_52l"}, {["x"] = 14, ["param2"] = 3, ["y"] = 8, ["param1"] = 156, ["z"] = 0, ["name"] = "stones:plot"}, {["x"] = 14, ["param2"] = 11, ["y"] = 8, ["param1"] = 108, ["z"] = 6, ["name"] = "stones:s_52ul"}, {["x"] = 14, ["param2"] = 19, ["y"] = 8, ["param1"] = 89, ["z"] = 7, ["name"] = "stones:arsh"}, {["x"] = 14, ["param2"] = 4, ["y"] = 8, ["param1"] = 73, ["z"] = 8, ["name"] = "stones:arsh"}, {["x"] = 14, ["param2"] = 5, ["y"] = 8, ["param1"] = 74, ["z"] = 9, ["name"] = "stones:s_52l"}, {["x"] = 14, ["param2"] = 4, ["y"] = 9, ["param1"] = 143, ["z"] = 0, ["name"] = "stones:shrub"}, {["x"] = 14, ["param2"] = 9, ["y"] = 9, ["param1"] = 108, ["z"] = 5, ["name"] = "stones:s_52l"}, {["x"] = 14, ["param2"] = 2, ["y"] = 9, ["param1"] = 123, ["z"] = 6, ["name"] = "stones:diagsteps_52rh"}, {["x"] = 14, ["param2"] = 19, ["y"] = 9, ["param1"] = 106, ["z"] = 7, ["name"] = "stones:arsh"}, {["x"] = 14, ["param2"] = 4, ["y"] = 9, ["param1"] = 90, ["z"] = 8, ["name"] = "stones:arsh"}, {["x"] = 14, ["param2"] = 7, ["y"] = 9, ["param1"] = 75, ["z"] = 9, ["name"] = "stones:s_52ur"}, {["x"] = 14, ["param2"] = 3, ["y"] = 9, ["param1"] = 76, ["z"] = 10, ["name"] = "stones:brushrock_3"}, {["x"] = 14, ["param2"] = 9, ["y"] = 10, ["param1"] = 124, ["z"] = 5, ["name"] = "stones:s_52l"}, {["x"] = 14, ["param2"] = 7, ["y"] = 10, ["param1"] = 140, ["z"] = 6, ["name"] = "stones:s_52l"}, {["x"] = 14, ["param2"] = 9, ["y"] = 10, ["param1"] = 108, ["z"] = 8, ["name"] = "stones:s_22r"}, {["x"] = 14, ["param2"] = 14, ["y"] = 10, ["param1"] = 92, ["z"] = 9, ["name"] = "stones:sku2_l"}, {["x"] = 14, ["param2"] = 21, ["y"] = 10, ["param1"] = 77, ["z"] = 10, ["name"] = "stones:stair_half_r"}, {["x"] = 15, ["param2"] = 8, ["y"] = 3, ["param1"] = 170, ["z"] = 3, ["name"] = "stones:s_22r"}, {["x"] = 15, ["param2"] = 9, ["y"] = 3, ["param1"] = 153, ["z"] = 4, ["name"] = "stones:sku_202"}, {["x"] = 15, ["param2"] = 20, ["y"] = 4, ["param1"] = 170, ["z"] = 2, ["name"] = "stones:s_52l"}, {["x"] = 15, ["param2"] = 4, ["y"] = 4, ["param1"] = 153, ["z"] = 3, ["name"] = "stones:s_52ur"}, {["x"] = 15, ["y"] = 4, ["param1"] = 85, ["z"] = 7, ["name"] = "runes:nbdx3"}, {["x"] = 15, ["y"] = 4, ["param1"] = 85, ["z"] = 8, ["name"] = "runes:nbdx2"}, {["x"] = 15, ["param2"] = 8, ["y"] = 5, ["param1"] = 172, ["z"] = 1, ["name"] = "stones:s_52r"}, {["x"] = 15, ["param2"] = 23, ["y"] = 5, ["param1"] = 153, ["z"] = 2, ["name"] = "stones:arsh"}, {["x"] = 15, ["param2"] = 6, ["y"] = 5, ["param1"] = 136, ["z"] = 3, ["name"] = "stones:skud_202r"}, {["x"] = 15, ["param2"] = 6, ["y"] = 5, ["param1"] = 119, ["z"] = 4, ["name"] = "stones:s_22r"}, {["x"] = 15, ["param2"] = 16, ["y"] = 5, ["param1"] = 103, ["z"] = 5, ["name"] = "stones:s_52r"}, {["x"] = 15, ["param2"] = 9, ["y"] = 5, ["param1"] = 87, ["z"] = 6, ["name"] = "stones:s_52ur"}, {["x"] = 15, ["param2"] = 10, ["y"] = 5, ["param1"] = 70, ["z"] = 7, ["name"] = "stones:arsh"}, {["x"] = 15, ["param2"] = 13, ["y"] = 5, ["param1"] = 85, ["z"] = 8, ["name"] = "stones:arsh"}, {["x"] = 15, ["param2"] = 1, ["y"] = 5, ["param1"] = 102, ["z"] = 9, ["name"] = "stones:stair_half_r"}, {["x"] = 15, ["param2"] = 10, ["y"] = 6, ["param1"] = 156, ["z"] = 1, ["name"] = "stones:s_52l"}, {["x"] = 15, ["param2"] = 9, ["y"] = 6, ["param1"] = 137, ["z"] = 2, ["name"] = "stones:arsh"}, {["x"] = 15, ["param2"] = 6, ["y"] = 6, ["param1"] = 105, ["z"] = 4, ["name"] = "stones:sku3_l"}, {["x"] = 15, ["param2"] = 16, ["y"] = 6, ["param1"] = 89, ["z"] = 5, ["name"] = "stones:s_52l"}, {["x"] = 15, ["param2"] = 16, ["y"] = 6, ["param1"] = 71, ["z"] = 6, ["name"] = "stones:sku_202"}, {["x"] = 15, ["param2"] = 13, ["y"] = 6, ["param1"] = 102, ["z"] = 8, ["name"] = "stones:arsh"}, {["x"] = 15, ["param2"] = 19, ["y"] = 6, ["param1"] = 119, ["z"] = 9, ["name"] = "stones:stair_half_l"}, {["x"] = 15, ["param2"] = 17, ["y"] = 7, ["param1"] = 124, ["z"] = 2, ["name"] = "stones:s_52u"}, {["x"] = 15, ["param2"] = 19, ["y"] = 7, ["param1"] = 92, ["z"] = 4, ["name"] = "stones:s_22r"}, {["x"] = 15, ["param2"] = 16, ["y"] = 7, ["param1"] = 76, ["z"] = 5, ["name"] = "stones:s_52l"}, {["x"] = 15, ["param2"] = 16, ["y"] = 7, ["param1"] = 73, ["z"] = 6, ["name"] = "stones:sku_202"}, {["x"] = 15, ["param2"] = 13, ["y"] = 7, ["param1"] = 87, ["z"] = 8, ["name"] = "stones:arsh"}, {["x"] = 15, ["param2"] = 19, ["y"] = 7, ["param1"] = 104, ["z"] = 9, ["name"] = "stones:stair_half_l"}, {["x"] = 15, ["y"] = 8, ["param1"] = 108, ["z"] = 2, ["name"] = "stones:plot"}, {["x"] = 15, ["param2"] = 11, ["y"] = 8, ["param1"] = 89, ["z"] = 6, ["name"] = "stones:s_52l"}, {["x"] = 15, ["param2"] = 10, ["y"] = 8, ["param1"] = 71, ["z"] = 7, ["name"] = "stones:arsh"}, {["x"] = 15, ["param2"] = 1, ["y"] = 8, ["param1"] = 89, ["z"] = 9, ["name"] = "stones:stair_half_r"}, {["x"] = 15, ["param2"] = 4, ["y"] = 9, ["param1"] = 95, ["z"] = 2, ["name"] = "stones:shrub"}, {["x"] = 15, ["param2"] = 3, ["y"] = 9, ["param1"] = 92, ["z"] = 5, ["name"] = "stones:sku2_r"}, {["x"] = 15, ["y"] = 9, ["param1"] = 106, ["z"] = 6, ["name"] = "stones:roch"}, {["x"] = 15, ["param2"] = 10, ["y"] = 9, ["param1"] = 89, ["z"] = 7, ["name"] = "stones:arsh"}, {["x"] = 15, ["param2"] = 4, ["y"] = 9, ["param1"] = 74, ["z"] = 9, ["name"] = "stones:panel"}, {["x"] = 15, ["param2"] = 11, ["y"] = 9, ["param1"] = 91, ["z"] = 10, ["name"] = "stones:brushrock_52ul"}, {["x"] = 15, ["param2"] = 3, ["y"] = 10, ["param1"] = 108, ["z"] = 5, ["name"] = "stones:sku2_r"}, {["x"] = 15, ["param2"] = 7, ["y"] = 10, ["param1"] = 92, ["z"] = 8, ["name"] = "stones:sku2_r"}, {["x"] = 15, ["param2"] = 5, ["y"] = 10, ["param1"] = 76, ["z"] = 10, ["name"] = "stones:sku2_r"}, {["x"] = 16, ["param2"] = 23, ["y"] = 3, ["param1"] = 153, ["z"] = 3, ["name"] = "stones:s_52l"}, {["x"] = 16, ["param2"] = 3, ["y"] = 4, ["param1"] = 136, ["z"] = 3, ["name"] = "stones:s_52l"}, {["x"] = 16, ["param2"] = 9, ["y"] = 5, ["param1"] = 103, ["z"] = 4, ["name"] = "stones:s_52l"}, {["x"] = 16, ["param2"] = 20, ["y"] = 5, ["param1"] = 86, ["z"] = 5, ["name"] = "stones:roch"}, {["x"] = 16, ["param2"] = 2, ["y"] = 5, ["param1"] = 70, ["z"] = 6, ["name"] = "stones:diagsteps"}, {["x"] = 16, ["param2"] = 14, ["y"] = 5, ["param1"] = 85, ["z"] = 7, ["name"] = "stones:s_52ul"}, {["x"] = 16, ["param2"] = 14, ["y"] = 5, ["param1"] = 102, ["z"] = 8, ["name"] = "stones:s_52l"}, {["x"] = 16, ["param2"] = 16, ["y"] = 6, ["param1"] = 108, ["z"] = 3, ["name"] = "stones:s_22r"}, {["x"] = 16, ["param2"] = 14, ["y"] = 6, ["param1"] = 89, ["z"] = 4, ["name"] = "stones:sku3_r"}, {["x"] = 16, ["param2"] = 14, ["y"] = 6, ["param1"] = 71, ["z"] = 5, ["name"] = "stones:s_52l"}, {["x"] = 16, ["param2"] = 14, ["y"] = 6, ["param1"] = 102, ["z"] = 7, ["name"] = "stones:skud_202r"}, {["x"] = 16, ["param2"] = 14, ["y"] = 6, ["param1"] = 119, ["z"] = 8, ["name"] = "stones:s_52l"}, {["x"] = 16, ["param2"] = 12, ["y"] = 7, ["param1"] = 76, ["z"] = 4, ["name"] = "stones:s_22r"}, {["x"] = 16, ["param2"] = 14, ["y"] = 7, ["param1"] = 57, ["z"] = 5, ["name"] = "stones:s_52l"}, {["x"] = 16, ["param2"] = 9, ["y"] = 7, ["param1"] = 86, ["z"] = 7, ["name"] = "stones:s_52l"}, {["x"] = 16, ["param2"] = 15, ["y"] = 7, ["param1"] = 102, ["z"] = 8, ["name"] = "stones:stair_2"}, {["x"] = 16, ["param2"] = 21, ["y"] = 7, ["param1"] = 119, ["z"] = 9, ["name"] = "stones:stair_half_r"}, {["x"] = 16, ["param2"] = 7, ["y"] = 8, ["param1"] = 71, ["z"] = 7, ["name"] = "stones:s_52ur"}, {["x"] = 16, ["param2"] = 5, ["y"] = 8, ["param1"] = 104, ["z"] = 9, ["name"] = "stones:sku2_l"}, {["x"] = 16, ["y"] = 9, ["param1"] = 73, ["z"] = 5, ["name"] = "stones:panel"}, {["x"] = 16, ["param2"] = 2, ["y"] = 9, ["param1"] = 89, ["z"] = 6, ["name"] = "stones:roch"}, {["x"] = 16, ["param2"] = 7, ["y"] = 9, ["param1"] = 73, ["z"] = 7, ["name"] = "stones:s_52ur"}, {["x"] = 16, ["param2"] = 5, ["y"] = 9, ["param1"] = 89, ["z"] = 9, ["name"] = "stones:sku2_l"}, {["x"] = 16, ["param2"] = 11, ["y"] = 9, ["param1"] = 106, ["z"] = 10, ["name"] = "stones:panel"}, {["x"] = 16, ["param2"] = 7, ["y"] = 10, ["param1"] = 92, ["z"] = 5, ["name"] = "stones:sku2_r"}, {["x"] = 16, ["param2"] = 9, ["y"] = 10, ["param1"] = 92, ["z"] = 7, ["name"] = "stones:s_52r"}, {["x"] = 16, ["param2"] = 7, ["y"] = 10, ["param1"] = 76, ["z"] = 8, ["name"] = "stones:s_52r"}, {["x"] = 16, ["param2"] = 11, ["y"] = 10, ["param1"] = 92, ["z"] = 10, ["name"] = "stones:panel"}, {["x"] = 17, ["param2"] = 20, ["y"] = 3, ["param1"] = 153, ["z"] = 2, ["name"] = "stones:s_22r"}, {["x"] = 17, ["param2"] = 14, ["y"] = 3, ["param1"] = 136, ["z"] = 3, ["name"] = "stones:s_22r"}, {["x"] = 17, ["param2"] = 20, ["y"] = 4, ["param1"] = 124, ["z"] = 1, ["name"] = "stones:s_52r"}, {["x"] = 17, ["param2"] = 8, ["y"] = 4, ["param1"] = 137, ["z"] = 2, ["name"] = "stones:sku_202"}, {["x"] = 17, ["param2"] = 12, ["y"] = 5, ["param1"] = 156, ["z"] = 0, ["name"] = "stones:diagstep"}, {["x"] = 17, ["param2"] = 11, ["y"] = 5, ["param1"] = 137, ["z"] = 1, ["name"] = "stones:arsh"}, {["x"] = 17, ["param2"] = 16, ["y"] = 5, ["param1"] = 105, ["z"] = 3, ["name"] = "stones:s_22r"}, {["x"] = 17, ["param2"] = 23, ["y"] = 5, ["param1"] = 87, ["z"] = 4, ["name"] = "stones:s_221"}, {["x"] = 17, ["param2"] = 20, ["y"] = 5, ["param1"] = 70, ["z"] = 5, ["name"] = "stones:roch"}, {["x"] = 17, ["param2"] = 22, ["y"] = 5, ["param1"] = 85, ["z"] = 6, ["name"] = "stones:diagstep"}, {["x"] = 17, ["param2"] = 15, ["y"] = 6, ["param1"] = 140, ["z"] = 0, ["name"] = "stones:s_52u"}, {["x"] = 17, ["param2"] = 16, ["y"] = 6, ["param1"] = 108, ["z"] = 2, ["name"] = "stones:s_22r"}, {["x"] = 17, ["param2"] = 9, ["y"] = 6, ["param1"] = 92, ["z"] = 3, ["name"] = "stones:sku_202"}, {["x"] = 17, ["param2"] = 7, ["y"] = 6, ["param1"] = 102, ["z"] = 6, ["name"] = "stones:sku_202"}, {["x"] = 17, ["param2"] = 14, ["y"] = 6, ["param1"] = 119, ["z"] = 7, ["name"] = "stones:s_22r"}, {["x"] = 17, ["param2"] = 3, ["y"] = 7, ["param1"] = 124, ["z"] = 0, ["name"] = "stones:plot"}, {["x"] = 17, ["param2"] = 11, ["y"] = 7, ["param1"] = 102, ["z"] = 7, ["name"] = "stones:s_52r"}, {["x"] = 17, ["param2"] = 20, ["y"] = 7, ["param1"] = 119, ["z"] = 8, ["name"] = "stones:roch"}, {["x"] = 17, ["param2"] = 5, ["y"] = 7, ["param1"] = 136, ["z"] = 9, ["name"] = "stones:s_52ur"}, {["x"] = 17, ["param2"] = 4, ["y"] = 8, ["param1"] = 111, ["z"] = 0, ["name"] = "stones:shrub"}, {["x"] = 17, ["param2"] = 5, ["y"] = 8, ["param1"] = 87, ["z"] = 7, ["name"] = "stones:sku2_l"}, {["x"] = 17, ["param2"] = 11, ["y"] = 8, ["param1"] = 121, ["z"] = 9, ["name"] = "stones:s_52l"}, {["x"] = 17, ["param2"] = 5, ["y"] = 8, ["param1"] = 137, ["z"] = 10, ["name"] = "stones:s_52l"}, {["x"] = 17, ["param2"] = 9, ["y"] = 9, ["param1"] = 57, ["z"] = 5, ["name"] = "stones:s_52ur"}, {["x"] = 17, ["param2"] = 3, ["y"] = 9, ["param1"] = 73, ["z"] = 6, ["name"] = "stones:roch"}, {["x"] = 17, ["param2"] = 5, ["y"] = 9, ["param1"] = 73, ["z"] = 7, ["name"] = "stones:s_52ul"}, {["x"] = 17, ["param2"] = 11, ["y"] = 9, ["param1"] = 108, ["z"] = 9, ["name"] = "stones:s_52l"}, {["x"] = 17, ["param2"] = 5, ["y"] = 9, ["param1"] = 124, ["z"] = 10, ["name"] = "stones:s_52l"}, {["x"] = 17, ["param2"] = 9, ["y"] = 10, ["param1"] = 60, ["z"] = 4, ["name"] = "stones:s_52r"}, {["x"] = 17, ["param2"] = 7, ["y"] = 10, ["param1"] = 76, ["z"] = 5, ["name"] = "stones:s_52r"}, {["x"] = 17, ["param2"] = 7, ["y"] = 10, ["param1"] = 76, ["z"] = 7, ["name"] = "stones:sku2_r"}, {["x"] = 18, ["param2"] = 16, ["y"] = 5, ["param1"] = 105, ["z"] = 2, ["name"] = "stones:s_52r"}, {["x"] = 18, ["param2"] = 23, ["y"] = 5, ["param1"] = 89, ["z"] = 3, ["name"] = "stones:s_221"}, {["x"] = 18, ["param2"] = 21, ["y"] = 5, ["param1"] = 71, ["z"] = 4, ["name"] = "stones:roch"}, {["x"] = 18, ["param2"] = 7, ["y"] = 5, ["param1"] = 86, ["z"] = 5, ["name"] = "stones:s_52ul"}, {["x"] = 18, ["param2"] = 16, ["y"] = 6, ["param1"] = 108, ["z"] = 1, ["name"] = "stones:s_22r"}, {["x"] = 18, ["param2"] = 9, ["y"] = 6, ["param1"] = 92, ["z"] = 2, ["name"] = "stones:sku_202"}, {["x"] = 18, ["param2"] = 7, ["y"] = 6, ["param1"] = 103, ["z"] = 5, ["name"] = "stones:sku_202"}, {["x"] = 18, ["param2"] = 14, ["y"] = 6, ["param1"] = 119, ["z"] = 6, ["name"] = "stones:s_22r"}, {["x"] = 18, ["param2"] = 11, ["y"] = 7, ["param1"] = 136, ["z"] = 8, ["name"] = "stones:s_52ur"}, {["x"] = 18, ["param2"] = 20, ["y"] = 7, ["param1"] = 153, ["z"] = 9, ["name"] = "stones:roch"}, {["x"] = 18, ["param2"] = 5, ["y"] = 7, ["param1"] = 170, ["z"] = 10, ["name"] = "stones:s_52r"}, {["x"] = 18, ["param2"] = 11, ["y"] = 8, ["param1"] = 103, ["z"] = 7, ["name"] = "stones:s_52l"}, {["x"] = 18, ["param2"] = 5, ["y"] = 8, ["param1"] = 121, ["z"] = 8, ["name"] = "stones:s_52l"}, {["x"] = 18, ["param2"] = 5, ["y"] = 8, ["param1"] = 153, ["z"] = 10, ["name"] = "stones:sku2_l"}, {["x"] = 18, ["param2"] = 9, ["y"] = 9, ["param1"] = 41, ["z"] = 4, ["name"] = "stones:s_52r"}, {["x"] = 18, ["param2"] = 3, ["y"] = 9, ["param1"] = 57, ["z"] = 5, ["name"] = "stones:roch"}, {["x"] = 18, ["param2"] = 7, ["y"] = 9, ["param1"] = 73, ["z"] = 6, ["name"] = "stones:s_52ur"}, {["x"] = 18, ["param2"] = 11, ["y"] = 9, ["param1"] = 89, ["z"] = 7, ["name"] = "stones:s_52l"}, {["x"] = 18, ["param2"] = 5, ["y"] = 9, ["param1"] = 108, ["z"] = 8, ["name"] = "stones:s_52l"}, {["x"] = 18, ["param2"] = 5, ["y"] = 9, ["param1"] = 140, ["z"] = 10, ["name"] = "stones:sku2_l"}, {["x"] = 18, ["param2"] = 7, ["y"] = 10, ["param1"] = 44, ["z"] = 4, ["name"] = "stones:sku2_r"}, {["x"] = 18, ["param2"] = 9, ["y"] = 10, ["param1"] = 76, ["z"] = 6, ["name"] = "stones:s_52r"}, {["x"] = 18, ["param2"] = 7, ["y"] = 10, ["param1"] = 76, ["z"] = 7, ["name"] = "stones:s_52r"}}