5:return {{["x"] = 0, ["param2"] = 11, ["y"] = 7, ["param1"] = 121, ["z"] = 1, ["name"] = "stones:s_52r"}, {["x"] = 0, ["param2"] = 20, ["y"] = 7, ["param1"] = 137, ["z"] = 2, ["name"] = "stones:roch"}, {["x"] = 0, ["param2"] = 5, ["y"] = 7, ["param1"] = 153, ["z"] = 3, ["name"] = "stones:s_52ur"}, {["x"] = 0, ["param2"] = 5, ["y"] = 8, ["param1"] = 105, ["z"] = 1, ["name"] = "stones:sku2_l"}, {["x"] = 0, ["param2"] = 11, ["y"] = 8, ["param1"] = 137, ["z"] = 3, ["name"] = "stones:s_52l"}, {["x"] = 0, ["param2"] = 5, ["y"] = 8, ["param1"] = 153, ["z"] = 4, ["name"] = "stones:s_52l"}, {["x"] = 0, ["param2"] = 5, ["y"] = 9, ["param1"] = 92, ["z"] = 1, ["name"] = "stones:sku2_l"}, {["x"] = 0, ["param2"] = 11, ["y"] = 9, ["param1"] = 124, ["z"] = 3, ["name"] = "stones:s_52l"}, {["x"] = 0, ["param2"] = 5, ["y"] = 9, ["param1"] = 140, ["z"] = 4, ["name"] = "stones:s_52l"}, {["x"] = 1, ["param2"] = 11, ["y"] = 7, ["param1"] = 124, ["z"] = 2, ["name"] = "stones:s_52ur"}, {["x"] = 1, ["param2"] = 20, ["y"] = 7, ["param1"] = 137, ["z"] = 3, ["name"] = "stones:roch"}, {["x"] = 1, ["param2"] = 5, ["y"] = 7, ["param1"] = 153, ["z"] = 4, ["name"] = "stones:s_52r"}, {["x"] = 1, ["param2"] = 11, ["y"] = 8, ["param1"] = 92, ["z"] = 1, ["name"] = "stones:s_52l"}, {["x"] = 1, ["param2"] = 5, ["y"] = 8, ["param1"] = 105, ["z"] = 2, ["name"] = "stones:s_52l"}, {["x"] = 1, ["param2"] = 5, ["y"] = 8, ["param1"] = 137, ["z"] = 4, ["name"] = "stones:sku2_l"}, {["x"] = 1, ["param2"] = 11, ["y"] = 9, ["param1"] = 76, ["z"] = 1, ["name"] = "stones:s_52l"}, {["x"] = 1, ["param2"] = 5, ["y"] = 9, ["param1"] = 92, ["z"] = 2, ["name"] = "stones:s_52l"}, {["x"] = 1, ["param2"] = 5, ["y"] = 9, ["param1"] = 124, ["z"] = 4, ["name"] = "stones:sku2_l"}, {["x"] = 2, ["param2"] = 11, ["y"] = 7, ["param1"] = 108, ["z"] = 2, ["name"] = "stones:s_52r"}, {["x"] = 2, ["param2"] = 20, ["y"] = 7, ["param1"] = 121, ["z"] = 3, ["name"] = "stones:roch"}, {["x"] = 2, ["param2"] = 5, ["y"] = 7, ["param1"] = 136, ["z"] = 4, ["name"] = "stones:s_52ur"}, {["x"] = 2, ["param2"] = 5, ["y"] = 8, ["param1"] = 92, ["z"] = 2, ["name"] = "stones:sku2_l"}, {["x"] = 2, ["param2"] = 11, ["y"] = 8, ["param1"] = 121, ["z"] = 4, ["name"] = "stones:s_52l"}, {["x"] = 2, ["param2"] = 5, ["y"] = 8, ["param1"] = 137, ["z"] = 5, ["name"] = "stones:s_52l"}, {["x"] = 2, ["param2"] = 5, ["y"] = 9, ["param1"] = 76, ["z"] = 2, ["name"] = "stones:sku2_l"}, {["x"] = 2, ["param2"] = 11, ["y"] = 9, ["param1"] = 108, ["z"] = 4, ["name"] = "stones:s_52l"}, {["x"] = 2, ["param2"] = 5, ["y"] = 9, ["param1"] = 124, ["z"] = 5, ["name"] = "stones:s_52l"}, {["x"] = 3, ["param2"] = 11, ["y"] = 7, ["param1"] = 92, ["z"] = 2, ["name"] = "stones:s_52r"}, {["x"] = 3, ["param2"] = 20, ["y"] = 7, ["param1"] = 108, ["z"] = 3, ["name"] = "stones:roch"}, {["x"] = 3, ["param2"] = 20, ["y"] = 7, ["param1"] = 121, ["z"] = 4, ["name"] = "stones:roch"}, {["x"] = 3, ["param2"] = 5, ["y"] = 7, ["param1"] = 136, ["z"] = 5, ["name"] = "stones:s_52r"}, {["x"] = 3, ["param2"] = 11, ["y"] = 8, ["param1"] = 76, ["z"] = 2, ["name"] = "stones:s_52"}, {["x"] = 3, ["param2"] = 5, ["y"] = 8, ["param1"] = 89, ["z"] = 3, ["name"] = "stones:s_52"}, {["x"] = 3, ["param2"] = 5, ["y"] = 8, ["param1"] = 121, ["z"] = 5, ["name"] = "stones:sku2_l"}, {["x"] = 3, ["param2"] = 11, ["y"] = 9, ["param1"] = 60, ["z"] = 2, ["name"] = "stones:s_52l"}, {["x"] = 3, ["param2"] = 5, ["y"] = 9, ["param1"] = 76, ["z"] = 3, ["name"] = "stones:s_52l"}, {["x"] = 3, ["param2"] = 5, ["y"] = 9, ["param1"] = 108, ["z"] = 5, ["name"] = "stones:sku2_l"}, {["x"] = 4, ["param2"] = 11, ["y"] = 7, ["param1"] = 92, ["z"] = 3, ["name"] = "stones:s_52r"}, {["x"] = 4, ["param2"] = 20, ["y"] = 7, ["param1"] = 105, ["z"] = 4, ["name"] = "stones:roch"}, {["x"] = 4, ["param2"] = 5, ["y"] = 7, ["param1"] = 119, ["z"] = 5, ["name"] = "stones:s_52ur"}, {["x"] = 4, ["param2"] = 5, ["y"] = 8, ["param1"] = 76, ["z"] = 3, ["name"] = "stones:sku2_r"}, {["x"] = 4, ["param2"] = 11, ["y"] = 8, ["param1"] = 105, ["z"] = 5, ["name"] = "stones:s_52l"}, {["x"] = 4, ["param2"] = 5, ["y"] = 8, ["param1"] = 89, ["z"] = 6, ["name"] = "stones:s_52l"}, {["x"] = 4, ["param2"] = 11, ["y"] = 9, ["param1"] = 92, ["z"] = 5, ["name"] = "stones:s_52l"}, {["x"] = 4, ["param2"] = 5, ["y"] = 9, ["param1"] = 76, ["z"] = 6, ["name"] = "stones:s_52l"}, {["x"] = 5, ["param2"] = 11, ["y"] = 7, ["param1"] = 76, ["z"] = 3, ["name"] = "stones:s_52r"}, {["x"] = 5, ["param2"] = 21, ["y"] = 7, ["param1"] = 92, ["z"] = 4, ["name"] = "stones:roch"}, {["x"] = 5, ["param2"] = 20, ["y"] = 7, ["param1"] = 105, ["z"] = 5, ["name"] = "stones:roch"}, {["x"] = 5, ["param2"] = 5, ["y"] = 7, ["param1"] = 87, ["z"] = 6, ["name"] = "stones:s_52r"}, {["x"] = 5, ["param2"] = 11, ["y"] = 8, ["param1"] = 60, ["z"] = 3, ["name"] = "stones:s_52"}, {["x"] = 5, ["param2"] = 5, ["y"] = 8, ["param1"] = 73, ["z"] = 4, ["name"] = "stones:s_52"}, {["x"] = 5, ["param2"] = 5, ["y"] = 8, ["param1"] = 73, ["z"] = 6, ["name"] = "stones:sku2_l"}, {["x"] = 5, ["param2"] = 11, ["y"] = 9, ["param1"] = 44, ["z"] = 3, ["name"] = "stones:s_52l"}, {["x"] = 5, ["param2"] = 5, ["y"] = 9, ["param1"] = 60, ["z"] = 4, ["name"] = "stones:s_52l"}, {["x"] = 5, ["param2"] = 5, ["y"] = 9, ["param1"] = 60, ["z"] = 6, ["name"] = "stones:sku2_l"}, {["x"] = 6, ["param2"] = 11, ["y"] = 7, ["param1"] = 76, ["z"] = 4, ["name"] = "stones:s_52r"}, {["x"] = 6, ["param2"] = 20, ["y"] = 7, ["param1"] = 89, ["z"] = 5, ["name"] = "stones:roch"}, {["x"] = 6, ["param2"] = 5, ["y"] = 7, ["param1"] = 71, ["z"] = 6, ["name"] = "stones:s_52ur"}, {["x"] = 6, ["param2"] = 5, ["y"] = 8, ["param1"] = 60, ["z"] = 4, ["name"] = "stones:sku2_l"}, {["x"] = 6, ["param2"] = 11, ["y"] = 8, ["param1"] = 57, ["z"] = 6, ["name"] = "stones:s_52l"}, {["x"] = 6, ["param2"] = 5, ["y"] = 8, ["param1"] = 41, ["z"] = 7, ["name"] = "stones:s_52l"}, {["x"] = 6, ["param2"] = 5, ["y"] = 9, ["param1"] = 44, ["z"] = 4, ["name"] = "stones:sku2_l"}, {["x"] = 6, ["param2"] = 11, ["y"] = 9, ["param1"] = 44, ["z"] = 6, ["name"] = "stones:s_52l"}, {["x"] = 6, ["param2"] = 5, ["y"] = 9, ["param1"] = 28, ["z"] = 7, ["name"] = "stones:s_52l"}, {["x"] = 7, ["param2"] = 11, ["y"] = 7, ["param1"] = 76, ["z"] = 5, ["name"] = "stones:s_52ur"}, {["x"] = 7, ["param2"] = 20, ["y"] = 7, ["param1"] = 57, ["z"] = 6, ["name"] = "stones:roch"}, {["x"] = 7, ["param2"] = 5, ["y"] = 7, ["param1"] = 41, ["z"] = 7, ["name"] = "stones:s_52ur"}, {["x"] = 7, ["param2"] = 11, ["y"] = 8, ["param1"] = 76, ["z"] = 4, ["name"] = "stones:s_52l"}, {["x"] = 7, ["param2"] = 5, ["y"] = 8, ["param1"] = 57, ["z"] = 5, ["name"] = "stones:s_52l"}, {["x"] = 7, ["param2"] = 5, ["y"] = 8, ["param1"] = 25, ["z"] = 7, ["name"] = "stones:sku"}, {["x"] = 7, ["param2"] = 11, ["y"] = 9, ["param1"] = 60, ["z"] = 4, ["name"] = "stones:s_52l"}, {["x"] = 7, ["param2"] = 5, ["y"] = 9, ["param1"] = 44, ["z"] = 5, ["name"] = "stones:s_52l"}, {["x"] = 7, ["param2"] = 5, ["y"] = 9, ["param1"] = 12, ["z"] = 7, ["name"] = "stones:sku2_l"}, {["x"] = 8, ["param2"] = 11, ["y"] = 7, ["param1"] = 92, ["z"] = 5, ["name"] = "stones:s_52r"}, {["x"] = 8, ["param2"] = 20, ["y"] = 7, ["param1"] = 73, ["z"] = 6, ["name"] = "stones:roch"}, {["x"] = 8, ["param2"] = 5, ["y"] = 7, ["param1"] = 57, ["z"] = 7, ["name"] = "stones:s_52ur"}, {["x"] = 8, ["param2"] = 5, ["y"] = 8, ["param1"] = 76, ["z"] = 5, ["name"] = "stones:sku2_l"}, {["x"] = 8, ["param2"] = 11, ["y"] = 8, ["param1"] = 44, ["z"] = 7, ["name"] = "stones:s_52r"}, {["x"] = 8, ["param2"] = 5, ["y"] = 8, ["param1"] = 28, ["z"] = 8, ["name"] = "stones:s_52r"}, {["x"] = 8, ["param2"] = 5, ["y"] = 9, ["param1"] = 60, ["z"] = 5, ["name"] = "stones:sku2_l"}, {["x"] = 9, ["param2"] = 11, ["y"] = 7, ["param1"] = 73, ["z"] = 6, ["name"] = "stones:s_52ur"}, {["x"] = 9, ["param2"] = 20, ["y"] = 7, ["param1"] = 57, ["z"] = 7, ["name"] = "stones:roch"}, {["x"] = 9, ["param2"] = 5, ["y"] = 7, ["param1"] = 39, ["z"] = 8, ["name"] = "stones:s_52ur"}, {["x"] = 9, ["param2"] = 11, ["y"] = 8, ["param1"] = 76, ["z"] = 5, ["name"] = "stones:s_52l"}, {["x"] = 9, ["param2"] = 5, ["y"] = 8, ["param1"] = 57, ["z"] = 6, ["name"] = "stones:s_52l"}, {["x"] = 9, ["param2"] = 5, ["y"] = 8, ["param1"] = 25, ["z"] = 8, ["name"] = "stones:sku"}, {["x"] = 9, ["param2"] = 11, ["y"] = 9, ["param1"] = 60, ["z"] = 5, ["name"] = "stones:s_52l"}, {["x"] = 9, ["param2"] = 5, ["y"] = 9, ["param1"] = 44, ["z"] = 6, ["name"] = "stones:s_52l"}, {["x"] = 9, ["param2"] = 5, ["y"] = 9, ["param1"] = 12, ["z"] = 8, ["name"] = "stones:sku2_l"}, {["x"] = 10, ["param2"] = 11, ["y"] = 7, ["param1"] = 87, ["z"] = 6, ["name"] = "stones:s_52r"}, {["x"] = 10, ["param2"] = 20, ["y"] = 7, ["param1"] = 73, ["z"] = 7, ["name"] = "stones:roch"}, {["x"] = 10, ["param2"] = 5, ["y"] = 7, ["param1"] = 55, ["z"] = 8, ["name"] = "stones:s_52ur"}, {["x"] = 10, ["param2"] = 5, ["y"] = 8, ["param1"] = 73, ["z"] = 6, ["name"] = "stones:sku2_l"}, {["x"] = 10, ["param2"] = 11, ["y"] = 8, ["param1"] = 41, ["z"] = 8, ["name"] = "stones:s_52l"}, {["x"] = 10, ["param2"] = 5, ["y"] = 8, ["param1"] = 25, ["z"] = 9, ["name"] = "stones:s_52l"}, {["x"] = 10, ["param2"] = 5, ["y"] = 9, ["param1"] = 60, ["z"] = 6, ["name"] = "stones:sku2_l"}, {["x"] = 10, ["param2"] = 11, ["y"] = 9, ["param1"] = 28, ["z"] = 8, ["name"] = "stones:s_52l"}, {["x"] = 10, ["param2"] = 5, ["y"] = 9, ["param1"] = 12, ["z"] = 9, ["name"] = "stones:s_52l"}, {["x"] = 11, ["param2"] = 11, ["y"] = 7, ["param1"] = 87, ["z"] = 7, ["name"] = "stones:s_52ur"}, {["x"] = 11, ["param2"] = 20, ["y"] = 7, ["param1"] = 73, ["z"] = 8, ["name"] = "stones:roch"}, {["x"] = 11, ["param2"] = 5, ["y"] = 7, ["param1"] = 55, ["z"] = 9, ["name"] = "stones:s_52r"}, {["x"] = 11, ["param2"] = 16, ["y"] = 8, ["param1"] = 124, ["z"] = 4, ["name"] = "stones:s_52r"}, {["x"] = 11, ["param2"] = 5, ["y"] = 8, ["param1"] = 108, ["z"] = 5, ["name"] = "stones:s_22r"}, {["x"] = 11, ["param2"] = 11, ["y"] = 8, ["param1"] = 89, ["z"] = 6, ["name"] = "stones:s_52l"}, {["x"] = 11, ["param2"] = 5, ["y"] = 8, ["param1"] = 73, ["z"] = 7, ["name"] = "stones:s_52l"}, {["x"] = 11, ["param2"] = 5, ["y"] = 8, ["param1"] = 41, ["z"] = 9, ["name"] = "stones:sku2_l"}, {["x"] = 11, ["param2"] = 11, ["y"] = 9, ["param1"] = 76, ["z"] = 6, ["name"] = "stones:s_52l"}, {["x"] = 11, ["param2"] = 5, ["y"] = 9, ["param1"] = 60, ["z"] = 7, ["name"] = "stones:s_52l"}, {["x"] = 11, ["param2"] = 5, ["y"] = 9, ["param1"] = 28, ["z"] = 9, ["name"] = "stones:sku2_l"}, {["x"] = 12, ["param2"] = 17, ["y"] = 7, ["param1"] = 170, ["z"] = 3, ["name"] = "stones:asect_2"}, {["x"] = 12, ["param2"] = 23, ["y"] = 7, ["param1"] = 153, ["z"] = 4, ["name"] = "stones:diagsteps_52rv"}, {["x"] = 12, ["param2"] = 23, ["y"] = 7, ["param1"] = 137, ["z"] = 5, ["name"] = "stones:diagsteps_52lv"}, {["x"] = 12, ["param2"] = 22, ["y"] = 7, ["param1"] = 119, ["z"] = 6, ["name"] = "stones:s_52ur"}, {["x"] = 12, ["param2"] = 20, ["y"] = 7, ["param1"] = 102, ["z"] = 7, ["name"] = "stones:roch"}, {["x"] = 12, ["param2"] = 2, ["y"] = 7, ["param1"] = 87, ["z"] = 8, ["name"] = "stones:brushrock_c"}, {["x"] = 12, ["param2"] = 5, ["y"] = 7, ["param1"] = 71, ["z"] = 9, ["name"] = "stones:brushrock_52ul"}, {["x"] = 12, ["param2"] = 6, ["y"] = 8, ["param1"] = 156, ["z"] = 3, ["name"] = "stones:skud_202r"}, {["x"] = 12, ["param2"] = 14, ["y"] = 8, ["param1"] = 140, ["z"] = 4, ["name"] = "stones:s_52r"}, {["x"] = 12, ["param2"] = 18, ["y"] = 8, ["param1"] = 124, ["z"] = 5, ["name"] = "stones:sku_202"}, {["x"] = 12, ["param2"] = 17, ["y"] = 8, ["param1"] = 105, ["z"] = 6, ["name"] = "stones:roch"}, {["x"] = 12, ["param2"] = 4, ["y"] = 8, ["param1"] = 87, ["z"] = 7, ["name"] = "stones:roch"}, {["x"] = 12, ["param2"] = 11, ["y"] = 8, ["param1"] = 57, ["z"] = 9, ["name"] = "stones:s_52l"}, {["x"] = 12, ["param2"] = 5, ["y"] = 8, ["param1"] = 41, ["z"] = 10, ["name"] = "stones:s_52l"}, {["x"] = 12, ["param2"] = 19, ["y"] = 9, ["param1"] = 92, ["z"] = 6, ["name"] = "stones:s_52"}, {["x"] = 12, ["param2"] = 1, ["y"] = 9, ["param1"] = 73, ["z"] = 7, ["name"] = "stones:s_52ur"}, {["x"] = 12, ["param2"] = 11, ["y"] = 9, ["param1"] = 44, ["z"] = 9, ["name"] = "stones:s_52l"}, {["x"] = 12, ["param2"] = 5, ["y"] = 9, ["param1"] = 28, ["z"] = 10, ["name"] = "stones:s_52l"}, {["x"] = 13, ["param2"] = 1, ["y"] = 4, ["param1"] = 238, ["z"] = 3, ["name"] = "stones:isokar"}, {["x"] = 13, ["param2"] = 3, ["y"] = 5, ["param1"] = 221, ["z"] = 3, ["name"] = "stones:isocol"}, {["x"] = 13, ["param2"] = 21, ["y"] = 6, ["param1"] = 204, ["z"] = 3, ["name"] = "stones:iso54"}, {["x"] = 13, ["param2"] = 9, ["y"] = 7, ["param1"] = 172, ["z"] = 2, ["name"] = "stones:s_252l"}, {["x"] = 13, ["y"] = 7, ["param1"] = 187, ["z"] = 3, ["name"] = "stones:rock"}, {["x"] = 13, ["param2"] = 22, ["y"] = 7, ["param1"] = 170, ["z"] = 4, ["name"] = "stones:diagsteps"}, {["x"] = 13, ["param2"] = 8, ["y"] = 7, ["param1"] = 153, ["z"] = 5, ["name"] = "stones:arsh"}, {["x"] = 13, ["param2"] = 17, ["y"] = 7, ["param1"] = 136, ["z"] = 6, ["name"] = "stones:arsh"}, {["x"] = 13, ["param2"] = 21, ["y"] = 7, ["param1"] = 119, ["z"] = 7, ["name"] = "stones:diagsteps"}, {["x"] = 13, ["param2"] = 1, ["y"] = 7, ["param1"] = 103, ["z"] = 8, ["name"] = "stones:brush"}, {["x"] = 13, ["param2"] = 2, ["y"] = 7, ["param1"] = 89, ["z"] = 9, ["name"] = "stones:brushrock_5"}, {["x"] = 13, ["param2"] = 5, ["y"] = 7, ["param1"] = 73, ["z"] = 10, ["name"] = "stones:s_52"}, {["x"] = 13, ["param2"] = 1, ["y"] = 8, ["param1"] = 153, ["z"] = 2, ["name"] = "stones:s_222"}, {["x"] = 13, ["param2"] = 19, ["y"] = 8, ["param1"] = 170, ["z"] = 3, ["name"] = "stones:s_222"}, {["x"] = 13, ["param2"] = 5, ["y"] = 8, ["param1"] = 57, ["z"] = 10, ["name"] = "stones:sku2_l"}, {["x"] = 13, ["y"] = 9, ["param1"] = 105, ["z"] = 6, ["name"] = "stones:arch"}, {["x"] = 13, ["y"] = 9, ["param1"] = 89, ["z"] = 7, ["name"] = "stones:arcshir"}, {["x"] = 13, ["param2"] = 5, ["y"] = 9, ["param1"] = 44, ["z"] = 10, ["name"] = "stones:sku2_l"}, {["x"] = 13, ["param2"] = 1, ["y"] = 10, ["param1"] = 89, ["z"] = 6, ["name"] = "stones:s_2"}, {["x"] = 13, ["param2"] = 7, ["y"] = 10, ["param1"] = 73, ["z"] = 7, ["name"] = "stones:s_52pr"}, {["x"] = 14, ["param2"] = 11, ["y"] = 7, ["param1"] = 170, ["z"] = 3, ["name"] = "stones:s_52u"}, {["x"] = 14, ["param2"] = 23, ["y"] = 7, ["param1"] = 153, ["z"] = 4, ["name"] = "stones:diagsteps"}, {["x"] = 14, ["param2"] = 15, ["y"] = 7, ["param1"] = 136, ["z"] = 5, ["name"] = "stones:arsh"}, {["x"] = 14, ["param2"] = 6, ["y"] = 7, ["param1"] = 119, ["z"] = 6, ["name"] = "stones:arsh"}, {["x"] = 14, ["param2"] = 20, ["y"] = 7, ["param1"] = 103, ["z"] = 7, ["name"] = "stones:diagsteps"}, {["x"] = 14, ["param2"] = 1, ["y"] = 7, ["param1"] = 89, ["z"] = 8, ["name"] = "stones:brushrock_c"}, {["x"] = 14, ["y"] = 7, ["param1"] = 73, ["z"] = 9, ["name"] = "stones:brushrock_c"}, {["x"] = 14, ["param2"] = 5, ["y"] = 7, ["param1"] = 58, ["z"] = 10, ["name"] = "stones:s_52u"}, {["x"] = 14, ["param2"] = 9, ["y"] = 8, ["param1"] = 140, ["z"] = 2, ["name"] = "stones:brushrock_527r"}, {["x"] = 14, ["param2"] = 5, ["y"] = 8, ["param1"] = 153, ["z"] = 3, ["name"] = "stones:brushrock_527l"}, {["x"] = 14, ["param2"] = 5, ["y"] = 8, ["param1"] = 136, ["z"] = 4, ["name"] = "stones:s_52l"}, {["x"] = 14, ["param2"] = 11, ["y"] = 8, ["param1"] = 41, ["z"] = 10, ["name"] = "stones:s_52l"}, {["x"] = 14, ["param2"] = 5, ["y"] = 8, ["param1"] = 25, ["z"] = 11, ["name"] = "stones:s_52l"}, {["x"] = 14, ["param2"] = 2, ["y"] = 9, ["param1"] = 87, ["z"] = 6, ["name"] = "stones:arschol"}, {["x"] = 14, ["param2"] = 11, ["y"] = 9, ["param1"] = 28, ["z"] = 10, ["name"] = "stones:s_52l"}, {["x"] = 14, ["param2"] = 5, ["y"] = 9, ["param1"] = 12, ["z"] = 11, ["name"] = "stones:s_52l"}, {["x"] = 14, ["param2"] = 3, ["y"] = 10, ["param1"] = 76, ["z"] = 0, ["name"] = "stones:plot"}, {["x"] = 14, ["param2"] = 3, ["y"] = 10, ["param1"] = 92, ["z"] = 1, ["name"] = "stones:s_52hul"}, {["x"] = 14, ["y"] = 10, ["param1"] = 108, ["z"] = 2, ["name"] = "stones:sku_202"}, {["x"] = 14, ["param2"] = 3, ["y"] = 10, ["param1"] = 105, ["z"] = 4, ["name"] = "stones:arschir"}, {["x"] = 14, ["param2"] = 1, ["y"] = 10, ["param1"] = 89, ["z"] = 5, ["name"] = "stones:arcshol"}, {["x"] = 14, ["param2"] = 7, ["y"] = 10, ["param1"] = 71, ["z"] = 6, ["name"] = "stones:s_52u"}, {["x"] = 14, ["param2"] = 4, ["y"] = 11, ["param1"] = 63, ["z"] = 0, ["name"] = "stones:shrub"}, {["x"] = 14, ["param2"] = 10, ["y"] = 11, ["param1"] = 92, ["z"] = 2, ["name"] = "stones:s_22r"}, {["x"] = 14, ["param2"] = 11, ["y"] = 11, ["param1"] = 108, ["z"] = 3, ["name"] = "stones:sku_202"}, {["x"] = 14, ["param2"] = 16, ["y"] = 11, ["param1"] = 92, ["z"] = 4, ["name"] = "stones:s_52l"}, {["x"] = 14, ["param2"] = 16, ["y"] = 11, ["param1"] = 76, ["z"] = 5, ["name"] = "stones:s_52ul"}, {["x"] = 14, ["param2"] = 2, ["y"] = 11, ["param1"] = 57, ["z"] = 6, ["name"] = "stones:diagstep_2"}, {["x"] = 14, ["param2"] = 2, ["y"] = 12, ["param1"] = 44, ["z"] = 6, ["name"] = "stones:plot"}, {["x"] = 14, ["param2"] = 4, ["y"] = 13, ["param1"] = 28, ["z"] = 6, ["name"] = "stones:shrub"}, {["x"] = 15, ["param2"] = 17, ["y"] = 6, ["param1"] = 137, ["z"] = 5, ["name"] = "stones:s_52l"}, {["x"] = 15, ["param2"] = 15, ["y"] = 7, ["param1"] = 153, ["z"] = 3, ["name"] = "stones:s_52ur"}, {["x"] = 15, ["param2"] = 8, ["y"] = 7, ["param1"] = 136, ["z"] = 4, ["name"] = "stones:s_52hul"}, {["x"] = 15, ["param2"] = 9, ["y"] = 7, ["param1"] = 119, ["z"] = 5, ["name"] = "stones:s_52hul"}, {["x"] = 15, ["param2"] = 14, ["y"] = 7, ["param1"] = 103, ["z"] = 6, ["name"] = "stones:s_52"}, {["x"] = 15, ["param2"] = 12, ["y"] = 7, ["param1"] = 76, ["z"] = 8, ["name"] = "stones:s_52"}, {["x"] = 15, ["param2"] = 3, ["y"] = 7, ["param1"] = 60, ["z"] = 9, ["name"] = "stones:s_21"}, {["x"] = 15, ["y"] = 7, ["param1"] = 43, ["z"] = 10, ["name"] = "stones:rock"}, {["x"] = 15, ["param2"] = 5, ["y"] = 7, ["param1"] = 26, ["z"] = 11, ["name"] = "stones:s_52r"}, {["x"] = 15, ["param2"] = 2, ["y"] = 8, ["param1"] = 124, ["z"] = 2, ["name"] = "stones:brushrock_0"}, {["x"] = 15, ["param2"] = 1, ["y"] = 8, ["param1"] = 137, ["z"] = 3, ["name"] = "stones:brushrock_3"}, {["x"] = 15, ["param2"] = 19, ["y"] = 8, ["param1"] = 119, ["z"] = 4, ["name"] = "stones:stair_5"}, {["x"] = 15, ["param2"] = 16, ["y"] = 8, ["param1"] = 105, ["z"] = 5, ["name"] = "stones:roch"}, {["x"] = 15, ["param2"] = 7, ["y"] = 8, ["param1"] = 87, ["z"] = 6, ["name"] = "stones:s_52"}, {["x"] = 15, ["param2"] = 5, ["y"] = 8, ["param1"] = 9, ["z"] = 11, ["name"] = "stones:sku2_l"}, {["x"] = 15, ["param2"] = 8, ["y"] = 9, ["param1"] = 124, ["z"] = 3, ["name"] = "stones:roch"}, {["x"] = 15, ["param2"] = 11, ["y"] = 9, ["param1"] = 105, ["z"] = 4, ["name"] = "stones:arschor"}, {["x"] = 15, ["param2"] = 5, ["y"] = 9, ["param1"] = 89, ["z"] = 5, ["name"] = "stones:arsh"}, {["x"] = 15, ["param2"] = 7, ["y"] = 9, ["param1"] = 71, ["z"] = 6, ["name"] = "stones:s_52"}, {["x"] = 15, ["param2"] = 5, ["y"] = 9, ["param1"] = 12, ["z"] = 11, ["name"] = "stones:sku2_l"}, {["x"] = 15, ["param2"] = 10, ["y"] = 10, ["param1"] = 108, ["z"] = 3, ["name"] = "stones:s_52"}, {["x"] = 15, ["param2"] = 2, ["y"] = 10, ["param1"] = 89, ["z"] = 4, ["name"] = "stones:arci"}, {["x"] = 15, ["param2"] = 1, ["y"] = 10, ["param1"] = 73, ["z"] = 5, ["name"] = "stones:arci"}, {["x"] = 15, ["param2"] = 7, ["y"] = 10, ["param1"] = 57, ["z"] = 6, ["name"] = "stones:s_52"}, {["x"] = 15, ["param2"] = 12, ["y"] = 11, ["param1"] = 92, ["z"] = 3, ["name"] = "stones:s_22r"}, {["x"] = 15, ["param2"] = 3, ["y"] = 11, ["param1"] = 76, ["z"] = 4, ["name"] = "stones:s_221"}, {["x"] = 15, ["param2"] = 7, ["y"] = 11, ["param1"] = 57, ["z"] = 5, ["name"] = "stones:s_52ur"}, {["x"] = 15, ["param2"] = 8, ["y"] = 12, ["param1"] = 25, ["z"] = 6, ["name"] = "stones:s_52hul"}, {["x"] = 15, ["param2"] = 17, ["y"] = 13, ["param1"] = 28, ["z"] = 5, ["name"] = "stones:s_22r"}, {["x"] = 15, ["param2"] = 18, ["y"] = 14, ["param1"] = 12, ["z"] = 5, ["name"] = "stones:s_52hul"}, {["x"] = 15, ["param2"] = 1, ["y"] = 15, ["param1"] = 12, ["z"] = 5, ["name"] = "stones:plot"}, {["x"] = 15, ["param2"] = 4, ["y"] = 16, ["param1"] = 15, ["z"] = 5, ["name"] = "stones:shrub"}, {["x"] = 16, ["param2"] = 20, ["y"] = 4, ["param1"] = 140, ["z"] = 6, ["name"] = "stones:s_52r"}, {["x"] = 16, ["param2"] = 6, ["y"] = 4, ["param1"] = 124, ["z"] = 7, ["name"] = "stones:s_22r"}, {["x"] = 16, ["param2"] = 8, ["y"] = 5, ["param1"] = 140, ["z"] = 5, ["name"] = "stones:s_52l"}, {["x"] = 16, ["param2"] = 11, ["y"] = 5, ["param1"] = 124, ["z"] = 6, ["name"] = "stones:arsh"}, {["x"] = 16, ["param2"] = 7, ["y"] = 5, ["param1"] = 108, ["z"] = 7, ["name"] = "stones:s_52hul"}, {["x"] = 16, ["param2"] = 13, ["y"] = 6, ["param1"] = 124, ["z"] = 5, ["name"] = "stones:s_52l"}, {["x"] = 16, ["param2"] = 3, ["y"] = 6, ["param1"] = 92, ["z"] = 7, ["name"] = "stones:plot"}, {["x"] = 16, ["param2"] = 3, ["y"] = 7, ["param1"] = 121, ["z"] = 4, ["name"] = "stones:sku2_r"}, {["x"] = 16, ["param2"] = 4, ["y"] = 7, ["param1"] = 76, ["z"] = 7, ["name"] = "stones:shrub"}, {["x"] = 16, ["param2"] = 8, ["y"] = 7, ["param1"] = 44, ["z"] = 9, ["name"] = "stones:roch"}, {["x"] = 16, ["param2"] = 22, ["y"] = 7, ["param1"] = 26, ["z"] = 10, ["name"] = "stones:diagsteps"}, {["x"] = 16, ["param2"] = 5, ["y"] = 7, ["param1"] = 9, ["z"] = 11, ["name"] = "stones:s_52ur"}, {["x"] = 16, ["param2"] = 11, ["y"] = 8, ["param1"] = 108, ["z"] = 2, ["name"] = "stones:brushrock_52ul"}, {["x"] = 16, ["param2"] = 5, ["y"] = 8, ["param1"] = 124, ["z"] = 3, ["name"] = "stones:brushrock_52ul"}, {["x"] = 16, ["param2"] = 12, ["y"] = 8, ["param1"] = 105, ["z"] = 4, ["name"] = "stones:brushrock_52ul"}, {["x"] = 16, ["param2"] = 14, ["y"] = 8, ["param1"] = 92, ["z"] = 5, ["name"] = "stones:brushrock_52ur"}, {["x"] = 16, ["param2"] = 9, ["y"] = 8, ["param1"] = 28, ["z"] = 9, ["name"] = "stones:panel"}, {["x"] = 16, ["param2"] = 11, ["y"] = 8, ["param1"] = 9, ["z"] = 11, ["name"] = "stones:s_52l"}, {["x"] = 16, ["param2"] = 5, ["y"] = 8, ["param1"] = 9, ["z"] = 12, ["name"] = "stones:s_52l"}, {["x"] = 16, ["param2"] = 6, ["y"] = 9, ["param1"] = 92, ["z"] = 4, ["name"] = "stones:stair_3_half_r"}, {["x"] = 16, ["param2"] = 10, ["y"] = 9, ["param1"] = 76, ["z"] = 5, ["name"] = "stones:stair_3_half_r"}, {["x"] = 16, ["param2"] = 19, ["y"] = 9, ["param1"] = 12, ["z"] = 9, ["name"] = "stones:s_22r"}, {["x"] = 16, ["param2"] = 11, ["y"] = 9, ["param1"] = 12, ["z"] = 11, ["name"] = "stones:s_52l"}, {["x"] = 16, ["param2"] = 5, ["y"] = 9, ["param1"] = 12, ["z"] = 12, ["name"] = "stones:s_52l"}, {["x"] = 16, ["param2"] = 13, ["y"] = 10, ["param1"] = 76, ["z"] = 4, ["name"] = "stones:s_52"}, {["x"] = 16, ["param2"] = 13, ["y"] = 10, ["param1"] = 60, ["z"] = 5, ["name"] = "stones:s_52"}, {["x"] = 16, ["param2"] = 7, ["y"] = 11, ["param1"] = 60, ["z"] = 4, ["name"] = "stones:sku3_r"}, {["x"] = 16, ["param2"] = 11, ["y"] = 11, ["param1"] = 41, ["z"] = 5, ["name"] = "stones:sku3_l"}, {["x"] = 16, ["param2"] = 3, ["y"] = 12, ["param1"] = 12, ["z"] = 6, ["name"] = "stones:sku3_r"}, {["x"] = 16, ["param2"] = 9, ["y"] = 13, ["param1"] = 28, ["z"] = 4, ["name"] = "stones:s_52l"}, {["x"] = 16, ["param2"] = 7, ["y"] = 13, ["param1"] = 12, ["z"] = 5, ["name"] = "stones:s_52l"}, {["x"] = 17, ["param2"] = 12, ["y"] = 7, ["param1"] = 108, ["z"] = 4, ["name"] = "stones:s_22r"}, {["x"] = 17, ["param2"] = 18, ["y"] = 7, ["param1"] = 92, ["z"] = 5, ["name"] = "stones:sku3_r"}, {["x"] = 17, ["param2"] = 22, ["y"] = 7, ["param1"] = 76, ["z"] = 6, ["name"] = "stones:s_22r"}, {["x"] = 17, ["param2"] = 11, ["y"] = 7, ["param1"] = 12, ["z"] = 10, ["name"] = "stones:s_52ur"}, {["x"] = 17, ["param2"] = 20, ["y"] = 7, ["param1"] = 9, ["z"] = 11, ["name"] = "stones:roch"}, {["x"] = 17, ["param2"] = 5, ["y"] = 7, ["param1"] = 7, ["z"] = 12, ["name"] = "stones:s_52r"}, {["x"] = 17, ["param2"] = 11, ["y"] = 8, ["param1"] = 92, ["z"] = 2, ["name"] = "stones:s_22"}, {["x"] = 17, ["param2"] = 14, ["y"] = 8, ["param1"] = 108, ["z"] = 3, ["name"] = "stones:s_52"}, {["x"] = 17, ["param2"] = 7, ["y"] = 8, ["param1"] = 60, ["z"] = 6, ["name"] = "stones:s_52hur"}, {["x"] = 17, ["param2"] = 11, ["y"] = 8, ["param1"] = 12, ["z"] = 9, ["name"] = "stones:s_52l"}, {["x"] = 17, ["param2"] = 5, ["y"] = 8, ["param1"] = 9, ["z"] = 10, ["name"] = "stones:s_52l"}, {["x"] = 17, ["param2"] = 5, ["y"] = 8, ["param1"] = 9, ["z"] = 12, ["name"] = "stones:sku2_l"}, {["x"] = 17, ["y"] = 9, ["param1"] = 44, ["z"] = 6, ["name"] = "stones:plot"}, {["x"] = 17, ["param2"] = 11, ["y"] = 9, ["param1"] = 12, ["z"] = 9, ["name"] = "stones:s_52l"}, {["x"] = 17, ["param2"] = 5, ["y"] = 9, ["param1"] = 12, ["z"] = 10, ["name"] = "stones:s_52l"}, {["x"] = 17, ["param2"] = 5, ["y"] = 9, ["param1"] = 12, ["z"] = 12, ["name"] = "stones:sku2_l"}, {["x"] = 17, ["param2"] = 4, ["y"] = 10, ["param1"] = 31, ["z"] = 6, ["name"] = "stones:shrub"}, {["x"] = 17, ["param2"] = 21, ["y"] = 11, ["param1"] = 44, ["z"] = 4, ["name"] = "stones:s_22r"}, {["x"] = 17, ["param2"] = 11, ["y"] = 11, ["param1"] = 28, ["z"] = 5, ["name"] = "stones:s_22r"}, {["x"] = 17, ["param2"] = 6, ["y"] = 11, ["param1"] = 12, ["z"] = 6, ["name"] = "stones:s_22r"}, {["x"] = 17, ["param2"] = 10, ["y"] = 12, ["param1"] = 28, ["z"] = 4, ["name"] = "stones:sku3_r"}, {["x"] = 17, ["param2"] = 13, ["y"] = 12, ["param1"] = 12, ["z"] = 6, ["name"] = "stones:s_22r"}, {["x"] = 17, ["param2"] = 17, ["y"] = 13, ["param1"] = 12, ["z"] = 4, ["name"] = "stones:sku_202"}, {["x"] = 18, ["param2"] = 11, ["y"] = 7, ["param1"] = 12, ["z"] = 10, ["name"] = "stones:s_52r"}, {["x"] = 18, ["param2"] = 20, ["y"] = 7, ["param1"] = 9, ["z"] = 11, ["name"] = "stones:roch"}, {["x"] = 18, ["param2"] = 5, ["y"] = 7, ["param1"] = 7, ["z"] = 12, ["name"] = "stones:s_52ur"}, {["x"] = 18, ["param2"] = 5, ["y"] = 8, ["param1"] = 12, ["z"] = 10, ["name"] = "stones:sku2_l"}, {["x"] = 18, ["param2"] = 11, ["y"] = 8, ["param1"] = 9, ["z"] = 12, ["name"] = "stones:s_52l"}, {["x"] = 18, ["param2"] = 5, ["y"] = 8, ["param1"] = 9, ["z"] = 13, ["name"] = "stones:s_52l"}, {["x"] = 18, ["param2"] = 5, ["y"] = 9, ["param1"] = 12, ["z"] = 10, ["name"] = "stones:sku2_l"}, {["x"] = 18, ["param2"] = 11, ["y"] = 9, ["param1"] = 12, ["z"] = 12, ["name"] = "stones:s_52l"}, {["x"] = 18, ["param2"] = 5, ["y"] = 9, ["param1"] = 12, ["z"] = 13, ["name"] = "stones:s_52l"}, {["x"] = 19, ["param2"] = 11, ["y"] = 7, ["param1"] = 12, ["z"] = 11, ["name"] = "stones:s_52ur"}, {["x"] = 19, ["param2"] = 20, ["y"] = 7, ["param1"] = 9, ["z"] = 12, ["name"] = "stones:roch"}, {["x"] = 19, ["param2"] = 5, ["y"] = 7, ["param1"] = 9, ["z"] = 13, ["name"] = "stones:s_52ur"}, {["x"] = 19, ["param2"] = 11, ["y"] = 8, ["param1"] = 12, ["z"] = 10, ["name"] = "stones:s_52l"}, {["x"] = 19, ["param2"] = 5, ["y"] = 8, ["param1"] = 9, ["z"] = 11, ["name"] = "stones:s_52l"}, {["x"] = 19, ["param2"] = 5, ["y"] = 8, ["param1"] = 9, ["z"] = 13, ["name"] = "stones:sku"}, {["x"] = 19, ["param2"] = 11, ["y"] = 9, ["param1"] = 12, ["z"] = 10, ["name"] = "stones:s_52l"}, {["x"] = 19, ["param2"] = 5, ["y"] = 9, ["param1"] = 12, ["z"] = 11, ["name"] = "stones:s_52l"}, {["x"] = 19, ["param2"] = 5, ["y"] = 9, ["param1"] = 12, ["z"] = 13, ["name"] = "stones:sku2_l"}, {["x"] = 20, ["param2"] = 11, ["y"] = 7, ["param1"] = 12, ["z"] = 11, ["name"] = "stones:s_52r"}, {["x"] = 20, ["param2"] = 20, ["y"] = 7, ["param1"] = 9, ["z"] = 12, ["name"] = "stones:roch"}, {["x"] = 20, ["param2"] = 5, ["y"] = 7, ["param1"] = 9, ["z"] = 13, ["name"] = "stones:s_52ur"}, {["x"] = 20, ["param2"] = 5, ["y"] = 8, ["param1"] = 12, ["z"] = 11, ["name"] = "stones:sku2_l"}, {["x"] = 20, ["param2"] = 11, ["y"] = 8, ["param1"] = 12, ["z"] = 13, ["name"] = "stones:s_52r"}, {["x"] = 20, ["param2"] = 5, ["y"] = 8, ["param1"] = 12, ["z"] = 14, ["name"] = "stones:s_52r"}, {["x"] = 20, ["param2"] = 5, ["y"] = 9, ["param1"] = 12, ["z"] = 11, ["name"] = "stones:sku2_l"}, {["x"] = 21, ["param2"] = 11, ["y"] = 7, ["param1"] = 12, ["z"] = 12, ["name"] = "stones:s_52ur"}, {["x"] = 21, ["param2"] = 20, ["y"] = 7, ["param1"] = 9, ["z"] = 13, ["name"] = "stones:roch"}, {["x"] = 21, ["param2"] = 5, ["y"] = 7, ["param1"] = 9, ["z"] = 14, ["name"] = "stones:s_52ur"}, {["x"] = 21, ["param2"] = 11, ["y"] = 8, ["param1"] = 12, ["z"] = 11, ["name"] = "stones:s_52l"}, {["x"] = 21, ["param2"] = 5, ["y"] = 8, ["param1"] = 9, ["z"] = 12, ["name"] = "stones:s_52l"}, {["x"] = 21, ["param2"] = 5, ["y"] = 8, ["param1"] = 9, ["z"] = 14, ["name"] = "stones:sku"}, {["x"] = 21, ["param2"] = 11, ["y"] = 9, ["param1"] = 12, ["z"] = 11, ["name"] = "stones:s_52l"}, {["x"] = 21, ["param2"] = 5, ["y"] = 9, ["param1"] = 12, ["z"] = 12, ["name"] = "stones:s_52l"}, {["x"] = 21, ["param2"] = 5, ["y"] = 9, ["param1"] = 12, ["z"] = 14, ["name"] = "stones:sku2_l"}, {["x"] = 22, ["param2"] = 11, ["y"] = 7, ["param1"] = 12, ["z"] = 12, ["name"] = "stones:s_52r"}, {["x"] = 22, ["param2"] = 20, ["y"] = 7, ["param1"] = 12, ["z"] = 13, ["name"] = "stones:roch"}, {["x"] = 22, ["param2"] = 5, ["y"] = 7, ["param1"] = 12, ["z"] = 14, ["name"] = "stones:s_52ur"}, {["x"] = 22, ["param2"] = 5, ["y"] = 8, ["param1"] = 12, ["z"] = 12, ["name"] = "stones:sku2_l"}, {["x"] = 22, ["param2"] = 11, ["y"] = 8, ["param1"] = 12, ["z"] = 14, ["name"] = "stones:s_52l"}, {["x"] = 22, ["param2"] = 5, ["y"] = 8, ["param1"] = 12, ["z"] = 15, ["name"] = "stones:s_52l"}, {["x"] = 22, ["param2"] = 5, ["y"] = 9, ["param1"] = 12, ["z"] = 12, ["name"] = "stones:sku2_l"}, {["x"] = 22, ["param2"] = 11, ["y"] = 9, ["param1"] = 12, ["z"] = 14, ["name"] = "stones:s_52l"}, {["x"] = 22, ["param2"] = 5, ["y"] = 9, ["param1"] = 12, ["z"] = 15, ["name"] = "stones:s_52l"}}