5:return {{["x"] = 0, ["param2"] = 9, ["y"] = 8, ["param1"] = 28, ["z"] = 19, ["name"] = "stones:panel"}, {["x"] = 0, ["param2"] = 16, ["y"] = 8, ["param1"] = 42, ["z"] = 20, ["name"] = "stones:brushrock_52ul"}, {["x"] = 0, ["param2"] = 1, ["y"] = 8, ["param1"] = 59, ["z"] = 21, ["name"] = "stones:brushrock_5"}, {["x"] = 0, ["param2"] = 9, ["y"] = 9, ["param1"] = 44, ["z"] = 19, ["name"] = "stones:panel"}, {["x"] = 0, ["param2"] = 14, ["y"] = 9, ["param1"] = 60, ["z"] = 20, ["name"] = "stones:sku2_r"}, {["x"] = 0, ["param2"] = 14, ["y"] = 9, ["param1"] = 76, ["z"] = 21, ["name"] = "stones:s_52r"}, {["x"] = 1, ["param2"] = 9, ["y"] = 8, ["param1"] = 41, ["z"] = 19, ["name"] = "stones:brushrock_52ur"}, {["x"] = 1, ["param2"] = 2, ["y"] = 8, ["param1"] = 60, ["z"] = 20, ["name"] = "stones:brush"}, {["x"] = 1, ["param2"] = 3, ["y"] = 8, ["param1"] = 76, ["z"] = 21, ["name"] = "stones:brush"}, {["x"] = 1, ["param2"] = 7, ["y"] = 9, ["param1"] = 60, ["z"] = 19, ["name"] = "stones:sku2_l"}, {["x"] = 2, ["param2"] = 9, ["y"] = 8, ["param1"] = 44, ["z"] = 18, ["name"] = "stones:s_52"}, {["x"] = 2, ["param2"] = 3, ["y"] = 8, ["param1"] = 57, ["z"] = 19, ["name"] = "stones:brushrock_2"}, {["x"] = 2, ["param2"] = 1, ["y"] = 8, ["param1"] = 76, ["z"] = 20, ["name"] = "stones:brush"}, {["x"] = 2, ["param2"] = 3, ["y"] = 8, ["param1"] = 92, ["z"] = 21, ["name"] = "stones:brush"}, {["x"] = 2, ["param2"] = 9, ["y"] = 9, ["param1"] = 60, ["z"] = 18, ["name"] = "stones:s_52l"}, {["x"] = 2, ["param2"] = 7, ["y"] = 9, ["param1"] = 76, ["z"] = 19, ["name"] = "stones:s_52l"}, {["x"] = 3, ["param2"] = 11, ["y"] = 8, ["param1"] = 60, ["z"] = 18, ["name"] = "stones:panel"}, {["x"] = 3, ["param2"] = 3, ["y"] = 8, ["param1"] = 73, ["z"] = 19, ["name"] = "stones:brushrock_21"}, {["x"] = 3, ["param2"] = 1, ["y"] = 8, ["param1"] = 92, ["z"] = 20, ["name"] = "stones:brush"}, {["x"] = 3, ["param2"] = 3, ["y"] = 8, ["param1"] = 108, ["z"] = 21, ["name"] = "stones:brushrock_5"}, {["x"] = 3, ["param2"] = 11, ["y"] = 9, ["param1"] = 76, ["z"] = 18, ["name"] = "stones:panel"}, {["x"] = 3, ["param2"] = 12, ["y"] = 9, ["param1"] = 92, ["z"] = 19, ["name"] = "stones:sku_202"}, {["x"] = 4, ["param2"] = 17, ["y"] = 7, ["param1"] = 90, ["z"] = 20, ["name"] = "stones:s_2"}, {["x"] = 4, ["param2"] = 15, ["y"] = 8, ["param1"] = 92, ["z"] = 19, ["name"] = "stones:estruk"}, {["x"] = 4, ["param2"] = 3, ["y"] = 8, ["param1"] = 108, ["z"] = 20, ["name"] = "stones:stair_3"}, {["x"] = 4, ["param2"] = 14, ["y"] = 8, ["param1"] = 123, ["z"] = 21, ["name"] = "stones:s_52"}, {["x"] = 4, ["param2"] = 15, ["y"] = 9, ["param1"] = 108, ["z"] = 19, ["name"] = "stones:estruk"}, {["x"] = 5, ["param2"] = 17, ["y"] = 6, ["param1"] = 89, ["z"] = 19, ["name"] = "stones:s_52l"}, {["x"] = 5, ["param2"] = 17, ["y"] = 6, ["param1"] = 89, ["z"] = 20, ["name"] = "stones:s_2"}, {["x"] = 5, ["param2"] = 18, ["y"] = 6, ["param1"] = 106, ["z"] = 21, ["name"] = "stones:s_52"}, {["x"] = 5, ["param2"] = 13, ["y"] = 7, ["param1"] = 92, ["z"] = 19, ["name"] = "stones:sku2_l"}, {["x"] = 5, ["param2"] = 3, ["y"] = 7, ["param1"] = 108, ["z"] = 20, ["name"] = "stones:stair_3"}, {["x"] = 5, ["param2"] = 13, ["y"] = 8, ["param1"] = 108, ["z"] = 19, ["name"] = "stones:s_52l"}, {["x"] = 5, ["param2"] = 16, ["y"] = 10, ["param1"] = 174, ["z"] = 21, ["name"] = "stones:s_52"}, {["x"] = 6, ["param2"] = 9, ["y"] = 6, ["param1"] = 92, ["z"] = 18, ["name"] = "stones:s_22"}, {["x"] = 6, ["y"] = 6, ["param1"] = 92, ["z"] = 19, ["name"] = "stones:brushrock_21"}, {["x"] = 6, ["param2"] = 3, ["y"] = 6, ["param1"] = 108, ["z"] = 20, ["name"] = "stones:brush"}, {["x"] = 6, ["y"] = 6, ["param1"] = 123, ["z"] = 21, ["name"] = "stones:brushrock_2"}, {["x"] = 6, ["param2"] = 16, ["y"] = 9, ["param1"] = 157, ["z"] = 20, ["name"] = "stones:s_22r"}, {["x"] = 6, ["param2"] = 16, ["y"] = 9, ["param1"] = 173, ["z"] = 21, ["name"] = "stones:s_52ur"}, {["x"] = 6, ["param2"] = 16, ["y"] = 10, ["param1"] = 174, ["z"] = 20, ["name"] = "stones:brushrock_22"}, {["x"] = 6, ["param2"] = 1, ["y"] = 10, ["param1"] = 190, ["z"] = 21, ["name"] = "stones:brushrock_5"}, {["x"] = 7, ["param2"] = 9, ["y"] = 6, ["param1"] = 108, ["z"] = 18, ["name"] = "stones:brushrock_52ur"}, {["x"] = 7, ["param2"] = 2, ["y"] = 6, ["param1"] = 92, ["z"] = 19, ["name"] = "stones:brush"}, {["x"] = 7, ["param2"] = 3, ["y"] = 6, ["param1"] = 92, ["z"] = 20, ["name"] = "stones:brush"}, {["x"] = 7, ["param2"] = 2, ["y"] = 6, ["param1"] = 106, ["z"] = 21, ["name"] = "stones:brush"}, {["x"] = 7, ["param2"] = 8, ["y"] = 9, ["param1"] = 140, ["z"] = 20, ["name"] = "stones:panel"}, {["x"] = 7, ["param2"] = 20, ["y"] = 9, ["param1"] = 157, ["z"] = 21, ["name"] = "stones:roch"}, {["x"] = 7, ["param2"] = 2, ["y"] = 10, ["param1"] = 157, ["z"] = 20, ["name"] = "stones:brushrock_0"}, {["x"] = 7, ["param2"] = 2, ["y"] = 10, ["param1"] = 174, ["z"] = 21, ["name"] = "stones:brush"}, {["x"] = 8, ["param2"] = 2, ["y"] = 6, ["param1"] = 124, ["z"] = 18, ["name"] = "stones:brushrock_0"}, {["x"] = 8, ["param2"] = 3, ["y"] = 6, ["param1"] = 108, ["z"] = 19, ["name"] = "stones:brush"}, {["x"] = 8, ["param2"] = 2, ["y"] = 6, ["param1"] = 92, ["z"] = 20, ["name"] = "stones:brush"}, {["x"] = 8, ["y"] = 6, ["param1"] = 92, ["z"] = 21, ["name"] = "stones:brush"}, {["x"] = 8, ["param2"] = 11, ["y"] = 9, ["param1"] = 124, ["z"] = 20, ["name"] = "stones:s_22r"}, {["x"] = 8, ["param2"] = 15, ["y"] = 9, ["param1"] = 140, ["z"] = 21, ["name"] = "stones:panel"}, {["x"] = 8, ["param2"] = 11, ["y"] = 10, ["param1"] = 140, ["z"] = 20, ["name"] = "stones:brushrock_22"}, {["x"] = 8, ["param2"] = 1, ["y"] = 10, ["param1"] = 157, ["z"] = 21, ["name"] = "stones:brushrock_0"}, {["x"] = 9, ["param2"] = 2, ["y"] = 6, ["param1"] = 140, ["z"] = 18, ["name"] = "stones:brushrock_0"}, {["x"] = 9, ["param2"] = 2, ["y"] = 6, ["param1"] = 124, ["z"] = 19, ["name"] = "stones:brush"}, {["x"] = 9, ["param2"] = 2, ["y"] = 6, ["param1"] = 108, ["z"] = 20, ["name"] = "stones:brush"}, {["x"] = 9, ["param2"] = 1, ["y"] = 6, ["param1"] = 92, ["z"] = 21, ["name"] = "stones:brushrock_2"}, {["x"] = 9, ["param2"] = 11, ["y"] = 10, ["param1"] = 140, ["z"] = 21, ["name"] = "stones:s_52"}, {["x"] = 10, ["param2"] = 11, ["y"] = 6, ["param1"] = 156, ["z"] = 18, ["name"] = "stones:brushrock_22"}, {["x"] = 10, ["param2"] = 2, ["y"] = 6, ["param1"] = 140, ["z"] = 19, ["name"] = "stones:brushrock_2"}, {["x"] = 10, ["param2"] = 3, ["y"] = 6, ["param1"] = 124, ["z"] = 20, ["name"] = "stones:brushrock_5"}, {["x"] = 10, ["param2"] = 14, ["y"] = 6, ["param1"] = 108, ["z"] = 21, ["name"] = "stones:brushrock_22"}, {["x"] = 11, ["param2"] = 2, ["y"] = 3, ["param1"] = 204, ["z"] = 19, ["name"] = "stones:sku_202"}, {["x"] = 11, ["param2"] = 16, ["y"] = 3, ["param1"] = 187, ["z"] = 20, ["name"] = "stones:sku3_r"}, {["x"] = 11, ["param2"] = 12, ["y"] = 3, ["param1"] = 170, ["z"] = 21, ["name"] = "stones:sku_202"}, {["x"] = 11, ["param2"] = 8, ["y"] = 4, ["param1"] = 172, ["z"] = 18, ["name"] = "stones:s_52r"}, {["x"] = 11, ["param2"] = 4, ["y"] = 4, ["param1"] = 187, ["z"] = 19, ["name"] = "stones:s_52r"}, {["x"] = 11, ["param2"] = 4, ["y"] = 5, ["param1"] = 187, ["z"] = 18, ["name"] = "stones:sku2_r"}, {["x"] = 11, ["param2"] = 1, ["y"] = 6, ["param1"] = 188, ["z"] = 17, ["name"] = "stones:arsh"}, {["x"] = 11, ["param2"] = 4, ["y"] = 6, ["param1"] = 170, ["z"] = 18, ["name"] = "stones:s_52r"}, {["x"] = 11, ["param2"] = 12, ["y"] = 6, ["param1"] = 153, ["z"] = 19, ["name"] = "stones:s_52"}, {["x"] = 11, ["param2"] = 14, ["y"] = 6, ["param1"] = 140, ["z"] = 20, ["name"] = "stones:s_52"}, {["x"] = 11, ["param2"] = 17, ["y"] = 7, ["param1"] = 172, ["z"] = 17, ["name"] = "stones:s_52u"}, {["x"] = 11, ["param2"] = 3, ["y"] = 8, ["param1"] = 156, ["z"] = 17, ["name"] = "stones:plot"}, {["x"] = 11, ["param2"] = 4, ["y"] = 9, ["param1"] = 143, ["z"] = 17, ["name"] = "stones:shrub"}, {["x"] = 12, ["param2"] = 8, ["y"] = 3, ["param1"] = 170, ["z"] = 20, ["name"] = "stones:s_22r"}, {["x"] = 12, ["param2"] = 9, ["y"] = 3, ["param1"] = 153, ["z"] = 21, ["name"] = "stones:sku_202"}, {["x"] = 12, ["param2"] = 20, ["y"] = 4, ["param1"] = 170, ["z"] = 19, ["name"] = "stones:s_52l"}, {["x"] = 12, ["param2"] = 4, ["y"] = 4, ["param1"] = 153, ["z"] = 20, ["name"] = "stones:s_52ur"}, {["x"] = 12, ["param2"] = 8, ["y"] = 5, ["param1"] = 172, ["z"] = 18, ["name"] = "stones:s_52r"}, {["x"] = 12, ["param2"] = 23, ["y"] = 5, ["param1"] = 153, ["z"] = 19, ["name"] = "stones:arsh"}, {["x"] = 12, ["param2"] = 6, ["y"] = 5, ["param1"] = 136, ["z"] = 20, ["name"] = "stones:skud_202r"}, {["x"] = 12, ["param2"] = 6, ["y"] = 5, ["param1"] = 119, ["z"] = 21, ["name"] = "stones:s_22r"}, {["x"] = 12, ["param2"] = 10, ["y"] = 6, ["param1"] = 156, ["z"] = 18, ["name"] = "stones:s_52l"}, {["x"] = 12, ["param2"] = 9, ["y"] = 6, ["param1"] = 137, ["z"] = 19, ["name"] = "stones:arsh"}, {["x"] = 12, ["param2"] = 6, ["y"] = 6, ["param1"] = 105, ["z"] = 21, ["name"] = "stones:sku3_l"}, {["x"] = 12, ["param2"] = 17, ["y"] = 7, ["param1"] = 124, ["z"] = 19, ["name"] = "stones:s_52u"}, {["x"] = 12, ["param2"] = 19, ["y"] = 7, ["param1"] = 92, ["z"] = 21, ["name"] = "stones:s_22r"}, {["x"] = 12, ["y"] = 8, ["param1"] = 108, ["z"] = 19, ["name"] = "stones:plot"}, {["x"] = 12, ["param2"] = 4, ["y"] = 9, ["param1"] = 95, ["z"] = 19, ["name"] = "stones:shrub"}, {["x"] = 13, ["param2"] = 23, ["y"] = 3, ["param1"] = 153, ["z"] = 20, ["name"] = "stones:s_52l"}, {["x"] = 13, ["param2"] = 3, ["y"] = 4, ["param1"] = 136, ["z"] = 20, ["name"] = "stones:s_52l"}, {["x"] = 13, ["param2"] = 9, ["y"] = 5, ["param1"] = 103, ["z"] = 21, ["name"] = "stones:s_52l"}, {["x"] = 13, ["param2"] = 16, ["y"] = 6, ["param1"] = 108, ["z"] = 20, ["name"] = "stones:s_22r"}, {["x"] = 13, ["param2"] = 14, ["y"] = 6, ["param1"] = 89, ["z"] = 21, ["name"] = "stones:sku3_r"}, {["x"] = 13, ["param2"] = 12, ["y"] = 7, ["param1"] = 76, ["z"] = 21, ["name"] = "stones:s_22r"}, {["x"] = 14, ["param2"] = 20, ["y"] = 3, ["param1"] = 153, ["z"] = 19, ["name"] = "stones:s_22r"}, {["x"] = 14, ["param2"] = 14, ["y"] = 3, ["param1"] = 136, ["z"] = 20, ["name"] = "stones:s_22r"}, {["x"] = 14, ["param2"] = 20, ["y"] = 4, ["param1"] = 124, ["z"] = 18, ["name"] = "stones:s_52r"}, {["x"] = 14, ["param2"] = 8, ["y"] = 4, ["param1"] = 137, ["z"] = 19, ["name"] = "stones:sku_202"}, {["x"] = 14, ["param2"] = 12, ["y"] = 5, ["param1"] = 156, ["z"] = 17, ["name"] = "stones:diagstep"}, {["x"] = 14, ["param2"] = 11, ["y"] = 5, ["param1"] = 137, ["z"] = 18, ["name"] = "stones:arsh"}, {["x"] = 14, ["param2"] = 16, ["y"] = 5, ["param1"] = 105, ["z"] = 20, ["name"] = "stones:s_22r"}, {["x"] = 14, ["param2"] = 23, ["y"] = 5, ["param1"] = 87, ["z"] = 21, ["name"] = "stones:s_221"}, {["x"] = 14, ["param2"] = 15, ["y"] = 6, ["param1"] = 140, ["z"] = 17, ["name"] = "stones:s_52u"}, {["x"] = 14, ["param2"] = 16, ["y"] = 6, ["param1"] = 108, ["z"] = 19, ["name"] = "stones:s_22r"}, {["x"] = 14, ["param2"] = 9, ["y"] = 6, ["param1"] = 92, ["z"] = 20, ["name"] = "stones:sku_202"}, {["x"] = 14, ["param2"] = 3, ["y"] = 7, ["param1"] = 124, ["z"] = 17, ["name"] = "stones:plot"}, {["x"] = 14, ["param2"] = 4, ["y"] = 8, ["param1"] = 111, ["z"] = 17, ["name"] = "stones:shrub"}, {["x"] = 14, ["param2"] = 9, ["y"] = 10, ["param1"] = 60, ["z"] = 21, ["name"] = "stones:s_52r"}, {["x"] = 15, ["param2"] = 16, ["y"] = 5, ["param1"] = 105, ["z"] = 19, ["name"] = "stones:s_52r"}, {["x"] = 15, ["param2"] = 23, ["y"] = 5, ["param1"] = 89, ["z"] = 20, ["name"] = "stones:s_221"}, {["x"] = 15, ["param2"] = 21, ["y"] = 5, ["param1"] = 71, ["z"] = 21, ["name"] = "stones:roch"}, {["x"] = 15, ["param2"] = 16, ["y"] = 6, ["param1"] = 108, ["z"] = 18, ["name"] = "stones:s_22r"}, {["x"] = 15, ["param2"] = 9, ["y"] = 6, ["param1"] = 92, ["z"] = 19, ["name"] = "stones:sku_202"}, {["x"] = 15, ["param2"] = 9, ["y"] = 9, ["param1"] = 41, ["z"] = 21, ["name"] = "stones:s_52r"}, {["x"] = 15, ["param2"] = 7, ["y"] = 10, ["param1"] = 44, ["z"] = 21, ["name"] = "stones:sku2_r"}, {["x"] = 16, ["param2"] = 20, ["y"] = 5, ["param1"] = 105, ["z"] = 18, ["name"] = "stones:diagstep"}, {["x"] = 16, ["param2"] = 20, ["y"] = 5, ["param1"] = 89, ["z"] = 19, ["name"] = "stones:roch"}, {["x"] = 16, ["param2"] = 20, ["y"] = 5, ["param1"] = 71, ["z"] = 20, ["name"] = "stones:roch"}, {["x"] = 16, ["param2"] = 14, ["y"] = 5, ["param1"] = 54, ["z"] = 21, ["name"] = "stones:s_52ur"}, {["x"] = 16, ["param2"] = 16, ["y"] = 6, ["param1"] = 108, ["z"] = 17, ["name"] = "stones:s_22r"}, {["x"] = 16, ["param2"] = 9, ["y"] = 6, ["param1"] = 92, ["z"] = 18, ["name"] = "stones:sku_202"}, {["x"] = 16, ["param2"] = 7, ["y"] = 6, ["param1"] = 71, ["z"] = 21, ["name"] = "stones:sku_202"}, {["x"] = 16, ["param2"] = 9, ["y"] = 9, ["param1"] = 12, ["z"] = 20, ["name"] = "stones:s_52"}, {["x"] = 16, ["param2"] = 2, ["y"] = 9, ["param1"] = 25, ["z"] = 21, ["name"] = "stones:diagsteps_52rh"}, {["x"] = 16, ["param2"] = 9, ["y"] = 10, ["param1"] = 12, ["z"] = 20, ["name"] = "stones:s_52r"}, {["x"] = 16, ["param2"] = 7, ["y"] = 10, ["param1"] = 28, ["z"] = 21, ["name"] = "stones:s_52r"}, {["x"] = 17, ["param2"] = 9, ["y"] = 5, ["param1"] = 121, ["z"] = 16, ["name"] = "stones:micro"}, {["x"] = 17, ["param2"] = 16, ["y"] = 5, ["param1"] = 105, ["z"] = 17, ["name"] = "stones:s_52ur"}, {["x"] = 17, ["param2"] = 20, ["y"] = 5, ["param1"] = 89, ["z"] = 18, ["name"] = "stones:roch"}, {["x"] = 17, ["param2"] = 20, ["y"] = 5, ["param1"] = 73, ["z"] = 19, ["name"] = "stones:roch"}, {["x"] = 17, ["param2"] = 22, ["y"] = 5, ["param1"] = 55, ["z"] = 20, ["name"] = "stones:diagstep"}, {["x"] = 17, ["param2"] = 9, ["y"] = 6, ["param1"] = 108, ["z"] = 16, ["name"] = "stones:panel"}, {["x"] = 17, ["param2"] = 9, ["y"] = 6, ["param1"] = 92, ["z"] = 17, ["name"] = "stones:sku_202"}, {["x"] = 17, ["param2"] = 7, ["y"] = 6, ["param1"] = 41, ["z"] = 20, ["name"] = "stones:sku_202"}, {["x"] = 17, ["param2"] = 14, ["y"] = 6, ["param1"] = 55, ["z"] = 21, ["name"] = "stones:s_22r"}, {["x"] = 17, ["param2"] = 9, ["y"] = 9, ["param1"] = 9, ["z"] = 20, ["name"] = "stones:s_52ur"}, {["x"] = 17, ["param2"] = 7, ["y"] = 9, ["param1"] = 9, ["z"] = 21, ["name"] = "stones:estruk"}, {["x"] = 17, ["param2"] = 7, ["y"] = 10, ["param1"] = 12, ["z"] = 20, ["name"] = "stones:sku2_r"}, {["x"] = 18, ["param2"] = 9, ["y"] = 5, ["param1"] = 105, ["z"] = 16, ["name"] = "stones:s_52ul"}, {["x"] = 18, ["param2"] = 20, ["y"] = 5, ["param1"] = 89, ["z"] = 17, ["name"] = "stones:roch"}, {["x"] = 18, ["param2"] = 21, ["y"] = 5, ["param1"] = 73, ["z"] = 18, ["name"] = "stones:s_221"}, {["x"] = 18, ["param2"] = 14, ["y"] = 5, ["param1"] = 55, ["z"] = 19, ["name"] = "stones:s_52r"}, {["x"] = 18, ["param2"] = 16, ["y"] = 6, ["param1"] = 76, ["z"] = 15, ["name"] = "stones:s_22r"}, {["x"] = 18, ["param2"] = 9, ["y"] = 6, ["param1"] = 92, ["z"] = 16, ["name"] = "stones:sku_202"}, {["x"] = 18, ["param2"] = 7, ["y"] = 6, ["param1"] = 41, ["z"] = 19, ["name"] = "stones:sku_202"}, {["x"] = 18, ["param2"] = 14, ["y"] = 6, ["param1"] = 23, ["z"] = 20, ["name"] = "stones:s_22r"}, {["x"] = 18, ["param2"] = 9, ["y"] = 9, ["param1"] = 12, ["z"] = 19, ["name"] = "stones:s_52"}, {["x"] = 18, ["param2"] = 2, ["y"] = 9, ["param1"] = 9, ["z"] = 20, ["name"] = "stones:diagsteps_52rh"}, {["x"] = 18, ["param2"] = 9, ["y"] = 9, ["param1"] = 9, ["z"] = 21, ["name"] = "stones:estruk"}, {["x"] = 18, ["param2"] = 9, ["y"] = 10, ["param1"] = 12, ["z"] = 19, ["name"] = "stones:s_52r"}, {["x"] = 18, ["param2"] = 7, ["y"] = 10, ["param1"] = 12, ["z"] = 20, ["name"] = "stones:s_52r"}, {["x"] = 19, ["param2"] = 20, ["y"] = 5, ["param1"] = 73, ["z"] = 15, ["name"] = "stones:diagstep"}, {["x"] = 19, ["param2"] = 20, ["y"] = 5, ["param1"] = 89, ["z"] = 16, ["name"] = "stones:roch"}, {["x"] = 19, ["param2"] = 21, ["y"] = 5, ["param1"] = 73, ["z"] = 17, ["name"] = "stones:s_221"}, {["x"] = 19, ["param2"] = 14, ["y"] = 5, ["param1"] = 57, ["z"] = 18, ["name"] = "stones:s_22r"}, {["x"] = 19, ["param2"] = 16, ["y"] = 6, ["param1"] = 44, ["z"] = 14, ["name"] = "stones:s_22r"}, {["x"] = 19, ["param2"] = 9, ["y"] = 6, ["param1"] = 60, ["z"] = 15, ["name"] = "stones:sku_202"}, {["x"] = 19, ["param2"] = 7, ["y"] = 6, ["param1"] = 44, ["z"] = 18, ["name"] = "stones:sku_202"}, {["x"] = 19, ["param2"] = 14, ["y"] = 6, ["param1"] = 25, ["z"] = 19, ["name"] = "stones:s_22r"}, {["x"] = 19, ["y"] = 9, ["param1"] = 9, ["z"] = 19, ["name"] = "stones:panel"}, {["x"] = 19, ["param2"] = 1, ["y"] = 9, ["param1"] = 9, ["z"] = 20, ["name"] = "stones:roch"}, {["x"] = 19, ["y"] = 9, ["param1"] = 9, ["z"] = 21, ["name"] = "stones:diagsteps_52rh"}, {["x"] = 19, ["param2"] = 7, ["y"] = 10, ["param1"] = 12, ["z"] = 19, ["name"] = "stones:sku2_r"}, {["x"] = 19, ["param2"] = 9, ["y"] = 10, ["param1"] = 12, ["z"] = 21, ["name"] = "stones:s_52r"}, {["x"] = 20, ["param2"] = 9, ["y"] = 5, ["param1"] = 41, ["z"] = 14, ["name"] = "stones:s_52l"}, {["x"] = 20, ["param2"] = 20, ["y"] = 5, ["param1"] = 57, ["z"] = 15, ["name"] = "stones:roch"}, {["x"] = 20, ["param2"] = 20, ["y"] = 5, ["param1"] = 73, ["z"] = 16, ["name"] = "stones:roch"}, {["x"] = 20, ["param2"] = 7, ["y"] = 5, ["param1"] = 57, ["z"] = 17, ["name"] = "stones:s_52l"}, {["x"] = 20, ["param2"] = 16, ["y"] = 6, ["param1"] = 60, ["z"] = 13, ["name"] = "stones:s_22r"}, {["x"] = 20, ["param2"] = 9, ["y"] = 6, ["param1"] = 44, ["z"] = 14, ["name"] = "stones:sku_202"}, {["x"] = 20, ["param2"] = 7, ["y"] = 6, ["param1"] = 44, ["z"] = 17, ["name"] = "stones:sku_202"}, {["x"] = 20, ["param2"] = 14, ["y"] = 6, ["param1"] = 25, ["z"] = 18, ["name"] = "stones:s_22r"}, {["x"] = 20, ["param2"] = 9, ["y"] = 9, ["param1"] = 9, ["z"] = 19, ["name"] = "stones:s_52ur"}, {["x"] = 20, ["param2"] = 1, ["y"] = 9, ["param1"] = 9, ["z"] = 20, ["name"] = "stones:roch"}, {["x"] = 20, ["param2"] = 7, ["y"] = 9, ["param1"] = 25, ["z"] = 21, ["name"] = "stones:s_52r"}, {["x"] = 20, ["param2"] = 9, ["y"] = 10, ["param1"] = 12, ["z"] = 18, ["name"] = "stones:s_52r"}, {["x"] = 20, ["param2"] = 7, ["y"] = 10, ["param1"] = 12, ["z"] = 19, ["name"] = "stones:s_52r"}, {["x"] = 20, ["param2"] = 7, ["y"] = 10, ["param1"] = 12, ["z"] = 21, ["name"] = "stones:sku2_r"}, {["x"] = 21, ["param2"] = 16, ["y"] = 5, ["param1"] = 57, ["z"] = 13, ["name"] = "stones:s_22r"}, {["x"] = 21, ["param2"] = 23, ["y"] = 5, ["param1"] = 41, ["z"] = 14, ["name"] = "stones:s_221"}, {["x"] = 21, ["param2"] = 20, ["y"] = 5, ["param1"] = 41, ["z"] = 15, ["name"] = "stones:roch"}, {["x"] = 21, ["param2"] = 22, ["y"] = 5, ["param1"] = 57, ["z"] = 16, ["name"] = "stones:diagstep"}, {["x"] = 21, ["param2"] = 16, ["y"] = 6, ["param1"] = 92, ["z"] = 12, ["name"] = "stones:s_22r"}, {["x"] = 21, ["param2"] = 9, ["y"] = 6, ["param1"] = 76, ["z"] = 13, ["name"] = "stones:sku_202"}, {["x"] = 21, ["param2"] = 7, ["y"] = 6, ["param1"] = 44, ["z"] = 16, ["name"] = "stones:sku_202"}, {["x"] = 21, ["param2"] = 14, ["y"] = 6, ["param1"] = 28, ["z"] = 17, ["name"] = "stones:s_22r"}, {["x"] = 21, ["param2"] = 9, ["y"] = 9, ["param1"] = 9, ["z"] = 18, ["name"] = "stones:s_52r"}, {["x"] = 21, ["param2"] = 1, ["y"] = 9, ["param1"] = 9, ["z"] = 19, ["name"] = "stones:roch"}, {["x"] = 21, ["param2"] = 7, ["y"] = 9, ["param1"] = 25, ["z"] = 20, ["name"] = "stones:s_52ur"}, {["x"] = 21, ["param2"] = 7, ["y"] = 10, ["param1"] = 12, ["z"] = 18, ["name"] = "stones:sku2_r"}, {["x"] = 21, ["param2"] = 9, ["y"] = 10, ["param1"] = 12, ["z"] = 20, ["name"] = "stones:s_52r"}, {["x"] = 21, ["param2"] = 7, ["y"] = 10, ["param1"] = 28, ["z"] = 21, ["name"] = "stones:s_52r"}, {["x"] = 22, ["param2"] = 16, ["y"] = 5, ["param1"] = 89, ["z"] = 12, ["name"] = "stones:s_52r"}, {["x"] = 22, ["param2"] = 23, ["y"] = 5, ["param1"] = 73, ["z"] = 13, ["name"] = "stones:s_221"}, {["x"] = 22, ["param2"] = 21, ["y"] = 5, ["param1"] = 57, ["z"] = 14, ["name"] = "stones:roch"}, {["x"] = 22, ["param2"] = 7, ["y"] = 5, ["param1"] = 41, ["z"] = 15, ["name"] = "stones:s_52ul"}, {["x"] = 22, ["param2"] = 16, ["y"] = 6, ["param1"] = 124, ["z"] = 11, ["name"] = "stones:s_22r"}, {["x"] = 22, ["param2"] = 9, ["y"] = 6, ["param1"] = 108, ["z"] = 12, ["name"] = "stones:sku_202"}, {["x"] = 22, ["param2"] = 7, ["y"] = 6, ["param1"] = 60, ["z"] = 15, ["name"] = "stones:sku_202"}, {["x"] = 22, ["param2"] = 14, ["y"] = 6, ["param1"] = 44, ["z"] = 16, ["name"] = "stones:s_22r"}, {["x"] = 22, ["param2"] = 9, ["y"] = 9, ["param1"] = 25, ["z"] = 18, ["name"] = "stones:s_52ur"}, {["x"] = 22, ["param2"] = 1, ["y"] = 9, ["param1"] = 25, ["z"] = 19, ["name"] = "stones:roch"}, {["x"] = 22, ["param2"] = 7, ["y"] = 9, ["param1"] = 41, ["z"] = 20, ["name"] = "stones:s_52r"}, {["x"] = 22, ["param2"] = 9, ["y"] = 10, ["param1"] = 28, ["z"] = 17, ["name"] = "stones:s_52r"}, {["x"] = 22, ["param2"] = 7, ["y"] = 10, ["param1"] = 12, ["z"] = 18, ["name"] = "stones:s_52r"}, {["x"] = 22, ["param2"] = 7, ["y"] = 10, ["param1"] = 28, ["z"] = 20, ["name"] = "stones:sku2_r"}, {["x"] = 23, ["param2"] = 20, ["y"] = 5, ["param1"] = 121, ["z"] = 11, ["name"] = "stones:diagstep"}, {["x"] = 23, ["param2"] = 20, ["y"] = 5, ["param1"] = 105, ["z"] = 12, ["name"] = "stones:roch"}, {["x"] = 23, ["param2"] = 20, ["y"] = 5, ["param1"] = 89, ["z"] = 13, ["name"] = "stones:roch"}, {["x"] = 23, ["param2"] = 14, ["y"] = 5, ["param1"] = 73, ["z"] = 14, ["name"] = "stones:s_52ur"}, {["x"] = 23, ["param2"] = 15, ["y"] = 5, ["param1"] = 57, ["z"] = 15, ["name"] = "stones:micro"}, {["x"] = 23, ["param2"] = 16, ["y"] = 6, ["param1"] = 156, ["z"] = 10, ["name"] = "stones:s_22r"}, {["x"] = 23, ["param2"] = 9, ["y"] = 6, ["param1"] = 140, ["z"] = 11, ["name"] = "stones:sku_202"}, {["x"] = 23, ["param2"] = 7, ["y"] = 6, ["param1"] = 92, ["z"] = 14, ["name"] = "stones:sku_202"}, {["x"] = 23, ["param2"] = 7, ["y"] = 6, ["param1"] = 76, ["z"] = 15, ["name"] = "stones:panel"}, {["x"] = 23, ["param2"] = 9, ["y"] = 9, ["param1"] = 57, ["z"] = 17, ["name"] = "stones:s_52r"}, {["x"] = 23, ["param2"] = 2, ["y"] = 9, ["param1"] = 41, ["z"] = 18, ["name"] = "stones:roch"}, {["x"] = 23, ["param2"] = 7, ["y"] = 9, ["param1"] = 41, ["z"] = 19, ["name"] = "stones:s_52ur"}, {["x"] = 23, ["param2"] = 7, ["y"] = 10, ["param1"] = 44, ["z"] = 17, ["name"] = "stones:sku2_r"}, {["x"] = 23, ["param2"] = 9, ["y"] = 10, ["param1"] = 28, ["z"] = 19, ["name"] = "stones:s_52r"}, {["x"] = 23, ["param2"] = 7, ["y"] = 10, ["param1"] = 44, ["z"] = 20, ["name"] = "stones:s_52r"}, {["x"] = 24, ["param2"] = 9, ["y"] = 5, ["param1"] = 170, ["z"] = 9, ["name"] = "stones:micro"}, {["x"] = 24, ["param2"] = 16, ["y"] = 5, ["param1"] = 153, ["z"] = 10, ["name"] = "stones:s_52ur"}, {["x"] = 24, ["param2"] = 20, ["y"] = 5, ["param1"] = 137, ["z"] = 11, ["name"] = "stones:roch"}, {["x"] = 24, ["param2"] = 20, ["y"] = 5, ["param1"] = 121, ["z"] = 12, ["name"] = "stones:roch"}, {["x"] = 24, ["param2"] = 22, ["y"] = 5, ["param1"] = 105, ["z"] = 13, ["name"] = "stones:diagstep"}, {["x"] = 24, ["param2"] = 9, ["y"] = 6, ["param1"] = 187, ["z"] = 9, ["name"] = "stones:panel"}, {["x"] = 24, ["param2"] = 9, ["y"] = 6, ["param1"] = 170, ["z"] = 10, ["name"] = "stones:sku_202"}, {["x"] = 24, ["param2"] = 7, ["y"] = 6, ["param1"] = 124, ["z"] = 13, ["name"] = "stones:sku_202"}, {["x"] = 24, ["param2"] = 14, ["y"] = 6, ["param1"] = 108, ["z"] = 14, ["name"] = "stones:s_22r"}, {["x"] = 24, ["param2"] = 8, ["y"] = 7, ["param1"] = 204, ["z"] = 9, ["name"] = "stones:s_52ur"}, {["x"] = 24, ["param2"] = 10, ["y"] = 8, ["param1"] = 221, ["z"] = 9, ["name"] = "stones:spikle"}, {["x"] = 24, ["param2"] = 9, ["y"] = 9, ["param1"] = 73, ["z"] = 17, ["name"] = "stones:s_52ur"}, {["x"] = 24, ["param2"] = 1, ["y"] = 9, ["param1"] = 57, ["z"] = 18, ["name"] = "stones:roch"}, {["x"] = 24, ["param2"] = 7, ["y"] = 9, ["param1"] = 57, ["z"] = 19, ["name"] = "stones:s_52r"}, {["x"] = 24, ["param2"] = 9, ["y"] = 10, ["param1"] = 76, ["z"] = 16, ["name"] = "stones:s_52r"}, {["x"] = 24, ["param2"] = 7, ["y"] = 10, ["param1"] = 60, ["z"] = 17, ["name"] = "stones:s_52r"}, {["x"] = 24, ["param2"] = 7, ["y"] = 10, ["param1"] = 44, ["z"] = 19, ["name"] = "stones:sku2_r"}, {["x"] = 25, ["param2"] = 9, ["y"] = 5, ["param1"] = 187, ["z"] = 9, ["name"] = "stones:s_52ul"}, {["x"] = 25, ["param2"] = 20, ["y"] = 5, ["param1"] = 170, ["z"] = 10, ["name"] = "stones:roch"}, {["x"] = 25, ["param2"] = 21, ["y"] = 5, ["param1"] = 153, ["z"] = 11, ["name"] = "stones:s_221"}, {["x"] = 25, ["param2"] = 14, ["y"] = 5, ["param1"] = 137, ["z"] = 12, ["name"] = "stones:s_52r"}, {["x"] = 25, ["param2"] = 16, ["y"] = 6, ["param1"] = 188, ["z"] = 8, ["name"] = "stones:s_22r"}, {["x"] = 25, ["param2"] = 9, ["y"] = 6, ["param1"] = 204, ["z"] = 9, ["name"] = "stones:sku_202"}, {["x"] = 25, ["param2"] = 7, ["y"] = 6, ["param1"] = 156, ["z"] = 12, ["name"] = "stones:sku_202"}, {["x"] = 25, ["param2"] = 14, ["y"] = 6, ["param1"] = 140, ["z"] = 13, ["name"] = "stones:s_22r"}, {["x"] = 25, ["param2"] = 13, ["y"] = 8, ["param1"] = 238, ["z"] = 9, ["name"] = "stones:estamp"}, {["x"] = 25, ["param2"] = 9, ["y"] = 9, ["param1"] = 105, ["z"] = 16, ["name"] = "stones:s_52r"}, {["x"] = 25, ["param2"] = 2, ["y"] = 9, ["param1"] = 89, ["z"] = 17, ["name"] = "stones:roch"}, {["x"] = 25, ["param2"] = 7, ["y"] = 9, ["param1"] = 73, ["z"] = 18, ["name"] = "stones:s_52ur"}, {["x"] = 25, ["param2"] = 7, ["y"] = 10, ["param1"] = 92, ["z"] = 16, ["name"] = "stones:sku2_r"}, {["x"] = 25, ["param2"] = 9, ["y"] = 10, ["param1"] = 60, ["z"] = 18, ["name"] = "stones:s_52r"}, {["x"] = 25, ["param2"] = 7, ["y"] = 10, ["param1"] = 44, ["z"] = 19, ["name"] = "stones:s_52r"}, {["x"] = 26, ["param2"] = 20, ["y"] = 5, ["param1"] = 153, ["z"] = 8, ["name"] = "stones:diagstep"}, {["x"] = 26, ["param2"] = 20, ["y"] = 5, ["param1"] = 170, ["z"] = 9, ["name"] = "stones:roch"}, {["x"] = 26, ["param2"] = 21, ["y"] = 5, ["param1"] = 153, ["z"] = 10, ["name"] = "stones:s_221"}, {["x"] = 26, ["param2"] = 14, ["y"] = 5, ["param1"] = 137, ["z"] = 11, ["name"] = "stones:s_22r"}, {["x"] = 26, ["param2"] = 16, ["y"] = 6, ["param1"] = 156, ["z"] = 7, ["name"] = "stones:s_22r"}, {["x"] = 26, ["param2"] = 9, ["y"] = 6, ["param1"] = 172, ["z"] = 8, ["name"] = "stones:sku_202"}, {["x"] = 26, ["param2"] = 7, ["y"] = 6, ["param1"] = 156, ["z"] = 11, ["name"] = "stones:sku_202"}, {["x"] = 26, ["param2"] = 14, ["y"] = 6, ["param1"] = 140, ["z"] = 12, ["name"] = "stones:s_22r"}, {["x"] = 26, ["param2"] = 9, ["y"] = 9, ["param1"] = 89, ["z"] = 16, ["name"] = "stones:s_52ur"}, {["x"] = 26, ["param2"] = 2, ["y"] = 9, ["param1"] = 73, ["z"] = 17, ["name"] = "stones:roch"}, {["x"] = 26, ["param2"] = 7, ["y"] = 9, ["param1"] = 57, ["z"] = 18, ["name"] = "stones:s_52r"}, {["x"] = 26, ["param2"] = 9, ["y"] = 10, ["param1"] = 92, ["z"] = 15, ["name"] = "stones:s_52r"}, {["x"] = 26, ["param2"] = 7, ["y"] = 10, ["param1"] = 76, ["z"] = 16, ["name"] = "stones:s_52r"}, {["x"] = 26, ["param2"] = 7, ["y"] = 10, ["param1"] = 44, ["z"] = 18, ["name"] = "stones:sku2_r"}, {["x"] = 27, ["param2"] = 20, ["y"] = 5, ["param1"] = 121, ["z"] = 7, ["name"] = "stones:diagstep"}, {["x"] = 27, ["param2"] = 20, ["y"] = 5, ["param1"] = 137, ["z"] = 8, ["name"] = "stones:roch"}, {["x"] = 27, ["param2"] = 20, ["y"] = 5, ["param1"] = 153, ["z"] = 9, ["name"] = "stones:roch"}, {["x"] = 27, ["param2"] = 7, ["y"] = 5, ["param1"] = 137, ["z"] = 10, ["name"] = "stones:s_52l"}, {["x"] = 27, ["param2"] = 16, ["y"] = 6, ["param1"] = 124, ["z"] = 6, ["name"] = "stones:s_22r"}, {["x"] = 27, ["param2"] = 9, ["y"] = 6, ["param1"] = 140, ["z"] = 7, ["name"] = "stones:sku_202"}, {["x"] = 27, ["param2"] = 7, ["y"] = 6, ["param1"] = 156, ["z"] = 10, ["name"] = "stones:sku_202"}, {["x"] = 27, ["param2"] = 14, ["y"] = 6, ["param1"] = 140, ["z"] = 11, ["name"] = "stones:s_22r"}, {["x"] = 27, ["param2"] = 9, ["y"] = 9, ["param1"] = 89, ["z"] = 15, ["name"] = "stones:s_52r"}, {["x"] = 27, ["param2"] = 2, ["y"] = 9, ["param1"] = 73, ["z"] = 16, ["name"] = "stones:roch"}, {["x"] = 27, ["param2"] = 7, ["y"] = 9, ["param1"] = 57, ["z"] = 17, ["name"] = "stones:s_52ur"}, {["x"] = 27, ["param2"] = 7, ["y"] = 10, ["param1"] = 76, ["z"] = 15, ["name"] = "stones:sku2_r"}, {["x"] = 27, ["param2"] = 9, ["y"] = 10, ["param1"] = 44, ["z"] = 17, ["name"] = "stones:s_52r"}, {["x"] = 27, ["param2"] = 7, ["y"] = 10, ["param1"] = 28, ["z"] = 18, ["name"] = "stones:s_52r"}, {["x"] = 28, ["param2"] = 20, ["y"] = 5, ["param1"] = 92, ["z"] = 6, ["name"] = "stones:diagstep"}, {["x"] = 28, ["param2"] = 20, ["y"] = 5, ["param1"] = 105, ["z"] = 7, ["name"] = "stones:roch"}, {["x"] = 28, ["param2"] = 20, ["y"] = 5, ["param1"] = 121, ["z"] = 8, ["name"] = "stones:roch"}, {["x"] = 28, ["param2"] = 22, ["y"] = 5, ["param1"] = 137, ["z"] = 9, ["name"] = "stones:diagstep"}, {["x"] = 28, ["param2"] = 9, ["y"] = 6, ["param1"] = 108, ["z"] = 6, ["name"] = "stones:sku_202"}, {["x"] = 28, ["param2"] = 7, ["y"] = 6, ["param1"] = 156, ["z"] = 9, ["name"] = "stones:sku_202"}, {["x"] = 28, ["param2"] = 14, ["y"] = 6, ["param1"] = 140, ["z"] = 10, ["name"] = "stones:s_22r"}, {["x"] = 28, ["param2"] = 9, ["y"] = 9, ["param1"] = 92, ["z"] = 14, ["name"] = "stones:s_52"}, {["x"] = 28, ["param2"] = 2, ["y"] = 9, ["param1"] = 73, ["z"] = 15, ["name"] = "stones:diagsteps_52rh"}, {["x"] = 28, ["param2"] = 1, ["y"] = 9, ["param1"] = 57, ["z"] = 16, ["name"] = "stones:roch"}, {["x"] = 28, ["param2"] = 2, ["y"] = 9, ["param1"] = 41, ["z"] = 17, ["name"] = "stones:panel"}, {["x"] = 28, ["param2"] = 9, ["y"] = 10, ["param1"] = 76, ["z"] = 14, ["name"] = "stones:s_52r"}, {["x"] = 28, ["param2"] = 7, ["y"] = 10, ["param1"] = 60, ["z"] = 15, ["name"] = "stones:s_52r"}, {["x"] = 28, ["param2"] = 7, ["y"] = 10, ["param1"] = 28, ["z"] = 17, ["name"] = "stones:sku2_r"}, {["x"] = 29, ["param2"] = 20, ["y"] = 5, ["param1"] = 76, ["z"] = 6, ["name"] = "stones:roch"}, {["x"] = 29, ["param2"] = 20, ["y"] = 5, ["param1"] = 92, ["z"] = 7, ["name"] = "stones:roch"}, {["x"] = 29, ["param2"] = 22, ["y"] = 5, ["param1"] = 108, ["z"] = 8, ["name"] = "stones:diagstep"}, {["x"] = 29, ["param2"] = 7, ["y"] = 6, ["param1"] = 124, ["z"] = 8, ["name"] = "stones:sku_202"}, {["x"] = 29, ["param2"] = 14, ["y"] = 6, ["param1"] = 140, ["z"] = 9, ["name"] = "stones:s_22r"}, {["x"] = 29, ["param2"] = 9, ["y"] = 9, ["param1"] = 73, ["z"] = 14, ["name"] = "stones:s_52ur"}, {["x"] = 29, ["param2"] = 7, ["y"] = 9, ["param1"] = 57, ["z"] = 15, ["name"] = "stones:estruk"}, {["x"] = 29, ["y"] = 9, ["param1"] = 41, ["z"] = 16, ["name"] = "stones:diagsteps_52rh"}, {["x"] = 29, ["param2"] = 7, ["y"] = 9, ["param1"] = 25, ["z"] = 17, ["name"] = "stones:s_52"}, {["x"] = 29, ["param2"] = 7, ["y"] = 10, ["param1"] = 60, ["z"] = 14, ["name"] = "stones:sku2_r"}, {["x"] = 29, ["param2"] = 9, ["y"] = 10, ["param1"] = 28, ["z"] = 16, ["name"] = "stones:s_52r"}, {["x"] = 29, ["param2"] = 7, ["y"] = 10, ["param1"] = 12, ["z"] = 17, ["name"] = "stones:s_52r"}}