5:return {{["x"] = 0, ["y"] = 0, ["param1"] = 94, ["z"] = 0, ["name"] = "stones:rock"}, {["x"] = 0, ["y"] = 0, ["param1"] = 110, ["z"] = 1, ["name"] = "stones:rock"}, {["x"] = 0, ["y"] = 0, ["param1"] = 94, ["z"] = 2, ["name"] = "stones:rock"}, {["x"] = 0, ["y"] = 1, ["param1"] = 110, ["z"] = 0, ["name"] = "stones:rock"}, {["x"] = 0, ["y"] = 1, ["param1"] = 110, ["z"] = 2, ["name"] = "stones:rock"}, {["x"] = 0, ["y"] = 2, ["param1"] = 126, ["z"] = 0, ["name"] = "stones:rock"}, {["x"] = 0, ["param2"] = 1, ["y"] = 2, ["param1"] = 142, ["z"] = 1, ["name"] = "runes:bu"}, {["x"] = 0, ["y"] = 2, ["param1"] = 126, ["z"] = 2, ["name"] = "stones:rock"}, {["x"] = 0, ["y"] = 3, ["param1"] = 142, ["z"] = 0, ["name"] = "stones:rock"}, {["x"] = 0, ["y"] = 3, ["param1"] = 142, ["z"] = 2, ["name"] = "stones:rock"}, {["x"] = 0, ["y"] = 4, ["param1"] = 158, ["z"] = 0, ["name"] = "stones:rock"}, {["x"] = 0, ["param2"] = 1, ["y"] = 4, ["param1"] = 174, ["z"] = 1, ["name"] = "runes:bu"}, {["x"] = 0, ["y"] = 4, ["param1"] = 158, ["z"] = 2, ["name"] = "stones:rock"}, {["x"] = 0, ["y"] = 5, ["param1"] = 174, ["z"] = 0, ["name"] = "stones:rock"}, {["x"] = 0, ["y"] = 5, ["param1"] = 174, ["z"] = 2, ["name"] = "stones:rock"}, {["x"] = 1, ["y"] = 2, ["param1"] = 142, ["z"] = 0, ["name"] = "runes:bu"}, {["x"] = 1, ["param2"] = 2, ["y"] = 2, ["param1"] = 142, ["z"] = 2, ["name"] = "runes:bu"}, {["x"] = 1, ["y"] = 4, ["param1"] = 174, ["z"] = 0, ["name"] = "stones:rock"}, {["x"] = 1, ["y"] = 5, ["param1"] = 190, ["z"] = 0, ["name"] = "stones:rock"}, {["x"] = 1, ["param2"] = 2, ["y"] = 5, ["param1"] = 190, ["z"] = 2, ["name"] = "runes:bu"}, {["x"] = 1, ["param2"] = 1, ["y"] = 7, ["param1"] = 238, ["z"] = 1, ["name"] = "stones:octa"}, {["x"] = 2, ["y"] = 0, ["param1"] = 94, ["z"] = 0, ["name"] = "stones:rock"}, {["x"] = 2, ["y"] = 0, ["param1"] = 94, ["z"] = 2, ["name"] = "stones:rock"}, {["x"] = 2, ["y"] = 1, ["param1"] = 110, ["z"] = 0, ["name"] = "stones:rock"}, {["x"] = 2, ["y"] = 1, ["param1"] = 110, ["z"] = 2, ["name"] = "stones:rock"}, {["x"] = 2, ["y"] = 2, ["param1"] = 126, ["z"] = 0, ["name"] = "stones:rock"}, {["x"] = 2, ["param2"] = 3, ["y"] = 2, ["param1"] = 142, ["z"] = 1, ["name"] = "runes:bu"}, {["x"] = 2, ["y"] = 2, ["param1"] = 126, ["z"] = 2, ["name"] = "stones:rock"}, {["x"] = 2, ["y"] = 3, ["param1"] = 142, ["z"] = 0, ["name"] = "stones:rock"}, {["x"] = 2, ["y"] = 3, ["param1"] = 142, ["z"] = 2, ["name"] = "stones:rock"}, {["x"] = 2, ["y"] = 4, ["param1"] = 158, ["z"] = 0, ["name"] = "stones:rock"}, {["x"] = 2, ["param2"] = 3, ["y"] = 4, ["param1"] = 174, ["z"] = 1, ["name"] = "runes:bu"}, {["x"] = 2, ["y"] = 4, ["param1"] = 158, ["z"] = 2, ["name"] = "stones:rock"}, {["x"] = 2, ["y"] = 5, ["param1"] = 174, ["z"] = 0, ["name"] = "stones:rock"}, {["x"] = 2, ["y"] = 5, ["param1"] = 174, ["z"] = 2, ["name"] = "stones:rock"}}