5:return {{["x"] = 0, ["param2"] = 9, ["y"] = 0, ["param1"] = 126, ["z"] = 14, ["name"] = "stones:s_22"}, {["x"] = 0, ["param2"] = 16, ["y"] = 0, ["param1"] = 110, ["z"] = 15, ["name"] = "stones:s_52u"}, {["x"] = 0, ["y"] = 0, ["param1"] = 110, ["z"] = 16, ["name"] = "stones:rock"}, {["x"] = 0, ["param2"] = 18, ["y"] = 0, ["param1"] = 126, ["z"] = 17, ["name"] = "stones:s_52u"}, {["x"] = 0, ["param2"] = 5, ["y"] = 0, ["param1"] = 142, ["z"] = 18, ["name"] = "stones:s_22"}, {["x"] = 0, ["param2"] = 16, ["y"] = 1, ["param1"] = 126, ["z"] = 15, ["name"] = "stones:s_52"}, {["x"] = 0, ["param2"] = 16, ["y"] = 1, ["param1"] = 126, ["z"] = 16, ["name"] = "stones:roch"}, {["x"] = 0, ["param2"] = 18, ["y"] = 1, ["param1"] = 142, ["z"] = 17, ["name"] = "stones:s_52"}, {["x"] = 0, ["param2"] = 16, ["y"] = 2, ["param1"] = 142, ["z"] = 15, ["name"] = "stones:s_52"}, {["x"] = 0, ["param2"] = 16, ["y"] = 2, ["param1"] = 142, ["z"] = 16, ["name"] = "stones:roch"}, {["x"] = 0, ["param2"] = 18, ["y"] = 2, ["param1"] = 158, ["z"] = 17, ["name"] = "stones:s_52"}, {["x"] = 0, ["param2"] = 16, ["y"] = 3, ["param1"] = 142, ["z"] = 15, ["name"] = "stones:s_52"}, {["x"] = 0, ["param2"] = 16, ["y"] = 3, ["param1"] = 158, ["z"] = 16, ["name"] = "stones:roch"}, {["x"] = 0, ["param2"] = 18, ["y"] = 3, ["param1"] = 142, ["z"] = 17, ["name"] = "stones:s_52"}, {["x"] = 0, ["param2"] = 16, ["y"] = 4, ["param1"] = 158, ["z"] = 15, ["name"] = "stones:s_52"}, {["x"] = 0, ["param2"] = 16, ["y"] = 4, ["param1"] = 174, ["z"] = 16, ["name"] = "stones:roch"}, {["x"] = 0, ["param2"] = 18, ["y"] = 4, ["param1"] = 158, ["z"] = 17, ["name"] = "stones:s_52"}, {["x"] = 0, ["param2"] = 9, ["y"] = 5, ["param1"] = 158, ["z"] = 14, ["name"] = "stones:s_22l"}, {["x"] = 0, ["param2"] = 20, ["y"] = 5, ["param1"] = 174, ["z"] = 15, ["name"] = "stones:diagsteps_13"}, {["x"] = 0, ["param2"] = 23, ["y"] = 5, ["param1"] = 190, ["z"] = 16, ["name"] = "stones:stair_2"}, {["x"] = 0, ["param2"] = 23, ["y"] = 5, ["param1"] = 174, ["z"] = 17, ["name"] = "stones:diagsteps_31"}, {["x"] = 0, ["param2"] = 18, ["y"] = 5, ["param1"] = 158, ["z"] = 18, ["name"] = "stones:s_22l"}, {["x"] = 1, ["param2"] = 1, ["y"] = 0, ["param1"] = 174, ["z"] = 8, ["name"] = "stones:stair_3"}, {["x"] = 1, ["param2"] = 1, ["y"] = 0, ["param1"] = 190, ["z"] = 9, ["name"] = "stones:stair_3"}, {["x"] = 1, ["y"] = 0, ["param1"] = 206, ["z"] = 10, ["name"] = "stones:rock"}, {["x"] = 1, ["param2"] = 18, ["y"] = 0, ["param1"] = 190, ["z"] = 11, ["name"] = "stones:s_52u"}, {["x"] = 1, ["param2"] = 16, ["y"] = 0, ["param1"] = 174, ["z"] = 12, ["name"] = "stones:roch"}, {["x"] = 1, ["param2"] = 18, ["y"] = 0, ["param1"] = 158, ["z"] = 13, ["name"] = "stones:s_52"}, {["x"] = 1, ["param2"] = 9, ["y"] = 0, ["param1"] = 141, ["z"] = 14, ["name"] = "stones:s_52u"}, {["x"] = 1, ["y"] = 0, ["param1"] = 125, ["z"] = 15, ["name"] = "stones:rock"}, {["x"] = 1, ["y"] = 0, ["param1"] = 125, ["z"] = 16, ["name"] = "stones:rock"}, {["x"] = 1, ["y"] = 0, ["param1"] = 141, ["z"] = 17, ["name"] = "stones:rock"}, {["x"] = 1, ["y"] = 0, ["param1"] = 157, ["z"] = 18, ["name"] = "stones:rock"}, {["x"] = 1, ["y"] = 0, ["param1"] = 174, ["z"] = 19, ["name"] = "stones:rock"}, {["x"] = 1, ["y"] = 0, ["param1"] = 190, ["z"] = 20, ["name"] = "stones:rock"}, {["x"] = 1, ["param2"] = 3, ["y"] = 1, ["param1"] = 222, ["z"] = 10, ["name"] = "stones:iso54"}, {["x"] = 1, ["param2"] = 9, ["y"] = 1, ["param1"] = 158, ["z"] = 14, ["name"] = "stones:s_52"}, {["x"] = 1, ["param2"] = 22, ["y"] = 1, ["param1"] = 141, ["z"] = 15, ["name"] = "stones:spirdiag_r"}, {["x"] = 1, ["y"] = 1, ["param1"] = 157, ["z"] = 17, ["name"] = "stones:spircod"}, {["x"] = 1, ["param2"] = 5, ["y"] = 1, ["param1"] = 174, ["z"] = 18, ["name"] = "stones:s_52"}, {["x"] = 1, ["param2"] = 3, ["y"] = 2, ["param1"] = 238, ["z"] = 10, ["name"] = "stones:isokar"}, {["x"] = 1, ["param2"] = 9, ["y"] = 2, ["param1"] = 174, ["z"] = 14, ["name"] = "stones:s_52"}, {["x"] = 1, ["param2"] = 3, ["y"] = 2, ["param1"] = 157, ["z"] = 15, ["name"] = "stones:spirdiag_r"}, {["x"] = 1, ["y"] = 2, ["param1"] = 157, ["z"] = 16, ["name"] = "stones:spirstax_r"}, {["x"] = 1, ["param2"] = 21, ["y"] = 2, ["param1"] = 173, ["z"] = 17, ["name"] = "stones:spirdiag_r"}, {["x"] = 1, ["param2"] = 5, ["y"] = 2, ["param1"] = 190, ["z"] = 18, ["name"] = "stones:s_52"}, {["x"] = 1, ["param2"] = 9, ["y"] = 3, ["param1"] = 158, ["z"] = 14, ["name"] = "stones:s_52"}, {["x"] = 1, ["param2"] = 3, ["y"] = 3, ["param1"] = 157, ["z"] = 15, ["name"] = "stones:spircod"}, {["x"] = 1, ["y"] = 3, ["param1"] = 157, ["z"] = 17, ["name"] = "stones:spirdiag_r"}, {["x"] = 1, ["param2"] = 2, ["y"] = 3, ["param1"] = 174, ["z"] = 18, ["name"] = "stones:diagsteps_31"}, {["x"] = 1, ["param2"] = 9, ["y"] = 4, ["param1"] = 158, ["z"] = 14, ["name"] = "stones:s_52"}, {["x"] = 1, ["param2"] = 3, ["y"] = 4, ["param1"] = 173, ["z"] = 15, ["name"] = "stones:spircod"}, {["x"] = 1, ["y"] = 4, ["param1"] = 173, ["z"] = 17, ["name"] = "stones:spircod"}, {["x"] = 1, ["param2"] = 5, ["y"] = 4, ["param1"] = 158, ["z"] = 18, ["name"] = "stones:s_52"}, {["x"] = 1, ["param2"] = 20, ["y"] = 5, ["param1"] = 174, ["z"] = 14, ["name"] = "stones:diagsteps_31"}, {["x"] = 1, ["param2"] = 22, ["y"] = 5, ["param1"] = 190, ["z"] = 15, ["name"] = "stones:spirdiag"}, {["x"] = 1, ["param2"] = 3, ["y"] = 5, ["param1"] = 205, ["z"] = 16, ["name"] = "stones:spirjoin_2l"}, {["x"] = 1, ["y"] = 5, ["param1"] = 189, ["z"] = 17, ["name"] = "stones:spircod"}, {["x"] = 1, ["param2"] = 23, ["y"] = 5, ["param1"] = 174, ["z"] = 18, ["name"] = "stones:diagsteps_13"}, {["x"] = 1, ["param2"] = 17, ["y"] = 6, ["param1"] = 222, ["z"] = 16, ["name"] = "stones:sku3_l"}, {["x"] = 1, ["param2"] = 5, ["y"] = 6, ["param1"] = 190, ["z"] = 18, ["name"] = "stones:s_22"}, {["x"] = 1, ["param2"] = 10, ["y"] = 7, ["param1"] = 206, ["z"] = 16, ["name"] = "stones:s_22r"}, {["x"] = 1, ["param2"] = 12, ["y"] = 7, ["param1"] = 190, ["z"] = 17, ["name"] = "stones:sku2_r"}, {["x"] = 1, ["param2"] = 5, ["y"] = 7, ["param1"] = 174, ["z"] = 18, ["name"] = "stones:s_22l"}, {["x"] = 2, ["param2"] = 16, ["y"] = 0, ["param1"] = 142, ["z"] = 7, ["name"] = "stones:brushrock_22"}, {["x"] = 2, ["param2"] = 3, ["y"] = 0, ["param1"] = 158, ["z"] = 8, ["name"] = "stones:brushrock_0"}, {["x"] = 2, ["y"] = 0, ["param1"] = 174, ["z"] = 9, ["name"] = "stones:brushrock_3"}, {["x"] = 2, ["param2"] = 1, ["y"] = 0, ["param1"] = 190, ["z"] = 10, ["name"] = "stones:brushrock_4"}, {["x"] = 2, ["param2"] = 1, ["y"] = 0, ["param1"] = 173, ["z"] = 11, ["name"] = "stones:brushrock_5"}, {["x"] = 2, ["param2"] = 3, ["y"] = 0, ["param1"] = 157, ["z"] = 12, ["name"] = "stones:brush"}, {["x"] = 2, ["y"] = 0, ["param1"] = 141, ["z"] = 13, ["name"] = "stones:brushrock_1"}, {["x"] = 2, ["y"] = 0, ["param1"] = 124, ["z"] = 14, ["name"] = "stones:rock"}, {["x"] = 2, ["y"] = 0, ["param1"] = 124, ["z"] = 15, ["name"] = "stones:rock"}, {["x"] = 2, ["y"] = 0, ["param1"] = 140, ["z"] = 16, ["name"] = "stones:rock"}, {["x"] = 2, ["y"] = 0, ["param1"] = 156, ["z"] = 17, ["name"] = "stones:rock"}, {["x"] = 2, ["y"] = 0, ["param1"] = 172, ["z"] = 18, ["name"] = "stones:rock"}, {["x"] = 2, ["y"] = 0, ["param1"] = 189, ["z"] = 19, ["name"] = "stones:rock"}, {["x"] = 2, ["y"] = 0, ["param1"] = 205, ["z"] = 20, ["name"] = "stones:rock"}, {["x"] = 2, ["param2"] = 4, ["y"] = 1, ["param1"] = 174, ["z"] = 12, ["name"] = "stones:shrub"}, {["x"] = 2, ["y"] = 1, ["param1"] = 141, ["z"] = 14, ["name"] = "stones:s_22"}, {["x"] = 2, ["param2"] = 23, ["y"] = 1, ["param1"] = 140, ["z"] = 15, ["name"] = "stones:spirout_r"}, {["x"] = 2, ["y"] = 1, ["param1"] = 156, ["z"] = 16, ["name"] = "stones:spircol_8"}, {["x"] = 2, ["y"] = 2, ["param1"] = 172, ["z"] = 16, ["name"] = "stones:spircol_8"}, {["x"] = 2, ["y"] = 2, ["param1"] = 238, ["z"] = 20, ["name"] = "stones:octa"}, {["x"] = 2, ["param2"] = 15, ["y"] = 3, ["param1"] = 157, ["z"] = 14, ["name"] = "stones:s_52r"}, {["x"] = 2, ["param2"] = 1, ["y"] = 3, ["param1"] = 188, ["z"] = 16, ["name"] = "stones:spircol_8"}, {["x"] = 2, ["param2"] = 21, ["y"] = 3, ["param1"] = 172, ["z"] = 17, ["name"] = "stones:spirout_r"}, {["x"] = 2, ["param2"] = 2, ["y"] = 3, ["param1"] = 189, ["z"] = 18, ["name"] = "stones:roch"}, {["x"] = 2, ["param2"] = 15, ["y"] = 4, ["param1"] = 173, ["z"] = 14, ["name"] = "stones:s_52ur"}, {["x"] = 2, ["param2"] = 1, ["y"] = 4, ["param1"] = 205, ["z"] = 16, ["name"] = "stones:spircol_8"}, {["x"] = 2, ["param2"] = 8, ["y"] = 5, ["param1"] = 189, ["z"] = 14, ["name"] = "stones:stair_2"}, {["x"] = 2, ["param2"] = 3, ["y"] = 5, ["param1"] = 205, ["z"] = 15, ["name"] = "stones:spirout_r"}, {["x"] = 2, ["param2"] = 2, ["y"] = 5, ["param1"] = 222, ["z"] = 16, ["name"] = "stones:spircol_8"}, {["x"] = 2, ["param2"] = 20, ["y"] = 5, ["param1"] = 189, ["z"] = 18, ["name"] = "stones:roch"}, {["x"] = 2, ["y"] = 6, ["param1"] = 238, ["z"] = 16, ["name"] = "stones:estamp"}, {["x"] = 2, ["param2"] = 4, ["y"] = 7, ["param1"] = 189, ["z"] = 18, ["name"] = "stones:panel"}, {["x"] = 3, ["param2"] = 11, ["y"] = 0, ["param1"] = 126, ["z"] = 7, ["name"] = "stones:brushrock_52ul"}, {["x"] = 3, ["param2"] = 3, ["y"] = 0, ["param1"] = 142, ["z"] = 8, ["name"] = "stones:brush"}, {["x"] = 3, ["param2"] = 2, ["y"] = 0, ["param1"] = 158, ["z"] = 9, ["name"] = "stones:brush"}, {["x"] = 3, ["param2"] = 1, ["y"] = 0, ["param1"] = 173, ["z"] = 10, ["name"] = "stones:brush"}, {["x"] = 3, ["y"] = 0, ["param1"] = 158, ["z"] = 11, ["name"] = "stones:brush"}, {["x"] = 3, ["y"] = 0, ["param1"] = 142, ["z"] = 12, ["name"] = "stones:brush"}, {["x"] = 3, ["y"] = 0, ["param1"] = 126, ["z"] = 13, ["name"] = "stones:brush"}, {["x"] = 3, ["param2"] = 2, ["y"] = 0, ["param1"] = 109, ["z"] = 14, ["name"] = "stones:brushrock_4"}, {["x"] = 3, ["y"] = 0, ["param1"] = 109, ["z"] = 15, ["name"] = "stones:rock"}, {["x"] = 3, ["y"] = 0, ["param1"] = 125, ["z"] = 16, ["name"] = "stones:rock"}, {["x"] = 3, ["y"] = 0, ["param1"] = 141, ["z"] = 17, ["name"] = "stones:rock"}, {["x"] = 3, ["y"] = 0, ["param1"] = 157, ["z"] = 18, ["name"] = "stones:rock"}, {["x"] = 3, ["y"] = 0, ["param1"] = 174, ["z"] = 19, ["name"] = "stones:rock"}, {["x"] = 3, ["y"] = 0, ["param1"] = 190, ["z"] = 20, ["name"] = "stones:rock"}, {["x"] = 3, ["y"] = 1, ["param1"] = 126, ["z"] = 14, ["name"] = "stones:s_22l"}, {["x"] = 3, ["param2"] = 14, ["y"] = 1, ["param1"] = 125, ["z"] = 15, ["name"] = "stones:s_52l"}, {["x"] = 3, ["param2"] = 1, ["y"] = 1, ["param1"] = 157, ["z"] = 17, ["name"] = "stones:spircod"}, {["x"] = 3, ["param2"] = 7, ["y"] = 1, ["param1"] = 174, ["z"] = 18, ["name"] = "stones:s_52"}, {["x"] = 3, ["param2"] = 1, ["y"] = 2, ["param1"] = 173, ["z"] = 17, ["name"] = "stones:spircod"}, {["x"] = 3, ["param2"] = 7, ["y"] = 2, ["param1"] = 190, ["z"] = 18, ["name"] = "stones:s_52"}, {["x"] = 3, ["param2"] = 20, ["y"] = 3, ["param1"] = 157, ["z"] = 17, ["name"] = "stones:spirdiag_r"}, {["x"] = 3, ["param2"] = 3, ["y"] = 3, ["param1"] = 174, ["z"] = 18, ["name"] = "stones:diagsteps_13"}, {["x"] = 3, ["param2"] = 20, ["y"] = 4, ["param1"] = 173, ["z"] = 15, ["name"] = "stones:diagstep"}, {["x"] = 3, ["param2"] = 2, ["y"] = 4, ["param1"] = 190, ["z"] = 16, ["name"] = "stones:spirstax_r"}, {["x"] = 3, ["param2"] = 1, ["y"] = 4, ["param1"] = 173, ["z"] = 17, ["name"] = "stones:spirdiag_r"}, {["x"] = 3, ["param2"] = 7, ["y"] = 4, ["param1"] = 158, ["z"] = 18, ["name"] = "stones:s_52"}, {["x"] = 3, ["param2"] = 21, ["y"] = 5, ["param1"] = 174, ["z"] = 14, ["name"] = "stones:diagsteps_13"}, {["x"] = 3, ["param2"] = 2, ["y"] = 5, ["param1"] = 190, ["z"] = 15, ["name"] = "stones:spirdiag_r"}, {["x"] = 3, ["param2"] = 1, ["y"] = 5, ["param1"] = 190, ["z"] = 17, ["name"] = "stones:spircod"}, {["x"] = 3, ["param2"] = 22, ["y"] = 5, ["param1"] = 174, ["z"] = 18, ["name"] = "stones:diagsteps_31"}, {["x"] = 3, ["param2"] = 7, ["y"] = 6, ["param1"] = 190, ["z"] = 18, ["name"] = "stones:s_22"}, {["x"] = 3, ["param2"] = 14, ["y"] = 7, ["param1"] = 190, ["z"] = 17, ["name"] = "stones:sku_202"}, {["x"] = 3, ["param2"] = 14, ["y"] = 7, ["param1"] = 174, ["z"] = 18, ["name"] = "stones:s_22l"}, {["x"] = 4, ["param2"] = 8, ["y"] = 0, ["param1"] = 110, ["z"] = 7, ["name"] = "stones:roch"}, {["x"] = 4, ["param2"] = 1, ["y"] = 0, ["param1"] = 126, ["z"] = 8, ["name"] = "stones:brush"}, {["x"] = 4, ["y"] = 0, ["param1"] = 142, ["z"] = 9, ["name"] = "stones:brush"}, {["x"] = 4, ["param2"] = 3, ["y"] = 0, ["param1"] = 157, ["z"] = 10, ["name"] = "stones:brush"}, {["x"] = 4, ["param2"] = 1, ["y"] = 0, ["param1"] = 142, ["z"] = 11, ["name"] = "stones:brush"}, {["x"] = 4, ["y"] = 0, ["param1"] = 126, ["z"] = 12, ["name"] = "stones:brush"}, {["x"] = 4, ["y"] = 0, ["param1"] = 110, ["z"] = 13, ["name"] = "stones:brush"}, {["x"] = 4, ["param2"] = 7, ["y"] = 0, ["param1"] = 93, ["z"] = 14, ["name"] = "stones:brushrock_52ur"}, {["x"] = 4, ["param2"] = 12, ["y"] = 0, ["param1"] = 94, ["z"] = 15, ["name"] = "stones:s_52"}, {["x"] = 4, ["param2"] = 12, ["y"] = 0, ["param1"] = 110, ["z"] = 16, ["name"] = "stones:s_52u"}, {["x"] = 4, ["param2"] = 14, ["y"] = 0, ["param1"] = 126, ["z"] = 17, ["name"] = "stones:s_52u"}, {["x"] = 4, ["param2"] = 7, ["y"] = 0, ["param1"] = 142, ["z"] = 18, ["name"] = "stones:s_22"}, {["x"] = 4, ["param2"] = 11, ["y"] = 1, ["param1"] = 126, ["z"] = 16, ["name"] = "stones:panel"}, {["x"] = 4, ["param2"] = 14, ["y"] = 1, ["param1"] = 142, ["z"] = 17, ["name"] = "stones:s_52"}, {["x"] = 4, ["param2"] = 11, ["y"] = 2, ["param1"] = 142, ["z"] = 16, ["name"] = "stones:panel"}, {["x"] = 4, ["param2"] = 14, ["y"] = 2, ["param1"] = 158, ["z"] = 17, ["name"] = "stones:s_52"}, {["x"] = 4, ["param2"] = 11, ["y"] = 3, ["param1"] = 158, ["z"] = 16, ["name"] = "stones:panel"}, {["x"] = 4, ["param2"] = 14, ["y"] = 3, ["param1"] = 142, ["z"] = 17, ["name"] = "stones:s_52"}, {["x"] = 4, ["param2"] = 12, ["y"] = 4, ["param1"] = 158, ["z"] = 15, ["name"] = "stones:s_52l"}, {["x"] = 4, ["param2"] = 20, ["y"] = 4, ["param1"] = 174, ["z"] = 16, ["name"] = "stones:stair_half_r"}, {["x"] = 4, ["param2"] = 14, ["y"] = 4, ["param1"] = 158, ["z"] = 17, ["name"] = "stones:s_52"}, {["x"] = 4, ["param2"] = 11, ["y"] = 5, ["param1"] = 158, ["z"] = 14, ["name"] = "stones:s_22r"}, {["x"] = 4, ["param2"] = 21, ["y"] = 5, ["param1"] = 174, ["z"] = 15, ["name"] = "stones:diagsteps_31"}, {["x"] = 4, ["param2"] = 21, ["y"] = 5, ["param1"] = 190, ["z"] = 16, ["name"] = "stones:stair_2"}, {["x"] = 4, ["param2"] = 22, ["y"] = 5, ["param1"] = 174, ["z"] = 17, ["name"] = "stones:diagsteps_13"}, {["x"] = 4, ["param2"] = 14, ["y"] = 5, ["param1"] = 158, ["z"] = 18, ["name"] = "stones:s_22r"}, {["x"] = 4, ["y"] = 6, ["param1"] = 190, ["z"] = 15, ["name"] = "stones:s_22l"}, {["x"] = 4, ["y"] = 6, ["param1"] = 206, ["z"] = 16, ["name"] = "stones:sku_202"}, {["x"] = 4, ["y"] = 7, ["param1"] = 190, ["z"] = 16, ["name"] = "stones:s_22l"}, {["x"] = 4, ["param2"] = 14, ["y"] = 7, ["param1"] = 174, ["z"] = 17, ["name"] = "stones:s_22l"}, {["x"] = 5, ["param2"] = 11, ["y"] = 0, ["param1"] = 94, ["z"] = 7, ["name"] = "stones:s_52"}, {["x"] = 5, ["y"] = 0, ["param1"] = 110, ["z"] = 8, ["name"] = "stones:brushrock_5"}, {["x"] = 5, ["param2"] = 1, ["y"] = 0, ["param1"] = 126, ["z"] = 9, ["name"] = "stones:brush"}, {["x"] = 5, ["param2"] = 1, ["y"] = 0, ["param1"] = 141, ["z"] = 10, ["name"] = "stones:brush"}, {["x"] = 5, ["param2"] = 1, ["y"] = 0, ["param1"] = 126, ["z"] = 11, ["name"] = "stones:brush"}, {["x"] = 5, ["param2"] = 3, ["y"] = 0, ["param1"] = 110, ["z"] = 12, ["name"] = "stones:brushrock_5"}, {["x"] = 5, ["param2"] = 14, ["y"] = 0, ["param1"] = 94, ["z"] = 13, ["name"] = "stones:brushrock_52ul"}, {["x"] = 5, ["param2"] = 7, ["y"] = 0, ["param1"] = 78, ["z"] = 14, ["name"] = "stones:s_22"}, {["x"] = 6, ["param2"] = 11, ["y"] = 0, ["param1"] = 94, ["z"] = 8, ["name"] = "stones:brushrock_22"}, {["x"] = 6, ["param2"] = 2, ["y"] = 0, ["param1"] = 110, ["z"] = 9, ["name"] = "stones:brushrock_2"}, {["x"] = 6, ["param2"] = 3, ["y"] = 0, ["param1"] = 125, ["z"] = 10, ["name"] = "stones:brushrock_5"}, {["x"] = 6, ["param2"] = 14, ["y"] = 0, ["param1"] = 110, ["z"] = 11, ["name"] = "stones:brushrock_52ul"}, {["x"] = 6, ["param2"] = 14, ["y"] = 0, ["param1"] = 94, ["z"] = 12, ["name"] = "stones:s_52"}, {["x"] = 7, ["param2"] = 16, ["y"] = 0, ["param1"] = 78, ["z"] = 8, ["name"] = "stones:brushrock_22"}, {["x"] = 7, ["param2"] = 3, ["y"] = 0, ["param1"] = 93, ["z"] = 9, ["name"] = "stones:brushrock_0"}, {["x"] = 7, ["param2"] = 3, ["y"] = 0, ["param1"] = 109, ["z"] = 10, ["name"] = "stones:brushrock_0"}, {["x"] = 7, ["param2"] = 5, ["y"] = 0, ["param1"] = 94, ["z"] = 11, ["name"] = "stones:brushrock_22"}, {["x"] = 7, ["param2"] = 7, ["y"] = 1, ["param1"] = 94, ["z"] = 8, ["name"] = "stones:sku_20"}, {["x"] = 7, ["param2"] = 7, ["y"] = 1, ["param1"] = 110, ["z"] = 9, ["name"] = "stones:panel"}, {["x"] = 7, ["param2"] = 11, ["y"] = 1, ["param1"] = 125, ["z"] = 10, ["name"] = "stones:panel"}, {["x"] = 7, ["param2"] = 11, ["y"] = 1, ["param1"] = 110, ["z"] = 11, ["name"] = "stones:sku_20"}, {["x"] = 8, ["param2"] = 9, ["y"] = 0, ["param1"] = 46, ["z"] = 7, ["name"] = "stones:s_52"}, {["x"] = 8, ["param2"] = 3, ["y"] = 0, ["param1"] = 61, ["z"] = 8, ["name"] = "stones:brushrock_2"}, {["x"] = 8, ["param2"] = 3, ["y"] = 0, ["param1"] = 77, ["z"] = 9, ["name"] = "stones:brushrock_5"}, {["x"] = 8, ["param2"] = 2, ["y"] = 0, ["param1"] = 92, ["z"] = 10, ["name"] = "stones:brushrock_2"}, {["x"] = 8, ["param2"] = 2, ["y"] = 0, ["param1"] = 77, ["z"] = 11, ["name"] = "stones:brushrock_5"}, {["x"] = 8, ["param2"] = 5, ["y"] = 0, ["param1"] = 62, ["z"] = 12, ["name"] = "stones:s_52"}, {["x"] = 8, ["param2"] = 9, ["y"] = 1, ["param1"] = 62, ["z"] = 7, ["name"] = "stones:s_52l"}, {["x"] = 8, ["param2"] = 7, ["y"] = 1, ["param1"] = 78, ["z"] = 8, ["name"] = "stones:s_52l"}, {["x"] = 8, ["param2"] = 9, ["y"] = 1, ["param1"] = 94, ["z"] = 9, ["name"] = "stones:s_22"}, {["x"] = 8, ["param2"] = 5, ["y"] = 1, ["param1"] = 109, ["z"] = 10, ["name"] = "stones:s_22"}, {["x"] = 8, ["param2"] = 11, ["y"] = 1, ["param1"] = 94, ["z"] = 11, ["name"] = "stones:s_52r"}, {["x"] = 8, ["param2"] = 5, ["y"] = 1, ["param1"] = 78, ["z"] = 12, ["name"] = "stones:s_52r"}, {["x"] = 9, ["param2"] = 11, ["y"] = 0, ["param1"] = 30, ["z"] = 7, ["name"] = "stones:s_52"}, {["x"] = 9, ["y"] = 0, ["param1"] = 45, ["z"] = 8, ["name"] = "stones:brushrock_5"}, {["x"] = 9, ["y"] = 0, ["param1"] = 61, ["z"] = 9, ["name"] = "stones:brushrock_2"}, {["x"] = 9, ["param2"] = 1, ["y"] = 0, ["param1"] = 76, ["z"] = 10, ["name"] = "stones:brushrock_5"}, {["x"] = 9, ["param2"] = 1, ["y"] = 0, ["param1"] = 61, ["z"] = 11, ["name"] = "stones:brushrock_2"}, {["x"] = 9, ["param2"] = 7, ["y"] = 0, ["param1"] = 46, ["z"] = 12, ["name"] = "stones:s_52"}, {["x"] = 9, ["param2"] = 11, ["y"] = 1, ["param1"] = 46, ["z"] = 7, ["name"] = "stones:s_52r"}, {["x"] = 9, ["param2"] = 5, ["y"] = 1, ["param1"] = 62, ["z"] = 8, ["name"] = "stones:s_52r"}, {["x"] = 9, ["param2"] = 11, ["y"] = 1, ["param1"] = 78, ["z"] = 9, ["name"] = "stones:s_22"}, {["x"] = 9, ["param2"] = 7, ["y"] = 1, ["param1"] = 93, ["z"] = 10, ["name"] = "stones:s_22"}, {["x"] = 9, ["param2"] = 9, ["y"] = 1, ["param1"] = 78, ["z"] = 11, ["name"] = "stones:s_52l"}, {["x"] = 9, ["param2"] = 7, ["y"] = 1, ["param1"] = 62, ["z"] = 12, ["name"] = "stones:s_52l"}, {["x"] = 10, ["param2"] = 11, ["y"] = 0, ["param1"] = 30, ["z"] = 8, ["name"] = "stones:brushrock_22"}, {["x"] = 10, ["param2"] = 2, ["y"] = 0, ["param1"] = 45, ["z"] = 9, ["name"] = "stones:brushrock_2"}, {["x"] = 10, ["param2"] = 3, ["y"] = 0, ["param1"] = 61, ["z"] = 10, ["name"] = "stones:brushrock_5"}, {["x"] = 10, ["param2"] = 14, ["y"] = 0, ["param1"] = 46, ["z"] = 11, ["name"] = "stones:brushrock_22"}, {["x"] = 10, ["param2"] = 5, ["y"] = 1, ["param1"] = 46, ["z"] = 8, ["name"] = "stones:sku_20"}, {["x"] = 10, ["param2"] = 5, ["y"] = 1, ["param1"] = 62, ["z"] = 9, ["name"] = "stones:s_22"}, {["x"] = 10, ["param2"] = 9, ["y"] = 1, ["param1"] = 77, ["z"] = 10, ["name"] = "stones:s_22"}, {["x"] = 10, ["param2"] = 16, ["y"] = 1, ["param1"] = 62, ["z"] = 11, ["name"] = "stones:sku_20"}, {["x"] = 11, ["param2"] = 16, ["y"] = 0, ["param1"] = 14, ["z"] = 1, ["name"] = "stones:s_52"}, {["x"] = 11, ["param2"] = 16, ["y"] = 0, ["param1"] = 14, ["z"] = 2, ["name"] = "stones:roch"}, {["x"] = 11, ["param2"] = 16, ["y"] = 0, ["param1"] = 14, ["z"] = 3, ["name"] = "stones:roch"}, {["x"] = 11, ["param2"] = 16, ["y"] = 0, ["param1"] = 30, ["z"] = 4, ["name"] = "stones:roch"}, {["x"] = 11, ["param2"] = 18, ["y"] = 0, ["param1"] = 46, ["z"] = 5, ["name"] = "stones:s_52"}, {["x"] = 11, ["param2"] = 9, ["y"] = 0, ["param1"] = 30, ["z"] = 8, ["name"] = "stones:s_2"}, {["x"] = 11, ["param2"] = 4, ["y"] = 0, ["param1"] = 29, ["z"] = 9, ["name"] = "stones:rock"}, {["x"] = 11, ["param2"] = 3, ["y"] = 0, ["param1"] = 45, ["z"] = 10, ["name"] = "stones:brushrock_2"}, {["x"] = 11, ["param2"] = 5, ["y"] = 0, ["param1"] = 62, ["z"] = 11, ["name"] = "stones:brushrock_22"}, {["x"] = 11, ["param2"] = 16, ["y"] = 1, ["param1"] = 14, ["z"] = 1, ["name"] = "stones:s_52r"}, {["x"] = 11, ["param2"] = 6, ["y"] = 1, ["param1"] = 14, ["z"] = 2, ["name"] = "stones:stair_half_l"}, {["x"] = 11, ["param2"] = 17, ["y"] = 1, ["param1"] = 30, ["z"] = 3, ["name"] = "stones:panel"}, {["x"] = 11, ["param2"] = 8, ["y"] = 1, ["param1"] = 46, ["z"] = 4, ["name"] = "stones:stair_half_r"}, {["x"] = 11, ["param2"] = 18, ["y"] = 1, ["param1"] = 62, ["z"] = 5, ["name"] = "stones:s_52l"}, {["x"] = 11, ["param2"] = 9, ["y"] = 1, ["param1"] = 46, ["z"] = 8, ["name"] = "stones:s_2"}, {["x"] = 11, ["param2"] = 7, ["y"] = 1, ["param1"] = 45, ["z"] = 9, ["name"] = "stones:s_52"}, {["x"] = 11, ["param2"] = 11, ["y"] = 1, ["param1"] = 61, ["z"] = 10, ["name"] = "stones:s_22"}, {["x"] = 11, ["param2"] = 11, ["y"] = 1, ["param1"] = 78, ["z"] = 11, ["name"] = "stones:sku_20"}, {["x"] = 11, ["param2"] = 16, ["y"] = 2, ["param1"] = 62, ["z"] = 8, ["name"] = "stones:vsect"}, {["x"] = 11, ["param2"] = 7, ["y"] = 2, ["param1"] = 62, ["z"] = 9, ["name"] = "stones:s_52p"}, {["x"] = 12, ["param2"] = 16, ["y"] = 0, ["param1"] = 14, ["z"] = 0, ["name"] = "stones:brushrock_22"}, {["x"] = 12, ["param2"] = 1, ["y"] = 0, ["param1"] = 13, ["z"] = 1, ["name"] = "stones:brushrock_5"}, {["x"] = 12, ["param2"] = 2, ["y"] = 0, ["param1"] = 14, ["z"] = 2, ["name"] = "stones:brush"}, {["x"] = 12, ["param2"] = 2, ["y"] = 0, ["param1"] = 30, ["z"] = 3, ["name"] = "stones:brush"}, {["x"] = 12, ["param2"] = 3, ["y"] = 0, ["param1"] = 46, ["z"] = 4, ["name"] = "stones:brush"}, {["x"] = 12, ["y"] = 0, ["param1"] = 61, ["z"] = 5, ["name"] = "stones:brushrock_2"}, {["x"] = 12, ["param2"] = 18, ["y"] = 0, ["param1"] = 78, ["z"] = 6, ["name"] = "stones:brushrock_52ur"}, {["x"] = 12, ["param2"] = 16, ["y"] = 0, ["param1"] = 62, ["z"] = 7, ["name"] = "stones:s_52u"}, {["x"] = 12, ["y"] = 0, ["param1"] = 45, ["z"] = 8, ["name"] = "stones:rock"}, {["x"] = 12, ["y"] = 0, ["param1"] = 44, ["z"] = 9, ["name"] = "stones:rock"}, {["x"] = 12, ["y"] = 0, ["param1"] = 60, ["z"] = 10, ["name"] = "stones:brushrock_5"}, {["x"] = 12, ["param2"] = 2, ["y"] = 0, ["param1"] = 77, ["z"] = 11, ["name"] = "stones:brushrock_5"}, {["x"] = 12, ["param2"] = 5, ["y"] = 0, ["param1"] = 94, ["z"] = 12, ["name"] = "stones:s_52"}, {["x"] = 12, ["param2"] = 7, ["y"] = 1, ["param1"] = 14, ["z"] = 0, ["name"] = "stones:sku_202"}, {["x"] = 12, ["param2"] = 14, ["y"] = 1, ["param1"] = 14, ["z"] = 1, ["name"] = "stones:s_52r"}, {["x"] = 12, ["param2"] = 12, ["y"] = 1, ["param1"] = 78, ["z"] = 5, ["name"] = "stones:s_52l"}, {["x"] = 12, ["param2"] = 12, ["y"] = 1, ["param1"] = 94, ["z"] = 6, ["name"] = "stones:sku2_l"}, {["x"] = 12, ["param2"] = 16, ["y"] = 1, ["param1"] = 78, ["z"] = 7, ["name"] = "stones:s_52u"}, {["x"] = 12, ["param2"] = 3, ["y"] = 1, ["param1"] = 61, ["z"] = 8, ["name"] = "stones:diagsteps_8r"}, {["x"] = 12, ["param2"] = 11, ["y"] = 1, ["param1"] = 94, ["z"] = 11, ["name"] = "stones:s_52r"}, {["x"] = 12, ["param2"] = 5, ["y"] = 1, ["param1"] = 110, ["z"] = 12, ["name"] = "stones:s_52r"}, {["x"] = 12, ["param2"] = 9, ["y"] = 2, ["param1"] = 94, ["z"] = 7, ["name"] = "stones:s_2"}, {["x"] = 12, ["param2"] = 7, ["y"] = 2, ["param1"] = 78, ["z"] = 8, ["name"] = "stones:s_2"}, {["x"] = 12, ["param2"] = 9, ["y"] = 3, ["param1"] = 110, ["z"] = 7, ["name"] = "stones:s_2"}, {["x"] = 12, ["param2"] = 4, ["y"] = 3, ["param1"] = 94, ["z"] = 8, ["name"] = "stones:vsect"}, {["x"] = 12, ["param2"] = 9, ["y"] = 4, ["param1"] = 126, ["z"] = 7, ["name"] = "stones:panel"}, {["x"] = 12, ["y"] = 5, ["param1"] = 142, ["z"] = 7, ["name"] = "stones:s_22r"}, {["x"] = 12, ["param2"] = 1, ["y"] = 5, ["param1"] = 126, ["z"] = 8, ["name"] = "stones:panel"}, {["x"] = 12, ["param2"] = 18, ["y"] = 5, ["param1"] = 110, ["z"] = 9, ["name"] = "stones:s_52r"}, {["x"] = 13, ["param2"] = 2, ["y"] = 0, ["param1"] = 14, ["z"] = 0, ["name"] = "stones:brushrock_0"}, {["x"] = 13, ["param2"] = 2, ["y"] = 0, ["param1"] = 14, ["z"] = 1, ["name"] = "stones:brush"}, {["x"] = 13, ["param2"] = 2, ["y"] = 0, ["param1"] = 30, ["z"] = 2, ["name"] = "stones:brush"}, {["x"] = 13, ["param2"] = 2, ["y"] = 0, ["param1"] = 46, ["z"] = 3, ["name"] = "stones:brush"}, {["x"] = 13, ["param2"] = 2, ["y"] = 0, ["param1"] = 62, ["z"] = 4, ["name"] = "stones:brush"}, {["x"] = 13, ["param2"] = 3, ["y"] = 0, ["param1"] = 78, ["z"] = 5, ["name"] = "stones:brush"}, {["x"] = 13, ["param2"] = 3, ["y"] = 0, ["param1"] = 93, ["z"] = 6, ["name"] = "stones:brush"}, {["x"] = 13, ["y"] = 0, ["param1"] = 77, ["z"] = 7, ["name"] = "stones:rock"}, {["x"] = 13, ["y"] = 0, ["param1"] = 61, ["z"] = 8, ["name"] = "stones:rock"}, {["x"] = 13, ["y"] = 0, ["param1"] = 60, ["z"] = 9, ["name"] = "stones:rock"}, {["x"] = 13, ["y"] = 0, ["param1"] = 77, ["z"] = 10, ["name"] = "stones:brushrock_4"}, {["x"] = 13, ["param2"] = 1, ["y"] = 0, ["param1"] = 94, ["z"] = 11, ["name"] = "stones:brush"}, {["x"] = 13, ["param2"] = 5, ["y"] = 0, ["param1"] = 110, ["z"] = 12, ["name"] = "stones:brushrock_52ul"}, {["x"] = 13, ["param2"] = 15, ["y"] = 1, ["param1"] = 14, ["z"] = 0, ["name"] = "stones:stair_half_l"}, {["x"] = 13, ["param2"] = 4, ["y"] = 1, ["param1"] = 93, ["z"] = 7, ["name"] = "runes:lit_hui"}, {["x"] = 13, ["param2"] = 2, ["y"] = 1, ["param1"] = 78, ["z"] = 8, ["name"] = "stones:diagsteps"}, {["x"] = 13, ["param2"] = 1, ["y"] = 1, ["param1"] = 77, ["z"] = 9, ["name"] = "stones:diagsteps_8l"}, {["x"] = 13, ["param2"] = 2, ["y"] = 1, ["param1"] = 94, ["z"] = 10, ["name"] = "stones:diaq"}, {["x"] = 13, ["param2"] = 5, ["y"] = 1, ["param1"] = 126, ["z"] = 12, ["name"] = "stones:sku2_r"}, {["x"] = 13, ["param2"] = 20, ["y"] = 2, ["param1"] = 126, ["z"] = 6, ["name"] = "stones:aset_2"}, {["x"] = 13, ["param2"] = 3, ["y"] = 2, ["param1"] = 110, ["z"] = 7, ["name"] = "stones:diagsteps_8r"}, {["x"] = 13, ["param2"] = 9, ["y"] = 2, ["param1"] = 78, ["z"] = 9, ["name"] = "stones:s_2"}, {["x"] = 13, ["param2"] = 2, ["y"] = 2, ["param1"] = 78, ["z"] = 10, ["name"] = "stones:diaq"}, {["x"] = 13, ["param2"] = 7, ["y"] = 3, ["param1"] = 142, ["z"] = 6, ["name"] = "stones:sku_20"}, {["x"] = 13, ["param2"] = 7, ["y"] = 3, ["param1"] = 126, ["z"] = 7, ["name"] = "stones:s_22"}, {["x"] = 13, ["param2"] = 9, ["y"] = 3, ["param1"] = 94, ["z"] = 9, ["name"] = "stones:s_2"}, {["x"] = 13, ["param2"] = 22, ["y"] = 3, ["param1"] = 78, ["z"] = 10, ["name"] = "stones:diaq"}, {["x"] = 13, ["y"] = 4, ["param1"] = 110, ["z"] = 9, ["name"] = "stones:diaq"}, {["x"] = 13, ["param2"] = 2, ["y"] = 4, ["param1"] = 94, ["z"] = 10, ["name"] = "stones:diaq"}, {["x"] = 13, ["y"] = 5, ["param1"] = 126, ["z"] = 9, ["name"] = "stones:diagstep"}, {["x"] = 13, ["param2"] = 2, ["y"] = 5, ["param1"] = 110, ["z"] = 10, ["name"] = "stones:diagstep_2"}, {["x"] = 14, ["param2"] = 2, ["y"] = 0, ["param1"] = 14, ["z"] = 0, ["name"] = "stones:brushrock_0"}, {["x"] = 14, ["param2"] = 3, ["y"] = 0, ["param1"] = 30, ["z"] = 1, ["name"] = "stones:brush"}, {["x"] = 14, ["param2"] = 1, ["y"] = 0, ["param1"] = 46, ["z"] = 2, ["name"] = "stones:brush"}, {["x"] = 14, ["param2"] = 1, ["y"] = 0, ["param1"] = 61, ["z"] = 3, ["name"] = "stones:brushrock_3"}, {["x"] = 14, ["y"] = 0, ["param1"] = 77, ["z"] = 4, ["name"] = "stones:rock"}, {["x"] = 14, ["param2"] = 2, ["y"] = 0, ["param1"] = 93, ["z"] = 5, ["name"] = "stones:brushrock_3"}, {["x"] = 14, ["param2"] = 3, ["y"] = 0, ["param1"] = 108, ["z"] = 6, ["name"] = "stones:brushrock_4"}, {["x"] = 14, ["y"] = 0, ["param1"] = 92, ["z"] = 7, ["name"] = "stones:rock"}, {["x"] = 14, ["y"] = 0, ["param1"] = 76, ["z"] = 8, ["name"] = "stones:rock"}, {["x"] = 14, ["y"] = 0, ["param1"] = 77, ["z"] = 9, ["name"] = "stones:rock"}, {["x"] = 14, ["param2"] = 1, ["y"] = 0, ["param1"] = 93, ["z"] = 10, ["name"] = "stones:brushrock_5"}, {["x"] = 14, ["param2"] = 1, ["y"] = 0, ["param1"] = 110, ["z"] = 11, ["name"] = "stones:brush"}, {["x"] = 14, ["param2"] = 2, ["y"] = 0, ["param1"] = 125, ["z"] = 12, ["name"] = "stones:brushrock_5"}, {["x"] = 14, ["param2"] = 5, ["y"] = 0, ["param1"] = 142, ["z"] = 13, ["name"] = "stones:s_52"}, {["x"] = 14, ["param2"] = 6, ["y"] = 1, ["param1"] = 30, ["z"] = 0, ["name"] = "stones:panel"}, {["x"] = 14, ["param2"] = 9, ["y"] = 1, ["param1"] = 78, ["z"] = 3, ["name"] = "stones:s_52r"}, {["x"] = 14, ["y"] = 1, ["param1"] = 94, ["z"] = 4, ["name"] = "stones:rock"}, {["x"] = 14, ["param2"] = 8, ["y"] = 1, ["param1"] = 109, ["z"] = 7, ["name"] = "stones:vr"}, {["x"] = 14, ["param2"] = 16, ["y"] = 1, ["param1"] = 93, ["z"] = 8, ["name"] = "runes:lit_hui"}, {["x"] = 14, ["param2"] = 3, ["y"] = 1, ["param1"] = 94, ["z"] = 9, ["name"] = "stones:plot"}, {["x"] = 14, ["param2"] = 11, ["y"] = 1, ["param1"] = 142, ["z"] = 12, ["name"] = "stones:s_52r"}, {["x"] = 14, ["param2"] = 5, ["y"] = 1, ["param1"] = 158, ["z"] = 13, ["name"] = "stones:s_52r"}, {["x"] = 14, ["param2"] = 13, ["y"] = 2, ["param1"] = 110, ["z"] = 4, ["name"] = "stones:stair_5"}, {["x"] = 14, ["param2"] = 3, ["y"] = 2, ["param1"] = 126, ["z"] = 5, ["name"] = "stones:arch"}, {["x"] = 14, ["param2"] = 7, ["y"] = 2, ["param1"] = 141, ["z"] = 6, ["name"] = "stones:arch"}, {["x"] = 14, ["param2"] = 2, ["y"] = 2, ["param1"] = 126, ["z"] = 7, ["name"] = "stones:diagsteps"}, {["x"] = 14, ["param2"] = 1, ["y"] = 2, ["param1"] = 110, ["z"] = 8, ["name"] = "stones:diagsteps_8l"}, {["x"] = 14, ["param2"] = 4, ["y"] = 2, ["param1"] = 94, ["z"] = 9, ["name"] = "stones:shrub"}, {["x"] = 14, ["param2"] = 13, ["y"] = 3, ["param1"] = 126, ["z"] = 4, ["name"] = "stones:cish"}, {["x"] = 14, ["param2"] = 12, ["y"] = 3, ["param1"] = 142, ["z"] = 5, ["name"] = "stones:roch"}, {["x"] = 14, ["param2"] = 7, ["y"] = 3, ["param1"] = 158, ["z"] = 6, ["name"] = "stones:s_22"}, {["x"] = 14, ["param2"] = 9, ["y"] = 3, ["param1"] = 126, ["z"] = 8, ["name"] = "stones:s_2"}, {["x"] = 14, ["param2"] = 3, ["y"] = 3, ["param1"] = 110, ["z"] = 9, ["name"] = "stones:cis"}, {["x"] = 15, ["param2"] = 2, ["y"] = 0, ["param1"] = 30, ["z"] = 0, ["name"] = "stones:brushrock_0"}, {["x"] = 15, ["param2"] = 2, ["y"] = 0, ["param1"] = 46, ["z"] = 1, ["name"] = "stones:brush"}, {["x"] = 15, ["param2"] = 1, ["y"] = 0, ["param1"] = 62, ["z"] = 2, ["name"] = "stones:brush"}, {["x"] = 15, ["y"] = 0, ["param1"] = 77, ["z"] = 3, ["name"] = "stones:rock"}, {["x"] = 15, ["y"] = 0, ["param1"] = 92, ["z"] = 4, ["name"] = "stones:rock"}, {["x"] = 15, ["y"] = 0, ["param1"] = 108, ["z"] = 5, ["name"] = "stones:rock"}, {["x"] = 15, ["y"] = 0, ["param1"] = 124, ["z"] = 6, ["name"] = "stones:rock"}, {["x"] = 15, ["param2"] = 2, ["y"] = 0, ["param1"] = 108, ["z"] = 7, ["name"] = "stones:brushrock_8"}, {["x"] = 15, ["param2"] = 2, ["y"] = 0, ["param1"] = 93, ["z"] = 8, ["name"] = "stones:brush"}, {["x"] = 15, ["param2"] = 2, ["y"] = 0, ["param1"] = 94, ["z"] = 9, ["name"] = "stones:brush"}, {["x"] = 15, ["param2"] = 1, ["y"] = 0, ["param1"] = 109, ["z"] = 10, ["name"] = "stones:brush"}, {["x"] = 15, ["param2"] = 1, ["y"] = 0, ["param1"] = 126, ["z"] = 11, ["name"] = "stones:brush"}, {["x"] = 15, ["y"] = 0, ["param1"] = 142, ["z"] = 12, ["name"] = "stones:brush"}, {["x"] = 15, ["param2"] = 3, ["y"] = 0, ["param1"] = 157, ["z"] = 13, ["name"] = "stones:brushrock_0"}, {["x"] = 15, ["param2"] = 3, ["y"] = 0, ["param1"] = 174, ["z"] = 14, ["name"] = "stones:brushrock_0"}, {["x"] = 15, ["param2"] = 3, ["y"] = 0, ["param1"] = 190, ["z"] = 15, ["name"] = "stones:brushrock_0"}, {["x"] = 15, ["param2"] = 3, ["y"] = 0, ["param1"] = 206, ["z"] = 16, ["name"] = "stones:brushrock_0"}, {["x"] = 15, ["param2"] = 3, ["y"] = 0, ["param1"] = 190, ["z"] = 17, ["name"] = "stones:brushrock_0"}, {["x"] = 15, ["param2"] = 3, ["y"] = 0, ["param1"] = 174, ["z"] = 18, ["name"] = "stones:brushrock_0"}, {["x"] = 15, ["param2"] = 3, ["y"] = 0, ["param1"] = 158, ["z"] = 19, ["name"] = "stones:brushrock_0"}, {["x"] = 15, ["param2"] = 6, ["y"] = 1, ["param1"] = 46, ["z"] = 0, ["name"] = "stones:panel"}, {["x"] = 15, ["y"] = 1, ["param1"] = 94, ["z"] = 3, ["name"] = "stones:panel"}, {["x"] = 15, ["y"] = 1, ["param1"] = 109, ["z"] = 4, ["name"] = "stones:rock"}, {["x"] = 15, ["param2"] = 6, ["y"] = 1, ["param1"] = 174, ["z"] = 13, ["name"] = "stones:stair_half_r"}, {["x"] = 15, ["param2"] = 6, ["y"] = 1, ["param1"] = 190, ["z"] = 14, ["name"] = "stones:stair_half_r"}, {["x"] = 15, ["param2"] = 6, ["y"] = 1, ["param1"] = 206, ["z"] = 15, ["name"] = "stones:stair_half_r"}, {["x"] = 15, ["param2"] = 6, ["y"] = 1, ["param1"] = 222, ["z"] = 16, ["name"] = "stones:stair_half_r"}, {["x"] = 15, ["param2"] = 6, ["y"] = 1, ["param1"] = 206, ["z"] = 17, ["name"] = "stones:stair_half_r"}, {["x"] = 15, ["param2"] = 6, ["y"] = 1, ["param1"] = 190, ["z"] = 18, ["name"] = "stones:stair_half_r"}, {["x"] = 15, ["param2"] = 6, ["y"] = 1, ["param1"] = 174, ["z"] = 19, ["name"] = "stones:stair_half_r"}, {["x"] = 15, ["y"] = 2, ["param1"] = 126, ["z"] = 4, ["name"] = "stones:panel"}, {["x"] = 15, ["param2"] = 3, ["y"] = 2, ["param1"] = 142, ["z"] = 5, ["name"] = "stones:arch"}, {["x"] = 15, ["y"] = 2, ["param1"] = 157, ["z"] = 6, ["name"] = "stones:arco"}, {["x"] = 15, ["param2"] = 3, ["y"] = 2, ["param1"] = 141, ["z"] = 7, ["name"] = "stones:arco"}, {["x"] = 15, ["param2"] = 1, ["y"] = 3, ["param1"] = 174, ["z"] = 6, ["name"] = "stones:cish"}, {["x"] = 15, ["param2"] = 1, ["y"] = 3, ["param1"] = 158, ["z"] = 7, ["name"] = "stones:diagsteps_8l"}, {["x"] = 15, ["param2"] = 8, ["y"] = 3, ["param1"] = 142, ["z"] = 8, ["name"] = "stones:arch"}, {["x"] = 16, ["param2"] = 2, ["y"] = 0, ["param1"] = 46, ["z"] = 0, ["name"] = "stones:brushrock_0"}, {["x"] = 16, ["param2"] = 2, ["y"] = 0, ["param1"] = 62, ["z"] = 1, ["name"] = "stones:brush"}, {["x"] = 16, ["param2"] = 1, ["y"] = 0, ["param1"] = 78, ["z"] = 2, ["name"] = "stones:brush"}, {["x"] = 16, ["y"] = 0, ["param1"] = 93, ["z"] = 3, ["name"] = "stones:rock"}, {["x"] = 16, ["y"] = 0, ["param1"] = 109, ["z"] = 4, ["name"] = "stones:rock"}, {["x"] = 16, ["y"] = 0, ["param1"] = 125, ["z"] = 5, ["name"] = "stones:rock"}, {["x"] = 16, ["y"] = 0, ["param1"] = 141, ["z"] = 6, ["name"] = "stones:rock"}, {["x"] = 16, ["param2"] = 1, ["y"] = 0, ["param1"] = 125, ["z"] = 7, ["name"] = "stones:brushrock_8"}, {["x"] = 16, ["param2"] = 2, ["y"] = 0, ["param1"] = 109, ["z"] = 8, ["name"] = "stones:brush"}, {["x"] = 16, ["param2"] = 2, ["y"] = 0, ["param1"] = 110, ["z"] = 9, ["name"] = "stones:brush"}, {["x"] = 16, ["param2"] = 1, ["y"] = 0, ["param1"] = 125, ["z"] = 10, ["name"] = "stones:brush"}, {["x"] = 16, ["param2"] = 1, ["y"] = 0, ["param1"] = 142, ["z"] = 11, ["name"] = "stones:brush"}, {["x"] = 16, ["y"] = 0, ["param1"] = 158, ["z"] = 12, ["name"] = "stones:brush"}, {["x"] = 16, ["y"] = 0, ["param1"] = 174, ["z"] = 13, ["name"] = "stones:brush"}, {["x"] = 16, ["y"] = 0, ["param1"] = 190, ["z"] = 14, ["name"] = "stones:brush"}, {["x"] = 16, ["param2"] = 1, ["y"] = 0, ["param1"] = 206, ["z"] = 15, ["name"] = "stones:brush"}, {["x"] = 16, ["y"] = 0, ["param1"] = 222, ["z"] = 16, ["name"] = "stones:brush"}, {["x"] = 16, ["y"] = 0, ["param1"] = 206, ["z"] = 17, ["name"] = "stones:brush"}, {["x"] = 16, ["y"] = 0, ["param1"] = 190, ["z"] = 18, ["name"] = "stones:brush"}, {["x"] = 16, ["y"] = 0, ["param1"] = 174, ["z"] = 19, ["name"] = "stones:brush"}, {["x"] = 16, ["param2"] = 15, ["y"] = 1, ["param1"] = 62, ["z"] = 0, ["name"] = "stones:stair_half_l"}, {["x"] = 16, ["y"] = 1, ["param1"] = 110, ["z"] = 3, ["name"] = "stones:panel"}, {["x"] = 16, ["y"] = 1, ["param1"] = 125, ["z"] = 4, ["name"] = "stones:rock"}, {["x"] = 16, ["param2"] = 18, ["y"] = 1, ["param1"] = 141, ["z"] = 5, ["name"] = "stones:s_52ur"}, {["x"] = 16, ["param2"] = 18, ["y"] = 1, ["param1"] = 157, ["z"] = 6, ["name"] = "stones:s_52r"}, {["x"] = 16, ["y"] = 1, ["param1"] = 239, ["z"] = 16, ["name"] = "tool:dice"}, {["x"] = 16, ["param2"] = 4, ["y"] = 1, ["param1"] = 191, ["z"] = 19, ["name"] = "stones:shrub"}, {["x"] = 16, ["y"] = 2, ["param1"] = 142, ["z"] = 4, ["name"] = "stones:panel"}, {["x"] = 16, ["param2"] = 2, ["y"] = 2, ["param1"] = 157, ["z"] = 5, ["name"] = "stones:arci"}, {["x"] = 16, ["param2"] = 2, ["y"] = 2, ["param1"] = 173, ["z"] = 6, ["name"] = "stones:arch"}, {["x"] = 16, ["param2"] = 2, ["y"] = 2, ["param1"] = 157, ["z"] = 7, ["name"] = "stones:arco"}, {["x"] = 16, ["param2"] = 16, ["y"] = 3, ["param1"] = 174, ["z"] = 5, ["name"] = "stones:brushrock_22"}, {["x"] = 16, ["param2"] = 3, ["y"] = 3, ["param1"] = 190, ["z"] = 6, ["name"] = "stones:brushrock_0"}, {["x"] = 16, ["y"] = 3, ["param1"] = 174, ["z"] = 7, ["name"] = "stones:brushrock_3"}, {["x"] = 16, ["param2"] = 10, ["y"] = 3, ["param1"] = 158, ["z"] = 8, ["name"] = "stones:arch"}, {["x"] = 17, ["param2"] = 11, ["y"] = 0, ["param1"] = 62, ["z"] = 0, ["name"] = "stones:brushrock_22"}, {["x"] = 17, ["param2"] = 1, ["y"] = 0, ["param1"] = 78, ["z"] = 1, ["name"] = "stones:brushrock_0"}, {["x"] = 17, ["param2"] = 1, ["y"] = 0, ["param1"] = 94, ["z"] = 2, ["name"] = "stones:brushrock_0"}, {["x"] = 17, ["param2"] = 7, ["y"] = 0, ["param1"] = 110, ["z"] = 3, ["name"] = "stones:s_2"}, {["x"] = 17, ["param2"] = 11, ["y"] = 0, ["param1"] = 126, ["z"] = 4, ["name"] = "stones:s_2"}, {["x"] = 17, ["y"] = 0, ["param1"] = 142, ["z"] = 5, ["name"] = "stones:rock"}, {["x"] = 17, ["y"] = 0, ["param1"] = 158, ["z"] = 6, ["name"] = "stones:rock"}, {["x"] = 17, ["y"] = 0, ["param1"] = 142, ["z"] = 7, ["name"] = "stones:rock"}, {["x"] = 17, ["y"] = 0, ["param1"] = 126, ["z"] = 8, ["name"] = "stones:rock"}, {["x"] = 17, ["y"] = 0, ["param1"] = 110, ["z"] = 9, ["name"] = "stones:rock"}, {["x"] = 17, ["y"] = 0, ["param1"] = 110, ["z"] = 10, ["name"] = "stones:rock"}, {["x"] = 17, ["param2"] = 1, ["y"] = 0, ["param1"] = 126, ["z"] = 11, ["name"] = "stones:rock"}, {["x"] = 17, ["param2"] = 2, ["y"] = 0, ["param1"] = 142, ["z"] = 12, ["name"] = "stones:brushrock_3"}, {["x"] = 17, ["param2"] = 1, ["y"] = 0, ["param1"] = 158, ["z"] = 13, ["name"] = "stones:brushrock_0"}, {["x"] = 17, ["param2"] = 1, ["y"] = 0, ["param1"] = 174, ["z"] = 14, ["name"] = "stones:brushrock_0"}, {["x"] = 17, ["param2"] = 1, ["y"] = 0, ["param1"] = 190, ["z"] = 15, ["name"] = "stones:brushrock_0"}, {["x"] = 17, ["param2"] = 1, ["y"] = 0, ["param1"] = 206, ["z"] = 16, ["name"] = "stones:brushrock_0"}, {["x"] = 17, ["param2"] = 1, ["y"] = 0, ["param1"] = 190, ["z"] = 17, ["name"] = "stones:brushrock_0"}, {["x"] = 17, ["param2"] = 1, ["y"] = 0, ["param1"] = 174, ["z"] = 18, ["name"] = "stones:brushrock_0"}, {["x"] = 17, ["param2"] = 1, ["y"] = 0, ["param1"] = 158, ["z"] = 19, ["name"] = "stones:brushrock_0"}, {["x"] = 17, ["param2"] = 18, ["y"] = 1, ["param1"] = 78, ["z"] = 0, ["name"] = "stones:sku_202"}, {["x"] = 17, ["param2"] = 6, ["y"] = 1, ["param1"] = 94, ["z"] = 1, ["name"] = "stones:stair_half_l"}, {["x"] = 17, ["param2"] = 8, ["y"] = 1, ["param1"] = 110, ["z"] = 2, ["name"] = "stones:stair_half_r"}, {["x"] = 17, ["param2"] = 11, ["y"] = 1, ["param1"] = 126, ["z"] = 3, ["name"] = "stones:s_52l"}, {["x"] = 17, ["y"] = 1, ["param1"] = 142, ["z"] = 4, ["name"] = "stones:rock"}, {["x"] = 17, ["y"] = 1, ["param1"] = 158, ["z"] = 5, ["name"] = "stones:rock"}, {["x"] = 17, ["y"] = 1, ["param1"] = 174, ["z"] = 6, ["name"] = "stones:rock"}, {["x"] = 17, ["param2"] = 2, ["y"] = 1, ["param1"] = 158, ["z"] = 7, ["name"] = "stones:s_52ul"}, {["x"] = 17, ["y"] = 1, ["param1"] = 142, ["z"] = 8, ["name"] = "stones:s_52ur"}, {["x"] = 17, ["y"] = 1, ["param1"] = 126, ["z"] = 9, ["name"] = "stones:rock"}, {["x"] = 17, ["param2"] = 2, ["y"] = 1, ["param1"] = 126, ["z"] = 10, ["name"] = "stones:s_52ul"}, {["x"] = 17, ["y"] = 1, ["param1"] = 142, ["z"] = 11, ["name"] = "stones:s_52ur"}, {["x"] = 17, ["param2"] = 18, ["y"] = 1, ["param1"] = 158, ["z"] = 12, ["name"] = "stones:s_52u"}, {["x"] = 17, ["param2"] = 4, ["y"] = 1, ["param1"] = 174, ["z"] = 13, ["name"] = "stones:estruk"}, {["x"] = 17, ["param2"] = 4, ["y"] = 1, ["param1"] = 190, ["z"] = 14, ["name"] = "stones:estruk"}, {["x"] = 17, ["param2"] = 4, ["y"] = 1, ["param1"] = 206, ["z"] = 15, ["name"] = "stones:estruk"}, {["x"] = 17, ["param2"] = 4, ["y"] = 1, ["param1"] = 222, ["z"] = 16, ["name"] = "stones:estruk"}, {["x"] = 17, ["param2"] = 4, ["y"] = 1, ["param1"] = 206, ["z"] = 17, ["name"] = "stones:estruk"}, {["x"] = 17, ["param2"] = 4, ["y"] = 1, ["param1"] = 190, ["z"] = 18, ["name"] = "stones:estruk"}, {["x"] = 17, ["param2"] = 4, ["y"] = 1, ["param1"] = 174, ["z"] = 19, ["name"] = "stones:estruk"}, {["x"] = 17, ["y"] = 2, ["param1"] = 126, ["z"] = 2, ["name"] = "stones:s_22r"}, {["x"] = 17, ["y"] = 2, ["param1"] = 142, ["z"] = 3, ["name"] = "stones:sku2_r"}, {["x"] = 17, ["y"] = 2, ["param1"] = 158, ["z"] = 4, ["name"] = "stones:rock"}, {["x"] = 17, ["y"] = 2, ["param1"] = 174, ["z"] = 5, ["name"] = "stones:rock"}, {["x"] = 17, ["y"] = 2, ["param1"] = 190, ["z"] = 6, ["name"] = "stones:rock"}, {["x"] = 17, ["param2"] = 3, ["y"] = 2, ["param1"] = 174, ["z"] = 7, ["name"] = "stones:arch"}, {["x"] = 17, ["param2"] = 1, ["y"] = 2, ["param1"] = 158, ["z"] = 8, ["name"] = "stones:arch"}, {["x"] = 17, ["y"] = 2, ["param1"] = 142, ["z"] = 9, ["name"] = "stones:rock"}, {["x"] = 17, ["param2"] = 3, ["y"] = 2, ["param1"] = 126, ["z"] = 10, ["name"] = "stones:arch"}, {["x"] = 17, ["param2"] = 1, ["y"] = 2, ["param1"] = 126, ["z"] = 11, ["name"] = "stones:arch"}, {["x"] = 17, ["param2"] = 18, ["y"] = 2, ["param1"] = 142, ["z"] = 12, ["name"] = "stones:s_52u"}, {["x"] = 17, ["param2"] = 13, ["y"] = 3, ["param1"] = 174, ["z"] = 4, ["name"] = "stones:cis"}, {["x"] = 17, ["param2"] = 2, ["y"] = 3, ["param1"] = 190, ["z"] = 5, ["name"] = "stones:brushrock_0"}, {["x"] = 17, ["param2"] = 1, ["y"] = 3, ["param1"] = 206, ["z"] = 6, ["name"] = "stones:brush"}, {["x"] = 17, ["y"] = 3, ["param1"] = 190, ["z"] = 7, ["name"] = "stones:brush"}, {["x"] = 17, ["y"] = 3, ["param1"] = 174, ["z"] = 8, ["name"] = "stones:brushrock_2"}, {["x"] = 17, ["param2"] = 3, ["y"] = 3, ["param1"] = 158, ["z"] = 9, ["name"] = "stones:brushrock_0"}, {["x"] = 17, ["param2"] = 3, ["y"] = 3, ["param1"] = 142, ["z"] = 10, ["name"] = "stones:brushrock_0"}, {["x"] = 17, ["param2"] = 3, ["y"] = 3, ["param1"] = 126, ["z"] = 11, ["name"] = "stones:brushrock_0"}, {["x"] = 17, ["param2"] = 18, ["y"] = 3, ["param1"] = 126, ["z"] = 12, ["name"] = "stones:brushrock_52ur"}, {["x"] = 17, ["param2"] = 4, ["y"] = 4, ["param1"] = 191, ["z"] = 8, ["name"] = "stones:shrub"}, {["x"] = 17, ["param2"] = 1, ["y"] = 5, ["param1"] = 238, ["z"] = 6, ["name"] = "stones:octa"}}