5:return {{["x"] = 0, ["y"] = 0, ["param1"] = 14, ["z"] = 0, ["name"] = "stones:plot"}, {["x"] = 0, ["param2"] = 4, ["y"] = 0, ["param1"] = 30, ["z"] = 5, ["name"] = "stones:roch"}, {["x"] = 0, ["y"] = 0, ["param1"] = 14, ["z"] = 9, ["name"] = "stones:rock"}, {["x"] = 0, ["y"] = 1, ["param1"] = 14, ["z"] = 9, ["name"] = "stones:rock"}, {["x"] = 0, ["y"] = 2, ["param1"] = 30, ["z"] = 9, ["name"] = "stones:rock"}, {["x"] = 0, ["y"] = 3, ["param1"] = 46, ["z"] = 9, ["name"] = "stones:rock"}, {["x"] = 0, ["param2"] = 1, ["y"] = 4, ["param1"] = 46, ["z"] = 8, ["name"] = "stones:arci"}, {["x"] = 0, ["y"] = 4, ["param1"] = 62, ["z"] = 9, ["name"] = "stones:rock"}, {["x"] = 0, ["param2"] = 2, ["y"] = 4, ["param1"] = 110, ["z"] = 12, ["name"] = "stones:spirjoin"}, {["x"] = 0, ["y"] = 5, ["param1"] = 62, ["z"] = 8, ["name"] = "stones:rock"}, {["x"] = 0, ["y"] = 5, ["param1"] = 46, ["z"] = 9, ["name"] = "stones:rock"}, {["x"] = 1, ["param2"] = 12, ["y"] = 0, ["param1"] = 14, ["z"] = 0, ["name"] = "stones:roch"}, {["x"] = 1, ["param2"] = 12, ["y"] = 0, ["param1"] = 14, ["z"] = 1, ["name"] = "stones:sku"}, {["x"] = 1, ["param2"] = 5, ["y"] = 0, ["param1"] = 30, ["z"] = 2, ["name"] = "stones:s_22"}, {["x"] = 1, ["param2"] = 5, ["y"] = 0, ["param1"] = 14, ["z"] = 5, ["name"] = "stones:sku"}, {["x"] = 1, ["y"] = 0, ["param1"] = 14, ["z"] = 8, ["name"] = "stones:rock"}, {["x"] = 1, ["y"] = 1, ["param1"] = 14, ["z"] = 8, ["name"] = "stones:rock"}, {["x"] = 1, ["y"] = 2, ["param1"] = 14, ["z"] = 8, ["name"] = "stones:rock"}, {["x"] = 1, ["y"] = 3, ["param1"] = 14, ["z"] = 8, ["name"] = "stones:rock"}, {["x"] = 1, ["y"] = 4, ["param1"] = 30, ["z"] = 8, ["name"] = "stones:rock"}, {["x"] = 1, ["param2"] = 3, ["y"] = 4, ["param1"] = 46, ["z"] = 9, ["name"] = "stones:arci"}, {["x"] = 1, ["param2"] = 9, ["y"] = 4, ["param1"] = 78, ["z"] = 11, ["name"] = "stones:s_52"}, {["x"] = 1, ["param2"] = 7, ["y"] = 4, ["param1"] = 94, ["z"] = 12, ["name"] = "stones:s_52u"}, {["x"] = 1, ["y"] = 5, ["param1"] = 46, ["z"] = 8, ["name"] = "stones:rock"}, {["x"] = 1, ["param2"] = 1, ["y"] = 5, ["param1"] = 30, ["z"] = 9, ["name"] = "stones:rock"}, {["x"] = 2, ["param2"] = 5, ["y"] = 0, ["param1"] = 14, ["z"] = 2, ["name"] = "stones:sku_20"}, {["x"] = 2, ["param2"] = 5, ["y"] = 0, ["param1"] = 30, ["z"] = 3, ["name"] = "stones:s_22"}, {["x"] = 2, ["param2"] = 11, ["y"] = 0, ["param1"] = 14, ["z"] = 5, ["name"] = "stones:s_22"}, {["x"] = 2, ["param2"] = 12, ["y"] = 0, ["param1"] = 14, ["z"] = 6, ["name"] = "stones:sku"}, {["x"] = 2, ["param2"] = 18, ["y"] = 0, ["param1"] = 14, ["z"] = 7, ["name"] = "stones:s_52"}, {["x"] = 2, ["param2"] = 8, ["y"] = 2, ["param1"] = 62, ["z"] = 13, ["name"] = "stones:s_22"}, {["x"] = 2, ["param2"] = 23, ["y"] = 2, ["param1"] = 78, ["z"] = 14, ["name"] = "stones:diagstep"}, {["x"] = 2, ["param2"] = 3, ["y"] = 3, ["param1"] = 78, ["z"] = 13, ["name"] = "stones:spirstax_l"}, {["x"] = 2, ["param2"] = 9, ["y"] = 4, ["param1"] = 62, ["z"] = 11, ["name"] = "stones:s_52u"}, {["x"] = 2, ["param2"] = 2, ["y"] = 4, ["param1"] = 78, ["z"] = 12, ["name"] = "stones:stair_2"}, {["x"] = 3, ["param2"] = 5, ["y"] = 0, ["param1"] = 14, ["z"] = 3, ["name"] = "stones:sku"}, {["x"] = 3, ["param2"] = 12, ["y"] = 0, ["param1"] = 14, ["z"] = 7, ["name"] = "stones:s_52"}, {["x"] = 3, ["param2"] = 11, ["y"] = 0, ["param1"] = 14, ["z"] = 8, ["name"] = "stones:sku_20"}, {["x"] = 3, ["y"] = 0, ["param1"] = 12, ["z"] = 12, ["name"] = "stones:rock"}, {["x"] = 3, ["y"] = 0, ["param1"] = 13, ["z"] = 13, ["name"] = "stones:rock"}, {["x"] = 3, ["param2"] = 16, ["y"] = 1, ["param1"] = 14, ["z"] = 10, ["name"] = "stones:s_52"}, {["x"] = 3, ["param2"] = 16, ["y"] = 1, ["param1"] = 13, ["z"] = 11, ["name"] = "stones:s_52u"}, {["x"] = 3, ["y"] = 1, ["param1"] = 12, ["z"] = 12, ["name"] = "stones:rock"}, {["x"] = 3, ["y"] = 1, ["param1"] = 29, ["z"] = 13, ["name"] = "stones:rock"}, {["x"] = 3, ["param2"] = 17, ["y"] = 1, ["param1"] = 46, ["z"] = 14, ["name"] = "stones:s_22"}, {["x"] = 3, ["param2"] = 16, ["y"] = 2, ["param1"] = 14, ["z"] = 10, ["name"] = "stones:s_52"}, {["x"] = 3, ["param2"] = 16, ["y"] = 2, ["param1"] = 13, ["z"] = 11, ["name"] = "stones:s_52u"}, {["x"] = 3, ["param2"] = 3, ["y"] = 2, ["param1"] = 28, ["z"] = 12, ["name"] = "stones:spirjoin"}, {["x"] = 3, ["param2"] = 3, ["y"] = 2, ["param1"] = 45, ["z"] = 13, ["name"] = "stones:spircol_8"}, {["x"] = 3, ["y"] = 2, ["param1"] = 62, ["z"] = 14, ["name"] = "stones:spirstax_l"}, {["x"] = 3, ["param2"] = 16, ["y"] = 3, ["param1"] = 14, ["z"] = 10, ["name"] = "stones:s_52"}, {["x"] = 3, ["param2"] = 3, ["y"] = 3, ["param1"] = 45, ["z"] = 12, ["name"] = "stones:spirjoin"}, {["x"] = 3, ["param2"] = 3, ["y"] = 3, ["param1"] = 62, ["z"] = 13, ["name"] = "stones:spircol_8"}, {["x"] = 3, ["param2"] = 16, ["y"] = 4, ["param1"] = 14, ["z"] = 9, ["name"] = "stones:s_52"}, {["x"] = 3, ["param2"] = 16, ["y"] = 4, ["param1"] = 30, ["z"] = 10, ["name"] = "stones:s_52u"}, {["x"] = 3, ["y"] = 4, ["param1"] = 46, ["z"] = 11, ["name"] = "stones:rock"}, {["x"] = 3, ["param2"] = 3, ["y"] = 4, ["param1"] = 61, ["z"] = 12, ["name"] = "stones:spirjoin"}, {["x"] = 3, ["param2"] = 3, ["y"] = 4, ["param1"] = 78, ["z"] = 13, ["name"] = "stones:spircol_8"}, {["x"] = 3, ["param2"] = 9, ["y"] = 5, ["param1"] = 46, ["z"] = 12, ["name"] = "stones:s_22r"}, {["x"] = 3, ["param2"] = 1, ["y"] = 5, ["param1"] = 62, ["z"] = 13, ["name"] = "stones:spircol_8"}, {["x"] = 4, ["param2"] = 8, ["y"] = 0, ["param1"] = 14, ["z"] = 3, ["name"] = "stones:roch"}, {["x"] = 4, ["param2"] = 11, ["y"] = 0, ["param1"] = 14, ["z"] = 8, ["name"] = "stones:s_52"}, {["x"] = 4, ["y"] = 0, ["param1"] = 13, ["z"] = 9, ["name"] = "stones:rock"}, {["x"] = 4, ["param2"] = 23, ["y"] = 0, ["param1"] = 13, ["z"] = 10, ["name"] = "stones:diagstep"}, {["x"] = 4, ["y"] = 0, ["param1"] = 13, ["z"] = 14, ["name"] = "stones:rock"}, {["x"] = 4, ["y"] = 1, ["param1"] = 13, ["z"] = 9, ["name"] = "stones:rock"}, {["x"] = 4, ["param2"] = 3, ["y"] = 1, ["param1"] = 13, ["z"] = 10, ["name"] = "stones:spirdiag_r"}, {["x"] = 4, ["y"] = 1, ["param1"] = 12, ["z"] = 11, ["name"] = "stones:spirstax_r"}, {["x"] = 4, ["y"] = 1, ["param1"] = 12, ["z"] = 12, ["name"] = "stones:rock"}, {["x"] = 4, ["y"] = 1, ["param1"] = 13, ["z"] = 13, ["name"] = "stones:rock"}, {["x"] = 4, ["param2"] = 4, ["y"] = 1, ["param1"] = 30, ["z"] = 14, ["name"] = "stones:rock"}, {["x"] = 4, ["y"] = 2, ["param1"] = 13, ["z"] = 9, ["name"] = "stones:rock"}, {["x"] = 4, ["param2"] = 3, ["y"] = 2, ["param1"] = 13, ["z"] = 10, ["name"] = "stones:spircod"}, {["x"] = 4, ["param2"] = 9, ["y"] = 3, ["param1"] = 14, ["z"] = 8, ["name"] = "stones:s_2"}, {["x"] = 4, ["y"] = 3, ["param1"] = 13, ["z"] = 9, ["name"] = "stones:rock"}, {["x"] = 4, ["param2"] = 22, ["y"] = 3, ["param1"] = 13, ["z"] = 10, ["name"] = "stones:spirdiag_r"}, {["x"] = 4, ["y"] = 4, ["param1"] = 14, ["z"] = 9, ["name"] = "stones:rock"}, {["x"] = 4, ["param2"] = 3, ["y"] = 4, ["param1"] = 14, ["z"] = 10, ["name"] = "stones:spirdiag_r"}, {["x"] = 4, ["y"] = 4, ["param1"] = 30, ["z"] = 11, ["name"] = "stones:spirstax_r"}, {["x"] = 4, ["param2"] = 22, ["y"] = 4, ["param1"] = 45, ["z"] = 12, ["name"] = "stones:diagstep"}, {["x"] = 4, ["y"] = 5, ["param1"] = 14, ["z"] = 9, ["name"] = "stones:rock"}, {["x"] = 4, ["param2"] = 9, ["y"] = 5, ["param1"] = 30, ["z"] = 12, ["name"] = "stones:s_52ur"}, {["x"] = 4, ["param2"] = 2, ["y"] = 5, ["param1"] = 46, ["z"] = 13, ["name"] = "stones:spirjoin"}, {["x"] = 4, ["param2"] = 16, ["y"] = 6, ["param1"] = 14, ["z"] = 9, ["name"] = "stones:spirjoin"}, {["x"] = 4, ["param2"] = 12, ["y"] = 7, ["param1"] = 14, ["z"] = 9, ["name"] = "stones:spircol_8"}, {["x"] = 5, ["param2"] = 11, ["y"] = 0, ["param1"] = 14, ["z"] = 3, ["name"] = "stones:s_52"}, {["x"] = 5, ["param2"] = 5, ["y"] = 0, ["param1"] = 14, ["z"] = 4, ["name"] = "stones:s_52"}, {["x"] = 5, ["y"] = 0, ["param1"] = 13, ["z"] = 9, ["name"] = "stones:diagstep"}, {["x"] = 5, ["param2"] = 23, ["y"] = 0, ["param1"] = 12, ["z"] = 10, ["name"] = "stones:spirout_r"}, {["x"] = 5, ["y"] = 0, ["param1"] = 11, ["z"] = 11, ["name"] = "stones:spircol_8"}, {["x"] = 5, ["param2"] = 1, ["y"] = 1, ["param1"] = 12, ["z"] = 11, ["name"] = "stones:spircol_8"}, {["x"] = 5, ["param2"] = 1, ["y"] = 1, ["param1"] = 12, ["z"] = 12, ["name"] = "stones:spirjoin"}, {["x"] = 5, ["y"] = 1, ["param1"] = 13, ["z"] = 13, ["name"] = "stones:rock"}, {["x"] = 5, ["y"] = 1, ["param1"] = 14, ["z"] = 14, ["name"] = "stones:rock"}, {["x"] = 5, ["y"] = 2, ["param1"] = 13, ["z"] = 9, ["name"] = "stones:arch"}, {["x"] = 5, ["param2"] = 3, ["y"] = 2, ["param1"] = 13, ["z"] = 11, ["name"] = "stones:spircol_8"}, {["x"] = 5, ["y"] = 3, ["param1"] = 14, ["z"] = 8, ["name"] = "runes:hui"}, {["x"] = 5, ["y"] = 3, ["param1"] = 13, ["z"] = 9, ["name"] = "stones:rock"}, {["x"] = 5, ["param2"] = 3, ["y"] = 3, ["param1"] = 14, ["z"] = 10, ["name"] = "stones:spirout_r"}, {["x"] = 5, ["param2"] = 3, ["y"] = 3, ["param1"] = 14, ["z"] = 11, ["name"] = "stones:spircol_8"}, {["x"] = 5, ["y"] = 4, ["param1"] = 14, ["z"] = 11, ["name"] = "stones:spircol_8"}, {["x"] = 5, ["param2"] = 2, ["y"] = 4, ["param1"] = 46, ["z"] = 13, ["name"] = "stones:arch"}, {["x"] = 5, ["y"] = 5, ["param1"] = 30, ["z"] = 11, ["name"] = "stones:spircol_8"}, {["x"] = 5, ["param2"] = 1, ["y"] = 5, ["param1"] = 46, ["z"] = 12, ["name"] = "stones:spirout_r"}, {["x"] = 5, ["y"] = 5, ["param1"] = 62, ["z"] = 13, ["name"] = "stones:rock"}, {["x"] = 5, ["param2"] = 13, ["y"] = 7, ["param1"] = 14, ["z"] = 9, ["name"] = "stones:spircol_8"}, {["x"] = 6, ["param2"] = 18, ["y"] = 0, ["param1"] = 14, ["z"] = 4, ["name"] = "stones:sku_20"}, {["x"] = 6, ["param2"] = 18, ["y"] = 0, ["param1"] = 14, ["z"] = 5, ["name"] = "stones:s_52"}, {["x"] = 6, ["param2"] = 3, ["y"] = 0, ["param1"] = 12, ["z"] = 10, ["name"] = "stones:diagstep"}, {["x"] = 6, ["param2"] = 12, ["y"] = 1, ["param1"] = 12, ["z"] = 12, ["name"] = "stones:s_2"}, {["x"] = 6, ["param2"] = 14, ["y"] = 1, ["param1"] = 13, ["z"] = 13, ["name"] = "stones:s_52u"}, {["x"] = 6, ["param2"] = 14, ["y"] = 1, ["param1"] = 30, ["z"] = 14, ["name"] = "stones:s_52"}, {["x"] = 6, ["param2"] = 2, ["y"] = 2, ["param1"] = 13, ["z"] = 9, ["name"] = "stones:arch"}, {["x"] = 6, ["param2"] = 20, ["y"] = 2, ["param1"] = 13, ["z"] = 10, ["name"] = "stones:diagstep"}, {["x"] = 6, ["param2"] = 2, ["y"] = 2, ["param1"] = 14, ["z"] = 11, ["name"] = "stones:spirout_r"}, {["x"] = 6, ["param2"] = 1, ["y"] = 2, ["param1"] = 13, ["z"] = 12, ["name"] = "stones:spirdiag_r"}, {["x"] = 6, ["y"] = 2, ["param1"] = 30, ["z"] = 13, ["name"] = "stones:rock"}, {["x"] = 6, ["param2"] = 11, ["y"] = 3, ["param1"] = 14, ["z"] = 8, ["name"] = "stones:s_52u"}, {["x"] = 6, ["y"] = 3, ["param1"] = 13, ["z"] = 9, ["name"] = "stones:rock"}, {["x"] = 6, ["param2"] = 2, ["y"] = 3, ["param1"] = 14, ["z"] = 10, ["name"] = "stones:spirdiag_r"}, {["x"] = 6, ["param2"] = 1, ["y"] = 3, ["param1"] = 30, ["z"] = 12, ["name"] = "stones:spircod"}, {["x"] = 6, ["y"] = 3, ["param1"] = 46, ["z"] = 13, ["name"] = "stones:rock"}, {["x"] = 6, ["y"] = 4, ["param1"] = 14, ["z"] = 9, ["name"] = "stones:rock"}, {["x"] = 6, ["param2"] = 2, ["y"] = 4, ["param1"] = 14, ["z"] = 10, ["name"] = "stones:spircod"}, {["x"] = 6, ["param2"] = 1, ["y"] = 4, ["param1"] = 46, ["z"] = 12, ["name"] = "stones:spircod"}, {["x"] = 6, ["y"] = 4, ["param1"] = 62, ["z"] = 13, ["name"] = "stones:rock"}, {["x"] = 6, ["y"] = 5, ["param1"] = 14, ["z"] = 9, ["name"] = "stones:rock"}, {["x"] = 6, ["param2"] = 2, ["y"] = 5, ["param1"] = 30, ["z"] = 10, ["name"] = "stones:spircod"}, {["x"] = 6, ["param2"] = 20, ["y"] = 5, ["param1"] = 62, ["z"] = 12, ["name"] = "stones:spirdiag_r"}, {["x"] = 6, ["y"] = 5, ["param1"] = 78, ["z"] = 13, ["name"] = "stones:rock"}, {["x"] = 6, ["param2"] = 16, ["y"] = 6, ["param1"] = 14, ["z"] = 9, ["name"] = "stones:spirjoin"}, {["x"] = 6, ["param2"] = 12, ["y"] = 7, ["param1"] = 14, ["z"] = 9, ["name"] = "stones:spircol_8"}, {["x"] = 7, ["param2"] = 12, ["y"] = 0, ["param1"] = 14, ["z"] = 5, ["name"] = "stones:s_52"}, {["x"] = 7, ["param2"] = 12, ["y"] = 0, ["param1"] = 14, ["z"] = 6, ["name"] = "stones:sku"}, {["x"] = 7, ["param2"] = 16, ["y"] = 0, ["param1"] = 14, ["z"] = 7, ["name"] = "stones:roch"}, {["x"] = 7, ["param2"] = 16, ["y"] = 0, ["param1"] = 14, ["z"] = 8, ["name"] = "stones:s_52u"}, {["x"] = 7, ["y"] = 0, ["param1"] = 14, ["z"] = 9, ["name"] = "stones:rock"}, {["x"] = 7, ["y"] = 1, ["param1"] = 14, ["z"] = 9, ["name"] = "stones:rock"}, {["x"] = 7, ["param2"] = 3, ["y"] = 1, ["param1"] = 13, ["z"] = 10, ["name"] = "stones:arch"}, {["x"] = 7, ["y"] = 2, ["param1"] = 14, ["z"] = 9, ["name"] = "stones:rock"}, {["x"] = 7, ["y"] = 2, ["param1"] = 13, ["z"] = 10, ["name"] = "stones:rock"}, {["x"] = 7, ["y"] = 2, ["param1"] = 13, ["z"] = 11, ["name"] = "stones:rock"}, {["x"] = 7, ["y"] = 2, ["param1"] = 29, ["z"] = 12, ["name"] = "stones:rock"}, {["x"] = 7, ["param2"] = 7, ["y"] = 2, ["param1"] = 46, ["z"] = 13, ["name"] = "stones:s_52u"}, {["x"] = 7, ["param2"] = 11, ["y"] = 3, ["param1"] = 14, ["z"] = 8, ["name"] = "stones:s_52"}, {["x"] = 7, ["y"] = 3, ["param1"] = 14, ["z"] = 9, ["name"] = "stones:rock"}, {["x"] = 7, ["param2"] = 3, ["y"] = 3, ["param1"] = 13, ["z"] = 10, ["name"] = "stones:spircod"}, {["x"] = 7, ["y"] = 3, ["param1"] = 45, ["z"] = 12, ["name"] = "stones:spircod"}, {["x"] = 7, ["param2"] = 7, ["y"] = 3, ["param1"] = 62, ["z"] = 13, ["name"] = "stones:s_52u"}, {["x"] = 7, ["y"] = 4, ["param1"] = 14, ["z"] = 9, ["name"] = "stones:rock"}, {["x"] = 7, ["param2"] = 3, ["y"] = 4, ["param1"] = 29, ["z"] = 10, ["name"] = "stones:spircod"}, {["x"] = 7, ["y"] = 4, ["param1"] = 61, ["z"] = 12, ["name"] = "stones:spircod"}, {["x"] = 7, ["param2"] = 7, ["y"] = 4, ["param1"] = 78, ["z"] = 13, ["name"] = "stones:s_52u"}, {["x"] = 7, ["param2"] = 3, ["y"] = 5, ["param1"] = 30, ["z"] = 9, ["name"] = "stones:plot"}, {["x"] = 7, ["y"] = 5, ["param1"] = 46, ["z"] = 10, ["name"] = "stones:rock"}, {["x"] = 7, ["y"] = 5, ["param1"] = 62, ["z"] = 11, ["name"] = "stones:rock"}, {["x"] = 7, ["y"] = 5, ["param1"] = 78, ["z"] = 12, ["name"] = "stones:rock"}, {["x"] = 7, ["param2"] = 7, ["y"] = 5, ["param1"] = 94, ["z"] = 13, ["name"] = "stones:s_52u"}, {["x"] = 7, ["param2"] = 4, ["y"] = 6, ["param1"] = 15, ["z"] = 9, ["name"] = "stones:shrub"}, {["x"] = 7, ["param2"] = 5, ["y"] = 6, ["param1"] = 78, ["z"] = 13, ["name"] = "stones:panel"}, {["x"] = 8, ["param2"] = 11, ["y"] = 2, ["param1"] = 14, ["z"] = 10, ["name"] = "stones:s_52u"}, {["x"] = 8, ["param2"] = 14, ["y"] = 2, ["param1"] = 29, ["z"] = 11, ["name"] = "runes:ke"}, {["x"] = 8, ["y"] = 2, ["param1"] = 45, ["z"] = 12, ["name"] = "stones:rock"}, {["x"] = 8, ["param2"] = 7, ["y"] = 2, ["param1"] = 62, ["z"] = 13, ["name"] = "stones:s_52"}, {["x"] = 8, ["param2"] = 12, ["y"] = 5, ["param1"] = 62, ["z"] = 10, ["name"] = "stones:s_52"}, {["x"] = 8, ["param2"] = 12, ["y"] = 5, ["param1"] = 78, ["z"] = 11, ["name"] = "stones:roch"}, {["x"] = 8, ["param2"] = 14, ["y"] = 5, ["param1"] = 94, ["z"] = 12, ["name"] = "stones:s_52"}, {["x"] = 9, ["y"] = 0, ["param1"] = 13, ["z"] = 11, ["name"] = "stones:rock"}, {["x"] = 9, ["y"] = 1, ["param1"] = 13, ["z"] = 11, ["name"] = "stones:rock"}, {["x"] = 9, ["param2"] = 11, ["y"] = 2, ["param1"] = 14, ["z"] = 10, ["name"] = "stones:s_52"}, {["x"] = 9, ["y"] = 2, ["param1"] = 14, ["z"] = 11, ["name"] = "stones:rock"}, {["x"] = 9, ["param2"] = 7, ["y"] = 2, ["param1"] = 30, ["z"] = 12, ["name"] = "stones:s_52u"}, {["x"] = 10, ["param2"] = 2, ["y"] = 0, ["param1"] = 14, ["z"] = 14, ["name"] = "stones:spircol_8"}, {["x"] = 10, ["param2"] = 2, ["y"] = 1, ["param1"] = 30, ["z"] = 14, ["name"] = "stones:spircol_8"}, {["x"] = 10, ["param2"] = 12, ["y"] = 2, ["param1"] = 14, ["z"] = 11, ["name"] = "stones:s_52"}, {["x"] = 10, ["param2"] = 7, ["y"] = 2, ["param1"] = 14, ["z"] = 12, ["name"] = "stones:s_22"}, {["x"] = 10, ["param2"] = 2, ["y"] = 2, ["param1"] = 46, ["z"] = 14, ["name"] = "stones:spircol_8"}, {["x"] = 10, ["param2"] = 2, ["y"] = 3, ["param1"] = 62, ["z"] = 14, ["name"] = "stones:spircol_8"}, {["x"] = 10, ["param2"] = 2, ["y"] = 4, ["param1"] = 78, ["z"] = 14, ["name"] = "stones:spircol_8"}, {["x"] = 10, ["param2"] = 2, ["y"] = 5, ["param1"] = 94, ["z"] = 14, ["name"] = "stones:spircol_8"}, {["x"] = 10, ["param2"] = 2, ["y"] = 6, ["param1"] = 78, ["z"] = 14, ["name"] = "stones:spircol_8"}, {["x"] = 10, ["param2"] = 2, ["y"] = 7, ["param1"] = 62, ["z"] = 14, ["name"] = "stones:spircol_8"}}