5:return {{["x"] = 0, ["param2"] = 1, ["y"] = 0, ["param1"] = 14, ["z"] = 0, ["name"] = "stones:spircol_8"}, {["x"] = 0, ["y"] = 0, ["param1"] = 126, ["z"] = 12, ["name"] = "stones:rock"}, {["x"] = 0, ["y"] = 0, ["param1"] = 110, ["z"] = 13, ["name"] = "stones:rock"}, {["x"] = 0, ["y"] = 0, ["param1"] = 94, ["z"] = 14, ["name"] = "stones:rock"}, {["x"] = 0, ["y"] = 0, ["param1"] = 78, ["z"] = 15, ["name"] = "stones:rock"}, {["x"] = 0, ["y"] = 0, ["param1"] = 62, ["z"] = 16, ["name"] = "stones:rock"}, {["x"] = 0, ["y"] = 0, ["param1"] = 46, ["z"] = 17, ["name"] = "stones:rock"}, {["x"] = 0, ["param2"] = 2, ["y"] = 0, ["param1"] = 30, ["z"] = 18, ["name"] = "stones:diagsteps_31"}, {["x"] = 0, ["y"] = 1, ["param1"] = 110, ["z"] = 12, ["name"] = "stones:rock"}, {["x"] = 0, ["y"] = 1, ["param1"] = 94, ["z"] = 13, ["name"] = "stones:rock"}, {["x"] = 0, ["y"] = 1, ["param1"] = 78, ["z"] = 14, ["name"] = "stones:rock"}, {["x"] = 0, ["y"] = 1, ["param1"] = 62, ["z"] = 15, ["name"] = "stones:rock"}, {["x"] = 0, ["y"] = 1, ["param1"] = 46, ["z"] = 16, ["name"] = "stones:rock"}, {["x"] = 0, ["y"] = 1, ["param1"] = 30, ["z"] = 17, ["name"] = "stones:rock"}, {["x"] = 1, ["y"] = 0, ["param1"] = 142, ["z"] = 12, ["name"] = "stones:s_52u"}, {["x"] = 1, ["y"] = 0, ["param1"] = 125, ["z"] = 13, ["name"] = "stones:rock"}, {["x"] = 1, ["y"] = 0, ["param1"] = 61, ["z"] = 17, ["name"] = "stones:rock"}, {["x"] = 1, ["param2"] = 2, ["y"] = 0, ["param1"] = 46, ["z"] = 18, ["name"] = "stones:stair_2"}, {["x"] = 1, ["param2"] = 22, ["y"] = 1, ["param1"] = 126, ["z"] = 12, ["name"] = "stones:s_52u"}, {["x"] = 1, ["y"] = 1, ["param1"] = 109, ["z"] = 13, ["name"] = "stones:s_52"}, {["x"] = 1, ["param2"] = 3, ["y"] = 1, ["param1"] = 93, ["z"] = 14, ["name"] = "stones:cish"}, {["x"] = 1, ["y"] = 1, ["param1"] = 46, ["z"] = 17, ["name"] = "stones:rock"}, {["x"] = 1, ["y"] = 2, ["param1"] = 110, ["z"] = 13, ["name"] = "stones:rock"}, {["x"] = 1, ["y"] = 2, ["param1"] = 94, ["z"] = 14, ["name"] = "stones:rock"}, {["x"] = 1, ["y"] = 2, ["param1"] = 78, ["z"] = 15, ["name"] = "stones:rock"}, {["x"] = 1, ["y"] = 2, ["param1"] = 62, ["z"] = 16, ["name"] = "stones:rock"}, {["x"] = 1, ["y"] = 3, ["param1"] = 126, ["z"] = 13, ["name"] = "stones:rock"}, {["x"] = 1, ["y"] = 3, ["param1"] = 110, ["z"] = 14, ["name"] = "stones:rock"}, {["x"] = 1, ["param2"] = 3, ["y"] = 3, ["param1"] = 94, ["z"] = 15, ["name"] = "stones:plot"}, {["x"] = 1, ["y"] = 3, ["param1"] = 78, ["z"] = 16, ["name"] = "stones:rock"}, {["x"] = 1, ["y"] = 4, ["param1"] = 142, ["z"] = 13, ["name"] = "stones:rock"}, {["x"] = 1, ["param2"] = 12, ["y"] = 4, ["param1"] = 126, ["z"] = 14, ["name"] = "runes:lit_hui"}, {["x"] = 1, ["param2"] = 4, ["y"] = 4, ["param1"] = 110, ["z"] = 15, ["name"] = "stones:shrub"}, {["x"] = 1, ["y"] = 4, ["param1"] = 94, ["z"] = 16, ["name"] = "stones:rock"}, {["x"] = 1, ["y"] = 5, ["param1"] = 126, ["z"] = 13, ["name"] = "stones:rock"}, {["x"] = 1, ["y"] = 5, ["param1"] = 110, ["z"] = 14, ["name"] = "stones:rock"}, {["x"] = 1, ["y"] = 5, ["param1"] = 94, ["z"] = 15, ["name"] = "stones:rock"}, {["x"] = 1, ["y"] = 5, ["param1"] = 78, ["z"] = 16, ["name"] = "stones:rock"}, {["x"] = 1, ["y"] = 6, ["param1"] = 110, ["z"] = 13, ["name"] = "stones:rock"}, {["x"] = 1, ["y"] = 6, ["param1"] = 94, ["z"] = 14, ["name"] = "stones:rock"}, {["x"] = 1, ["y"] = 6, ["param1"] = 78, ["z"] = 15, ["name"] = "stones:rock"}, {["x"] = 1, ["y"] = 6, ["param1"] = 62, ["z"] = 16, ["name"] = "stones:rock"}, {["x"] = 1, ["y"] = 7, ["param1"] = 94, ["z"] = 13, ["name"] = "stones:rock"}, {["x"] = 1, ["y"] = 7, ["param1"] = 46, ["z"] = 16, ["name"] = "stones:rock"}, {["x"] = 1, ["y"] = 8, ["param1"] = 78, ["z"] = 13, ["name"] = "stones:rock"}, {["x"] = 1, ["y"] = 8, ["param1"] = 62, ["z"] = 14, ["name"] = "stones:rock"}, {["x"] = 1, ["y"] = 8, ["param1"] = 46, ["z"] = 15, ["name"] = "stones:rock"}, {["x"] = 1, ["y"] = 8, ["param1"] = 30, ["z"] = 16, ["name"] = "stones:rock"}, {["x"] = 1, ["y"] = 9, ["param1"] = 62, ["z"] = 13, ["name"] = "stones:rock"}, {["x"] = 1, ["y"] = 9, ["param1"] = 14, ["z"] = 16, ["name"] = "stones:rock"}, {["x"] = 1, ["y"] = 10, ["param1"] = 46, ["z"] = 13, ["name"] = "stones:rock"}, {["x"] = 1, ["y"] = 10, ["param1"] = 30, ["z"] = 14, ["name"] = "stones:rock"}, {["x"] = 1, ["y"] = 10, ["param1"] = 14, ["z"] = 15, ["name"] = "stones:rock"}, {["x"] = 1, ["y"] = 10, ["param1"] = 14, ["z"] = 16, ["name"] = "stones:rock"}, {["x"] = 2, ["param2"] = 1, ["y"] = 0, ["param1"] = 14, ["z"] = 0, ["name"] = "stones:rock"}, {["x"] = 2, ["y"] = 0, ["param1"] = 14, ["z"] = 1, ["name"] = "stones:rock"}, {["x"] = 2, ["y"] = 0, ["param1"] = 30, ["z"] = 2, ["name"] = "stones:rock"}, {["x"] = 2, ["y"] = 0, ["param1"] = 46, ["z"] = 3, ["name"] = "stones:rock"}, {["x"] = 2, ["y"] = 0, ["param1"] = 62, ["z"] = 4, ["name"] = "stones:rock"}, {["x"] = 2, ["y"] = 0, ["param1"] = 78, ["z"] = 5, ["name"] = "stones:rock"}, {["x"] = 2, ["y"] = 0, ["param1"] = 94, ["z"] = 6, ["name"] = "stones:rock"}, {["x"] = 2, ["y"] = 0, ["param1"] = 110, ["z"] = 7, ["name"] = "stones:rock"}, {["x"] = 2, ["y"] = 0, ["param1"] = 126, ["z"] = 8, ["name"] = "stones:rock"}, {["x"] = 2, ["y"] = 0, ["param1"] = 142, ["z"] = 9, ["name"] = "stones:rock"}, {["x"] = 2, ["y"] = 0, ["param1"] = 158, ["z"] = 10, ["name"] = "stones:rock"}, {["x"] = 2, ["y"] = 0, ["param1"] = 174, ["z"] = 11, ["name"] = "stones:rock"}, {["x"] = 2, ["y"] = 0, ["param1"] = 157, ["z"] = 12, ["name"] = "stones:rock"}, {["x"] = 2, ["y"] = 0, ["param1"] = 140, ["z"] = 13, ["name"] = "stones:rock"}, {["x"] = 2, ["y"] = 0, ["param1"] = 77, ["z"] = 17, ["name"] = "stones:rock"}, {["x"] = 2, ["param2"] = 2, ["y"] = 0, ["param1"] = 62, ["z"] = 18, ["name"] = "stones:stair_2"}, {["x"] = 2, ["y"] = 1, ["param1"] = 14, ["z"] = 0, ["name"] = "stones:rock"}, {["x"] = 2, ["y"] = 1, ["param1"] = 14, ["z"] = 1, ["name"] = "stones:rock"}, {["x"] = 2, ["y"] = 1, ["param1"] = 14, ["z"] = 2, ["name"] = "stones:rock"}, {["x"] = 2, ["y"] = 1, ["param1"] = 30, ["z"] = 3, ["name"] = "stones:rock"}, {["x"] = 2, ["y"] = 1, ["param1"] = 46, ["z"] = 4, ["name"] = "stones:rock"}, {["x"] = 2, ["y"] = 1, ["param1"] = 62, ["z"] = 5, ["name"] = "stones:rock"}, {["x"] = 2, ["y"] = 1, ["param1"] = 78, ["z"] = 6, ["name"] = "stones:rock"}, {["x"] = 2, ["y"] = 1, ["param1"] = 94, ["z"] = 7, ["name"] = "stones:rock"}, {["x"] = 2, ["y"] = 1, ["param1"] = 110, ["z"] = 8, ["name"] = "stones:rock"}, {["x"] = 2, ["y"] = 1, ["param1"] = 126, ["z"] = 9, ["name"] = "stones:rock"}, {["x"] = 2, ["y"] = 1, ["param1"] = 142, ["z"] = 10, ["name"] = "stones:rock"}, {["x"] = 2, ["y"] = 1, ["param1"] = 158, ["z"] = 11, ["name"] = "stones:rock"}, {["x"] = 2, ["y"] = 1, ["param1"] = 141, ["z"] = 12, ["name"] = "stones:rock"}, {["x"] = 2, ["y"] = 1, ["param1"] = 124, ["z"] = 13, ["name"] = "stones:rock"}, {["x"] = 2, ["y"] = 1, ["param1"] = 62, ["z"] = 17, ["name"] = "stones:rock"}, {["x"] = 2, ["param2"] = 9, ["y"] = 2, ["param1"] = 30, ["z"] = 3, ["name"] = "stones:panel"}, {["x"] = 2, ["param2"] = 18, ["y"] = 2, ["param1"] = 46, ["z"] = 4, ["name"] = "stones:s_52r"}, {["x"] = 2, ["param2"] = 17, ["y"] = 2, ["param1"] = 78, ["z"] = 6, ["name"] = "stones:s_52"}, {["x"] = 2, ["param2"] = 17, ["y"] = 2, ["param1"] = 110, ["z"] = 8, ["name"] = "stones:s_52"}, {["x"] = 2, ["param2"] = 17, ["y"] = 2, ["param1"] = 142, ["z"] = 10, ["name"] = "stones:s_52"}, {["x"] = 2, ["param2"] = 16, ["y"] = 2, ["param1"] = 142, ["z"] = 12, ["name"] = "stones:s_52l"}, {["x"] = 2, ["y"] = 2, ["param1"] = 125, ["z"] = 13, ["name"] = "stones:rock"}, {["x"] = 2, ["y"] = 2, ["param1"] = 109, ["z"] = 14, ["name"] = "stones:rock"}, {["x"] = 2, ["y"] = 2, ["param1"] = 93, ["z"] = 15, ["name"] = "stones:rock"}, {["x"] = 2, ["y"] = 2, ["param1"] = 77, ["z"] = 16, ["name"] = "stones:rock"}, {["x"] = 2, ["param2"] = 1, ["y"] = 2, ["param1"] = 62, ["z"] = 17, ["name"] = "stones:s_52"}, {["x"] = 2, ["param2"] = 9, ["y"] = 3, ["param1"] = 46, ["z"] = 3, ["name"] = "stones:panel"}, {["x"] = 2, ["y"] = 3, ["param1"] = 62, ["z"] = 4, ["name"] = "stones:estruk"}, {["x"] = 2, ["y"] = 3, ["param1"] = 78, ["z"] = 5, ["name"] = "stones:estruk"}, {["x"] = 2, ["y"] = 3, ["param1"] = 94, ["z"] = 6, ["name"] = "stones:estruk"}, {["x"] = 2, ["y"] = 3, ["param1"] = 110, ["z"] = 7, ["name"] = "stones:estruk"}, {["x"] = 2, ["y"] = 3, ["param1"] = 126, ["z"] = 8, ["name"] = "stones:estruk"}, {["x"] = 2, ["y"] = 3, ["param1"] = 142, ["z"] = 9, ["name"] = "stones:estruk"}, {["x"] = 2, ["y"] = 3, ["param1"] = 158, ["z"] = 10, ["name"] = "stones:estruk"}, {["x"] = 2, ["y"] = 3, ["param1"] = 174, ["z"] = 11, ["name"] = "stones:estruk"}, {["x"] = 2, ["y"] = 3, ["param1"] = 158, ["z"] = 12, ["name"] = "stones:estruk"}, {["x"] = 2, ["y"] = 3, ["param1"] = 141, ["z"] = 13, ["name"] = "stones:rock"}, {["x"] = 2, ["param2"] = 3, ["y"] = 3, ["param1"] = 125, ["z"] = 14, ["name"] = "stones:spirdiag_r"}, {["x"] = 2, ["y"] = 3, ["param1"] = 109, ["z"] = 15, ["name"] = "stones:roch"}, {["x"] = 2, ["y"] = 3, ["param1"] = 94, ["z"] = 16, ["name"] = "stones:rock"}, {["x"] = 2, ["y"] = 4, ["param1"] = 157, ["z"] = 13, ["name"] = "stones:rock"}, {["x"] = 2, ["y"] = 4, ["param1"] = 110, ["z"] = 16, ["name"] = "stones:rock"}, {["x"] = 2, ["y"] = 5, ["param1"] = 141, ["z"] = 13, ["name"] = "stones:rock"}, {["x"] = 2, ["param2"] = 3, ["y"] = 5, ["param1"] = 125, ["z"] = 14, ["name"] = "stones:arci"}, {["x"] = 2, ["y"] = 5, ["param1"] = 109, ["z"] = 15, ["name"] = "stones:arci"}, {["x"] = 2, ["y"] = 5, ["param1"] = 94, ["z"] = 16, ["name"] = "stones:rock"}, {["x"] = 2, ["param2"] = 9, ["y"] = 6, ["param1"] = 142, ["z"] = 12, ["name"] = "stones:s_52"}, {["x"] = 2, ["y"] = 6, ["param1"] = 125, ["z"] = 13, ["name"] = "stones:rock"}, {["x"] = 2, ["y"] = 6, ["param1"] = 109, ["z"] = 14, ["name"] = "stones:rock"}, {["x"] = 2, ["y"] = 6, ["param1"] = 93, ["z"] = 15, ["name"] = "stones:rock"}, {["x"] = 2, ["y"] = 6, ["param1"] = 78, ["z"] = 16, ["name"] = "stones:rock"}, {["x"] = 2, ["y"] = 8, ["param1"] = 94, ["z"] = 13, ["name"] = "stones:rock"}, {["x"] = 2, ["y"] = 8, ["param1"] = 78, ["z"] = 14, ["name"] = "stones:rock"}, {["x"] = 2, ["y"] = 8, ["param1"] = 62, ["z"] = 15, ["name"] = "stones:rock"}, {["x"] = 2, ["y"] = 8, ["param1"] = 46, ["z"] = 16, ["name"] = "stones:rock"}, {["x"] = 2, ["y"] = 10, ["param1"] = 62, ["z"] = 13, ["name"] = "stones:rock"}, {["x"] = 2, ["y"] = 10, ["param1"] = 14, ["z"] = 16, ["name"] = "stones:rock"}, {["x"] = 3, ["y"] = 0, ["param1"] = 14, ["z"] = 0, ["name"] = "stones:rock"}, {["x"] = 3, ["param2"] = 3, ["y"] = 0, ["param1"] = 30, ["z"] = 1, ["name"] = "stones:cish"}, {["x"] = 3, ["param2"] = 12, ["y"] = 0, ["param1"] = 155, ["z"] = 13, ["name"] = "stones:s_52"}, {["x"] = 3, ["param2"] = 12, ["y"] = 0, ["param1"] = 139, ["z"] = 14, ["name"] = "stones:s_52u"}, {["x"] = 3, ["param2"] = 18, ["y"] = 0, ["param1"] = 124, ["z"] = 15, ["name"] = "stones:s_52u"}, {["x"] = 3, ["param2"] = 18, ["y"] = 0, ["param1"] = 109, ["z"] = 16, ["name"] = "stones:asect_2"}, {["x"] = 3, ["y"] = 0, ["param1"] = 93, ["z"] = 17, ["name"] = "stones:rock"}, {["x"] = 3, ["param2"] = 2, ["y"] = 0, ["param1"] = 78, ["z"] = 18, ["name"] = "stones:stair_2"}, {["x"] = 3, ["param2"] = 13, ["y"] = 1, ["param1"] = 14, ["z"] = 0, ["name"] = "stones:estruk"}, {["x"] = 3, ["param2"] = 18, ["y"] = 1, ["param1"] = 109, ["z"] = 7, ["name"] = "stones:arch"}, {["x"] = 3, ["param2"] = 12, ["y"] = 1, ["param1"] = 139, ["z"] = 13, ["name"] = "stones:s_52"}, {["x"] = 3, ["param2"] = 12, ["y"] = 1, ["param1"] = 123, ["z"] = 14, ["name"] = "stones:s_52u"}, {["x"] = 3, ["param2"] = 18, ["y"] = 1, ["param1"] = 108, ["z"] = 15, ["name"] = "stones:s_52u"}, {["x"] = 3, ["y"] = 1, ["param1"] = 78, ["z"] = 17, ["name"] = "stones:rock"}, {["x"] = 3, ["param2"] = 20, ["y"] = 2, ["param1"] = 62, ["z"] = 4, ["name"] = "stones:s_52u"}, {["x"] = 3, ["y"] = 2, ["param1"] = 78, ["z"] = 5, ["name"] = "stones:rock"}, {["x"] = 3, ["y"] = 2, ["param1"] = 94, ["z"] = 6, ["name"] = "stones:rock"}, {["x"] = 3, ["y"] = 2, ["param1"] = 110, ["z"] = 7, ["name"] = "stones:rock"}, {["x"] = 3, ["y"] = 2, ["param1"] = 126, ["z"] = 8, ["name"] = "stones:rock"}, {["x"] = 3, ["y"] = 2, ["param1"] = 142, ["z"] = 9, ["name"] = "stones:rock"}, {["x"] = 3, ["y"] = 2, ["param1"] = 158, ["z"] = 10, ["name"] = "stones:rock"}, {["x"] = 3, ["y"] = 2, ["param1"] = 174, ["z"] = 11, ["name"] = "stones:rock"}, {["x"] = 3, ["y"] = 2, ["param1"] = 157, ["z"] = 12, ["name"] = "stones:rock"}, {["x"] = 3, ["y"] = 2, ["param1"] = 140, ["z"] = 13, ["name"] = "stones:rock"}, {["x"] = 3, ["y"] = 2, ["param1"] = 124, ["z"] = 14, ["name"] = "stones:rock"}, {["x"] = 3, ["y"] = 2, ["param1"] = 108, ["z"] = 15, ["name"] = "stones:rock"}, {["x"] = 3, ["y"] = 2, ["param1"] = 93, ["z"] = 16, ["name"] = "stones:rock"}, {["x"] = 3, ["param2"] = 1, ["y"] = 2, ["param1"] = 78, ["z"] = 17, ["name"] = "stones:s_52u"}, {["x"] = 3, ["y"] = 3, ["param1"] = 110, ["z"] = 16, ["name"] = "stones:rock"}, {["x"] = 3, ["y"] = 4, ["param1"] = 126, ["z"] = 16, ["name"] = "stones:rock"}, {["x"] = 3, ["y"] = 5, ["param1"] = 157, ["z"] = 13, ["name"] = "stones:rock"}, {["x"] = 3, ["param2"] = 3, ["y"] = 5, ["param1"] = 141, ["z"] = 14, ["name"] = "stones:arch"}, {["x"] = 3, ["param2"] = 1, ["y"] = 5, ["param1"] = 125, ["z"] = 15, ["name"] = "stones:arch"}, {["x"] = 3, ["y"] = 5, ["param1"] = 110, ["z"] = 16, ["name"] = "stones:rock"}, {["x"] = 3, ["param2"] = 9, ["y"] = 6, ["param1"] = 158, ["z"] = 12, ["name"] = "stones:s_52u"}, {["x"] = 3, ["y"] = 6, ["param1"] = 141, ["z"] = 13, ["name"] = "stones:rock"}, {["x"] = 3, ["y"] = 6, ["param1"] = 126, ["z"] = 14, ["name"] = "stones:rock"}, {["x"] = 3, ["y"] = 6, ["param1"] = 110, ["z"] = 15, ["name"] = "stones:rock"}, {["x"] = 3, ["y"] = 6, ["param1"] = 94, ["z"] = 16, ["name"] = "stones:rock"}, {["x"] = 3, ["y"] = 8, ["param1"] = 110, ["z"] = 13, ["name"] = "stones:rock"}, {["x"] = 3, ["y"] = 8, ["param1"] = 62, ["z"] = 16, ["name"] = "stones:rock"}, {["x"] = 3, ["y"] = 10, ["param1"] = 78, ["z"] = 13, ["name"] = "stones:rock"}, {["x"] = 3, ["y"] = 10, ["param1"] = 30, ["z"] = 16, ["name"] = "stones:rock"}, {["x"] = 4, ["y"] = 0, ["param1"] = 30, ["z"] = 0, ["name"] = "stones:rock"}, {["x"] = 4, ["param2"] = 16, ["y"] = 0, ["param1"] = 172, ["z"] = 9, ["name"] = "stones:s_52u"}, {["x"] = 4, ["param2"] = 4, ["y"] = 0, ["param1"] = 188, ["z"] = 10, ["name"] = "stones:s_52"}, {["x"] = 4, ["param2"] = 10, ["y"] = 0, ["param1"] = 204, ["z"] = 11, ["name"] = "stones:s_52"}, {["x"] = 4, ["param2"] = 5, ["y"] = 0, ["param1"] = 187, ["z"] = 12, ["name"] = "stones:s_2"}, {["x"] = 4, ["y"] = 0, ["param1"] = 109, ["z"] = 17, ["name"] = "stones:rock"}, {["x"] = 4, ["param2"] = 3, ["y"] = 0, ["param1"] = 94, ["z"] = 18, ["name"] = "stones:diagsteps_13"}, {["x"] = 4, ["param2"] = 13, ["y"] = 1, ["param1"] = 14, ["z"] = 0, ["name"] = "stones:estruk"}, {["x"] = 4, ["param2"] = 12, ["y"] = 1, ["param1"] = 124, ["z"] = 7, ["name"] = "stones:arch"}, {["x"] = 4, ["param2"] = 16, ["y"] = 1, ["param1"] = 156, ["z"] = 9, ["name"] = "stones:s_52u"}, {["x"] = 4, ["param2"] = 3, ["y"] = 1, ["param1"] = 172, ["z"] = 10, ["name"] = "stones:arch"}, {["x"] = 4, ["param2"] = 1, ["y"] = 1, ["param1"] = 188, ["z"] = 11, ["name"] = "stones:arch"}, {["x"] = 4, ["param2"] = 5, ["y"] = 1, ["param1"] = 171, ["z"] = 12, ["name"] = "stones:s_2"}, {["x"] = 4, ["y"] = 1, ["param1"] = 94, ["z"] = 17, ["name"] = "stones:rock"}, {["x"] = 4, ["param2"] = 20, ["y"] = 2, ["param1"] = 78, ["z"] = 4, ["name"] = "stones:s_52u"}, {["x"] = 4, ["y"] = 2, ["param1"] = 93, ["z"] = 5, ["name"] = "stones:rock"}, {["x"] = 4, ["y"] = 2, ["param1"] = 109, ["z"] = 6, ["name"] = "stones:rock"}, {["x"] = 4, ["y"] = 2, ["param1"] = 125, ["z"] = 7, ["name"] = "stones:rock"}, {["x"] = 4, ["y"] = 2, ["param1"] = 141, ["z"] = 8, ["name"] = "stones:rock"}, {["x"] = 4, ["param2"] = 1, ["y"] = 2, ["param1"] = 157, ["z"] = 9, ["name"] = "stones:brushrock_5"}, {["x"] = 4, ["param2"] = 3, ["y"] = 2, ["param1"] = 173, ["z"] = 10, ["name"] = "stones:brush"}, {["x"] = 4, ["param2"] = 3, ["y"] = 2, ["param1"] = 189, ["z"] = 11, ["name"] = "stones:brush"}, {["x"] = 4, ["y"] = 2, ["param1"] = 172, ["z"] = 12, ["name"] = "stones:brushrock_1"}, {["x"] = 4, ["y"] = 2, ["param1"] = 155, ["z"] = 13, ["name"] = "stones:rock"}, {["x"] = 4, ["y"] = 2, ["param1"] = 140, ["z"] = 14, ["name"] = "stones:rock"}, {["x"] = 4, ["y"] = 2, ["param1"] = 125, ["z"] = 15, ["name"] = "stones:rock"}, {["x"] = 4, ["y"] = 2, ["param1"] = 110, ["z"] = 16, ["name"] = "stones:rock"}, {["x"] = 4, ["y"] = 2, ["param1"] = 94, ["z"] = 17, ["name"] = "stones:rock"}, {["x"] = 4, ["param2"] = 9, ["y"] = 3, ["param1"] = 110, ["z"] = 5, ["name"] = "stones:panel"}, {["x"] = 4, ["param2"] = 14, ["y"] = 3, ["param1"] = 126, ["z"] = 6, ["name"] = "stones:diagsteps"}, {["x"] = 4, ["param2"] = 11, ["y"] = 3, ["param1"] = 142, ["z"] = 7, ["name"] = "stones:stair_2"}, {["x"] = 4, ["param2"] = 4, ["y"] = 3, ["param1"] = 190, ["z"] = 10, ["name"] = "stones:shrub"}, {["x"] = 4, ["y"] = 3, ["param1"] = 172, ["z"] = 13, ["name"] = "stones:rock"}, {["x"] = 4, ["y"] = 3, ["param1"] = 126, ["z"] = 16, ["name"] = "stones:rock"}, {["x"] = 4, ["param2"] = 8, ["y"] = 4, ["param1"] = 126, ["z"] = 5, ["name"] = "stones:s_52ur"}, {["x"] = 4, ["param2"] = 4, ["y"] = 4, ["param1"] = 142, ["z"] = 6, ["name"] = "stones:stair_half_l"}, {["x"] = 4, ["param2"] = 11, ["y"] = 4, ["param1"] = 158, ["z"] = 7, ["name"] = "stones:stair_2"}, {["x"] = 4, ["y"] = 4, ["param1"] = 188, ["z"] = 13, ["name"] = "stones:rock"}, {["x"] = 4, ["y"] = 4, ["param1"] = 142, ["z"] = 16, ["name"] = "stones:rock"}, {["x"] = 4, ["param2"] = 16, ["y"] = 5, ["param1"] = 94, ["z"] = 4, ["name"] = "stones:s_52"}, {["x"] = 4, ["param2"] = 16, ["y"] = 5, ["param1"] = 110, ["z"] = 5, ["name"] = "stones:s_52u"}, {["x"] = 4, ["param2"] = 15, ["y"] = 5, ["param1"] = 126, ["z"] = 6, ["name"] = "stones:stair_2"}, {["x"] = 4, ["param2"] = 12, ["y"] = 5, ["param1"] = 142, ["z"] = 7, ["name"] = "stones:stair_7"}, {["x"] = 4, ["param2"] = 6, ["y"] = 5, ["param1"] = 158, ["z"] = 8, ["name"] = "stones:s_52l"}, {["x"] = 4, ["y"] = 5, ["param1"] = 172, ["z"] = 13, ["name"] = "stones:rock"}, {["x"] = 4, ["param2"] = 3, ["y"] = 5, ["param1"] = 157, ["z"] = 14, ["name"] = "stones:arch"}, {["x"] = 4, ["param2"] = 1, ["y"] = 5, ["param1"] = 142, ["z"] = 15, ["name"] = "stones:arch"}, {["x"] = 4, ["y"] = 5, ["param1"] = 126, ["z"] = 16, ["name"] = "stones:rock"}, {["x"] = 4, ["y"] = 6, ["param1"] = 126, ["z"] = 7, ["name"] = "stones:s_52r"}, {["x"] = 4, ["y"] = 6, ["param1"] = 142, ["z"] = 8, ["name"] = "stones:s_52ur"}, {["x"] = 4, ["param2"] = 16, ["y"] = 6, ["param1"] = 158, ["z"] = 9, ["name"] = "stones:roch"}, {["x"] = 4, ["param2"] = 16, ["y"] = 6, ["param1"] = 174, ["z"] = 10, ["name"] = "stones:roch"}, {["x"] = 4, ["param2"] = 16, ["y"] = 6, ["param1"] = 190, ["z"] = 11, ["name"] = "stones:s_52u"}, {["x"] = 4, ["y"] = 6, ["param1"] = 174, ["z"] = 12, ["name"] = "stones:rock"}, {["x"] = 4, ["param2"] = 4, ["y"] = 6, ["param1"] = 157, ["z"] = 13, ["name"] = "stones:rock"}, {["x"] = 4, ["y"] = 6, ["param1"] = 141, ["z"] = 14, ["name"] = "stones:rock"}, {["x"] = 4, ["y"] = 6, ["param1"] = 126, ["z"] = 15, ["name"] = "stones:rock"}, {["x"] = 4, ["y"] = 6, ["param1"] = 110, ["z"] = 16, ["name"] = "stones:rock"}, {["x"] = 4, ["y"] = 7, ["param1"] = 142, ["z"] = 13, ["name"] = "stones:rock"}, {["x"] = 4, ["y"] = 7, ["param1"] = 94, ["z"] = 16, ["name"] = "stones:rock"}, {["x"] = 4, ["y"] = 8, ["param1"] = 126, ["z"] = 13, ["name"] = "stones:rock"}, {["x"] = 4, ["y"] = 8, ["param1"] = 78, ["z"] = 16, ["name"] = "stones:rock"}, {["x"] = 4, ["y"] = 9, ["param1"] = 110, ["z"] = 13, ["name"] = "stones:rock"}, {["x"] = 4, ["y"] = 9, ["param1"] = 62, ["z"] = 16, ["name"] = "stones:rock"}, {["x"] = 4, ["y"] = 10, ["param1"] = 94, ["z"] = 13, ["name"] = "stones:rock"}, {["x"] = 4, ["y"] = 10, ["param1"] = 78, ["z"] = 14, ["name"] = "stones:rock"}, {["x"] = 4, ["y"] = 10, ["param1"] = 62, ["z"] = 15, ["name"] = "stones:rock"}, {["x"] = 4, ["y"] = 10, ["param1"] = 46, ["z"] = 16, ["name"] = "stones:rock"}, {["x"] = 5, ["y"] = 0, ["param1"] = 46, ["z"] = 0, ["name"] = "stones:rock"}, {["x"] = 5, ["y"] = 0, ["param1"] = 155, ["z"] = 7, ["name"] = "stones:rock"}, {["x"] = 5, ["y"] = 0, ["param1"] = 187, ["z"] = 9, ["name"] = "stones:rock"}, {["x"] = 5, ["param2"] = 2, ["y"] = 0, ["param1"] = 204, ["z"] = 10, ["name"] = "stones:stair_7"}, {["x"] = 5, ["param2"] = 1, ["y"] = 0, ["param1"] = 221, ["z"] = 11, ["name"] = "stones:stair_7"}, {["x"] = 5, ["y"] = 0, ["param1"] = 204, ["z"] = 12, ["name"] = "stones:rock"}, {["x"] = 5, ["y"] = 0, ["param1"] = 188, ["z"] = 13, ["name"] = "stones:rock"}, {["x"] = 5, ["param2"] = 13, ["y"] = 1, ["param1"] = 30, ["z"] = 0, ["name"] = "stones:estruk"}, {["x"] = 5, ["y"] = 1, ["param1"] = 139, ["z"] = 7, ["name"] = "stones:rock"}, {["x"] = 5, ["y"] = 1, ["param1"] = 172, ["z"] = 9, ["name"] = "stones:rock"}, {["x"] = 5, ["param2"] = 6, ["y"] = 1, ["param1"] = 187, ["z"] = 10, ["name"] = "stones:stair_7"}, {["x"] = 5, ["param2"] = 9, ["y"] = 1, ["param1"] = 204, ["z"] = 11, ["name"] = "stones:stair_7"}, {["x"] = 5, ["y"] = 1, ["param1"] = 187, ["z"] = 12, ["name"] = "stones:rock"}, {["x"] = 5, ["y"] = 1, ["param1"] = 172, ["z"] = 13, ["name"] = "stones:rock"}, {["x"] = 5, ["y"] = 1, ["param1"] = 110, ["z"] = 17, ["name"] = "stones:arch"}, {["x"] = 5, ["param2"] = 20, ["y"] = 2, ["param1"] = 93, ["z"] = 4, ["name"] = "stones:s_52u"}, {["x"] = 5, ["y"] = 2, ["param1"] = 108, ["z"] = 5, ["name"] = "stones:rock"}, {["x"] = 5, ["y"] = 2, ["param1"] = 124, ["z"] = 6, ["name"] = "stones:rock"}, {["x"] = 5, ["y"] = 2, ["param1"] = 140, ["z"] = 7, ["name"] = "stones:rock"}, {["x"] = 5, ["y"] = 2, ["param1"] = 157, ["z"] = 8, ["name"] = "stones:rock"}, {["x"] = 5, ["param2"] = 3, ["y"] = 2, ["param1"] = 173, ["z"] = 9, ["name"] = "stones:brush"}, {["x"] = 5, ["param2"] = 3, ["y"] = 2, ["param1"] = 188, ["z"] = 10, ["name"] = "stones:brush"}, {["x"] = 5, ["y"] = 2, ["param1"] = 204, ["z"] = 11, ["name"] = "stones:rock"}, {["x"] = 5, ["param2"] = 3, ["y"] = 2, ["param1"] = 187, ["z"] = 12, ["name"] = "stones:brush"}, {["x"] = 5, ["y"] = 2, ["param1"] = 172, ["z"] = 13, ["name"] = "stones:brushrock_1"}, {["x"] = 5, ["y"] = 2, ["param1"] = 157, ["z"] = 14, ["name"] = "stones:rock"}, {["x"] = 5, ["y"] = 2, ["param1"] = 142, ["z"] = 15, ["name"] = "stones:rock"}, {["x"] = 5, ["y"] = 2, ["param1"] = 110, ["z"] = 17, ["name"] = "stones:rock"}, {["x"] = 5, ["param2"] = 8, ["y"] = 3, ["param1"] = 157, ["z"] = 7, ["name"] = "stones:roch"}, {["x"] = 5, ["param2"] = 3, ["y"] = 3, ["param1"] = 221, ["z"] = 11, ["name"] = "stones:iso54"}, {["x"] = 5, ["param2"] = 4, ["y"] = 3, ["param1"] = 204, ["z"] = 12, ["name"] = "stones:shrub"}, {["x"] = 5, ["param2"] = 9, ["y"] = 4, ["param1"] = 173, ["z"] = 7, ["name"] = "stones:panel"}, {["x"] = 5, ["param2"] = 3, ["y"] = 4, ["param1"] = 238, ["z"] = 11, ["name"] = "stones:isokar"}, {["x"] = 5, ["param2"] = 16, ["y"] = 5, ["param1"] = 78, ["z"] = 2, ["name"] = "stones:s_52"}, {["x"] = 5, ["param2"] = 14, ["y"] = 5, ["param1"] = 94, ["z"] = 3, ["name"] = "stones:sku"}, {["x"] = 5, ["param2"] = 14, ["y"] = 5, ["param1"] = 110, ["z"] = 4, ["name"] = "stones:s_52"}, {["x"] = 5, ["param2"] = 11, ["y"] = 5, ["param1"] = 126, ["z"] = 5, ["name"] = "stones:s_52u"}, {["x"] = 5, ["param2"] = 23, ["y"] = 5, ["param1"] = 142, ["z"] = 6, ["name"] = "stones:diagsteps"}, {["x"] = 5, ["param2"] = 8, ["y"] = 5, ["param1"] = 157, ["z"] = 7, ["name"] = "stones:stair_2"}, {["x"] = 5, ["param2"] = 6, ["y"] = 5, ["param1"] = 174, ["z"] = 8, ["name"] = "stones:s_52"}, {["x"] = 5, ["param2"] = 23, ["y"] = 5, ["param1"] = 221, ["z"] = 11, ["name"] = "stones:iso54"}, {["x"] = 5, ["y"] = 5, ["param1"] = 189, ["z"] = 13, ["name"] = "stones:arch"}, {["x"] = 5, ["y"] = 6, ["param1"] = 142, ["z"] = 7, ["name"] = "stones:s_52"}, {["x"] = 5, ["y"] = 6, ["param1"] = 158, ["z"] = 8, ["name"] = "stones:s_52u"}, {["x"] = 5, ["y"] = 6, ["param1"] = 174, ["z"] = 9, ["name"] = "stones:rock"}, {["x"] = 5, ["y"] = 6, ["param1"] = 190, ["z"] = 10, ["name"] = "stones:rock"}, {["x"] = 5, ["y"] = 6, ["param1"] = 206, ["z"] = 11, ["name"] = "stones:rock"}, {["x"] = 5, ["y"] = 6, ["param1"] = 190, ["z"] = 12, ["name"] = "stones:rock"}, {["x"] = 5, ["y"] = 6, ["param1"] = 174, ["z"] = 13, ["name"] = "stones:rock"}, {["x"] = 5, ["param2"] = 8, ["y"] = 6, ["param1"] = 158, ["z"] = 14, ["name"] = "stones:arch"}, {["x"] = 6, ["y"] = 0, ["param1"] = 30, ["z"] = 0, ["name"] = "stones:rock"}, {["x"] = 6, ["y"] = 0, ["param1"] = 93, ["z"] = 4, ["name"] = "stones:rock"}, {["x"] = 6, ["y"] = 0, ["param1"] = 139, ["z"] = 7, ["name"] = "stones:rock"}, {["x"] = 6, ["param2"] = 12, ["y"] = 0, ["param1"] = 172, ["z"] = 9, ["name"] = "stones:s_52u"}, {["x"] = 6, ["y"] = 0, ["param1"] = 3, ["z"] = 10, ["name"] = "stones:rubble"}, {["x"] = 6, ["param2"] = 3, ["y"] = 0, ["param1"] = 238, ["z"] = 11, ["name"] = "stones:octa"}, {["x"] = 6, ["y"] = 0, ["param1"] = 3, ["z"] = 12, ["name"] = "stones:rubble"}, {["x"] = 6, ["param2"] = 14, ["y"] = 0, ["param1"] = 172, ["z"] = 13, ["name"] = "stones:s_2"}, {["x"] = 6, ["y"] = 1, ["param1"] = 14, ["z"] = 0, ["name"] = "stones:rock"}, {["x"] = 6, ["param2"] = 3, ["y"] = 1, ["param1"] = 30, ["z"] = 1, ["name"] = "stones:arch"}, {["x"] = 6, ["param2"] = 1, ["y"] = 1, ["param1"] = 62, ["z"] = 3, ["name"] = "stones:arch"}, {["x"] = 6, ["y"] = 1, ["param1"] = 77, ["z"] = 4, ["name"] = "stones:rock"}, {["x"] = 6, ["param2"] = 3, ["y"] = 1, ["param1"] = 92, ["z"] = 5, ["name"] = "stones:arch"}, {["x"] = 6, ["param2"] = 1, ["y"] = 1, ["param1"] = 108, ["z"] = 6, ["name"] = "stones:arch"}, {["x"] = 6, ["y"] = 1, ["param1"] = 124, ["z"] = 7, ["name"] = "stones:rock"}, {["x"] = 6, ["param2"] = 12, ["y"] = 1, ["param1"] = 157, ["z"] = 9, ["name"] = "stones:s_52u"}, {["x"] = 6, ["y"] = 1, ["param1"] = 3, ["z"] = 10, ["name"] = "stones:rubble"}, {["x"] = 6, ["y"] = 1, ["param1"] = 3, ["z"] = 11, ["name"] = "stones:rubble"}, {["x"] = 6, ["y"] = 1, ["param1"] = 3, ["z"] = 12, ["name"] = "stones:rubble"}, {["x"] = 6, ["param2"] = 14, ["y"] = 1, ["param1"] = 156, ["z"] = 13, ["name"] = "stones:s_2"}, {["x"] = 6, ["param2"] = 2, ["y"] = 1, ["param1"] = 94, ["z"] = 17, ["name"] = "stones:arch"}, {["x"] = 6, ["y"] = 2, ["param1"] = 14, ["z"] = 0, ["name"] = "stones:rock"}, {["x"] = 6, ["y"] = 2, ["param1"] = 30, ["z"] = 1, ["name"] = "stones:rock"}, {["x"] = 6, ["y"] = 2, ["param1"] = 46, ["z"] = 2, ["name"] = "stones:rock"}, {["x"] = 6, ["y"] = 2, ["param1"] = 62, ["z"] = 3, ["name"] = "stones:rock"}, {["x"] = 6, ["y"] = 2, ["param1"] = 77, ["z"] = 4, ["name"] = "stones:rock"}, {["x"] = 6, ["y"] = 2, ["param1"] = 93, ["z"] = 5, ["name"] = "stones:rock"}, {["x"] = 6, ["y"] = 2, ["param1"] = 109, ["z"] = 6, ["name"] = "stones:rock"}, {["x"] = 6, ["y"] = 2, ["param1"] = 125, ["z"] = 7, ["name"] = "stones:rock"}, {["x"] = 6, ["y"] = 2, ["param1"] = 142, ["z"] = 8, ["name"] = "stones:rock"}, {["x"] = 6, ["param2"] = 2, ["y"] = 2, ["param1"] = 158, ["z"] = 9, ["name"] = "stones:brushrock_2"}, {["x"] = 6, ["y"] = 2, ["param1"] = 173, ["z"] = 10, ["name"] = "stones:brush"}, {["x"] = 6, ["y"] = 2, ["param1"] = 189, ["z"] = 11, ["name"] = "stones:rock"}, {["x"] = 6, ["param2"] = 3, ["y"] = 2, ["param1"] = 172, ["z"] = 12, ["name"] = "stones:brush"}, {["x"] = 6, ["param2"] = 1, ["y"] = 2, ["param1"] = 157, ["z"] = 13, ["name"] = "stones:brushrock_1"}, {["x"] = 6, ["y"] = 2, ["param1"] = 142, ["z"] = 14, ["name"] = "stones:rock"}, {["x"] = 6, ["param2"] = 1, ["y"] = 2, ["param1"] = 126, ["z"] = 15, ["name"] = "stones:rock"}, {["x"] = 6, ["y"] = 2, ["param1"] = 94, ["z"] = 17, ["name"] = "stones:rock"}, {["x"] = 6, ["y"] = 3, ["param1"] = 30, ["z"] = 0, ["name"] = "stones:rock"}, {["x"] = 6, ["y"] = 3, ["param1"] = 46, ["z"] = 1, ["name"] = "stones:rock"}, {["x"] = 6, ["y"] = 3, ["param1"] = 62, ["z"] = 2, ["name"] = "stones:rock"}, {["x"] = 6, ["y"] = 3, ["param1"] = 78, ["z"] = 3, ["name"] = "stones:rock"}, {["x"] = 6, ["y"] = 3, ["param1"] = 94, ["z"] = 4, ["name"] = "stones:rock"}, {["x"] = 6, ["y"] = 3, ["param1"] = 110, ["z"] = 5, ["name"] = "stones:rock"}, {["x"] = 6, ["param2"] = 7, ["y"] = 3, ["param1"] = 142, ["z"] = 7, ["name"] = "stones:s_52u"}, {["x"] = 6, ["param2"] = 4, ["y"] = 3, ["param1"] = 189, ["z"] = 12, ["name"] = "stones:shrub"}, {["x"] = 6, ["y"] = 3, ["param1"] = 142, ["z"] = 15, ["name"] = "stones:iso54"}, {["x"] = 6, ["y"] = 4, ["param1"] = 46, ["z"] = 0, ["name"] = "stones:rock"}, {["x"] = 6, ["y"] = 4, ["param1"] = 62, ["z"] = 1, ["name"] = "stones:rock"}, {["x"] = 6, ["y"] = 4, ["param1"] = 94, ["z"] = 3, ["name"] = "stones:rock"}, {["x"] = 6, ["y"] = 4, ["param1"] = 110, ["z"] = 4, ["name"] = "stones:rock"}, {["x"] = 6, ["y"] = 4, ["param1"] = 126, ["z"] = 5, ["name"] = "stones:rock"}, {["x"] = 6, ["param2"] = 7, ["y"] = 4, ["param1"] = 158, ["z"] = 7, ["name"] = "stones:s_52u"}, {["x"] = 6, ["y"] = 4, ["param1"] = 158, ["z"] = 15, ["name"] = "stones:estamp"}, {["x"] = 6, ["y"] = 5, ["param1"] = 30, ["z"] = 0, ["name"] = "stones:rock"}, {["x"] = 6, ["y"] = 5, ["param1"] = 46, ["z"] = 1, ["name"] = "stones:rock"}, {["x"] = 6, ["y"] = 5, ["param1"] = 62, ["z"] = 2, ["name"] = "stones:rock"}, {["x"] = 6, ["y"] = 5, ["param1"] = 78, ["z"] = 3, ["name"] = "stones:rock"}, {["x"] = 6, ["y"] = 5, ["param1"] = 94, ["z"] = 4, ["name"] = "stones:rock"}, {["x"] = 6, ["y"] = 5, ["param1"] = 110, ["z"] = 5, ["name"] = "stones:rock"}, {["x"] = 6, ["y"] = 5, ["param1"] = 126, ["z"] = 6, ["name"] = "stones:rock"}, {["x"] = 6, ["param2"] = 7, ["y"] = 5, ["param1"] = 142, ["z"] = 7, ["name"] = "stones:s_52u"}, {["x"] = 6, ["param2"] = 12, ["y"] = 6, ["param1"] = 174, ["z"] = 10, ["name"] = "stones:s_52"}, {["x"] = 6, ["param2"] = 12, ["y"] = 6, ["param1"] = 190, ["z"] = 11, ["name"] = "stones:s_52u"}, {["x"] = 6, ["param2"] = 4, ["y"] = 6, ["param1"] = 174, ["z"] = 12, ["name"] = "stones:rock"}, {["x"] = 6, ["param2"] = 20, ["y"] = 6, ["param1"] = 158, ["z"] = 13, ["name"] = "runes:hui"}, {["x"] = 7, ["y"] = 0, ["param1"] = 110, ["z"] = 4, ["name"] = "stones:rock"}, {["x"] = 7, ["param2"] = 11, ["y"] = 0, ["param1"] = 156, ["z"] = 7, ["name"] = "stones:s_2"}, {["x"] = 7, ["y"] = 0, ["param1"] = 126, ["z"] = 17, ["name"] = "stones:rock"}, {["x"] = 7, ["y"] = 1, ["param1"] = 94, ["z"] = 4, ["name"] = "stones:rock"}, {["x"] = 7, ["param2"] = 11, ["y"] = 1, ["param1"] = 141, ["z"] = 7, ["name"] = "stones:s_2"}, {["x"] = 7, ["y"] = 1, ["param1"] = 110, ["z"] = 17, ["name"] = "stones:rock"}, {["x"] = 7, ["y"] = 2, ["param1"] = 78, ["z"] = 4, ["name"] = "stones:rock"}, {["x"] = 7, ["y"] = 2, ["param1"] = 94, ["z"] = 5, ["name"] = "stones:rock"}, {["x"] = 7, ["y"] = 2, ["param1"] = 110, ["z"] = 6, ["name"] = "stones:rock"}, {["x"] = 7, ["y"] = 2, ["param1"] = 126, ["z"] = 7, ["name"] = "stones:rock"}, {["x"] = 7, ["y"] = 2, ["param1"] = 142, ["z"] = 8, ["name"] = "stones:rock"}, {["x"] = 7, ["y"] = 2, ["param1"] = 158, ["z"] = 9, ["name"] = "stones:rock"}, {["x"] = 7, ["param2"] = 1, ["y"] = 2, ["param1"] = 174, ["z"] = 10, ["name"] = "stones:rock"}, {["x"] = 7, ["y"] = 2, ["param1"] = 190, ["z"] = 11, ["name"] = "stones:rock"}, {["x"] = 7, ["y"] = 2, ["param1"] = 173, ["z"] = 12, ["name"] = "stones:rock"}, {["x"] = 7, ["y"] = 2, ["param1"] = 157, ["z"] = 13, ["name"] = "stones:rock"}, {["x"] = 7, ["y"] = 2, ["param1"] = 142, ["z"] = 14, ["name"] = "stones:rock"}, {["x"] = 7, ["param2"] = 1, ["y"] = 2, ["param1"] = 126, ["z"] = 15, ["name"] = "stones:rock"}, {["x"] = 7, ["param2"] = 4, ["y"] = 2, ["param1"] = 110, ["z"] = 16, ["name"] = "stones:rock"}, {["x"] = 7, ["y"] = 2, ["param1"] = 94, ["z"] = 17, ["name"] = "stones:rock"}, {["x"] = 7, ["param2"] = 2, ["y"] = 5, ["param1"] = 158, ["z"] = 13, ["name"] = "stones:arch"}, {["x"] = 7, ["param2"] = 11, ["y"] = 6, ["param1"] = 158, ["z"] = 12, ["name"] = "stones:s_52u"}, {["x"] = 7, ["y"] = 6, ["param1"] = 142, ["z"] = 13, ["name"] = "stones:rock"}, {["x"] = 8, ["y"] = 0, ["param1"] = 93, ["z"] = 4, ["name"] = "stones:rock"}, {["x"] = 8, ["y"] = 0, ["param1"] = 156, ["z"] = 8, ["name"] = "stones:rock"}, {["x"] = 8, ["y"] = 0, ["param1"] = 171, ["z"] = 13, ["name"] = "stones:rock"}, {["x"] = 8, ["y"] = 1, ["param1"] = 77, ["z"] = 4, ["name"] = "stones:rock"}, {["x"] = 8, ["y"] = 1, ["param1"] = 141, ["z"] = 8, ["name"] = "stones:rock"}, {["x"] = 8, ["y"] = 1, ["param1"] = 156, ["z"] = 13, ["name"] = "stones:rock"}, {["x"] = 8, ["y"] = 2, ["param1"] = 62, ["z"] = 4, ["name"] = "stones:rock"}, {["x"] = 8, ["y"] = 2, ["param1"] = 77, ["z"] = 5, ["name"] = "stones:rock"}, {["x"] = 8, ["y"] = 2, ["param1"] = 93, ["z"] = 6, ["name"] = "stones:rock"}, {["x"] = 8, ["y"] = 2, ["param1"] = 109, ["z"] = 7, ["name"] = "stones:rock"}, {["x"] = 8, ["y"] = 2, ["param1"] = 126, ["z"] = 8, ["name"] = "stones:rock"}, {["x"] = 8, ["y"] = 2, ["param1"] = 141, ["z"] = 13, ["name"] = "stones:rock"}, {["x"] = 8, ["y"] = 2, ["param1"] = 125, ["z"] = 14, ["name"] = "stones:rock"}, {["x"] = 8, ["y"] = 2, ["param1"] = 77, ["z"] = 17, ["name"] = "stones:rock"}, {["x"] = 8, ["y"] = 3, ["param1"] = 142, ["z"] = 13, ["name"] = "stones:rock"}, {["x"] = 8, ["y"] = 3, ["param1"] = 110, ["z"] = 15, ["name"] = "stones:rock"}, {["x"] = 8, ["y"] = 3, ["param1"] = 94, ["z"] = 16, ["name"] = "stones:rock"}, {["x"] = 8, ["y"] = 4, ["param1"] = 158, ["z"] = 13, ["name"] = "stones:rock"}, {["x"] = 8, ["y"] = 4, ["param1"] = 126, ["z"] = 15, ["name"] = "stones:rock"}, {["x"] = 8, ["y"] = 4, ["param1"] = 110, ["z"] = 16, ["name"] = "stones:rock"}, {["x"] = 8, ["y"] = 5, ["param1"] = 142, ["z"] = 13, ["name"] = "stones:rock"}, {["x"] = 8, ["param2"] = 7, ["y"] = 5, ["param1"] = 126, ["z"] = 14, ["name"] = "stones:spircol_8"}, {["x"] = 8, ["y"] = 5, ["param1"] = 110, ["z"] = 15, ["name"] = "stones:rock"}, {["x"] = 8, ["y"] = 5, ["param1"] = 94, ["z"] = 16, ["name"] = "stones:rock"}, {["x"] = 8, ["param2"] = 1, ["y"] = 6, ["param1"] = 126, ["z"] = 9, ["name"] = "stones:cish"}, {["x"] = 8, ["param2"] = 2, ["y"] = 6, ["param1"] = 142, ["z"] = 10, ["name"] = "stones:cish"}, {["x"] = 8, ["param2"] = 11, ["y"] = 6, ["param1"] = 142, ["z"] = 12, ["name"] = "stones:s_52"}, {["x"] = 8, ["y"] = 6, ["param1"] = 126, ["z"] = 13, ["name"] = "stones:rock"}, {["x"] = 8, ["y"] = 6, ["param1"] = 94, ["z"] = 15, ["name"] = "stones:rock"}, {["x"] = 8, ["y"] = 6, ["param1"] = 78, ["z"] = 16, ["name"] = "stones:rock"}, {["x"] = 8, ["param2"] = 1, ["y"] = 7, ["param1"] = 110, ["z"] = 13, ["name"] = "stones:plot"}, {["x"] = 8, ["param2"] = 4, ["y"] = 7, ["param1"] = 94, ["z"] = 14, ["name"] = "stones:spircol_8"}, {["x"] = 8, ["param2"] = 1, ["y"] = 7, ["param1"] = 78, ["z"] = 15, ["name"] = "stones:plot"}, {["x"] = 8, ["param2"] = 4, ["y"] = 8, ["param1"] = 94, ["z"] = 13, ["name"] = "stones:shrub"}, {["x"] = 8, ["param2"] = 4, ["y"] = 8, ["param1"] = 62, ["z"] = 15, ["name"] = "stones:shrub"}, {["x"] = 9, ["param2"] = 3, ["y"] = 2, ["param1"] = 62, ["z"] = 5, ["name"] = "stones:stair_2of3"}, {["x"] = 9, ["param2"] = 3, ["y"] = 2, ["param1"] = 78, ["z"] = 6, ["name"] = "stones:stair_2of3"}, {["x"] = 9, ["param2"] = 3, ["y"] = 2, ["param1"] = 94, ["z"] = 7, ["name"] = "stones:stair_2of3"}, {["x"] = 9, ["y"] = 2, ["param1"] = 110, ["z"] = 14, ["name"] = "stones:rock"}, {["x"] = 9, ["y"] = 2, ["param1"] = 61, ["z"] = 17, ["name"] = "stones:rock"}, {["x"] = 9, ["y"] = 3, ["param1"] = 94, ["z"] = 15, ["name"] = "stones:rock"}, {["x"] = 9, ["y"] = 3, ["param1"] = 78, ["z"] = 16, ["name"] = "stones:rock"}, {["x"] = 9, ["y"] = 4, ["param1"] = 110, ["z"] = 15, ["name"] = "stones:rock"}, {["x"] = 9, ["y"] = 4, ["param1"] = 94, ["z"] = 16, ["name"] = "stones:rock"}, {["x"] = 9, ["y"] = 5, ["param1"] = 94, ["z"] = 15, ["name"] = "stones:rock"}, {["x"] = 9, ["y"] = 5, ["param1"] = 78, ["z"] = 16, ["name"] = "stones:rock"}, {["x"] = 9, ["y"] = 6, ["param1"] = 110, ["z"] = 9, ["name"] = "stones:cish"}, {["x"] = 9, ["param2"] = 3, ["y"] = 6, ["param1"] = 126, ["z"] = 10, ["name"] = "stones:cish"}, {["x"] = 9, ["y"] = 6, ["param1"] = 78, ["z"] = 15, ["name"] = "stones:rock"}, {["x"] = 9, ["y"] = 6, ["param1"] = 62, ["z"] = 16, ["name"] = "stones:rock"}, {["x"] = 10, ["y"] = 0, ["param1"] = 124, ["z"] = 14, ["name"] = "stones:rock"}, {["x"] = 10, ["param2"] = 3, ["y"] = 0, ["param1"] = 75, ["z"] = 17, ["name"] = "stones:spirjoin"}, {["x"] = 10, ["param2"] = 3, ["y"] = 0, ["param1"] = 60, ["z"] = 18, ["name"] = "stones:spircol_8"}, {["x"] = 10, ["y"] = 1, ["param1"] = 109, ["z"] = 14, ["name"] = "stones:rock"}, {["x"] = 10, ["param2"] = 3, ["y"] = 1, ["param1"] = 59, ["z"] = 17, ["name"] = "stones:spirjoin"}, {["x"] = 10, ["param2"] = 3, ["y"] = 1, ["param1"] = 44, ["z"] = 18, ["name"] = "stones:spircol_8"}, {["x"] = 10, ["y"] = 2, ["param1"] = 94, ["z"] = 14, ["name"] = "stones:rock"}, {["x"] = 10, ["y"] = 2, ["param1"] = 78, ["z"] = 15, ["name"] = "stones:rock"}, {["x"] = 10, ["y"] = 2, ["param1"] = 61, ["z"] = 16, ["name"] = "stones:rock"}, {["x"] = 10, ["param2"] = 3, ["y"] = 2, ["param1"] = 44, ["z"] = 17, ["name"] = "stones:spirjoin"}, {["x"] = 10, ["param2"] = 3, ["y"] = 2, ["param1"] = 29, ["z"] = 18, ["name"] = "stones:spircol_8"}, {["x"] = 10, ["param2"] = 3, ["y"] = 3, ["param1"] = 30, ["z"] = 18, ["name"] = "stones:spircol_8"}, {["x"] = 10, ["param2"] = 3, ["y"] = 4, ["param1"] = 46, ["z"] = 18, ["name"] = "stones:spircol_8"}, {["x"] = 10, ["param2"] = 3, ["y"] = 5, ["param1"] = 30, ["z"] = 18, ["name"] = "stones:spircol_8"}, {["x"] = 10, ["param2"] = 3, ["y"] = 6, ["param1"] = 14, ["z"] = 18, ["name"] = "stones:spircol_8"}, {["x"] = 10, ["param2"] = 3, ["y"] = 7, ["param1"] = 14, ["z"] = 18, ["name"] = "stones:spircol_8"}, {["x"] = 10, ["param2"] = 3, ["y"] = 8, ["param1"] = 14, ["z"] = 18, ["name"] = "stones:spircol_8"}, {["x"] = 10, ["param2"] = 3, ["y"] = 9, ["param1"] = 14, ["z"] = 18, ["name"] = "stones:spircol_8"}, {["x"] = 10, ["param2"] = 3, ["y"] = 10, ["param1"] = 14, ["z"] = 18, ["name"] = "stones:spircol_8"}}